Workbook

Sheet Locaçao Mensal
B1: CONTROLE UTILIZAÇÃO CARRO CORPORATIVO LOCAÇÕES MENSAIS - ATIVOS
A3: Legenda
A4: BARREIRAS | D4: NATAL
A5: BRASILIA | D5: RECIFE
A6: GARULHOS | D6: SÃO JOSE DO RIO PRETO
A7: AEROPORTO GOIANIA | D7: SOROCABA
A8: JUAZEIRO | D8: TERESINA
A9: LONDRINA | D9: PIRAJU
A10: PETROLINA | D10: SALVADOR
A11: FORTALEZA
A13: Quant | B13: RETIRADA | C13: PLACA | D13: CARRO | E13: Categoria | F13: DATA SUBS | G13: CARRO SUBS | H13: DATA SUBS2 | I13: CARRO SUBS2 | J13: DATA SUBS4 | K13: CARRO SUBS5 | L13: DATA ENCERRAMENTO | M13: STATUS | N13: USUARIO | O13: Obra | P13: CODIGO | Q13: LOCADORA | R13: LOCAL DE RETIRADA | S13: OBS | T13: KM CONTRATADO
A14: 1 | B14: 44135 | C14: QXA 8199 | D14: DUSTER | E14: Passeio | F14: 44260 | G14: DUSTER QXE 7794 | H14: 44303 | I14: RENEGADE RFW6A64 | M14: ATIVO | N14: ANDRE PLACIDO | O14: PARANAPANEMA | P14: 20022 | Q14: UNIDAS | R14: LONDRINA | S14: Foi entregue um veículo 4x2 devido não ter carro passeio no patio | T14: 6000KM
A15: 2 | B15: 44169 | C15: RFH5G63 | D15: TORO | E15: 4X2 | F15: 44552 | G15: TORO RNX0C53 | M15: ATIVO | N15: RICARDO TORUNSKY | O15: SGG | P15: 20003 | Q15: UNIDAS | R15: RECIFE | S15: Veículo chegou na cidade no final de semana e entrou no parque dia 07/12/ Carro passou para Ricardo em 17/01/2022 | T15: 6000KM
A16: 3 | B16: 44182 | C16: QYE 6085 | D16: TCROSS | E16: 4x2 | F16: 44344 | G16: TCROSS QYS7I76 | M16: ATIVO | N16: NATANAEL GRANGEIRO | O16: SGG | P16: 20003 | Q16: PARVI | R16: RECIFE | S16: Veículo não estava abastecido | T16: 5000KM
A17: 4 | B17: 44188 | C17: QYP3A76 | D17: TCROSS | E17: 4X2 | M17: ATIVO | N17: ALAIN SIQUEIRA | O17: SGG | P17: 20003 | Q17: PARVI | R17: RECIFE | S17: Veículo não estava abastecido | T17: 5000KM
A18: 5 | B18: 44262 | C18: RFY7G67 | D18: S10 | E18: 4X4 | F18: 44529 | G18: S10 RNS0F31 | M18: ATIVO | N18: AUGUSTO JAEGER | O18: SGG | P18: 20003 | Q18: UNIDAS | R18: TERESINA | S18: Veículo foi substituido pelo Marcos, devido a solicitação da Unidas | T18: 6000KM
A19: 6 | B19: 44286 | C19: QYR6C58 | D19: TORO | E19: 4X4 | M19: ATIVO | N19: ROBERTO FERREIRA | O19: SGG | P19: 20003 | Q19: PARVI | R19: RECIFE | S19: Passou para o Roberto em 28/12/2021 | T19: 5000KM
B20: 44293 | C20: RFJ5B90 | D20: RENEGADE | E20: 4X2 | L20: 44680 | M20: INATIVO | N20: JOAO CARLOS | O20: SGG | P20: 20003 | Q20: UNIDAS | R20: BRASILIA | S20: Veículo retirado pelo Iram e entregue no dia 08/04/ Carro passou para Joao em 17/01/2022 | T20: 3000KM
A21: 7 | B21: 44322 | C21: RME5J55 | D21: RENEGADE | E21: 4X2 | F21: 44463 | G21: TCROSS RFM4J87 | M21: ATIVO | N21: WESLEY | O21: SGG | P21: 20003 | Q21: UNIDAS | R21: BRASILIA | S21: Veículo retirado pelo iram e entregue dia 07/05 | T21: 3000KM
A22: 8 | B22: 44323 | C22: RML8I33 | D22: TRACKER | E22: 4X2 | M22: ATIVO | N22: JAMILLE | O22: DESAPROPRIAÇÃO | P22: 19011 | Q22: UNIDAS | R22: JUAZEIRO - BA | T22: 3000KM
A23: 9 | B23: 44332 | C23: RMP4D25 | D23: LOGAN | E23: Passeio | M23: ATIVO | N23: ESEQUIAS | O23: CUMARU | P23: 20013 | Q23: UNIDAS | R23: NATAL
A24: 11 | B24: 44340 | C24: QUD 8801 | D24: DUSTER | E24: 4X2 | F24: 44552 | G24: DUSTER RND2C46 | M24: ATIVO | N24: JOAO CARLOS | O24: SGG | P24: 20003 | Q24: UNIDAS | R24: BRASILIA | S24: Veículo estava com o André e repassado para a Melânia em 15/04 | T24: 3000KM
A25: 12 | B25: 44344 | C25: QYS2C06 | D25: TCROSS | E25: 4X2 | M25: ATIVO | N25: MELANIA | O25: SGG | P25: 20003 | Q25: PARVI | R25: BARREIRAS | S25: Veículo estava com o Jailton e repassado para o João em 27/04 | T25: 5000KM
A26: 13 | B26: 44344 | C26: QYT3B20 | D26: TCROSS | E26: 4X2 | M26: ATIVO | N26: RODRIGO MORILHO | O26: SGG | P26: 20003 | Q26: PARVI | R26: BARREIRAS | T26: 5000KM
A27: 14 | B27: 44345 | C27: QYS3A26 | D27: TCROSS | E27: 4X2 | M27: ATIVO | N27: LUCAS RIBEIRO | O27: SGG | P27: 20003 | Q27: PARVI | R27: BARREIRAS | T27: 5000KM
A28: 15 | B28: 44345 | C28: QYS7J36 | D28: TCROSS | E28: 4X2 | M28: ATIVO | N28: JONATHAN | O28: SGG | P28: 20003 | Q28: PARVI | R28: BARREIRAS | T28: 5000KM
A29: 16 | B29: 44345 | C29: QYS7J86 | D29: TCROSS | E29: 4X2 | M29: ATIVO | N29: MARCO ANTONIO | O29: SGG | P29: 20003 | Q29: PARVI | R29: BARREIRAS | T29: 5000KM
A30: 17 | B30: 44506 | C30: RNY0D96 | D30: S10 | E30: 4X4 | M30: ATIVO | N30: JOELSON | O30: SGG | P30: 20003 | Q30: UNIDAS | R30: TERESINA | S30: Retirado pelo Iram em 06/11 e entregue ao Joelson em 07/11/2021
A31: 18 | B31: 44568 | C31: RFL8J66 | D31: UNO | E31: Passeio | F31: 44575 | G31: ONIX RFZ7I71 | M31: ATIVO | N31: WARLEY | O31: AEROPORTO GOIANIA | P31: 21029 | Q31: UNIDAS | R31: GOIANIA
A32: 19 | B32: 44568 | C32: RFL8500 | D32: UNO | E32: Passeio | F32: 44575 | G32: ARGO RFH6B50 | M32: ATIVO | N32: PEDRO | O32: AEROPORTO GOIANIA | P32: 21029 | Q32: UNIDAS | R32: GOIANIA
A33: 20 | B33: 44573 | C33: RFV6A52 | D33: ONIX | E33: Passeio | F33: 44582 | G33: FORD KA QXV5E41 | H33: 44583 | I33: ARGO RTE1I62 | M33: ATIVO | N33: GLEISON | O33: AEROPORTO GOIANIA | P33: 21029 | Q33: UNIDAS | R33: GOIANIA
A34: 21 | B34: 44578 | C34: RFG4F42 | D34: ARGO | E34: Passeio | M34: ATIVO | N34: RAINOR | O34: AEROPORTO GOIANIA | P34: 21029 | Q34: UNIDAS | R34: GOIANIA
B35: 44591 | C35: RFY5F27 | D35: RENEGADE | E35: 4x2 | L35: 44691 | M35: INATIVO | N35: JANE | O35: TERESINA | P35: 20003 | Q35: UNIDAS | R35: TERESINA
A36: 22 | B36: 44612 | C36: RNB2F48 | D36: RENEGADE | E36: 4X2 | M36: ATIVO | N36: ANNE | O36: AVALIAÇÕES | P36: 22005 | Q36: UNIDAS | R36: RECIFE
A37: 23 | B37: 44621 | C37: RTQ1E09 | D37: HB20 | E37: Passeio | M37: ATIVO | N37: JOSE LEONARDO | O37: AROEIRA | P37: 22006 | Q37: UNIDAS | R37: JUAZEIRO - BA
A38: 24 | B38: 44622 | C38: RFE4D91 | D38: ARGO | E38: Passeio | M38: ATIVO | N38: ADEILSON | O38: AROEIRA | P38: 22006 | Q38: UNIDAS | R38: JUAZEIRO - BA
A39: 25 | B39: 44625 | C39: RNS5H28 | D39: S10 | E39: 4X4 | M39: ATIVO | N39: RAIMUNDO GERSON | O39: LAGOA | P39: 22007 | Q39: UNIDAS | R39: RECIFE | S39: Carro foi retirado por Gerardo e entregue ao Raimundo em 07/03
A40: 26 | B40: 44627 | C40: RT03A77 | D40: C4 | E40: 4X2 | F40: 44679 | G40: RENEGADE RMQ4B22 | M40: ATIVO | N40: THAIS MEDEIROS | O40: LAGOA | P40: 22007 | Q40: UNIDAS | R40: JUAZEIRO - BA
A41: 27 | B41: 44629 | C41: RFK1H13 | D41: RENEGADE | E41: 4x2 | M41: ATIVO | N41: DIOSTENES | O41: AROEIRA | P41: 22006 | Q41: UNIDAS | R41: AEROPORTO SALVADOR | S41: Carro retirado no dia 09/03 pelo Rodrigo e passado para o Diostenes dia 21/03
A42: 28 | B42: 44628 | C42: RNR1J89 | D42: S10 | E42: 4X4 | M42: ATIVO | N42: DOUGLAS BOSCHETTI | O42: AROEIRA | P42: 22006 | Q42: UNIDAS | R42: NATAL PONTA NEGRA
...

Sheet Locação Mensal
A1: GESTÃO DE FROTAS
A2: CONTROLE GERAL DE VEÍCULOS - ATIVOS E INATIVOS
A3: Quant | B3: STATUS | C3: OBRA | D3: CÓDIGO | E3: RETIRADA | F3: USUARIO | G3: LOCAL | H3: PLACA | I3: CARRO | J3: CARRO COM RASTREADOR | K3: CATEGORIA | L3: TESTE FUMAÇA PRETA | M3: DATA TESTE DE FUMAÇA PRETA | N3: LOCADORA | O3: DATA 1ª SUBS | P3: MODELO | Q3: DATA 2ª SUBS | R3: MODELO2 | S3: DATA 3 SUBS | T3: MODELO3 | U3: DATA 4ª SUBS | V3: MODELO4 | W3: DATA 5ª SUBS2 | X3: MODELO6 | Y3: DATA 6ª SUBS22 | Z3: MODELO7 | AA3: DATA ENCERRAMENTO | AB3: KM CONTRATADO | AC3: LOCAL DE RETIRADA | AD3: OBS
A4: 1 | B4: INATIVO | C4: MAPEAMENTO | D4: 22005 | E4: 44323 | F4: RENATA | G4: JUAZEIRO | H4: RML8I33 | I4: TRACKER | J4: SIM | K4: 4X2 | L4: NÃO | M4: NÃO | N4: LOCALIZA | O4: 44895 | P4: TCROSS ENI9F24 | Q4: 44990 | AA4: 45401 | AB4: 3000 | AC4: JUAZEIRO - BA | AD4: Veículo migrado para a Localiza. Repasse para Renata em 24/03/2023. Condutora antiga Jamille. Dia 19/01/2024 Renata repassou o veiculo para Jamille
A5: 2 | B5: INATIVO | C5: GOIANIA | D5: 21029 | E5: 44568 | F5: PEDRO | G5: GOIANIA | H5: RFL8J66 | I5: UNO | J5: NÃO | K5: Passeio | L5: NÃO | M5: NÃO | N5: UNIDAS | O5: 44575 | P5: ONIX RFZ7I71 | Q5: 44798 | R5: ARGO RUM5I29 | S5: 45154 | T5: ARGO RGD4F42 | AA5: 45163 | AB5: 3000 | AC5: GOIANIA
A6: 284 | B6: INATIVO | C6: AUREN | D6: 25001 | E6: 45714 | F6: ALAIN | G6: PONTA NEGRA | H6: TDP1E16 | I6: S10 | J6: SIM | K6: 4X4 | L6: SIM | M6: 46086 | N6: UNIDAS | AA6: 46112 | AB6: 3000 | AC6: PONTA NEGRA - RN | AD6: Uso particular carnaval 28/02 a 05/03/2025
A7: 111. | B7: ATIVO | C7: SUSTENTABILIDADE | D7: 24006 | E7: 45384 | F7: ALIRE CAVALCANTE | G7: SALVADOR | H7: EGK2E03 | I7: TCROSS | J7: SIM | K7: 4X2 | L7: NÃO | M7: NÃO | N7: UNIDAS | O7: 45883 | P7: Tracker TEL5D67 | Q7: 46088 | R7: Tracker TEL2B29 | AB7: 3000 | AC7: SALVADOR - BA
A8: 5 | B8: INATIVO | C8: AROEIRA | D8: 22006 | E8: 44621 | F8: ROBERTA MELO | G8: JUAZEIRO | H8: RTQ1E09 | I8: HB20 | J8: SIM | K8: Passeio | L8: NÃO | M8: NÃO | N8: LOCALIZA | AA8: 45129 | AB8: 3000 | AC8: JUAZEIRO - BA | AD8: Veículo migrado para a Localiza
A9: 6 | B9: INATIVO | C9: LAGOA | D9: 22007 | E9: 44625 | F9: RAIMUNDO GERSON | G9: RECIFE | H9: RNS5H28 | I9: S10 | J9: SIM | K9: 4X4 | L9: NÃO | N9: UNIDAS | O9: 45012 | P9: S10 RVS1B18 | AA9: 45331 | AB9: 6000 | AC9: RECIFE | AD9: Carro foi retirado por Gerardo e entregue ao Raimundo em 07/03
A10: 7 | B10: INATIVO | C10: LAGOA | D10: 22007 | E10: 44627 | F10: CONTIGÊNCIA QUALIDADE | G10: JUAZEIRO | H10: RT03A77 | I10: C4 | J10: SIM | K10: 4X2 | L10: NÃO | M10: NÃO | N10: LOCALIZA | O10: 44679 | P10: RENEGADE RMQ4B22 | Q10: 44946 | R10: RENEGADE RUY6G80 | S10: 44966 | T10: TRACKER RUW4B73 | U10: 44993 | V10: TRACKER RUX6E92 | W10: 45134 | X10: RENEGADE RVF2B30 | Y10: 45141 | Z10: RVH2E00 TRACKER | AA10: 45184 | AB10: 3000 | AC10: JUAZEIRO - BA | AD10: Veículo sofreu sinistro no dia 15/02/2023 e foi retirada um em substituição apenas em 08/03/2023
A11: 8 | B11: INATIVO | C11: AROEIRA | D11: 22006 | E11: 44640 | F11: LUCAS | G11: SALVADOR | H11: RNA2B29 | I11: ARGO | J11: CARRO INATIVO | K11: Passeio | L11: NÃO | M11: NÃO | N11: UNIDAS | O11: 44728 | P11: VOYAGE GBK0J65 | AA11: ?? | AB11: 3000 | AC11: AEROPORTO SALVADOR | AD11: Veículo do George foi entregue no lugar do veículo do Lucas
A12: 9 | B12: INATIVO | C12: AROEIRA | D12: 22006 | E12: 44694 | F12: CAIO / ROBERTA MELO / CHICÃO | G12: SALVADOR | H12: RND2C28 | I12: DUSTER | J12: NÃO | K12: 4X2 | L12: NÃO | M12: NÃO | N12: UNIDAS | O12: 44756 | P12: RENEGADE RUF4J65 | Q12: 45059 | R12: HB20X RNU4G47 | AA12: 45222 | AB12: 4500 | AC12: SALVADOR | AD12: Veículo era do Andre e foi repassado ao Douglas, com saída do Douglas, foi passado ao Caio. DIA 25/09 FOI REPASSADO O CARRO PRA CHICAO
A13: 10 | B13: INATIVO | C13: PROJETOS CEARA | D13: 22004 | E13: 44750 | F13: ROGERIO | G13: FORTALEZA | H13: RFQ0178 | I13: ARGO | J13: NÃO | K13: Passeio | L13: NÃO | M13: NÃO | N13: LOCALIZA | O13: 45240 | P13: ARGO RNF0E22 | AA13: 45162 | AB13: 5000
A14: 11 | B14: INATIVO | C14: MAPEAMENTO | D14: 22005 | E14: 44753 | F14: SUIANNE | G14: RECIFE | H14: RUL4E12 | I14: CRETA | J14: NÃO | K14: 4X2 | L14: NÃO | M14: NÃO | N14: LOCALIZA | O14: 44769 | P14: C4 RNZ1C32 | Q14: 45118 | R14: PULSE SHB4H30 | AA14: 45310 | AB14: 4000 | AC14: RECIFE | AD14: Veiculo utilizado por Anne, repassado para Suianne no dia 23/01/2023
A15: 12 | B15: INATIVO | C15: LAGOA | D15: 22007 | E15: 44758 | F15: PAULO | G15: PICOS | H15: RTA2A27 | I15: RENEGADE | J15: CARRO INATIVO | K15: 4X2 | L15: NÃO | M15: NÃO | N15: LOCALIZA | AA15: 45045 | AB15: 5000 | AC15: PICOS
A16: 13 | B16: INATIVO | C16: LAGOA | D16: 22007 | E16: 44758 | F16: ALDEMIR | G16: SALVADOR | H16: RNU6J01 | I16: S10 | J16: SIM | K16: 4X4 | L16: NÃO | N16: LOCALIZA | O16: 44878 | P16: VOYAGE GBK0J65 | Q16: 44971 | R16: L200 RUK9G41 | AA16: 45142 | AB16: 5000 | AC16: SALVADOR | AD16: Veículo foi repassado para a obra de Lagoa em 14/02/2023
A17: 14 | B17: INATIVO | C17: LAGOA | D17: 22007 | E17: 44758 | F17: VALMIR | G17: PICOS | H17: RGC2G70 | I17: S10 | J17: SIM | K17: 4X4 | L17: NÃO | N17: LOCALIZA | O17: 45213 | P17: C4 RFZ1A35 | Q17: 44855 | R17: RTX9C83 S10 | AA17: 45076 | AB17: 5000 | AC17: PICOS | AD17: Veículo foi entregue em Petrolina, devido a precisar ter sido entregue o carro em Petrolina, impossibilitando a logistica até Picos
A18: 15 | B18: INATIVO | C18: LAGOA | D18: 22007 | E18: 44758 | F18: CLAUDIO AMARAL | G18: PICOS | H18: RFZ3C18 | I18: S10 | J18: SIM | K18: 4X4 | L18: NÃO | N18: LOCALIZA | O18: 44868 | P18: S10 RNY7D61 | Q18: 44946 | R18: RTF5A73 S10 | AA18: 45071 | AB18: 5000 | AC18: PICOS | AD18: Veículo foi entregue em Petrolina, devido a precisar ter sido entregue o carro em Petrolina, impossibilitando a logistica até Picos
A19: 16 | B19: INATIVO | C19: LAGOA | D19: 22007 | E19: 44765 | F19: FABIN | G19: PICOS | H19: RUM5D82 | I19: KICKS | J19: SIM | K19: 4X2 | L19: NÃO | M19: NÃO | N19: LOCALIZA | O19: 44874 | P19: C4 RMT8A08 | AA19: 45110 | AB19: 5000 | AC19: PICOS | AD19: Veículo foi entregue em Petrolina, devido a precisar ter sido entregue o carro em Petrolina, impossibilitando a logistica até Picos. Veículo foi passado para o Fabin, com a saída do Arthur.
A20: 17 | B20: INATIVO | C20: LAGOA | D20: 22007 | E20: 44765 | F20: EIDER BRENO | G20: PICOS | H20: RFY4F46 | I20: RENEGADE | J20: CARRO INATIVO | K20: 4X2 | L20: NÃO | M20: NÃO | N20: LOCALIZA | AA20: 45033 | AB20: 5000 | AC20: PICOS | AD20: Veículo foi entregue em Petrolina, devido a precisar ter sido entregue o carro em Petrolina, impossibilitando a logistica até Picos/ Veículo repasso para o Breno em 14/11/2022
A21: 18 | B21: INATIVO | C21: AROEIRA | D21: 22006 | E21: 44767 | F21: ALIRE | G21: FEIRA DE SANTANA | H21: RUH2D55 | I21: C4 | J21: CARRO INATIVO | K21: 4x2 | L21: NÃO | M21: NÃO | N21: LOCALIZA | AA21: 45033 | AB21: 3000 | AC21: FEIRA DE SANTANA | AD21: Veículo retirado pelo Augusto e Gerardo
A22: 19 | B22: INATIVO | C22: AROEIRA | D22: 22006 | E22: 44767 | F22: ALVARO | G22: FEIRA DE SANTANA | H22: RGC2G78 | I22: S10 | J22: SIM | K22: 4X4 | L22: NÃO | N22: LOCALIZA | O22: 44828 | P22: RUZ0D64 L200 | AA22: 45087 | AB22: 5000 | AC22: FEIRA DE SANTANA | AD22: Veículo retirado pelo Antonio, entregue ao Jose Erivan e em novembro repassado para Rita, CARRO PASSADO PARA ALVARO
A23: 20 | B23: INATIVO | C23: AROEIRA | D23: 22006 | E23: 44769 | F23: GIVALDO | G23: FEIRA DE SANTANA | H23: QWR9447 | I23: S10 | J23: SIM | K23: 4X2 | L23: NÃO | M23: NÃO | N23: LOCALIZA | O23: 44898 | P23: RVD3B25 RENEGADE | AA23: 45068 | AB23: 5000 | AC23: FEIRA DE SANTANA | AD23: Devido a indisponibilidade do veículo do grupo foi entregue um superior
A24: 21 | B24: INATIVO | C24: LAGOA | D24: 22007 | E24: 44779 | F24: NADSON | G24: PICOS | H24: RTN8C48 | I24: RENEGADE | J24: SIM | K24: 4X2 | L24: NÃO | M24: NÃO | N24: LOCALIZA | O24: 44903 | P24: RTN8D64 RENEGADE | Q24: 45010 | R24: RTA4H88 RENEGADE | AA24: 45114 | AB24: 3000 | AC24: PICOS
A25: 22 | B25: INATIVO | C25: AROEIRA | D25: 22006 | E25: 44794 | F25: GEORGE ANUNCIAÇÃO | G25: SALVADOR | H25: RUN6D05 | I25: PEUGEOT | J25: NÃO | K25: Passeio | L25: NÃO | M25: NÃO | N25: LOCALIZA | AA25: 45055 | AB25: 3000 | AC25: SALVADOR | AD25: Veículo passou para George em 29/03/2023
A26: 23 | B26: INATIVO | C26: LAGOA | D26: 22007 | E26: 44807 | F26: KLEBER | G26: SALVADOR | H26: RUO8I29 | I26: HILUX | J26: CARRO INATIVO | K26: 4X4 | L26: NÃO | N26: LOCALIZA | AA26: 45050 | AB26: 5000 | AC26: SALVADOR
A27: 24 | B27: INATIVO | C27: AROEIRA | D27: 22006 | E27: 44810 | F27: MICHEL | G27: PICOS | H27: RTM7E34 | I27: HB20 | J27: SIM | K27: Passeio | L27: NÃO | M27: NÃO | N27: LOCALIZA | O27: 45014 | P27: RUX4D45 HB20 | AA27: 45188 | AB27: 5000 | AC27: PICOS
A28: 25 | B28: INATIVO | C28: LAGOA | D28: 22007 | E28: 44810 | F28: MARCONIS FRANCISCO EDILSON | G28: PICOS | H28: RFZ4B11 | I28: RENEGADE | J28: SIM | K28: 4X2 | L28: NÃO | M28: NÃO | N28: LOCALIZA | O28: 44820 | P28: RENEGADE RNZ5J61 | Q28: 44924 | R28: RENEGADE RUX1H96 | S28: 45097 | T28: RENEGADE SHY2C77 | AA28: 45334 | AB28: 5000 | AC28: PICOS
A29: 26 | B29: INATIVO | C29: LAGOA | D29: 22007 | E29: 44830 | F29: ARLEN | G29: PICOS | H29: RTA2B45 | I29: RENEGADE | J29: NÃO | K29: 4X2 | L29: NÃO | M29: NÃO | N29: LOCALIZA | O29: 44872 | P29: RENEGADE RUX0H17 | AA29: 45069 | AB29: 5000
A30: 27 | B30: INATIVO | C30: AROEIRA | D30: 22006 | E30: 44834 | F30: DEVALDO | G30: FEIRA DE SANTANA | H30: RUH9C37 | I30: CRONOS | J30: SIM | K30: Passeio | L30: NÃO | M30: NÃO | N30: UNIDAS | AA30: 45199 | AB30: 4500 | AC30: FEIRA DE SANTANA | AD30: Veículo foi repassado para o Joao Adriano
A31: 28 | B31: INATIVO | C31: HORIZONTE | D31: 22035 | E31: 44849 | F31: JOSE SANTANA | G31: BARREIRAS | H31: RVA2C75 | I31: ARGO | J31: CARRO INATIVO | K31: Passeio | L31: NÃO | M31: NÃO | N31: LOCALIZA | AA31: 45033 | AB31: 3000 | AC31: BARREIRAS
A32: 29 | B32: INATIVO | C32: HORIZONTE | D32: 22035 | E32: 44851 | F32: ADEMIR | G32: BARREIRAS | H32: RTY9H03 | I32: HB20 | J32: NÃO | K32: Passeio | L32: NÃO | M32: NÃO | N32: LOCALIZA | AA32: 45091 | AB32: 3000 | AC32: BARREIRAS
A33: 30 | B33: INATIVO | C33: AROEIRA | D33: 22006 | E33: 44859 | F33: ANDRE AMARAL | G33: SALVADOR | H33: RUX1I22 | I33: GOL | J33: CARRO INATIVO | K33: Passeio | L33: NÃO | M33: NÃO | N33: UNIDAS | AA33: 45019 | AB33: 4500 | AC33: SALVADOR | AD33: Veículo estava com Maria Luiza e foi devolvido no lugar do veículo do Andre
A34: 31 | B34: INATIVO | C34: AROEIRA | D34: 22006 | E34: 44863 | F34: MARIA LUIZA / GILVALDO | G34: FEIRA DE SANTANA | H34: RUL2D73 | I34: CRONOS | J34: SIM | K34: Passeio | L34: NÃO | M34: NÃO | N34: UNIDAS | AA34: 45103 | AB34: 4500 | AC34: FEIRA DE SANTANA | AD34: Veículo retirado pelo Antonio (Chicão) / Veículo repassado para Maria Luiza em 31/03/2023
A35: 32 | B35: INATIVO | C35: LAGOA | D35: 22007 | E35: 44866 | F35: BRAZ | G35: JUAZEIRO | H35: RFUD7D97 | I35: VIRTUS | J35: SIM | K35: Passeio | L35: NÃO | M35: NÃO | N35: UNIDAS | O35: 44884 | P35: GOL SDX5H38 | AA35: 45133 | AB35: 4500 | AC35: JUAZEIRO - BA
A36: 33 | B36: INATIVO | C36: AROEIRA | D36: 22006 | E36: 44871 | F36: RITA MERCIA / MARIA LUIZA | G36: SALVADOR | H36: RNX9A67 | I36: RENEGADE | J36: SIM | K36: 4X2 | L36: NÃO | M36: NÃO | N36: UNIDAS | O36: 45059 | P36: 208 SHS9A71 | AA36: 45189 | AB36: 4500 | AC36: SALVADOR | AD36: Veículo retirado pelo George, Carro esta sendo utilizado por RITA MERCIA
A37: 34 | B37: INATIVO | C37: LAGOA | D37: 22007 | E37: 44877 | F37: THAIS/ CLAUDIO | G37: PICOS | H37: RUE9A65 | I37: RENEGADE | J37: SIM | K37: 4X2 | L37: NÃO | M37: NÃO | N37: LOCALIZA | O37: 45098 | P37: RENEGADE RNZ5J33 | AA37: 45113 | AB37: 5000 | AC37: PICOS
A38: 35 | B38: INATIVO | C38: LAGOA | D38: 22007 | E38: 44894 | F38: EDILSON /CLAUDIO AMARAL | G38: PICOS | H38: RUY1D37 | I38: RENEGADE | J38: SIM | K38: 4X2 | L38: NÃO | M38: NÃO | N38: LOCALIZA | O38: 45112 | P38: RVH2E00 TRACKER | Q38: 45141 | R38: RENEGADE RVF2B30 | AA38: 45229 | AB38: 5000 | AC38: PICOS
A39: 36 | B39: INATIVO | C39: SGG | D39: 20003 | E39: 44898 | F39: JONATHAN | G39: BARREIRAS | H39: RVL0A39 | I39: TRACKER | J39: NÃO | K39: 4X2 | L39: NÃO | M39: NÃO | N39: LOCALIZA | AA39: 45031 | AB39: 4000 | AC39: BARREIRAS
A40: 37 | B40: INATIVO | C40: HORIZONTE | D40: 22035 | E40: 44905 | F40: SAMIRA | G40: BARREIRAS | H40: RNE0B60 | I40: ARGO | J40: CARRO INATIVO | K40: Passeio | L40: NÃO | M40: NÃO | N40: LOCALIZA | AA40: 45044 | AB40: 3000 | AC40: BARREIRAS
...

Sheet Uso Particular 
C1: Folga / Uso Particular
A2: STATUS | B2: OBRA | C2: CONDUTOR | D2: MODELO | E2: PLACA | F2: USO PARTICULAR | G2: OBSERVAÇÕES
A3: INATIVO | B3: GOIANIA | C3: RAINOR | D3: ARGO | E3: RUM5I29
A4: INATIVO | B4: GOIANIA | C4: GLEISON | D4: ARGO | E4: RTE1I62
A5: INATIVO | B5: RIACHO | C5: ISAAC/UALACE | D5: TCROSS | E5: FZP1E71 | F5: 5
A6: ATIVO | B6: RIACHO | C6: UALACE
A7: ATIVO | B7: RIACHO | C7: ANDRE PLACIDO | D7: ARGO | E7: TDY8E51 | F7: 1
A8: INATIVO | B8: RIACHO | C8: EDNEI | D8: HB20 | E8: TCZ6B67 | F8: 3
A9: ATIVO | B9: RIACHO | C9: CLAUDIO
A10: INATIVO | B10: RIACHO | C10: ANDRE | D10: TCROSS | E10: SVW5E64 | F10: 2
A11: ATIVO | B11: CGN lagoa | C11: JERFFERSON MOREIRA | D11: TCROSS | E11: SUI0E07
A12: ATIVO | B12: CGN russas | C12: ROGERIO | D12: TRACKER | E12: TEU0E62 | F12: 1 | G12: uso não solicitado
A13: INATIVO | B13: CGN russas | C13: ELIOMAR | D13: TCROSS | E13: SIJ3F45 | F13: 1 | G13: Não enviou fotos | H13: RECESSO 2025
A14: ATIVO | B14: CGN russas | C14: ANDRE GADELHA | D14: TCROSS | E14: TYA5C83 | F14: 1
A15: ATIVO | B15: CGN russas | C15: CLEBERSON
A16: ATIVO | B16: ELERA | C16: ROBSON
A17: INATIVO | B17: SUSTENTABILIDADE | C17: LUCIANE
A18: ATIVO | B18: SUSTENTABILIDADE | C18: ALIRE | D18: TRACKER | E18: TEL5D67 | F18: 1
A19: INATIVO | B19: SUSTENTABILIDADE | C19: EUCILENE | D19: RENEGADE | E19: SIG2E45 | F19: 5
A20: INATIVO | B20: SUSTENTABILIDADE | C20: EUCILENE | D20: TCROSS | E20: SUO8H64 | F20: 3 | G20: Ocorrencia de avarias
A21: INATIVO | B21: STATKRAFT mdc | C21: GEFERSON
A22: INATIVO | B22: STATKRAFT mdc | C22: JOAO CARLOS
A23: INATIVO | B23: STATKRAFT mdc | C23: ANA PAULA
A24: INATIVO | B24: STATKRAFT vse | C24: FRANCISCO AUGUSTO | D24: TCROSS | E24: EJA1H12 | F24: 1 | G24: falta de informação | H24: RECESSO 2025
A25: ATIVO | B25: STATKRAFT vse | C25: FRANCISCO AUGUSTO | D25: CRETA | E25: TXZ1G58 | F25: 2 | G25: uso não solicitado
A26: ATIVO | B26: STATKRAFT vse | C26: JURANDIR
A27: INATIVO | B27: STATKRAFT vse | C27: JHONNY
A28: INATIVO | B28: STATKRAFT vse | C28: NILBERTO | D28: TCROSS | E28: TKX8G73 | F28: 3 | G28: uso não solicitado
A29: INATIVO | B29: STATKRAFT vse | C29: ANA LUIZA
A30: ATIVO | B30: STATKRAFT vse | C30: ANA CAROLINE | D30: TCROSS | E30: TJE8B31 | F30: 2
A31: ATIVO | B31: STATKRAFT vse | C31: RONIERI | D31: TCROSS | E31: TJR5F89 | F31: 2 | G31: pendente envio retorno | H31: RECESSO 2025
A32: INATIVO | B32: STATKRAFT vse | C32: WASHINGTON | D32: TCROSS | E32: FFW5H24 | F32: 1
A33: INATIVO | B33: STATKRAFT vse | C33: FRANCISCO DE MORAIS | D33: TCROSS | E33: SWD0G64 | F33: 1 | H33: RECESSO 2025
A34: ATIVO | B34: STATKRAFT vse | C34: FRANCISCO DE MORAIS | D34: CRETA | E34: TXW4I69 | F34: 1 | G34: uso não solicitado
A35: ATIVO | B35: STATKRAFT vse | C35: ERIC
A36: INATIVO | B36: STATKRAFT vse | C36: JAIR | D36: TRACKER | E36: TEL5D17 | F36: 1 | G36: envio atrasado e não seguiu orientação de troca de veículo | H36: RECESSO 2025
A37: INATIVO | B37: STATKRAFT rsh | C37: FRANCISCO IRANILDO | D37: TCROSS | E37: SWH5H35 | F37: 1
A38: ATIVO | B38: STATKRAFT vse | C38: LUIS DALADIUER | D38: RENEGADE | E38: TXL2A88 | F38: 1 | G38: pendente envio retorno
A39: ATIVO | B39: STATKRAFT rsh | C39: IZADORA | D39: CRETA | E39: TXB9I08 | F39: 3 | G39: pendente envio retorno | H39: RECESSO 2025
A40: ATIVO | B40: STATKRAFT rsh | C40: GEFERSON | D40: TRACKER | E40: TEU0E78 | F40: 7 | G40: Uso não solicitado | H40: RECESSO 2025
...

Sheet Valor Mensal - Faturas
B1: PLANILHA DE VEÍCULOS ATIVOS
A2: OBRA | B2: CONDUTOR | C2: MODELO | D2: PLACA | E2: KM | F2: CONTRATADO | G2: FATURA | H2: LOCADORA | I2: EXTRAS | J2: OBSERVAÇÕES
A3: LAGOA | B3: RAIMUNDO GERSON | C3: S10 | D3: RVS1B18 | E3: 6000 | F3: 7434 | H3: Unidas | I3: nenhuma | J3: Desmobilizado 09/02/2024
A4: LAGOA | B4: CONTINGÊNCIA QUALIDADE | C4: TRACKER | D4: RVH2E00 | E4: 3000 | F4: 3467.99 | H4: Localiza | I4: nenhuma | J4: Desmobilizado 15/09
A5: LAGOA | B5: CLAUDIO | C5: RENEGADE | D5: RVF2B30 | E5: 3000 | F5: 3476.26 | H5: Localiza | I5: nenhuma | J5: Desmobilizado 30/10
A6: LAGOA | B6: MATHEUS MIRANDA | C6: RENEGADE | D6: RVI1H11 | E6: 5000 | F6: 3952.03 | H6: Localiza | I6: nenhuma | J6: Desmobilizado 28/12
A7: LAGOA | B7: FRANCISCO EDILSON | C7: RENEGADE | D7: SHY2C77 | E7: 5000 | F7: 3145.99 | H7: Localiza | I7: nenhuma | J7: Desmobilizado 12/02/2024
A8: LAGOA | B8: ANTONIO VAGNER | C8: RENEGADE | D8: SIG2E24 | E8: 6000 | F8: 3775.99 | H8: Unidas | I8: nenhuma | J8: Desmobilizado 08/04/2024
A9: LAGOA | B9: FABIO SIQUEIRA | C9: RENEGADE | D9: RNX9A52 | E9: 6000 | F9: 3775.99 | H9: Unidas | I9: nenhuma | J9: Desmobilizado 14/02/2024
A10: CAJUÍNAS | B10: ALAIN | C10: S10 | D10: TDP1E16 | E10: 3000 | F10: 7553 | G10: 7553 | H10: Unidas
A11: LAGOA | B11: IRMA MACEDO | C11: PULSE | D11: SDW7B57 | E11: 4500 | F11: 3455.99 | H11: Unidas | I11: nenhuma | J11: Desmobilizado 01/11
A12: AROEIRA | B12: ANTONIO (CHICÃO) | C12: HB20X | D12: RNU4G47 | E12: 3000 | F12: 2986 | H12: Unidas | I12: com proteção de vidros | J12: Desmobilizado 23/10
A13: AROEIRA | B13: MICHEL | C13: HB20 | D13: RUX4D45 | E13: x | F13: 2169.99 | H13: Localiza | I13: nenhuma | J13: Desmobilizado 19/09
A14: AROEIRA | B14: DEVALDO | C14: CHRONOS | D14: RUH9C37 | E14: x | F14: 2554 | H14: Unidas | I14: nenhuma | J14: Desmobilizado 30/09
A15: AROEIRA | B15: MARIA LUIZA | C15: 208 | D15: SHS9A71 | E15: x | F15: 2986 | H15: Unidas | I15: nenhuma | J15: Desmobilizado 20/09
A16: AROEIRA | B16: JONATHAN | C16: 208 | D16: RT05B73 | E16: 4500 | F16: 2741 | H16: Unidas | I16: nenhuma | J16: Desmobilizado 05/01/2024
A17: AROEIRA | B17: ANTÔNIO (CHICÃO) | C17: ONIX | D17: SHQ9B43 | E17: x | F17: 2473.97 | H17: Localiza | I17: nenhuma | J17: Desmobilizado 16/09
A18: ENG AGRONOMO | B18: GUSTAVO | C18: TRACKER | D18: SIM2I94 | E18: 3000 | F18: 4227 | H18: Localiza | I18: com proteção de vidros e pneus | J18: Desmobilizado 08/06/2024
A19: AROEIRA | B19: ALVARO | C19: ARGO | D19: RVA0H10 | E19: x | F19: 2591.23 | H19: Localiza | I19: nenhuma | J19: Desmobilizado 25/09
A20: CAJUÍNAS | B20: ALVERSON | C20: POLO | D20: TJL7E95 | E20: 3000 | F20: 2484 | G20: 2484 | H20: Unidas
A21: FURNAS ANGRA | B21: MARIO RAIMO | C21: S10 | D21: RNY1D98 | E21: 5000 | F21: 8294.4 | H21: Localiza | I21: nenhuma | J21: Desmobilizado 01/02/2024
A22: CAJUÍNAS | B22: CHRIS | C22: ARGO | D22: TDQ6D38 | E22: 3000 | F22: 2484 | G22: 2484 | H22: Unidas
A23: CAJUÍNAS | B23: EIDER BRENO | C23: ONIX | D23: SJH8E03 | E23: 3000 | F23: 2484 | G23: 2484 | H23: Unidas
A24: CAJUÍNAS | B24: GEOVANI | C24: POLO | D24: SSW2I35 | E24: 3000 | F24: 2484 | G24: 2484 | H24: Unidas
A25: CAJUÍNAS | B25: IDALECIO | C25: POLO | D25: STZ7D92 | E25: 3000 | F25: 2484 | G25: 2484 | H25: Unidas
A26: CAJUÍNAS | B26: MARCILIO | C26: DUSTER | D26: TDJ7G97 | E26: 3000 | F26: 3837 | G26: 3837 | H26: Unidas
A27: CAJUÍNAS | B27: ROBERTO | C27: S10 | D27: UAI4B92 | E27: 4500 | F27: 8158 | G27: 8158 | H27: Unidas
A28: CAJUÍNAS | B28: TIAGO GONÇALVES | C28: S10 | D28: TEZ5D42 | E28: 3000 | F28: 7553 | H28: Unidas
A29: CAJUÍNAS | B29: WILDSON | C29: POLO | D29: TJF8C34 | E29: 3000 | F29: 2484 | H29: Unidas
A30: CAJUÍNAS | B30: UBIRATAN | C30: S10 | D30: TDP1D97 | E30: 3000 | F30: 7553 | H30: Unidas
A31: CGN | B31: ELIOMAR | C31: TCROSS | D31: SIJ3F45 | E31: 5000 | F31: 4335.99 | G31: 4335.99 | H31: Unidas
A32: CGN | B32: JERFFERSON MOREIRA | C32: TCROSS | D32: SUI0E07 | E32: 4500 | F32: 4144 | G32: 4144 | H32: Unidas
A33: CGN | B33: ROGERIO | C33: TCROSS | D33: SVW2F07 | E33: 3000 | F33: 3837 | G33: 3837 | H33: Unidas
A34: GOIANIA | B34: RAINOR | C34: POLO | D34: TJZ9J36 | E34: 3000 | F34: 2484 | G34: 2484 | H34: Unidas
A35: GOIANIA | B35: GLEISON | C35: ARGO | D35: RTE1I62 | E35: 3000 | F35: 2484 | G35: 2484 | H35: Unidas
A36: MAPEAMENTO | B36: RENATA | C36: T-CROSS | D36: ENI9F24 | E36: 3000 | F36: 4191.94 | H36: Localiza | I36: nenhuma | J36: Desmobilizado 19/04/2024
A37: MAPEAMENTO | B37: SUIANE | C37: PULSE | D37: SHB4H30 | E37: 4000 | F37: 3702.72 | H37: Localiza | I37: com proteção de vidros e pneus | J37: Desmobilizado 19/01
A38: MAPEAMENTO | B38: PAULO RICARDO | C38: RENEGADE | D38: SIM9C98 | E38: 4500 | F38: 3455.99 | H38: Unidas | I38: nenhuma | J38: Desmobilizado 22/05/2024
A39: LABORATORIO | B39: LABORATORIO | C39: S10 | D39: SHG4A46 | E39: x | F39: 7434 | H39: Unidas | I39: nenhuma | J39: Desmobilizado 17/10
A40: LABORATORIO | B40: LABORATORIO | C40: S10 | D40: SHG4A45 | E40: x | F40: 7467.8 | H40: Unidas | I40: nenhuma | J40: Desmobilizado 03/10
...

Sheet Obras Diversas - Laboratorio
C1: LABORATÓRIO
A2: DATA DE USO | B2: PLACA | C2: CARRO | D2: TESTE DE FUMAÇA PRETA | E2: DATA SUBST. CARRO | F2: CARRO SUBSTITUIDO | G2: DATA SUBST. CARRO | H2: CARRO SUBSTITUIDO | I2: REBOQUE/TEREZA | J2: USUÁRIO | K2: LOCADORA | L2: OBRA | M2: DESTINO | N2: DATA FINALIZAÇÃO USO | O2: OBS
A3: 42668 | B3: PGS9869 | C3: S10 | E3: - | F3: - | J3: UFV BJ | K3: ACCESS | L3: 16020 | N3: 42669
A4: 42713 | B4: PGS 9869 | C4: S10 | E4: - | F4: - | J4: Carlos/Luis | K4: ACCESS | L4: 16023 | N4: 17.12.2016 | O4: Carro no galpão em 16.12
A5: 42821 | B5: PFY 4358 | C5: S10 | E5: - | F5: - | J5: LUIS | K5: ACCESS | L5: PIRAPORA | N5: 42831 | O5: Carro entregue em 25/03-mais uso a ser considerado a partir de 27/03-Entregue Felipe dia 07/04
A6: 42940 | B6: PGS 9869 | C6: S10 | E6: - | F6: - | J6: VICTOR | K6: ACCESS | L6: PIRAPORA | N6: 42951 | O6: Carro entregue em 24/07 - Retirada no galpão dia 07/08/2017
A7: 43046 | B7: PGS 9869 | C7: S10 | E7: - | F7: - | J7: VICTOR | K7: ACCESS | L7: S.J.BELMONTE | N7: 43052 | O7: Carro entregue em 13/11/2017 por Romero
A8: 43111 | B8: PFY 4358 | C8: 4 X 4 | E8: - | F8: - | I8: PDY6842 | J8: VICTOR | K8: ACCESS | L8: 18001 | M8: GUIMARANEA -MG | N8: 43126 | O8: Carro entregue por Edilson em 10/01 com problema freio de mão, retornou a entrega em 11/01
A9: 43154 | B9: PDA 1177 | C9: AMAROK 4X4 | E9: - | F9: - | J9: VICTOR | K9: ACCESS | L9: 18006 | N9: 43175 | O9: Entregue em 23/03/2018
A10: 43222 | B10: PDJ 2372 | C10: ONIX | E10: - | F10: - | J10: FERNANDA | K10: ACCESS | L10: 18011 | N10: 43224 | O10: Foi trocado dois óleos (aguardando foto) KM:32.119
A11: 43279 | B11: QNF 9482 | C11: ONIX | E11: - | F11: - | J11: VICTOR | K11: LOCALIZA | L11: 18014 | N11: 43279 | O11: Carro entregue Victor.28/06/2018
A12: 43286 | B12: GNI 6925 | C12: PRISMA | E12: - | F12: - | J12: VICTOR | K12: LOCALIZA | L12: 18015 | N12: 43286 | O12: Carro entregue Victor. 05/07/2018
A13: 43296 | B13: PCT 9415 | C13: 4 X 4 | E13: - | F13: - | I13: PDY6842 | J13: VICTOR | K13: ACCESS | L13: 18.016/18.018 e 18.019 | M13: S.JOAO GURGUEIA(PI)- DRACENA(SP) - CEILANDIA(DF) | N13: 43330 | O13: Acrescer uma diaria 12/07 e troca em 18/08/2018
A14: 43299 | B14: PGR 2514 | C14: 4 x 4 | E14: - | F14: - | I14: PDY 6842 | J14: VICTOR | K14: ACCESS | L14: 18017 | M14: SÃO JOAO DO PIAUI - PI | N14: 43363 | O14: Carro saiu em 08/09/2018 e entregue em dia 20/09/2018 e substituido pela S10 de placa PGS 9869 entregue no dia 21/09/2018
A15: 43346 | B15: QOR 2213 | C15: 4 x 2 | E15: - | F15: - | J15: JAMILE | K15: LOCALIZA | L15: 18020 | N15: 43374
A16: 43369 | B16: QMX 2231 | C16: ONIX | E16: - | F16: - | J16: VICTOR | K16: LOCALIZA | L16: 18026 | N16: 43370 | O16: CARRO ENTREGUE POR VARELA
A17: 43377 | B17: QMX 0135 | C17: UNO | E17: - | F17: - | J17: VICTOR | K17: LOCALIZA | L17: 18026 | N17: 43377 | O17: CARRO ENTREGUE POR VICTOR
A18: 43374 | B18: QNE 1560 | C18: S10 | E18: - | F18: - | J18: ANNE | K18: LOCALIZA | L18: 18024 | N18: 43414 | O18: CARRO ENTREGUE POR JAMILE/ANNE
A19: 43374 | B19: PZZ 0552 | C19: S10 | E19: - | F19: - | J19: JAMILE | K19: LOCALIZA | L19: 18024 | N19: 43379 | O19: CARRO ENTREGUE POR ANNE
A20: 43392 | B20: PZP 8902 | C20: S10 | E20: - | F20: - | J20: ALVES | K20: LOCALIZA | L20: 18029 | N20: 43409 | O20: CARRO ENTREGUE POR ALVES
A21: 43396 | B21: PDI 0158 | C21: AMAROK | E21: - | F21: - | I21: PDY 6842 | J21: VICTOR | K21: SUCESSO | L21: 18031 | M21: PEREIRA BARRETO - SP | N21: 43425 | O21: **11/11/2018 chegaram de viagem/ Carrro entregue por Fernanda
A22: 43425 | B22: QPJ 4916 | C22: GOL | E22: - | F22: - | J22: ALVES | K22: LOCALIZA | L22: 18029 | N22: 43430 | O22: CARRO ENTREGUE POR ALVES
A23: 43443 | B23: FKP 7088 | C23: GOL | E23: - | F23: - | J23: VICTOR | K23: LOCALIZA | L23: 18033 | N23: 43445 | O23: CARRO ENTREGUE POR VICTOR
A24: 43588 | B24: QQF 5990 | C24: S10 | I24: PDY 6842 | J24: VICTOR HUGO | K24: UNIDAS | L24: Obra 19.004 | M24: PAULO AFONSO - BA | N24: 43605 | O24: chegou sexta dia 17/05 - 17/05 seguiu conserto
A25: 43592 | B25: QPM 4740 | C25: HILUX | J25: FERNANDA TOLENTINO | K25: UNIDAS | L25: Obra 19.006 | N25: 43599 | O25: Chegou sexta 10/05 - 13/05 seguiu para conserto
A26: 43595 | B26: QPM 4740 | C26: HILUX | I26: PDY 6842 | J26: RAFAEL GOMES | K26: UNIDAS | L26: Obra 19.007 | M26: DELMIRO GOUVEIA(AL) E CEILANDIA - DF | N26: 43602
A27: 43633 | B27: QPM 4740 | C27: HILUX | E27: - | F27: - | I27: PDY 6842 | J27: RAFAEL GOMES | K27: UNIDAS | L27: Obra 19.010 | M27: TORRINHA E EMBUGUAÇU - SP | N27: 43644 | O27: Carro entregue por Victor - sem avarias
A28: 43654 | B28: QQF 5990 | C28: S10 | I28: PDY 6842 | J28: MARCOS DA COSTA | K28: UNIDAS | L28: Obra 19.013 | M28: RIO DO PEIXE - PB | N28: 43661 | O28: Carro chegou no sábado dia 13/07,porém precisava tirar o reboque e lavar, por issoa entrega na segunda 15/07
A29: 43682 | B29: QQF 5990 | C29: S10 | E29: 43698 | F29: RANGER - QOW 9208 | I29: PDY 6842 | J29: MARCOS DA COSTA | K29: UNIDAS | L29: Obra 19.015/19.017 | M29: ARAXA - MG | N29: 43706 | O29: Troca devido a embreagem parar de funcionar
A30: 43683 | B30: QQY 1385 | C30: SAVEIRO | J30: VICTOR HUGO | K30: UNIDAS | L30: Obra 19.016 | N30: 43704
A31: 43717 | B31: QUE 8657 | C31: PRISMA | E31: - | F31: - | J31: MARCELO PORTUGAL | K31: LOCALIZA | L31: Consorcio Conen | N31: 43728
A32: 43742 | B32: QUJ 5225 | C32: AMAROK | J32: VICTOR HUGO | K32: UNIDAS | L32: Obra 19.015 | N32: 43754 | O32: Carro chegou no dia 15/09 às 17:00
A33: 43612 | B33: PDU 4368 | C33: AMAROK | E33: 43766 | F33: S10 - QPI 4065 | J33: SOLA | K33: LOCALIZA | L33: Obra 18.030 | N33: 43766 | O33: Carro com para-brisas trincado , ar não funciona
A34: 43794 | B34: QUT 0500 | C34: STRADA | J34: MARCOS DA COSTA | K34: UNIDAS | L34: Obra 19.001
A35: 43809 | B35: PCE 8966 | C35: GOL | J35: FELIPE HIPOLITO | K35: LOCALIZA | L35: Obra 19.011 | N35: 43813 | O35: Entregue por Felipe
A36: 43836 | B36: QUJ 2156 | C36: ECOSPORT | J36: NILO CESAR | K36: UNIDAS | L36: CONSORCIO CONEN | N36: 43847
A37: 43846 | B37: QPM 2436 | C37: HILUX | I37: PDY 6842 | J37: MARCOS DA COSTA | K37: UNIDAS | L37: Obra 19.009 | M37: BARREIRAS/BA | N37: 43908 | O37: Carro foi entregue a Rafael em 01/02/ Carro com avarias, chegou ao galpão dia 13/03
A38: 43860 | B38: QUK 8329 | C38: S10 | J38: VICTOR HUGO | K38: LOCALIZA | L38: OBRA 20.001 | N38: 43902 | O38: Carro chegou no galpão dia 08/03/ Devolvido por Marcos
A39: 43860 | B39: QWR 0464 | C39: S10 | J39: RAFAEL GOMES | K39: LOCALIZA | L39: OBRA 20.001 | N39: 43901 | O39: Carro foi entregue a Marcos em 01/02/2020 - Carro chegou no galpão dia 07/03 e foi para revitalização/ Devolvido por Marcos
A40: 44021 | B40: QUT 0507 | C40: STRADA | J40: MARCOS DA COSTA | K40: UNIDAS | L40: - | N40: 44022 | O40: Carro locado para levar o reboque para manutenção
...

Sheet Controle Combustivel
C1: OBRAS ATIVA | D1: VEÍCULOS ATIVO | E1: RESUMO DO CONTROLE DE COMBUSTÍVEL | AQ1: DATA DE ATUALIZAÇÃO
C2: =COUNTIF(E5:E82,"ATIVA") -> 8 | D2: =SUM(D5:D82) -> 8 | AQ2: 45348
A3: OBRA | B3: LOCAL | D3: QUANTIDADE VEÍCULO | E3: SITUAÇÃO DA OBRA | F3: ACUMULADO ABAST. | G3: JANEIRO | J3: FEVEREIRO | M3: MARÇO | P3: ABRIL | S3: MAIO | V3: JUNHO | Y3: JULHO | AB3: AGOSTO | AE3: SETEMBRO | AH3: OUTUBRO | AK3: NOVEMBRO | AN3: DEZEMBRO | AQ3: OBSERVAÇÕES
G4: KM | H4: QTD ABAST. | I4: VALOR TOTAL | J4: KM | K4: QTD ABAST. | L4: VALOR TOTAL | M4: KM | N4: QTD ABAST. | O4: VALOR TOTAL | P4: KM | Q4: QTD ABAST. | R4: VALOR TOTAL | S4: KM | T4: QTD ABAST. | U4: VALOR TOTAL | V4: KM | W4: QTD ABAST. | X4: VALOR TOTAL | Y4: KM | Z4: QTD. ABAST. | AA4: VALOR TOTAL | AB4: KM | AC4: QTD. ABAST. | AD4: VALOR TOTAL | AE4: KM | AF4: QTD. ABAST. | AG4: VALOR TOTAL | AH4: KM | AI4: QTD. ABAST. | AJ4: VALOR TOTAL | AK4: KM | AL4: QTD. ABAST. | AM4: VALOR TOTAL | AN4: KM | AO4: QTD. ABAST. | AP4: VALOR TOTAL
A5: 22023 | B5: ENG. AGRONOMO | D5: =COUNTIF('22039_ARINOS'!D5:D24,"ATIVO") -> 0 | E5: ATIVA | F5: =SUM(H5+K5+N5+Q5+T5+W5+Z5+AC5+AF5+AI5+AL5+AO5) -> 70 | G5: =SUM('22039_ARINOS'!G5:G6) -> 3433 | H5: =SUM('22039_ARINOS'!H5:H6) -> 2 | I5: =SUM('22039_ARINOS'!J5:J6) -> 745.95 | J5: =SUM('22039_ARINOS'!G7:G8) -> 3319 | K5: =SUM('22039_ARINOS'!H7:H8) -> 7 | L5: =SUM('22039_ARINOS'!J7:J8) -> 1683.72 | M5: =SUM('22039_ARINOS'!G9:G10) -> 4673 | N5: =SUM('22039_ARINOS'!H9:H10) -> 9 | O5: =SUM('22039_ARINOS'!J9:J10) -> 2344.12 | P5: =SUM('22039_ARINOS'!G11:G13) -> 3922 | Q5: =SUM('22039_ARINOS'!H11:H13) -> 11 | R5: =SUM('22039_ARINOS'!J11:J13) -> 2734.83 | S5: =SUM('22039_ARINOS'!G14:G15) -> 5004 | T5: =SUM('22039_ARINOS'!H14:H15) -> 5 | U5: =SUM('22039_ARINOS'!J14:J15) -> 1603.34 | V5: =SUM('22039_ARINOS'!G16) -> 2610 | W5: =SUM('22039_ARINOS'!H16) -> 4 | X5: =SUM('22039_ARINOS'!J16) -> 1458.97 | Y5: =SUM('22039_ARINOS'!G17:G18) -> 4186 | Z5: =SUM('22039_ARINOS'!H17:H18) -> 6 | AA5: =SUM('22039_ARINOS'!J17:J18) -> 2712.12 | AB5: =SUM('22039_ARINOS'!G19:G20) -> 6455 | AC5: =SUM('22039_ARINOS'!H19:H20) -> 13 | AD5: =SUM('22039_ARINOS'!H19:J20) -> 4394.25 | AE5: =SUM('22039_ARINOS'!G21:G22) -> 4903 | AF5: =SUM('22039_ARINOS'!H21:H22) -> 13 | AG5: =SUM('22039_ARINOS'!H21:J22) -> 3990.101
A6: 22007 | B6: LDV-V | D6: =COUNTIF('22007_LDV-V'!D3:D47,"ATIVO") -> 2 | E6: ATIVA | F6: =SUM(H6+K6+N6+Q6+T6+W6+Z6+AC6+AF6+AI6+AL6+AO6) -> 157 | G6: =SUM('22007_LDV-V'!G3:G10) -> 21980 | H6: =SUM('22007_LDV-V'!I3:I10) -> 29 | I6: =SUM('22007_LDV-V'!H3:H10) -> 7071.16 | J6: =SUM('22007_LDV-V'!G11:G17) -> 14221 | K6: =SUM('22007_LDV-V'!I11:I17) -> 18 | L6: =SUM('22007_LDV-V'!H11:H17) -> 4173.11 | M6: =SUM('22007_LDV-V'!G18:G21) -> 10784 | N6: =SUM('22007_LDV-V'!I18:I21) -> 19 | O6: =SUM('22007_LDV-V'!H18:H21) -> 3674.26 | P6: =SUM('22007_LDV-V'!G22:G25) -> 10094 | Q6: =SUM('22007_LDV-V'!I22:I25) -> 19 | R6: =SUM('22007_LDV-V'!H22:H25) -> 3461.17 | S6: =SUM('22007_LDV-V'!G26:G28) -> 8629 | T6: =SUM('22007_LDV-V'!I26:I28) -> 18 | U6: =SUM('22007_LDV-V'!H26:H28) -> 3283.73 | V6: =SUM('22007_LDV-V'!G29:G31) -> 7953 | W6: =SUM('22007_LDV-V'!I29:I31) -> 15 | X6: =SUM('22007_LDV-V'!H29:H31) -> 2788.51 | Y6: =SUM('22007_LDV-V'!G32:G34) -> 9416 | Z6: =SUM('22007_LDV-V'!I32:I34) -> 16 | AA6: =SUM('22007_LDV-V'!H32:H34) -> 3189.14 | AB6: =SUM('22007_LDV-V'!G35:G37) -> 6798 | AC6: =SUM('22007_LDV-V'!I35:I37) -> 15 | AD6: =SUM('22007_LDV-V'!H35:H37) -> 2899.27 | AE6: =SUM('22007_LDV-V'!G38:G40) -> 9254 | AF6: =SUM('22007_LDV-V'!I38:I40) -> 8 | AG6: =SUM('22007_LDV-V'!I38:I40) -> 8
A7: 23018 | B7: IBIMIRIM | D7: 4 | E7: ATIVA | F7: =SUM(H7+K7+N7+Q7+T7+W7+Z7+AC7+AF7+AI7+AL7+AO7) -> 217 | G7: =SUM('23018_IBIMIRIM'!G3:G7) -> 13920 | H7: =SUM('23018_IBIMIRIM'!I3:I7) -> 39 | I7: =SUM('23018_IBIMIRIM'!H3:H7) -> 7822 | J7: =SUM('23018_IBIMIRIM'!G8:G13) -> 9298 | K7: =SUM('23018_IBIMIRIM'!I8:I13) -> 28 | L7: =SUM('23018_IBIMIRIM'!H8:H13) -> 6023.17 | M7: =SUM('23018_IBIMIRIM'!G14:G21) -> 13843 | N7: =SUM('23018_IBIMIRIM'!I14:I21) -> 23 | O7: =SUM('23018_IBIMIRIM'!H14:H21) -> 5401.18 | P7: =SUM('23018_IBIMIRIM'!G22:G26) -> 10038 | Q7: =SUM('23018_IBIMIRIM'!I22:I26) -> 20 | R7: =SUM('23018_IBIMIRIM'!H22:H26) -> 3627.57 | S7: =SUM('23018_IBIMIRIM'!G27:G31) -> 7338 | T7: =SUM('23018_IBIMIRIM'!I27:I31) -> 24 | U7: =SUM('23018_IBIMIRIM'!H27:H31) -> 4469.63 | V7: =SUM('23018_IBIMIRIM'!G32:G35) -> 7489 | W7: =SUM('23018_IBIMIRIM'!I32:I35) -> 20 | X7: =SUM('23018_IBIMIRIM'!H32:H35) -> 3574.37 | Y7: =SUM('23018_IBIMIRIM'!G36:G40) -> 8352 | Z7: =SUM('23018_IBIMIRIM'!I36:I40) -> 20 | AA7: =SUM('23018_IBIMIRIM'!H36:H40) -> 3725.82 | AB7: =SUM('23018_IBIMIRIM'!G41:G44) -> 9716 | AC7: =SUM('23018_IBIMIRIM'!I41:I44) -> 22 | AD7: =SUM('23018_IBIMIRIM'!H41:H44) -> 3875.31 | AE7: =SUM('23018_IBIMIRIM'!G45:G48) -> 6178 | AF7: =SUM('23018_IBIMIRIM'!I45:I48) -> 21 | AG7: =SUM('23018_IBIMIRIM'!H45:H48) -> 3597.97
A8: 23026 | B8: RETROFIT LAGOA CGN | D8: =COUNTIF('23026_LAGOA_CGN'!D3:D13,"ATIVO") -> 0 | E8: ATIVA | F8: =SUM(H8+K8+N8+Q8+T8+W8+Z8+AC8+AF8+AI8+AL8+AO8) -> 85 | G8: =SUM('23026_LAGOA_CGN'!G3:G5) -> 9806 | H8: =SUM('23026_LAGOA_CGN'!I3:I5) -> 13 | I8: =SUM('23026_LAGOA_CGN'!H3:H5) -> 3159.99 | J8: =SUM('23026_LAGOA_CGN'!G6:G7) -> 6733 | K8: =SUM('23026_LAGOA_CGN'!I6:I7) -> 14 | L8: =SUM('23026_LAGOA_CGN'!H6:H7) -> 3037.36 | M8: =SUM('23026_LAGOA_CGN'!G8:G9) -> 7358 | N8: =SUM('23026_LAGOA_CGN'!I8:I9) -> 14 | O8: =SUM('23026_LAGOA_CGN'!H8:H9) -> 2870.45 | P8: =SUM('23026_LAGOA_CGN'!G10) -> 3327 | Q8: =SUM('23026_LAGOA_CGN'!I10) -> 10 | R8: =SUM('23026_LAGOA_CGN'!H10) -> 1798.46 | S8: =SUM('23026_LAGOA_CGN'!G12) -> 3148 | T8: =SUM('23026_LAGOA_CGN'!I12) -> 10 | U8: =SUM('23026_LAGOA_CGN'!H12) -> 1562.64 | V8: =SUM('23026_LAGOA_CGN'!G13) -> 2997 | W8: =SUM('23026_LAGOA_CGN'!I13) -> 9 | X8: =SUM('23026_LAGOA_CGN'!H13) -> 2053.27 | Y8: =SUM('23026_LAGOA_CGN'!G14:G15) -> 6808 | Z8: =SUM('23026_LAGOA_CGN'!I14:I15) -> 10 | AA8: =SUM('23026_LAGOA_CGN'!H14:H15) -> 2290.77 | AB8: =SUM('23026_LAGOA_CGN'!H6) -> 1777.53 | AC8: 5 | AD8: =SUM('23026_LAGOA_CGN'!G16) -> 1298
A9: 22005 | B9: MAPEAMENTO DE IMÓVEIS | D9: =COUNTIF('22005_MAPEAMENTO'!D5:D14,"ATIVO") -> 0 | E9: ATIVA | F9: =SUM(H9+K9+N9+Q9+T9+W9+Z9+AC9+AF9+AI9+AL9+AO9) -> 40 | G9: =SUM('22005_MAPEAMENTO'!G5:G7) -> 6790 | H9: =SUM('22005_MAPEAMENTO'!K5:K7) -> 15 | I9: =SUM('22005_MAPEAMENTO'!H5:H7) -> 3110.47 | J9: =SUM('22005_MAPEAMENTO'!G8:G9) -> 3600 | K9: =SUM('22005_MAPEAMENTO'!K8:K9) -> 8 | L9: =SUM('22005_MAPEAMENTO'!H8:H9) -> 2126.45 | M9: =SUM('22005_MAPEAMENTO'!G10:G11) -> 5422 | N9: =SUM('22005_MAPEAMENTO'!K10:K11) -> 10 | O9: =SUM('22005_MAPEAMENTO'!H10:H11) -> 2274.21 | P9: =SUM('22005_MAPEAMENTO'!G12:G13) -> 3024 | Q9: =SUM('22005_MAPEAMENTO'!K12:K13) -> 6 | R9: =SUM('22005_MAPEAMENTO'!H12:H13) -> 1594.26 | S9: =SUM('22005_MAPEAMENTO'!H12:H13) -> 1594.26 | T9: =SUM('22005_MAPEAMENTO'!K14) -> 1 | U9: =SUM('22005_MAPEAMENTO'!H14) -> 276.97
A10: 21029 | B10: ENEL GOIANIA | D10: 2 | E10: ATIVA | F10: =SUM(H10+K10+N10+Q10+T10+W10+Z10+AC10+AF10+AI10+AL10+AO10) -> 45 | G10: =SUM('21029_ENEL GOIANIA'!G5:G6) -> 1993 | H10: =SUM('21029_ENEL GOIANIA'!K5:K6) -> 8 | I10: =SUM('21029_ENEL GOIANIA'!H5:H6) -> 966.71 | J10: =SUM('21029_ENEL GOIANIA'!G7:G8) -> 1074 | K10: =SUM('21029_ENEL GOIANIA'!K7:K8) -> 4 | L10: =SUM('21029_ENEL GOIANIA'!H7:H8) -> 505.1 | M10: =SUM('21029_ENEL GOIANIA'!G9:G10) -> 2139 | N10: =SUM('21029_ENEL GOIANIA'!K9:K10) -> 6 | O10: =SUM('21029_ENEL GOIANIA'!H9:H10) -> 955.29 | P10: =SUM('21029_ENEL GOIANIA'!G11:G12) -> 1899 | Q10: =SUM('21029_ENEL GOIANIA'!K11:K12) -> 8 | R10: =SUM('21029_ENEL GOIANIA'!H11:H12) -> 1310.95 | S10: =SUM('21029_ENEL GOIANIA'!G13:G14) -> 1520 | T10: =SUM('21029_ENEL GOIANIA'!K13:K14) -> 4 | U10: =SUM('21029_ENEL GOIANIA'!H13:H14) -> 430.12 | V10: =SUM('21029_ENEL GOIANIA'!G15:G16) -> 1055 | W10: =SUM('21029_ENEL GOIANIA'!K15:K16) -> 3 | X10: =SUM('21029_ENEL GOIANIA'!H15:H16) -> 540.89 | Y10: =SUM('21029_ENEL GOIANIA'!G17:G18) -> 1633 | Z10: =SUM('21029_ENEL GOIANIA'!K17:K18) -> 4 | AA10: =SUM('21029_ENEL GOIANIA'!H17:H18) -> 996.91 | AB10: =SUM('21029_ENEL GOIANIA'!G19:G20) -> 1806 | AC10: =SUM('21029_ENEL GOIANIA'!K19:K20) -> 5 | AD10: =SUM('21029_ENEL GOIANIA'!H19:H20) -> 916.668 | AE10: =SUM('21029_ENEL GOIANIA'!G21:G22) -> 1130 | AF10: =SUM('21029_ENEL GOIANIA'!K21:K22) -> 3 | AG10: =SUM('21029_ENEL GOIANIA'!H21:H22) -> 541.6
A11: 19018 | B11: FURNAS ANGRA | D11: =COUNTIF('19018_F.Angra'!D5:D17,"ATIVO") -> 0 | E11: ATIVA | F11: =SUM(H11+K11+N11+Q11+T11+W11+Z11+AC11+AF11+AI11+AL11+AO11) -> 35 | G11: =SUM('19018_F.Angra'!G5:G6) -> 4222 | H11: =SUM('19018_F.Angra'!K5:K6) -> 6 | I11: =SUM('19018_F.Angra'!H5:H6) -> 1800 | J11: =('19018_F.Angra'!G7) -> 2768 | K11: =('19018_F.Angra'!K7) -> 5 | L11: =('19018_F.Angra'!H7) -> 1200.01 | M11: =('19018_F.Angra'!G8) -> 2655 | N11: =('19018_F.Angra'!K8) -> 6 | O11: =('19018_F.Angra'!H8) -> 1250 | P11: =('19018_F.Angra'!G9) -> 1727 | Q11: =('19018_F.Angra'!K9) -> 4 | R11: =('19018_F.Angra'!H9) -> 950 | S11: =('19018_F.Angra'!G10) -> 2135 | T11: =('19018_F.Angra'!K10) -> 3 | U11: =('19018_F.Angra'!H10) -> 1000 | V11: =('19018_F.Angra'!G11) -> 1832 | W11: =('19018_F.Angra'!K11) -> 4 | X11: =('19018_F.Angra'!H11) -> 1000 | Y11: =('19018_F.Angra'!G12) -> 1983 | Z11: =('19018_F.Angra'!K12) -> 5 | AA11: =('19018_F.Angra'!H12) -> 1080.1 | AB11: =('19018_F.Angra'!G13) -> 1517 | AC11: =('19018_F.Angra'!K13) -> 2 | AD11: =('19018_F.Angra'!H13) -> 700
A12: 20017 | B12: DNIT | D12: =COUNTIF('20017_DNIT'!D5:D28,"ATIVO") -> 0 | E12: DESATIVADA | F12: =SUM(H12+K12+N12+Q12+T12+W12+Z12+AC12+AF12+AI12+AL12+AO12) -> 14 | G12: =SUM('20017_DNIT'!G5:G6) -> 2582 | H12: =SUM('20017_DNIT'!K5:K6) -> 0 | I12: =SUM('20017_DNIT'!H5:H6) -> 1035.58 | J12: =SUM('20017_DNIT'!G7:G8) -> 2663 | K12: 4 | L12: =SUM('20017_DNIT'!H7:H8) -> 1037.74 | M12: =SUM('23026_LAGOA_CGN'!G12:G12) -> 3148 | N12: =SUM('23026_LAGOA_CGN'!I12:I12) -> 10 | O12: =SUM('23026_LAGOA_CGN'!H12:H12) -> 1562.64
A13: - | B13: ARO | D13: =COUNTIF('0000_ARO'!D3:D33,"ATIVO") -> 0 | E13: DESATIVADA | F13: =SUM(H13+K13+N13+Q13+T13+W13+Z13+AC13+AF13+AI13+AL13+AO13) -> 7070 | G13: =SUM('0000_ARO'!D3:D3) -> 0 | H13: =SUM('0000_ARO'!F3:F3) -> 7062 | I13: =SUM('0000_ARO'!E3:E3) -> 4907 | J13: =('0000_ARO'!G3) -> 2155 | K13: =('0000_ARO'!I3) -> 4 | L13: =('0000_ARO'!H3) -> 1141.65 | M13: =('0000_ARO'!G4) -> 2038 | N13: =('0000_ARO'!I4) -> 4 | O13: =('0000_ARO'!H4) -> 987.56
A14: - | B14: OBRA_LABORATÓRIO | E14: ATIVA | F14: =SUM(H14+K14+N14+Q14+T14+W14+Z14+AC14+AF14+AI14+AL14+AO14) -> 9 | M14: =SUM('23026_LAGOA_CGN'!G13:G13) -> 2997 | N14: =SUM('23026_LAGOA_CGN'!I13:I13) -> 9 | O14: =SUM('23026_LAGOA_CGN'!H13:H13) -> 2053.27
A15: TOTAL GERAL | F15: =SUBTOTAL(9,F5:F14) -> 7742 | G15: =SUBTOTAL(9,G5:G14) -> 64726 | H15: =SUBTOTAL(9,H5:H14) -> 7174 | I15: =SUBTOTAL(9,I5:I14) -> 30618.86 | J15: =SUBTOTAL(9,J5:J14) -> 45831 | K15: =SUBTOTAL(9,K5:K14) -> 92 | L15: =SUBTOTAL(9,L5:L14) -> 20928.31 | M15: =SUBTOTAL(9,M5:M14) -> 55057 | N15: =SUBTOTAL(9,N5:N14) -> 110 | O15: =SUM(O5:O14) -> 23372.98 | P15: =SUBTOTAL(9,P5:P14) -> 34031 | Q15: =SUBTOTAL(9,Q5:Q14) -> 78 | R15: =SUM(R5:R14) -> 15477.24 | S15: =SUBTOTAL(9,S5:S14) -> 29368.26 | T15: =SUBTOTAL(9,T5:T14) -> 65 | U15: =SUM(U5:U14) -> 12626.43 | V15: =SUBTOTAL(9,V5:V14) -> 23936 | W15: =SUBTOTAL(9,W5:W14) -> 55 | X15: =SUM(X5:X14) -> 11416.01 | Y15: =SUBTOTAL(9,Y5:Y14) -> 32378 | Z15: =SUBTOTAL(9,Z5:Z14) -> 61 | AA15: =SUM(AA5:AA14) -> 13994.86 | AB15: =SUBTOTAL(9,AB5:AB14) -> 28069.53 | AC15: =SUBTOTAL(9,AC5:AC14) -> 62 | AD15: =SUM(AD5:AD14) -> 14083.498 | AE15: =SUBTOTAL(9,AE5:AE14) -> 21465 | AF15: =SUBTOTAL(9,AF5:AF14) -> 45 | AG15: =SUM(AG5:AG14) -> 8137.671 | AH15: =SUBTOTAL(9,AH5:AH14) -> 0 | AI15: =SUBTOTAL(9,AI5:AI14) -> 0 | AJ15: =SUM(AJ5:AJ14) -> 0 | AK15: =SUM(AK5:AK14) -> 0 | AL15: =SUM(AL5:AL14) -> 0 | AM15: =SUM(AM5:AM14) -> 0 | AN15: =SUM(AN5:AN12) -> 0 | AO15: =SUM(AO5:AO12) -> 0 | AP15: =SUM(AP5:AP12) -> 0
A16: TOTAL ACUMULADO DE DESPESAS 2024 | G16: =I15+L15+O15+R15+U15+X15+AA15+AD15+AG15+AJ15+AM15+AQ15 -> 150655.86
A17: ECONOMIA NO MÊS | G17: =I15/L15-1 -> 0.46303548

Sheet 22039_ARINOS
A4: CONDUTOR | B4: VEICULO | C4: PLACA | D4: STATUS | E4: KM INICIAL | F4: KM FINAL | G4: KM PERCORRIDA | H4: CONSUMO | I4: QTD LITROS | J4: ABASTECIMENTO MÊS | K4: CONSUMO DE 01 A 15 | L4: CONSUMO DE 16 A 31 | M4: MÊS | N4: OBS
A5: AUGUSTO | B5: L200 | C5: RMJ6B86 | D5: - | E5: 66265 | F5: 68739 | G5: =F5-E5 -> 2474 | H5: 1 | I5: 52.561 | J5: =SUM(K5:L5) -> 335.86 | K5: 335.86 | M5: Janeiro
A6: GUSTAVO | B6: TRACKER | C6: SIM2I94 | D6: - | E6: 7968 | F6: 8927 | G6: =F6-E6 -> 959 | H6: 1 | I6: 69.74 | J6: =SUM(K6:L6) -> 410.09 | K6: 215.16 | L6: 194.93 | M6: Janeiro
A7: AUGUSTO | B7: L200 | C7: RMJ6B86 | D7: - | E7: 68739 | F7: 70689 | G7: =F7-E7 -> 1950 | H7: 3 | I7: 156.26 | J7: =SUM(K7:L7) -> 1017.65 | K7: 297.25 | L7: 720.4 | M7: Fevereiro
A8: GUSTAVO | B8: TRACKER | C8: SIM2I94 | D8: - | E8: 8927 | F8: 10296 | G8: =F8-E8 -> 1369 | H8: 4 | I8: 109.95 | J8: =SUM(K8:L8) -> 666.07 | K8: 277.68 | L8: 388.39 | M8: Fevereiro
A9: AUGUSTO | B9: L200 | C9: RMJ6B86 | D9: - | E9: 70689 | F9: 73837 | G9: =F9-E9 -> 3148 | H9: 5 | I9: 233.21 | J9: =SUM(K9:L9) -> 1518.21 | K9: 1025.46 | L9: 492.75 | M9: Março
A10: GUSTAVO | B10: TRACKER | C10: SIM2I94 | D10: - | E10: 10296 | F10: 11821 | G10: =F10-E10 -> 1525 | H10: 4 | I10: 134.73 | J10: =SUM(K10:L10) -> 825.91 | K10: 450.51 | L10: 375.4 | M10: Março
A11: AUGUSTO | B11: L200 | C11: RMJ6B86 | D11: - | E11: 73837 | F11: 76390 | G11: =F11-E11 -> 2553 | H11: 5 | I11: 108.4 | J11: =SUM(K11:L11) -> 1529.46 | K11: 692.53 | L11: 836.93 | M11: Abril
A12: GUSTAVO | B12: TRACKER | C12: SIM2I94 | D12: - | E12: 11821 | F12: 12874 | G12: =F12-E12 -> 1053 | H12: 3 | I12: 101.28 | J12: =SUM(K12:L12) -> 602.69 | K12: 406.17 | L12: 196.52 | M12: Abril
A13: GUSTAVO | B13: TCROSS | C13: SHX9G91 | D13: - | E13: 24047 | F13: 24363 | G13: =F13-E13 -> 316 | H13: 3 | I13: 98.31 | J13: =SUM(K13:L13) -> 602.68 | K13: 406.16 | L13: 196.52 | M13: Abril
A14: AUGUSTO | B14: L200 | C14: RMJ6B86 | D14: - | E14: 76390 | F14: 80350 | G14: =F14-E14 -> 3960 | H14: 3 | I14: 161.06 | J14: 998.76 | K14: 710.09 | L14: 288.67 | M14: Maio
A15: GUSTAVO | B15: TCROSS | C15: SHX9G91 | D15: - | E15: 24363 | F15: 25407 | G15: =F15-E15 -> 1044 | H15: 2 | I15: 92.01 | J15: 604.58 | K15: 0 | L15: 604.58 | M15: Maio
A16: AUGUSTO | B16: L200 | C16: RMJ6B86 | D16: - | E16: 80350 | F16: 82960 | G16: =F16-E16 -> 2610 | H16: 4 | I16: 235.32 | J16: 1458.97 | K16: 726.93 | L16: 732.04 | M16: Junho
A17: AUGUSTO | B17: L200 | C17: RMJ6B86 | D17: - | E17: 82960 | F17: 85402 | G17: =F17-E17 -> 2442 | H17: 2 | I17: 243.64 | J17: 1511.64 | K17: 641.95 | L17: 869.69 | M17: Julho
A18: EZEQUIAS | B18: RENEGADE | C18: SIH5G62 | D18: - | E18: 43742 | F18: 45486 | G18: =F18-E18 -> 1744 | H18: 4 | I18: 185.56 | J18: 1200.48 | K18: 582.8 | L18: 617.68 | M18: Julho
A19: AUGUSTO | B19: L200 | C19: SEO0D82 | D19: - | E19: 85402 | F19: 89968 | G19: =F19-E19 -> 4566 | H19: 8 | I19: 373.19 | J19: =SUM(K19+L19) -> 2338.87 | K19: 1057.8 | L19: 1281.07 | M19: Agosto
A20: EZEQUIAS | B20: RENEGADE | C20: SIH5G62 | D20: - | E20: 45486 | F20: 47375 | G20: =F20-E20 -> 1889 | H20: 5 | I20: 219.92 | J20: =SUM(K20+L20) -> 1449.27 | K20: 952.98 | L20: 496.29 | M20: Agosto
A21: AUGUSTO | B21: L200 | C21: RMJ6B86 | D21: - | E21: 89968 | F21: 93345 | G21: =F21-E21 -> 3377 | H21: 8 | I21: 329 | J21: =SUM(K21+L21) -> 2053.4 | K21: 827.28 | L21: 1226.12 | M21: Setembro
A22: EZEQUIAS | B22: RENEGADE | C22: SIH5G62 | D22: - | E22: 47375 | F22: 48901 | G22: =F22-E22 -> 1526 | H22: 5 | I22: 210.081 | J22: =SUM(K22+L22) -> 1384.62 | K22: 624.14 | L22: 760.48 | M22: Setembro
A23: AUGUSTO | B23: L200 | C23: RMJ6B86 | G23: =F23-E23 -> 0 | J23: =SUM(K23+L23) -> 0 | M23: Outubro
A24: AUGUSTO | B24: L200 | C24: RMJ6B86 | E24: 96977 | F24: 100925 | G24: =F24-E24 -> 3948 | J24: =SUM(K24+L24) -> 0 | M24: Novembro

Sheet 22007_LDV-V
A1: QTD DE VEICULOS ATIVO | B1: =COUNTIF(D3:D47,"ATIVO") -> 2 | C1: CONTROLE DE KM - 2024 - 22007_LDV-V | M1: ABASTECIMENTO | P1: ABASTECIMENTO | S1: ABASTECIMENTO | V1: ABASTECIMENTO | Y1: ABASTECIMENTO | AB1: ABASTECIMENTO | AE1: ABASTECIMENTO | AH1: ABASTECIMENTO | AK1: ABASTECIMENTO | AN1: ABASTECIMENTO | AQ1: ABASTECIMENTO | AT1: ABASTECIMENTO | AW1: ABASTECIMENTO | AZ1: ABASTECIMENTO | BC1: ABASTECIMENTO | BF1: ABASTECIMENTO | BI1: ABASTECIMENTO | BL1: ABASTECIMENTO | BO1: ABASTECIMENTO | BR1: ABASTECIMENTO | BU1: ABASTECIMENTO | BX1: ABASTECIMENTO | CA1: ABASTECIMENTO | CD1: ABASTECIMENTO | CG1: ABASTECIMENTO | CJ1: ABASTECIMENTO | CM1: ABASTECIMENTO | CP1: ABASTECIMENTO | CS1: ABASTECIMENTO | CV1: ABASTECIMENTO | CY1: ABASTECIMENTO | DB1: OBS | DC1: Folga
A2: CONDUTOR | B2: VEICULO | C2: PLACA | D2: STATUS | E2: KM INICIAL | F2: KM FINAL | G2: KM PERCORRIDA | H2: CONSUMO TOTAL | I2: ABASTECIMENTO MÊS | J2: POSTO SANTA RITA | K2: POSTO VIP | L2: MÊS | M2: 1º DIA VALOR | N2: QTD LITROS | O2: POSTO | P2: 2º DIA VALOR | Q2: QTD LITROS | R2: POSTO | S2: 3º DIA VALOR | T2: QTD LITROS | U2: POSTO | V2: 4º DIA VALOR | W2: QTD LITROS | X2: POSTO | Y2: 5º DIA VALOR | Z2: QTD LITROS | AA2: POSTO | AB2: 6º DIA VALOR | AC2: QTD LITROS | AD2: POSTO | AE2: 7º DIA VALOR | AF2: QTD LITROS | AG2: POSTO | AH2: 8º DIA VALOR | AI2: QTD LITROS | AJ2: POSTO | AK2: 9º DIA VALOR | AL2: QTD LITROS | AM2: POSTO | AN2: 10º DIA VALOR | AO2: QTD LITROS | AP2: POSTO | AQ2: 11º DIA VALOR | AR2: QTD LITROS | AS2: POSTO | AT2: 12º DIA VALOR | AU2: QTD LITROS | AV2: POSTO | AW2: 13º DIA VALOR | AX2: QTD LITROS | AY2: POSTO | AZ2: 14º DIA VALOR | BA2: QTD LITROS | BB2: POSTO | BC2: 15º DIA VALOR | BD2: QTD LITROS | BE2: POSTO | BF2: 16º DIA VALOR | BG2: QTD LITROS | BH2: POSTO | BI2: 17º DIA VALOR | BJ2: QTD LITROS | BK2: POSTO | BL2: 18º DIA VALOR | BM2: QTD LITROS | BN2: POSTO | BO2: 19º DIA VALOR | BP2: QTD LITROS | BQ2: POSTO | BR2: 20º DIA VALOR | BS2: QTD LITROS | BT2: POSTO | BU2: 21º DIA VALOR | BV2: QTD LITROS | BW2: POSTO | BX2: 22º DIA VALOR | BY2: QTD LITROS | BZ2: POSTO | CA2: 23º DIA VALOR | CB2: QTD LITROS | CC2: POSTO | CD2: 24º DIA VALOR | CE2: QTD LITROS | CF2: POSTO | CG2: 25º DIA VALOR | CH2: QTD LITROS | CI2: POSTO | CJ2: 26º DIA VALOR | CK2: QTD LITROS | CL2: POSTO | CM2: 27º DIA VALOR | CN2: QTD LITROS | CO2: POSTO | CP2: 28º DIA VALOR | CQ2: QTD LITROS | CR2: POSTO | CS2: 29º DIA VALOR | CT2: QTD LITROS | CU2: POSTO | CV2: 30º DIA VALOR | CW2: QTD LITROS | CX2: POSTO | CY2: 31º DIA VALOR | CZ2: QTD LITROS | DA2: POSTO
A3: ADEMIR DOMINGOS | B3: ARGO | C3: SHW6C40 | D3: - | E3: 13603 | F3: 14931 | G3: =F3-E3 -> 1328 | H3: =SUM(M3+P3+S3+V3+Y3+AB3+AE3+AH3+AK3+AN3+AQ3+AT3+AW3+AZ3+BC3+BF3+BI3+BL3+BO3+BR3+BU3+BX3+CA3+CD3+CG3+CJ3+CM3+CP3+CS3+CV3+CY3) -> 625.52 | I3: =COUNTA(N3,Q3,T3,W3,Z3,AC3,AF3,AI3,AL3,AO3,AR3,AU3,AX3,BA3,BD3,BG3,BJ3,BM3,BP3,BS3,BV3,BY3,CB3,CE3,CH3,CK3,CN3,CQ3,CT3,CW3,CZ3) -> 3 | J3: =COUNTIF(M3:DC3,"POSTO SANTA RITA") -> 2 | K3: =COUNTIF(M3:DD3,"POSTO VIP") -> 1 | L3: Janeiro | AQ3: 223.17 | AR3: 38.114 | AS3: POSTO VIP | BX3: 223.05 | BY3: 38.59 | BZ3: POSTO SANTA RITA | CV3: 179.3 | CW3: 30.65 | CX3: POSTO SANTA RITA
A4: FRANCISCO EDILSON | B4: RENEGADE | C4: SHY2C77 | D4: - | E4: 29041 | F4: 33321 | G4: =F4-E4 -> 4280 | H4: =SUM(M4+P4+S4+V4+Y4+AB4+AE4+AH4+AK4+AN4+AQ4+AT4+AW4+AZ4+BC4+BF4+BI4+BL4+BO4+BR4+BU4+BX4+CA4+CD4+CG4+CJ4+CM4+CP4+CS4+CV4+CY4) -> 1925.93 | I4: =COUNTA(N4,Q4,T4,W4,Z4,AC4,AF4,AI4,AL4,AO4,AR4,AU4,AX4,BA4,BD4,BG4,BJ4,BM4,BP4,BS4,BV4,BY4,CB4,CE4,CH4,CK4,CN4,CQ4,CT4,CW4,CZ4) -> 8 | J4: =COUNTIF(M4:DC4,"POSTO SANTA RITA") -> 0 | K4: =COUNTIF(N4:DD4,"POSTO VIP") -> 8 | L4: Janeiro | P4: 299.52 | Q4: 51.2 | R4: POSTO VIP | AB4: 180.76 | AC4: 30.9 | AD4: POSTO VIP | AK4: 179.71 | AL4: 30.72 | AM4: POSTO VIP | AW4: 228.2 | AX4: 39.009 | AY4: POSTO VIP | BF4: 286.82 | BG4: 49.03 | BH4: POSTO VIP | BR4: 219.58 | BS4: 37.19 | BT4: POSTO VIP | CD4: 219.64 | CE4: 38 | CF4: POSTO VIP | CS4: 311.7 | CT4: 53.94 | CU4: POSTO VIP
A5: RAIMUNDO GERSON | B5: S10 | C5: RVS1B18 | D5: - | E5: 33422 | F5: 36626 | G5: =F5-E5 -> 3204 | H5: =SUM(M5+P5+S5+V5+Y5+AB5+AE5+AH5+AK5+AN5+AQ5+AT5+AW5+AZ5+BC5+BF5+BI5+BL5+BO5+BR5+BU5+BX5+CA5+CD5+CG5+CJ5+CM5+CP5+CS5+CV5+CY5) -> 1930.61 | I5: =COUNTA(N5,Q5,T5,W5,Z5,AC5,AF5,AI5,AL5,AO5,AR5,AU5,AX5,BA5,BD5,BG5,BJ5,BM5,BP5,BS5,BV5,BY5,CB5,CE5,CH5,CK5,CN5,CQ5,CT5,CW5,CZ5) -> 6 | J5: =COUNTIF(M5:DC5,"POSTO SANTA RITA") -> 4 | K5: =COUNTIF(N5:DD5,"POSTO VIP") -> 2 | L5: Janeiro | P5: 244.5 | Q5: 39.12 | R5: POSTO SANTA RITA | AB5: 314.37 | AC5: 50.3 | AD5: POSTO VIP | AQ5: 326.98 | AR5: 53.17 | AS5: POSTO VIP | AW5: 159.96 | AX5: 26.01 | AY5: POSTO SANTA RITA | BR5: 457.8 | BS5: 75.08 | BT5: POSTO SANTA RITA | CM5: 427 | CN5: 70 | CO5: POSTO SANTA RITA
A6: ANTONIO VAGNER | B6: TRACKER | C6: RVJ0I15 | D6: DESMOBILIZADO | E6: 34811 | F6: 41722 | G6: =F6-E6 -> 6911 | H6: =SUM(M6+P6+S6+V6+Y6+AB6+AE6+AH6+AK6+AN6+AQ6+AT6+AW6+AZ6+BC6+BF6+BI6+BL6+BO6+BR6+BU6+BX6+CA6+CD6+CG6+CJ6+CM6+CP6+CS6+CV6+CY6) -> 335.78 | I6: =COUNTA(N6,Q6,T6,W6,Z6,AC6,AF6,AI6,AL6,AO6,AR6,AU6,AX6,BA6,BD6,BG6,BJ6,BM6,BP6,BS6,BV6,BY6,CB6,CE6,CH6,CK6,CN6,CQ6,CT6,CW6,CZ6) -> 2 | J6: =COUNTIF(M6:DC6,"POSTO SANTA RITA") -> 0 | K6: =COUNTIF(N6:DD6,"POSTO VIP") -> 1 | L6: Janeiro | AK6: 202.23 | AL6: 34.57 | AM6: POSTO VIP | AT6: 133.55 | AU6: 22.33 | AV6: POTO VIP
A7: ANTONIO VAGNER | B7: RENEGADE | C7: SIG2E24 | D7: - | E7: 19768 | F7: 21340 | G7: =F7-E7 -> 1572 | H7: =SUM(M7+P7+S7+V7+Y7+AB7+AE7+AH7+AK7+AN7+AQ7+AT7+AW7+AZ7+BC7+BF7+BI7+BL7+BO7+BR7+BU7+BX7+CA7+CD7+CG7+CJ7+CM7+CP7+CS7+CV7+CY7) -> 261.77 | I7: =COUNTA(N7,Q7,T7,W7,Z7,AC7,AF7,AI7,AL7,AO7,AR7,AU7,AX7,BA7,BD7,BG7,BJ7,BM7,BP7,BS7,BV7,BY7,CB7,CE7,CH7,CK7,CN7,CQ7,CT7,CW7,CZ7) -> 1 | J7: =COUNTIF(M7:DC7,"POSTO SANTA RITA") -> 0 | K7: =COUNTIF(N7:DD7,"POSTO VIP") -> 1 | L7: Janeiro | CA7: 261.77 | CB7: 45.29 | CC7: POSTO VIP
A8: SAMILA RIBEIRO | B8: ONIX | C8: SIT1G63 | D8: - | E8: 3373 | F8: 5051 | G8: =F8-E8 -> 1678 | H8: =SUM(M8+P8+S8+V8+Y8+AB8+AE8+AH8+AK8+AN8+AQ8+AT8+AW8+AZ8+BC8+BF8+BI8+BL8+BO8+BR8+BU8+BX8+CA8+CD8+CG8+CJ8+CM8+CP8+CS8+CV8+CY8) -> 659.47 | I8: =COUNTA(N8,Q8,T8,W8,Z8,AC8,AF8,AI8,AL8,AO8,AR8,AU8,AX8,BA8,BD8,BG8,BJ8,BM8,BP8,BS8,BV8,BY8,CB8,CE8,CH8,CK8,CN8,CQ8,CT8,CW8,CZ8) -> 4 | J8: =COUNTIF(M8:DC8,"POSTO SANTA RITA") -> 4 | K8: =COUNTIF(N8:DD8,"POSTO VIP") -> 0 | L8: Janeiro | AQ8: 234.53 | AR8: 40.09 | AS8: POSTO SANTA RITA | BI8: 219.58 | BJ8: 37.99 | BK8: POSTO SANTA RITA | BO8: 114.27 | BP8: 19.77 | BQ8: POSTO SANTA RITA | CM8: 91.09 | CN8: 15.76 | CO8: POSTO SANTA RITA
A9: FABIO SIQUEIRA | B9: RENEGADE | C9: RNX9A52 | D9: - | E9: 44491 | F9: 47015 | G9: =F9-E9 -> 2524 | H9: =SUM(M9+P9+S9+V9+Y9+AB9+AE9+AH9+AK9+AN9+AQ9+AT9+AW9+AZ9+BC9+BF9+BI9+BL9+BO9+BR9+BU9+BX9+CA9+CD9+CG9+CJ9+CM9+CP9+CS9+CV9+CY9) -> 1099.96 | I9: =COUNTA(N9,Q9,T9,W9,Z9,AC9,AF9,AI9,AL9,AO9,AR9,AU9,AX9,BA9,BD9,BG9,BJ9,BM9,BP9,BS9,BV9,BY9,CB9,CE9,CH9,CK9,CN9,CQ9,CT9,CW9,CZ9) -> 4 | J9: =COUNTIF(M9:DC9,"POSTO SANTA RITA") -> 0 | K9: =COUNTIF(N9:DD9,"POSTO VIP") -> 4 | L9: Janeiro | P9: 312.97 | Q9: 53.5 | R9: POSTO VIP | AT9: 198.6 | AU9: 33.95 | AV9: POSTO VIP | BO9: 294.54 | BP9: 50.059 | BQ9: POSTO VIP | CG9: 293.85 | CH9: 50.84 | CI9: POSTO VIP
A10: HERMES XAVIER | B10: ONIX | C10: SIU5B06 | D10: - | E10: 1529 | F10: 2012 | G10: =F10-E10 -> 483 | H10: =SUM(M10+P10+S10+V10+Y10+AB10+AE10+AH10+AK10+AN10+AQ10+AT10+AW10+AZ10+BC10+BF10+BI10+BL10+BO10+BR10+BU10+BX10+CA10+CD10+CG10+CJ10+CM10+CP10+CS10+CV10+CY10) -> 232.12 | I10: =COUNTA(N10,Q10,T10,W10,Z10,AC10,AF10,AI10,AL10,AO10,AR10,AU10,AX10,BA10,BD10,BG10,BJ10,BM10,BP10,BS10,BV10,BY10,CB10,CE10,CH10,CK10,CN10,CQ10,CT10,CW10,CZ10) -> 1 | J10: =COUNTIF(M10:DC10,"POSTO SANTA RITA") -> 0 | K10: =COUNTIF(N10:DD10,"POSTO VIP") -> 1 | L10: Janeiro | CA10: 232.12 | CB10: 40.164 | CC10: POSTO VIP
A11: ADEMIR DOMINGOS | B11: ARGO | C11: SHW6C40 | D11: - | E11: 14931 | F11: 16318 | G11: =F11-E11 -> 1387 | H11: =SUM(M11+P11+S11+V11+Y11+AB11+AE11+AH11+AK11+AN11+AQ11+AT11+AW11+AZ11+BC11+BF11+BI11+BL11+BO11+BR11+BU11+BX11+CA11+CD11+CG11+CJ11+CM11+CP11+CS11+CV11+CY11) -> 620.75 | I11: =COUNTA(N11,Q11,T11,W11,Z11,AC11,AF11,AI11,AL11,AO11,AR11,AU11,AX11,BA11,BD11,BG11,BJ11,BM11,BP11,BS11,BV11,BY11,CB11,CE11,CH11,CK11,CN11,CQ11,CT11,CW11,CZ11) -> 3 | J11: =COUNTIF(M11:DC11,"POSTO SANTA RITA") -> 0 | K11: =COUNTIF(M11:DD11,"POSTO VIP") -> 3 | L11: Fevereiro | S11: 222.76 | T11: 38.54 | U11: POSTO VIP | AN11: 167.49 | AO11: 28.68 | AP11: POSTO VIP | CD11: 230.5 | CE11: 39.47 | CF11: POSTO VIP
A12: FRANCISCO EDILSON | B12: RENEGADE | C12: SHY2C77 | D12: - | E12: 33321 | F12: 34867 | G12: =F12-E12 -> 1546 | H12: =SUM(M12+P12+S12+V12+Y12+AB12+AE12+AH12+AK12+AN12+AQ12+AT12+AW12+AZ12+BC12+BF12+BI12+BL12+BO12+BR12+BU12+BX12+CA12+CD12+CG12+CJ12+CM12+CP12+CS12+CV12+CY12) -> 438.15 | I12: =COUNTA(N12,Q12,T12,W12,Z12,AC12,AF12,AI12,AL12,AO12,AR12,AU12,AX12,BA12,BD12,BG12,BJ12,BM12,BP12,BS12,BV12,BY12,CB12,CE12,CH12,CK12,CN12,CQ12,CT12,CW12,CZ12) -> 2 | J12: =COUNTIF(M12:DC12,"POSTO SANTA RITA") -> 0 | K12: =COUNTIF(N12:DD12,"POSTO VIP") -> 2 | L12: Fevereiro | P12: 231.54 | Q12: 40.059 | R12: POSTO VIP | AH12: 206.61 | AI12: 35.379 | AJ12: POSTO VIP
