Workbook

Sheet RESUMO
A1: NOME DA OBRA
B5: JAN | C5: FEV | D5: MAR | E5: ABR | F5: MAI | G5: JUN | H5: JUL | I5: AGO | J5: SET | K5: OUT | L5: NOV | M5: DEZ
A6: ABASTECIMENTO | B6: =SUM('Controle Central'!D4+'Controle Central'!K4+'Controle Central'!R4+'Controle Central'!Y4+'Controle Central'!D23+'Controle Central'!K23+'Controle Central'!R23+'Controle Central'!Y23+'Controle Central'!D42+'Controle Central'!K42+'Controle Central'!R42+'Controle Central'!Y42+'Controle Central'!D61+'Controle Central'!K61+'Controle Central'!R61+'Controle Central'!Y61+'Controle Central'!D80+'Controle Central'!K80+'Controle Central'!R80+'Controle Central'!Y80+'Controle Central'!D98+'Controle Central'!K98+'Controle Central'!R98+'Controle Central'!Y98+'Controle Central'!D116+'Controle Central'!K116+'Controle Central'!R116+'Controle Central'!Y116+'Controle Central'!D134+'Controle Central'!K134) -> 0 | C6: =SUM('Controle Central'!D5+'Controle Central'!K5+'Controle Central'!R5+'Controle Central'!Y5+'Controle Central'!D24+'Controle Central'!K24+'Controle Central'!R24+'Controle Central'!Y24+'Controle Central'!D43+'Controle Central'!K43+'Controle Central'!R43+'Controle Central'!Y43+'Controle Central'!D62+'Controle Central'!K62+'Controle Central'!R62+'Controle Central'!Y62+'Controle Central'!D81+'Controle Central'!K81+'Controle Central'!R81+'Controle Central'!D99+'Controle Central'!K99+'Controle Central'!R99+'Controle Central'!Y99+'Controle Central'!D117+'Controle Central'!K117+'Controle Central'!R117+'Controle Central'!Y117+'Controle Central'!D135+'Controle Central'!K135) -> 0 | D6: =SUM('Controle Central'!D6+'Controle Central'!K6+'Controle Central'!R6+'Controle Central'!Y6+'Controle Central'!D25+'Controle Central'!K25+'Controle Central'!R25+'Controle Central'!Y25+'Controle Central'!D44+'Controle Central'!K44+'Controle Central'!R44+'Controle Central'!Y44+'Controle Central'!D63+'Controle Central'!K63+'Controle Central'!R63+'Controle Central'!Y63+'Controle Central'!D82+'Controle Central'!K82+'Controle Central'!R82+'Controle Central'!Y82+'Controle Central'!D100+'Controle Central'!K100+'Controle Central'!R100+'Controle Central'!Y100+'Controle Central'!D118+'Controle Central'!K118+'Controle Central'!R118+'Controle Central'!Y118+'Controle Central'!D136+'Controle Central'!K136) -> 0 | E6: ='Controle Central'!D7+'Controle Central'!K7+'Controle Central'!R7+'Controle Central'!Y7+'Controle Central'!D26+'Controle Central'!K26+'Controle Central'!R26+'Controle Central'!Y26+'Controle Central'!D45+'Controle Central'!K45+'Controle Central'!R45+'Controle Central'!Y45+'Controle Central'!D64+'Controle Central'!K64+'Controle Central'!R64+'Controle Central'!D83+'Controle Central'!K83+'Controle Central'!R83+'Controle Central'!Y83+'Controle Central'!D101+'Controle Central'!K101+'Controle Central'!R101+'Controle Central'!Y101+'Controle Central'!D119+'Controle Central'!K119+'Controle Central'!R119+'Controle Central'!Y119+'Controle Central'!D137+'Controle Central'!K137 -> 0 | F6: =SUM('Controle Central'!D8+'Controle Central'!K8+'Controle Central'!R8+'Controle Central'!Y8+'Controle Central'!D27+'Controle Central'!K27+'Controle Central'!R27+'Controle Central'!Y27+'Controle Central'!D46+'Controle Central'!K46+'Controle Central'!R46+'Controle Central'!Y46+'Controle Central'!D65+'Controle Central'!K65+'Controle Central'!R65+'Controle Central'!Y65+'Controle Central'!D84+'Controle Central'!K84+'Controle Central'!R84+'Controle Central'!Y84+'Controle Central'!D102+'Controle Central'!K102+'Controle Central'!R102+'Controle Central'!Y102+'Controle Central'!D120+'Controle Central'!K120+'Controle Central'!R120+'Controle Central'!Y120+'Controle Central'!D138+'Controle Central'!K138) -> 0 | G6: =SUM('Controle Central'!D9+'Controle Central'!K9+'Controle Central'!R9+'Controle Central'!Y9+'Controle Central'!D28+'Controle Central'!K28+'Controle Central'!R28+'Controle Central'!Y28+'Controle Central'!D47+'Controle Central'!K47+'Controle Central'!R47+'Controle Central'!Y47+'Controle Central'!D66+'Controle Central'!K66+'Controle Central'!R66+'Controle Central'!Y66+'Controle Central'!D85+'Controle Central'!K85+'Controle Central'!R85+'Controle Central'!Y85+'Controle Central'!D103+'Controle Central'!K103+'Controle Central'!R103+'Controle Central'!Y103+'Controle Central'!D121+'Controle Central'!K121+'Controle Central'!R121+'Controle Central'!Y121+'Controle Central'!D139+'Controle Central'!K139) -> 0 | H6: =SUM('Controle Central'!D10+'Controle Central'!K10+'Controle Central'!R10+'Controle Central'!Y10+'Controle Central'!D29+'Controle Central'!K29+'Controle Central'!R29+'Controle Central'!D48+'Controle Central'!K48+'Controle Central'!R48+'Controle Central'!Y48+'Controle Central'!D67+'Controle Central'!K67+'Controle Central'!R67+'Controle Central'!Y67+'Controle Central'!D86+'Controle Central'!K86+'Controle Central'!R86+'Controle Central'!Y86+'Controle Central'!D104+'Controle Central'!K104+'Controle Central'!R104+'Controle Central'!Y104+'Controle Central'!D122+'Controle Central'!K122+'Controle Central'!R122+'Controle Central'!Y122+'Controle Central'!D140+'Controle Central'!K140) -> 2201.95 | I6: =SUM('Controle Central'!D11+'Controle Central'!K11+'Controle Central'!R11+'Controle Central'!Y11+'Controle Central'!D30+'Controle Central'!K30+'Controle Central'!R30+'Controle Central'!Y30+'Controle Central'!D49+'Controle Central'!K49+'Controle Central'!R49+'Controle Central'!Y49+'Controle Central'!D68+'Controle Central'!K68+'Controle Central'!R68+'Controle Central'!Y68+'Controle Central'!D87+'Controle Central'!K87+'Controle Central'!R87+'Controle Central'!Y87+'Controle Central'!D105+'Controle Central'!K105+'Controle Central'!R105+'Controle Central'!Y105+'Controle Central'!D123+'Controle Central'!K123+'Controle Central'!R123+'Controle Central'!Y123+'Controle Central'!D141+'Controle Central'!K141) -> 3396.83 | J6: =SUM('Controle Central'!D12+'Controle Central'!K12+'Controle Central'!R12+'Controle Central'!Y12+'Controle Central'!D31+'Controle Central'!K31+'Controle Central'!R31+'Controle Central'!Y31+'Controle Central'!D50+'Controle Central'!K50+'Controle Central'!R50+'Controle Central'!Y50+'Controle Central'!D69+'Controle Central'!K69+'Controle Central'!R69+'Controle Central'!Y69+'Controle Central'!D88+'Controle Central'!K88+'Controle Central'!R88+'Controle Central'!Y88+'Controle Central'!D106+'Controle Central'!K106+'Controle Central'!R106+'Controle Central'!Y106+'Controle Central'!D124+'Controle Central'!K124+'Controle Central'!R124+'Controle Central'!Y124+'Controle Central'!D142+'Controle Central'!K142) -> 3567.35 | K6: =SUM('Controle Central'!D13+'Controle Central'!K13+'Controle Central'!R13+'Controle Central'!Y13+'Controle Central'!D32+'Controle Central'!K32+'Controle Central'!R32+'Controle Central'!Y32+'Controle Central'!D51+'Controle Central'!K51+'Controle Central'!R51+'Controle Central'!Y51+'Controle Central'!D70+'Controle Central'!K70+'Controle Central'!R70+'Controle Central'!Y70+'Controle Central'!D89+'Controle Central'!K89+'Controle Central'!R89+'Controle Central'!Y89+'Controle Central'!D107+'Controle Central'!K107+'Controle Central'!R107+'Controle Central'!Y107+'Controle Central'!D125+'Controle Central'!K125+'Controle Central'!R125+'Controle Central'!Y125+'Controle Central'!D143+'Controle Central'!K143) -> 3736.15 | L6: =SUM('Controle Central'!D14+'Controle Central'!K14+'Controle Central'!R14+'Controle Central'!Y14+'Controle Central'!D33+'Controle Central'!K33+'Controle Central'!R33+'Controle Central'!Y33+'Controle Central'!D52+'Controle Central'!K52+'Controle Central'!R52+'Controle Central'!Y52+'Controle Central'!D71+'Controle Central'!K71+'Controle Central'!R71+'Controle Central'!Y71+'Controle Central'!D90+'Controle Central'!K90+'Controle Central'!R90+'Controle Central'!Y90+'Controle Central'!D108+'Controle Central'!K108+'Controle Central'!R108+'Controle Central'!Y108+'Controle Central'!D126+'Controle Central'!K126+'Controle Central'!R126+'Controle Central'!Y126+'Controle Central'!D144+'Controle Central'!K144) -> 2952.15 | M6: =SUM('Controle Central'!D15+'Controle Central'!K15+'Controle Central'!R15+'Controle Central'!Y15+'Controle Central'!D34+'Controle Central'!K34+'Controle Central'!R34+'Controle Central'!Y34+'Controle Central'!D53+'Controle Central'!K53+'Controle Central'!R53+'Controle Central'!Y53+'Controle Central'!D72+'Controle Central'!K72+'Controle Central'!R72+'Controle Central'!Y72+'Controle Central'!D91+'Controle Central'!K91+'Controle Central'!R91+'Controle Central'!Y91+'Controle Central'!D109+'Controle Central'!K109+'Controle Central'!R109+'Controle Central'!Y109+'Controle Central'!D127+'Controle Central'!K127+'Controle Central'!R127+'Controle Central'!Y127+'Controle Central'!D145+'Controle Central'!K145) -> 2149.43
A8: LAVA_RAPIDO | B8: =SUM('Controle Central'!E4+'Controle Central'!L4+'Controle Central'!S4+'Controle Central'!Z4+'Controle Central'!E23+'Controle Central'!L23+'Controle Central'!S23+'Controle Central'!Z23+'Controle Central'!E42+'Controle Central'!L42+'Controle Central'!S42+'Controle Central'!Z42+'Controle Central'!E61+'Controle Central'!L61+'Controle Central'!S61+'Controle Central'!Z61+'Controle Central'!E80+'Controle Central'!L80+'Controle Central'!S80+'Controle Central'!Z80+'Controle Central'!E98+'Controle Central'!L98+'Controle Central'!S98+'Controle Central'!Z98+'Controle Central'!E116+'Controle Central'!L116+'Controle Central'!S116+'Controle Central'!Z116+'Controle Central'!E134+'Controle Central'!L134) -> 0 | C8: =SUM('Controle Central'!E5,'Controle Central'!L5,'Controle Central'!S5,'Controle Central'!Z5,'Controle Central'!E24,'Controle Central'!L24,'Controle Central'!S24,'Controle Central'!Z24,'Controle Central'!E43,'Controle Central'!L43,'Controle Central'!S43,'Controle Central'!Z43,'Controle Central'!E62,'Controle Central'!L62,'Controle Central'!S62,'Controle Central'!Z62,'Controle Central'!E81,'Controle Central'!L81,'Controle Central'!S81,'Controle Central'!Z81,'Controle Central'!E99,'Controle Central'!L99,'Controle Central'!S99,'Controle Central'!Z99,'Controle Central'!E117,'Controle Central'!L117,'Controle Central'!S117,'Controle Central'!Z117,'Controle Central'!E135,'Controle Central'!L135) -> 0 | D8: =SUM('Controle Central'!E6,'Controle Central'!L6,'Controle Central'!S6,'Controle Central'!Z6,'Controle Central'!E25,'Controle Central'!L25,'Controle Central'!S25,'Controle Central'!Z25,'Controle Central'!E44,'Controle Central'!L44,'Controle Central'!S44,'Controle Central'!Z44,'Controle Central'!E63,'Controle Central'!L63,'Controle Central'!S63,'Controle Central'!Z63,'Controle Central'!E82,'Controle Central'!L82,'Controle Central'!S82,'Controle Central'!Z82,'Controle Central'!E100,'Controle Central'!L100,'Controle Central'!S100,'Controle Central'!Z100,'Controle Central'!E118,'Controle Central'!L118,'Controle Central'!S118,'Controle Central'!Z118,'Controle Central'!E136,'Controle Central'!L136) -> 0 | E8: =SUM('Controle Central'!E7,'Controle Central'!L7,'Controle Central'!S7,'Controle Central'!Z7,'Controle Central'!E26,'Controle Central'!L26,'Controle Central'!S26,'Controle Central'!Z26,'Controle Central'!E45,'Controle Central'!L45,'Controle Central'!S45,'Controle Central'!Z45,'Controle Central'!E64,'Controle Central'!L64,'Controle Central'!S64,'Controle Central'!Z64,'Controle Central'!E83,'Controle Central'!L83,'Controle Central'!S83,'Controle Central'!Z83,'Controle Central'!E101,'Controle Central'!L101,'Controle Central'!S101,'Controle Central'!Z101,'Controle Central'!E119,'Controle Central'!L119,'Controle Central'!S119,'Controle Central'!Z119,'Controle Central'!E137,'Controle Central'!L137) -> 0 | F8: =SUM('Controle Central'!E8,'Controle Central'!L8,'Controle Central'!S8,'Controle Central'!Z8,'Controle Central'!E27,'Controle Central'!L27,'Controle Central'!S27,'Controle Central'!Z27,'Controle Central'!E46,'Controle Central'!L46,'Controle Central'!S46,'Controle Central'!Z46,'Controle Central'!E65,'Controle Central'!L65,'Controle Central'!S65,'Controle Central'!Z65,'Controle Central'!E84,'Controle Central'!L84,'Controle Central'!S84,'Controle Central'!Z84,'Controle Central'!E102,'Controle Central'!L102,'Controle Central'!S102,'Controle Central'!Z102,'Controle Central'!E120,'Controle Central'!L120,'Controle Central'!S120,'Controle Central'!Z120,'Controle Central'!E138,'Controle Central'!L138) -> 0 | G8: =SUM('Controle Central'!E9,'Controle Central'!L9,'Controle Central'!S9,'Controle Central'!Z9,'Controle Central'!E28,'Controle Central'!L28,'Controle Central'!S28,'Controle Central'!Z28,'Controle Central'!E47,'Controle Central'!L47,'Controle Central'!S47,'Controle Central'!Z47,'Controle Central'!E66,'Controle Central'!L66,'Controle Central'!S66,'Controle Central'!Z66,'Controle Central'!E85,'Controle Central'!L85,'Controle Central'!S85,'Controle Central'!Z85,'Controle Central'!E103,'Controle Central'!L103,'Controle Central'!S103,'Controle Central'!Z103,'Controle Central'!E121,'Controle Central'!L121,'Controle Central'!S121,'Controle Central'!Z121,'Controle Central'!E139+'Controle Central'!L139) -> 0 | H8: =SUM('Controle Central'!E10,'Controle Central'!L10,'Controle Central'!S10,'Controle Central'!Z10,'Controle Central'!E29,'Controle Central'!L29,'Controle Central'!S29,'Controle Central'!Z29,'Controle Central'!E48,'Controle Central'!L48,'Controle Central'!S48,'Controle Central'!Z48,'Controle Central'!E67,'Controle Central'!L67,'Controle Central'!S67,'Controle Central'!Z67,'Controle Central'!E86,'Controle Central'!L86,'Controle Central'!S86,'Controle Central'!Z86,'Controle Central'!E104,'Controle Central'!L104,'Controle Central'!S104,'Controle Central'!Z104,'Controle Central'!E122,'Controle Central'!L122,'Controle Central'!S122,'Controle Central'!Z122,'Controle Central'!E140,'Controle Central'!L140) -> 0 | I8: =SUM('Controle Central'!L11,'Controle Central'!S11,'Controle Central'!E11,'Controle Central'!Z11,'Controle Central'!Z30,'Controle Central'!S30,'Controle Central'!L30,'Controle Central'!E30,'Controle Central'!E49,'Controle Central'!L49,'Controle Central'!S49,'Controle Central'!Z49,'Controle Central'!Z68,'Controle Central'!S68,'Controle Central'!L68,'Controle Central'!E68,'Controle Central'!E87,'Controle Central'!L87,'Controle Central'!S87,'Controle Central'!Z87,'Controle Central'!Z105,'Controle Central'!Z123,'Controle Central'!S105,'Controle Central'!S123,'Controle Central'!L123,'Controle Central'!L105,'Controle Central'!E123,'Controle Central'!E105,'Controle Central'!E141,'Controle Central'!L141) -> 110 | J8: =SUM('Controle Central'!E12,'Controle Central'!E31,'Controle Central'!L12,'Controle Central'!L31,'Controle Central'!S12,'Controle Central'!S31,'Controle Central'!Z12,'Controle Central'!Z31,'Controle Central'!Z50,'Controle Central'!Z69,'Controle Central'!S50,'Controle Central'!S69,'Controle Central'!L50,'Controle Central'!L69,'Controle Central'!E50,'Controle Central'!E69,'Controle Central'!E88,'Controle Central'!E106,'Controle Central'!L88,'Controle Central'!L106,'Controle Central'!S88,'Controle Central'!S106,'Controle Central'!Z88,'Controle Central'!Z106,'Controle Central'!Z124,'Controle Central'!S124,'Controle Central'!L124,'Controle Central'!E124,'Controle Central'!E142,'Controle Central'!L142) -> 55 | K8: =SUM('Controle Central'!E13,'Controle Central'!L13,'Controle Central'!E32,'Controle Central'!L32,'Controle Central'!S13,'Controle Central'!S32,'Controle Central'!Z13,'Controle Central'!Z32,'Controle Central'!Z51,'Controle Central'!Z70,'Controle Central'!S51,'Controle Central'!S70,'Controle Central'!L51,'Controle Central'!L70,'Controle Central'!E51,'Controle Central'!E70,'Controle Central'!E89,'Controle Central'!E107,'Controle Central'!L89,'Controle Central'!L107,'Controle Central'!S89,'Controle Central'!S107,'Controle Central'!Z107,'Controle Central'!Z89,'Controle Central'!Z125,'Controle Central'!S125,'Controle Central'!L143,'Controle Central'!L125,'Controle Central'!E125,'Controle Central'!E143) -> 55 | L8: =SUM('Controle Central'!E14,'Controle Central'!E33,'Controle Central'!L14,'Controle Central'!L33,'Controle Central'!S14,'Controle Central'!S33,'Controle Central'!Z14,'Controle Central'!Z33,'Controle Central'!Z52,'Controle Central'!Z71,'Controle Central'!S52,'Controle Central'!S71,'Controle Central'!L52,'Controle Central'!L71,'Controle Central'!E52,'Controle Central'!E71,'Controle Central'!E90,'Controle Central'!E108,'Controle Central'!L90,'Controle Central'!L108,'Controle Central'!S90,'Controle Central'!S108,'Controle Central'!Z90,'Controle Central'!Z108,'Controle Central'!Z126,'Controle Central'!S126,'Controle Central'!L126,'Controle Central'!L144,'Controle Central'!E126,'Controle Central'!E144) -> 55 | M8: =SUM('Controle Central'!E15,'Controle Central'!E34,'Controle Central'!L15,'Controle Central'!L34,'Controle Central'!S15,'Controle Central'!S34,'Controle Central'!Z15,'Controle Central'!Z34,'Controle Central'!Z53,'Controle Central'!Z72,'Controle Central'!S53,'Controle Central'!S72,'Controle Central'!L53,'Controle Central'!L72,'Controle Central'!E53,'Controle Central'!E72,'Controle Central'!E91,'Controle Central'!E109,'Controle Central'!L91,'Controle Central'!L109,'Controle Central'!S91,'Controle Central'!S109,'Controle Central'!Z91,'Controle Central'!Z109,'Controle Central'!Z127,'Controle Central'!S127,'Controle Central'!L127,'Controle Central'!E127,'Controle Central'!E145,'Controle Central'!L145) -> 0
A10: BORRACHARIA | B10: =SUM('Controle Central'!F4,'Controle Central'!M4,'Controle Central'!M23,'Controle Central'!F23,'Controle Central'!T4,'Controle Central'!T23,'Controle Central'!AA4,'Controle Central'!AA23,'Controle Central'!AA61,'Controle Central'!AA42,'Controle Central'!T42,'Controle Central'!M42,'Controle Central'!M61,'Controle Central'!F61,'Controle Central'!F42,'Controle Central'!F98,'Controle Central'!F80,'Controle Central'!M80,'Controle Central'!M98,'Controle Central'!T80,'Controle Central'!T98,'Controle Central'!AA80,'Controle Central'!AA98,'Controle Central'!AA116,'Controle Central'!T116,'Controle Central'!M116,'Controle Central'!F116,'Controle Central'!F134,'Controle Central'!M134) -> 0 | C10: =SUM('Controle Central'!F5,'Controle Central'!F24,'Controle Central'!M5,'Controle Central'!M24,'Controle Central'!T24,'Controle Central'!T5,'Controle Central'!AA5,'Controle Central'!AA24,'Controle Central'!AA43,'Controle Central'!AA62,'Controle Central'!T43,'Controle Central'!T62,'Controle Central'!M43,'Controle Central'!M62,'Controle Central'!F43,'Controle Central'!F62,'Controle Central'!F81,'Controle Central'!F99,'Controle Central'!M99,'Controle Central'!M81,'Controle Central'!T99,'Controle Central'!T81,'Controle Central'!AA81,'Controle Central'!AA99,'Controle Central'!AA117,'Controle Central'!T117,'Controle Central'!M117,'Controle Central'!F117,'Controle Central'!F135,'Controle Central'!M135) -> 0 | D10: =SUM('Controle Central'!F6,'Controle Central'!F25,'Controle Central'!M6,'Controle Central'!M25,'Controle Central'!T6,'Controle Central'!T25,'Controle Central'!AA25,'Controle Central'!AA6,'Controle Central'!AA44,'Controle Central'!AA63,'Controle Central'!T63,'Controle Central'!T44,'Controle Central'!M44,'Controle Central'!M63,'Controle Central'!F63,'Controle Central'!F44,'Controle Central'!F82,'Controle Central'!F100,'Controle Central'!M100,'Controle Central'!M82,'Controle Central'!T82,'Controle Central'!T100,'Controle Central'!AA100,'Controle Central'!AA82,'Controle Central'!AA118,'Controle Central'!T118,'Controle Central'!M118,'Controle Central'!M136,'Controle Central'!F118,'Controle Central'!F136) -> 0 | E10: =SUM('Controle Central'!F7,'Controle Central'!F26,'Controle Central'!M26,'Controle Central'!M7,'Controle Central'!T7,'Controle Central'!T26,'Controle Central'!AA7,'Controle Central'!AA26,'Controle Central'!AA45,'Controle Central'!T45,'Controle Central'!AA64,'Controle Central'!T64,'Controle Central'!M45,'Controle Central'!M64,'Controle Central'!F45,'Controle Central'!F64,'Controle Central'!F83,'Controle Central'!F101,'Controle Central'!M83,'Controle Central'!M101,'Controle Central'!T83,'Controle Central'!T101,'Controle Central'!AA83,'Controle Central'!AA101,'Controle Central'!AA119,'Controle Central'!T119,'Controle Central'!M119,'Controle Central'!M137,'Controle Central'!F137,'Controle Central'!F119) -> 0 | F10: =SUM('Controle Central'!F8,'Controle Central'!F27,'Controle Central'!M8,'Controle Central'!M27,'Controle Central'!T8,'Controle Central'!T27,'Controle Central'!AA27,'Controle Central'!AA8,'Controle Central'!AA46,'Controle Central'!AA65,'Controle Central'!T46,'Controle Central'!T65,'Controle Central'!M65,'Controle Central'!M46,'Controle Central'!F46,'Controle Central'!F65,'Controle Central'!F84,'Controle Central'!F102,'Controle Central'!M84,'Controle Central'!M102,'Controle Central'!T84,'Controle Central'!T102,'Controle Central'!AA84,'Controle Central'!AA102,'Controle Central'!AA120,'Controle Central'!T120,'Controle Central'!M120,'Controle Central'!M138,'Controle Central'!F120,'Controle Central'!F138) -> 0 | G10: =SUM('Controle Central'!F9,'Controle Central'!F28,'Controle Central'!M9,'Controle Central'!M28,'Controle Central'!T9,'Controle Central'!T28,'Controle Central'!AA9,'Controle Central'!AA28,'Controle Central'!AA47,'Controle Central'!AA66,'Controle Central'!T47,'Controle Central'!T66,'Controle Central'!M47,'Controle Central'!M66,'Controle Central'!F47,'Controle Central'!F66,'Controle Central'!F85,'Controle Central'!F103,'Controle Central'!M85,'Controle Central'!M103,'Controle Central'!T85,'Controle Central'!T103,'Controle Central'!AA85,'Controle Central'!AA103,'Controle Central'!AA121,'Controle Central'!T121,'Controle Central'!M121,'Controle Central'!M139,'Controle Central'!F139) -> 0 | H10: =SUM('Controle Central'!F10,'Controle Central'!F29,'Controle Central'!M10,'Controle Central'!M29,'Controle Central'!T10,'Controle Central'!T29,'Controle Central'!AA10,'Controle Central'!AA29,'Controle Central'!AA48,'Controle Central'!T48,'Controle Central'!AA67,'Controle Central'!T67,'Controle Central'!M48,'Controle Central'!M67,'Controle Central'!F48,'Controle Central'!F67,'Controle Central'!F86,'Controle Central'!F104,'Controle Central'!M104,'Controle Central'!M86,'Controle Central'!T86,'Controle Central'!T104,'Controle Central'!AA86,'Controle Central'!AA104,'Controle Central'!AA122,'Controle Central'!T122,'Controle Central'!M122,'Controle Central'!M140,'Controle Central'!F122,'Controle Central'!F140) -> 0 | I10: =SUM('Controle Central'!F11,'Controle Central'!F30,'Controle Central'!M11,'Controle Central'!M30,'Controle Central'!T11,'Controle Central'!T30,'Controle Central'!AA11,'Controle Central'!AA30,'Controle Central'!AA49,'Controle Central'!AA68,'Controle Central'!T49,'Controle Central'!T68,'Controle Central'!M49,'Controle Central'!M68,'Controle Central'!F68,'Controle Central'!F49,'Controle Central'!F87,'Controle Central'!F105,'Controle Central'!M87,'Controle Central'!M105,'Controle Central'!T87,'Controle Central'!T105,'Controle Central'!AA87,'Controle Central'!AA105,'Controle Central'!AA123,'Controle Central'!T123,'Controle Central'!M123,'Controle Central'!M141,'Controle Central'!F123,'Controle Central'!F141) -> 25 | J10: =SUM('Controle Central'!F12,'Controle Central'!F31,'Controle Central'!M12,'Controle Central'!M31,'Controle Central'!T12,'Controle Central'!T31,'Controle Central'!AA12,'Controle Central'!AA31,'Controle Central'!AA50,'Controle Central'!T50,'Controle Central'!T69,'Controle Central'!AA69,'Controle Central'!M50,'Controle Central'!M69,'Controle Central'!F69,'Controle Central'!F50,'Controle Central'!F88,'Controle Central'!F106,'Controle Central'!M88,'Controle Central'!M106,'Controle Central'!T88,'Controle Central'!T106,'Controle Central'!AA88,'Controle Central'!AA106,'Controle Central'!AA124,'Controle Central'!T124,'Controle Central'!M124,'Controle Central'!F124,'Controle Central'!F142,'Controle Central'!M142) -> 40 | K10: =SUM('Controle Central'!F13,'Controle Central'!F32,'Controle Central'!M13,'Controle Central'!M32,'Controle Central'!T13,'Controle Central'!T32,'Controle Central'!AA13,'Controle Central'!AA32,'Controle Central'!AA51,'Controle Central'!T51,'Controle Central'!T70,'Controle Central'!AA70,'Controle Central'!M51,'Controle Central'!M70,'Controle Central'!F70,'Controle Central'!F51,'Controle Central'!F89,'Controle Central'!F107,'Controle Central'!M89,'Controle Central'!M107,'Controle Central'!T89,'Controle Central'!T107,'Controle Central'!AA107,'Controle Central'!AA89,'Controle Central'!AA125,'Controle Central'!T125,'Controle Central'!M125,'Controle Central'!F125,'Controle Central'!F143,'Controle Central'!M143) -> 30 | L10: =SUM('Controle Central'!F14,'Controle Central'!M14,'Controle Central'!F33,'Controle Central'!M33,'Controle Central'!T14,'Controle Central'!T33,'Controle Central'!AA33,'Controle Central'!AA14,'Controle Central'!AA52,'Controle Central'!T52,'Controle Central'!M52,'Controle Central'!M71,'Controle Central'!T71,'Controle Central'!AA71,'Controle Central'!AA90,'Controle Central'!T90,'Controle Central'!M90,'Controle Central'!F90,'Controle Central'!F108,'Controle Central'!F126,'Controle Central'!M108,'Controle Central'!M126,'Controle Central'!T108,'Controle Central'!T126,'Controle Central'!AA108,'Controle Central'!AA126,'Controle Central'!M144,'Controle Central'!F144) -> 0 | M10: =SUM('Controle Central'!F15,'Controle Central'!F34,'Controle Central'!M15,'Controle Central'!M34,'Controle Central'!T15,'Controle Central'!T34,'Controle Central'!AA15,'Controle Central'!AA34,'Controle Central'!AA53,'Controle Central'!T53,'Controle Central'!AA72,'Controle Central'!T72,'Controle Central'!M53,'Controle Central'!F53,'Controle Central'!F72,'Controle Central'!M72,'Controle Central'!F91,'Controle Central'!F109,'Controle Central'!M91,'Controle Central'!M109,'Controle Central'!T91,'Controle Central'!T109,'Controle Central'!AA91,'Controle Central'!AA109,'Controle Central'!AA127,'Controle Central'!T127,'Controle Central'!M127,'Controle Central'!M145,'Controle Central'!F127,'Controle Central'!F145) -> 0
B14: JAN | C14: FEV | D14: MAR | E14: ABR | F14: MAI | G14: JUN | H14: JUL | I14: AGO | J14: SET | K14: OUT | L14: NOV | M14: DEZ
A15: Medição
A17: Contrato de Locação
A19: Lucro Car's | B19: =B15-B17 -> 0 | C19: =C15-C17 -> 0 | D19: =D15-D17 -> 0 | E19: =E15-E17 -> 0 | F19: =F15-F17 -> 0 | G19: =G15-G17 -> 0 | H19: =H15-H17 -> 0 | I19: =I15-I17 -> 0 | ... M19: =M15-M17 -> 0

Sheet Controle Central
B2: ERIKA | I2: JOSEANE | P2: ALIRE | W2: LUCIANE
B3: KM RODADO | C3: KM MENSAL | D3: ABASTECIMENTO | E3: LAVA_RAPIDO | F3: BORRACHARIA | I3: KM RODADO | J3: KM MENSAL | K3: ABASTECIMENTO | L3: LAVA_RAPIDO | M3: BORRACHARIA | P3: KM RODADO | Q3: KM MENSAL | R3: ABASTECIMENTO | S3: LAVA_RAPIDO | T3: BORRACHARIA | W3: KM RODADO | X3: KM MENSAL | Y3: ABASTECIMENTO | Z3: LAVA_RAPIDO | AA3: BORRACHARIA
A4: JAN | C4: 0 | D4: 0 | E4: 0 | F4: 0 | H4: JAN | J4: 0 | K4: 0 | L4: 0 | M4: 0 | O4: JAN | Q4: 0 | R4: 0 | S4: 0 | T4: 0 | V4: JAN | X4: 0 | Y4: 0 | Z4: 0 | AA4: 0
A5: FEV | B5: =ELIKESTH!H11 -> 0 | C5: =SUM(5000-B5) -> 5000 | D5: =ELIKESTH!Z12 -> 0 | E5: =ELIKESTH!AJ12 -> 0 | F5: =ELIKESTH!AR12 -> 0 | H5: FEV | I5: =CAR_02!H11 -> 0 | J5: =SUM(5000-I5) -> 5000 | K5: =CAR_02!U12 -> 0 | L5: =CAR_02!AC12 -> 0 | M5: =CAR_02!AK12 -> 0 | O5: FEV | P5: =CAR_03!H11 -> 0 | Q5: =SUM(5000-P5) -> 5000 | R5: =CAR_03!U12 -> 0 | S5: =CAR_03!AI12 -> 0 | T5: =CAR_03!AR12 -> 0 | V5: FEV | W5: =CAR_04!H11 -> 0 | X5: =SUM(5000-W5) -> 5000 | Y5: =CAR_04!U12 -> 0 | Z5: =CAR_04!AI12 -> 0 | AA5: =CAR_04!AR12 -> 0
A6: MAR | B6: =ELIKESTH!H15 -> 0 | C6: =SUM(5000-B6) -> 5000 | D6: =ELIKESTH!Z16 -> 0 | E6: =ELIKESTH!AJ16 -> 0 | F6: =ELIKESTH!AR16 -> 0 | H6: MAR | I6: =CAR_02!H15 -> 0 | J6: =SUM(5000-I6) -> 5000 | K6: =CAR_02!U16 -> 0 | L6: =CAR_02!AC16 -> 0 | M6: =CAR_02!AK16 -> 0 | O6: MAR | P6: =CAR_03!H15 -> 0 | Q6: =SUM(5000-P6) -> 5000 | R6: =CAR_03!U16 -> 0 | S6: =CAR_03!AI16 -> 0 | T6: =CAR_03!AR16 -> 0 | V6: MAR | W6: =CAR_04!H15 -> 0 | X6: =SUM(5000-W6) -> 5000 | Y6: =CAR_04!U16 -> 0 | Z6: =CAR_04!AI16 -> 0 | AA6: =CAR_04!AR16 -> 0
A7: ABR | B7: =ELIKESTH!H19 -> 0 | C7: =SUM(5000-B7) -> 5000 | D7: =ELIKESTH!Z20 -> 0 | E7: =ELIKESTH!AJ20 -> 0 | F7: =ELIKESTH!AR20 -> 0 | H7: ABR | I7: =CAR_02!H19 -> 0 | J7: =SUM(5000-I7) -> 5000 | K7: =CAR_02!U20 -> 0 | L7: =CAR_02!AC20 -> 0 | M7: =CAR_02!AK20 -> 0 | O7: ABR | P7: =CAR_03!H19 -> 0 | Q7: =SUM(5000-P7) -> 5000 | R7: =CAR_03!Z20 -> 0 | S7: =CAR_03!AI20 -> 0 | T7: =CAR_03!AR20 -> 0 | V7: ABR | W7: =CAR_04!H19 -> 0 | X7: =SUM(5000-W7) -> 5000 | Y7: =CAR_04!Z20 -> 0 | Z7: =CAR_04!AI20 -> 0 | AA7: =CAR_04!AR20 -> 0
A8: MAI | B8: =ELIKESTH!H23 -> 0 | C8: =SUM(5000-B8) -> 5000 | D8: =ELIKESTH!Z24 -> 0 | E8: =ELIKESTH!AJ24 -> 0 | F8: =ELIKESTH!AR24 -> 0 | H8: MAI | I8: =CAR_02!H23 -> 0 | J8: =SUM(5000-I8) -> 5000 | K8: =CAR_02!U24 -> 0 | L8: =CAR_02!AC24 -> 0 | M8: =CAR_02!AK24 -> 0 | O8: MAI | P8: =CAR_03!H23 -> 0 | Q8: =SUM(5000-P8) -> 5000 | R8: =CAR_03!Z24 -> 0 | S8: =CAR_03!AI24 -> 0 | T8: =CAR_03!AR24 -> 0 | V8: MAI | W8: =CAR_04!H23 -> 0 | X8: =SUM(5000-W8) -> 5000 | Y8: =CAR_04!Z24 -> 0 | Z8: =CAR_04!AI24 -> 0 | AA8: =CAR_04!AR24 -> 0
A9: JUN | B9: =ELIKESTH!H27 -> 0 | C9: =SUM(5000-B9) -> 5000 | D9: =ELIKESTH!Z28 -> 0 | E9: =ELIKESTH!AJ28 -> 0 | F9: =ELIKESTH!AR28 -> 0 | H9: JUN | I9: =CAR_02!H27 -> 0 | J9: =SUM(5000-I9) -> 5000 | K9: =CAR_02!U28 -> 0 | L9: =CAR_02!AC28 -> 0 | M9: =ELIKESTH!AR28 -> 0 | O9: JUN | P9: =CAR_03!H27 -> 0 | Q9: =SUM(5000-P9) -> 5000 | R9: =CAR_03!Z28 -> 0 | S9: =CAR_03!AI28 -> 0 | T9: =CAR_03!AR28 -> 0 | V9: JUN | W9: =CAR_04!H27 -> 0 | X9: =SUM(5000-W9) -> 5000 | Y9: =CAR_04!Z28 -> 0 | Z9: =CAR_04!AI28 -> 0 | AA9: =CAR_04!AR28 -> 0
A10: JUL | B10: =ELIKESTH!H31 -> 4401 | C10: =SUM(5000-B10) -> 599 | D10: =ELIKESTH!Z32 -> 2201.95 | E10: =ELIKESTH!AJ32 -> 0 | F10: =ELIKESTH!AR32 -> 0 | H10: JUL | I10: =CAR_02!H31 -> 0 | J10: =SUM(5000-I10) -> 5000 | K10: =CAR_02!U32 -> 0 | L10: =CAR_02!AC32 -> 0 | M10: =CAR_02!AK32 -> 0 | O10: JUL | P10: =CAR_03!H31 -> 0 | Q10: =SUM(5000-P10) -> 5000 | R10: =CAR_03!Z32 -> 0 | S10: =CAR_03!AI32 -> 0 | T10: =CAR_03!AR32 -> 0 | V10: JUL | W10: =CAR_04!H31 -> 0 | X10: =SUM(5000-W10) -> 5000 | Y10: =CAR_04!Z32 -> 0 | Z10: =CAR_04!AI32 -> 0 | AA10: =CAR_04!AR32 -> 0
A11: AGO | B11: =ELIKESTH!H35 -> 7454 | C11: =SUM(5000-B11) -> -2454 | D11: =ELIKESTH!Z36 -> 3396.83 | E11: =ELIKESTH!AJ36 -> 110 | F11: =ELIKESTH!AR36 -> 25 | H11: AGO | I11: =CAR_02!H35 -> 0 | J11: =SUM(5000-I11) -> 5000 | K11: =CAR_02!U36 -> 0 | L11: =CAR_02!AC36 -> 0 | M11: =CAR_02!AK36 -> 0 | O11: AGO | P11: =CAR_03!H35 -> 0 | Q11: =SUM(5000-P11) -> 5000 | R11: =CAR_03!Z36 -> 0 | S11: =CAR_03!AI36 -> 0 | T11: =CAR_03!AR36 -> 0 | V11: AGO | W11: =CAR_04!H35 -> 0 | X11: =SUM(5000-W11) -> 5000 | Y11: =CAR_04!Z36 -> 0 | Z11: =CAR_04!AI36 -> 0 | AA11: =CAR_04!AR36 -> 0
A12: SET | B12: =ELIKESTH!H39 -> 7239 | C12: =SUM(5000-B12) -> -2239 | D12: =ELIKESTH!Z40 -> 3567.35 | E12: =ELIKESTH!AJ40 -> 55 | F12: =ELIKESTH!AR40 -> 40 | H12: SET | I12: =CAR_02!H39 -> 0 | J12: =SUM(5000-I12) -> 5000 | K12: =CAR_02!U40 -> 0 | L12: =CAR_02!AC40 -> 0 | M12: =CAR_02!AK40 -> 0 | O12: SET | P12: =CAR_03!H35 -> 0 | Q12: =SUM(5000-P12) -> 5000 | R12: =CAR_03!Z40 -> 0 | S12: =CAR_03!AI40 -> 0 | T12: =CAR_03!AR40 -> 0 | V12: SET | W12: =CAR_04!H39 -> 0 | X12: =SUM(5000-W12) -> 5000 | Y12: =CAR_04!Z40 -> 0 | Z12: =CAR_04!AI40 -> 0 | AA12: =CAR_04!AR40 -> 0
A13: OUT | B13: =ELIKESTH!H43 -> 3775 | C13: =SUM(5000-B13) -> 1225 | D13: =ELIKESTH!Z44 -> 3736.15 | E13: =ELIKESTH!AJ44 -> 55 | F13: =ELIKESTH!AR44 -> 30 | H13: OUT | I13: =CAR_02!H43 -> 0 | J13: =SUM(5000-I13) -> 5000 | K13: =CAR_02!U44 -> 0 | L13: =CAR_02!AC44 -> 0 | M13: =CAR_02!AK44 -> 0 | O13: OUT | P13: =CAR_03!H39 -> 0 | Q13: =SUM(5000-P13) -> 5000 | R13: =CAR_03!Z44 -> 0 | S13: =CAR_03!AI44 -> 0 | T13: =CAR_03!AR44 -> 0 | V13: OUT | W13: =CAR_04!H43 -> 0 | X13: =SUM(5000-W13) -> 5000 | Y13: =CAR_04!Z44 -> 0 | Z13: =CAR_04!AI44 -> 0 | AA13: =CAR_04!AR44 -> 0
A14: NOV | B14: =ELIKESTH!H47 -> 6833 | C14: =SUM(5000-B14) -> -1833 | D14: =ELIKESTH!Z48 -> 2952.15 | E14: =ELIKESTH!AJ48 -> 55 | F14: =ELIKESTH!AR48 -> 0 | H14: NOV | I14: =CAR_02!H47 -> 0 | J14: =SUM(5000-I14) -> 5000 | K14: =CAR_02!U48 -> 0 | L14: =CAR_02!AC48 -> 0 | M14: =CAR_02!AK48 -> 0 | O14: NOV | P14: =CAR_03!H43 -> 0 | Q14: =SUM(5000-P14) -> 5000 | R14: =CAR_03!Z48 -> 0 | S14: =CAR_03!AI48 -> 0 | T14: =CAR_03!AR48 -> 0 | V14: NOV | W14: =CAR_04!H47 -> 0 | X14: =SUM(5000-W14) -> 5000 | Y14: =CAR_04!Z48 -> 0 | Z14: =CAR_04!AI48 -> 0 | AA14: =CAR_04!AR48 -> 0
A15: DEZ | B15: =ELIKESTH!H51 -> 5144 | C15: =SUM(5000-B15) -> -144 | D15: =ELIKESTH!Z52 -> 2149.43 | E15: =ELIKESTH!AJ52 -> 0 | F15: =ELIKESTH!AR52 -> 0 | H15: DEZ | I15: =CAR_02!H51 -> 0 | J15: =SUM(5000-I15) -> 5000 | K15: =CAR_02!U52 -> 0 | L15: =CAR_02!AC48 -> 0 | M15: =CAR_02!AK48 -> 0 | O15: DEZ | P15: =CAR_03!H47 -> 0 | Q15: =SUM(5000-P15) -> 5000 | R15: =CAR_03!Z52 -> 0 | S15: =CAR_03!AI48 -> 0 | T15: =CAR_03!AR52 -> 0 | V15: DEZ | W15: =CAR_04!H51 -> 0 | X15: =SUM(5000-W15) -> 5000 | Y15: =CAR_04!Z52 -> 0 | Z15: =CAR_04!AI52 -> 0 | AA15: =CAR_04!AR52 -> 0
A17: TOTAL | B17: =SUM(B4:B15) -> 34846 | D17: =SUM(D4:D15) -> 18003.86 | E17: =SUM(E4:E15) -> 275 | F17: =SUM(F4:F15) -> 95 | H17: TOTAL | I17: =SUM(I4:I15) -> 0 | K17: =SUM(K4:K15) -> 0 | L17: =SUM(L4:L15) -> 0 | M17: =SUM(M4:M15) -> 0 | O17: TOTAL | P17: =SUM(P4:P15) -> 0 | R17: =SUM(R4:R15) -> 0 | S17: =SUM(S4:S15) -> 0 | T17: =SUM(T4:T15) -> 0 | V17: TOTAL | W17: =SUM(W4:W15) -> 0 | Y17: =SUM(Y4:Y15) -> 0 | Z17: =SUM(Z4:Z15) -> 0 | AA17: =SUM(AA4:AA15) -> 0
A18: SALDO KM | B18: =SUM(60000-B17) -> 25154 | H18: SALDO KM | I18: =SUM(60000-I17) -> 60000 | O18: SALDO KM | P18: =SUM(60000-P17) -> 60000 | V18: SALDO KM | W18: =SUM(60000-W17) -> 60000
B21: CAR_05 | I21: CAR_06 | P21: CAR_07 | W21: CAR_08
B22: KM RODADO | C22: KM MENSAL | D22: ABASTECIMENTO | E22: LAVA_RAPIDO | F22: BORRACHARIA | I22: KM RODADO | J22: KM MENSAL | K22: ABASTECIMENTO | L22: LAVA_RAPIDO | M22: BORRACHARIA | P22: KM RODADO | Q22: KM MENSAL | R22: ABASTECIMENTO | S22: LAVA_RAPIDO | T22: BORRACHARIA | W22: KM RODADO | X22: KM MENSAL | Y22: ABASTECIMENTO | Z22: LAVA_RAPIDO | AA22: BORRACHARIA
A23: JAN | C23: 0 | D23: 0 | E23: 0 | F23: 0 | H23: JAN | J23: 0 | K23: 0 | L23: 0 | M23: 0 | O23: JAN | Q23: 0 | R23: 0 | S23: 0 | T23: 0 | V23: JAN | X23: 0 | Y23: 0 | Z23: 0 | AA23: 0
A24: FEV | B24: =CAR_05!H11 -> 0 | C24: =SUM(5000-B24) -> 5000 | D24: =CAR_05!U12 -> 0 | E24: =CAR_05!AC12 -> 0 | F24: =CAR_05!AK12 -> 0 | H24: FEV | I24: =CAR_06!H11 -> 0 | J24: =SUM(5000-I24) -> 5000 | K24: =CAR_06!U12 -> 0 | L24: =CAR_06!AC12 -> 0 | M24: =CAR_06!AK12 -> 0 | O24: FEV | P24: =CAR_07!H11 -> 0 | Q24: =SUM(5000-P24) -> 5000 | R24: =CAR_07!U12 -> 0 | S24: =CAR_07!AC12 -> 0 | T24: =CAR_07!AK12 -> 0 | V24: FEV | W24: =CAR_08!H11 -> 0 | X24: =SUM(5000-W24) -> 5000 | Y24: =CAR_08!U12 -> 0 | Z24: =CAR_08!AE12 -> 0 | AA24: =CAR_08!AN12 -> 0
A25: MAR | B25: =CAR_05!H15 -> 0 | C25: =SUM(5000-B25) -> 5000 | D25: =CAR_05!U16 -> 0 | E25: =CAR_05!AC16 -> 0 | F25: =CAR_05!AK16 -> 0 | H25: MAR | I25: =CAR_06!H15 -> 0 | J25: =SUM(5000-I25) -> 5000 | K25: =CAR_06!U16 -> 0 | L25: =CAR_06!AC16 -> 0 | M25: =CAR_06!AK16 -> 0 | O25: MAR | P25: =CAR_07!H15 -> 0 | Q25: =SUM(5000-P25) -> 5000 | R25: =CAR_07!U16 -> 0 | S25: =CAR_07!AC16 -> 0 | T25: =CAR_07!AK16 -> 0 | V25: MAR | W25: =CAR_08!H15 -> 0 | X25: =SUM(5000-W25) -> 5000 | Y25: =CAR_08!U16 -> 0 | Z25: =CAR_08!AE16 -> 0 | AA25: =CAR_08!AN16 -> 0
A26: ABR | B26: =CAR_05!H19 -> 0 | C26: =SUM(5000-B26) -> 5000 | D26: =CAR_05!U20 -> 0 | E26: =CAR_05!AC20 -> 0 | F26: =CAR_05!AK20 -> 0 | H26: ABR | I26: =CAR_06!H19 -> 0 | J26: =SUM(5000-I26) -> 5000 | K26: =CAR_06!U20 -> 0 | L26: =CAR_06!AC20 -> 0 | M26: =CAR_06!AK20 -> 0 | O26: ABR | P26: =CAR_07!H19 -> 0 | Q26: =SUM(5000-P26) -> 5000 | R26: =CAR_07!U20 -> 0 | S26: =CAR_07!AC20 -> 0 | T26: =CAR_07!AK20 -> 0 | V26: ABR | W26: =CAR_08!H19 -> 0 | X26: =SUM(5000-W26) -> 5000 | Y26: =CAR_08!U200 -> 0 | Z26: =CAR_08!AE20 -> 0 | AA26: =CAR_08!AN200 -> 0
A27: MAI | B27: =CAR_05!H23 -> 0 | C27: =SUM(5000-B27) -> 5000 | D27: =CAR_05!U24 -> 0 | E27: =CAR_05!AC24 -> 0 | F27: =CAR_05!AK24 -> 0 | H27: MAI | I27: =CAR_06!H23 -> 0 | J27: =SUM(5000-I27) -> 5000 | K27: =CAR_06!U24 -> 0 | L27: =CAR_06!AC24 -> 0 | M27: =CAR_06!AK24 -> 0 | O27: MAI | P27: =CAR_07!H23 -> 0 | Q27: =SUM(5000-P27) -> 5000 | R27: =CAR_07!U24 -> 0 | S27: =CAR_07!AC24 -> 0 | T27: =CAR_07!AK24 -> 0 | V27: MAI | W27: =CAR_08!H23 -> 0 | X27: =SUM(5000-W27) -> 5000 | Y27: =CAR_08!U24 -> 0 | Z27: =CAR_08!AE24 -> 0 | AA27: =CAR_08!AN24 -> 0
A28: JUN | B28: =CAR_05!H27 -> 0 | C28: =SUM(5000-B28) -> 5000 | D28: =CAR_05!U28 -> 0 | E28: =CAR_05!AC28 -> 0 | F28: =CAR_05!AK28 -> 0 | H28: JUN | I28: =CAR_06!H27 -> 0 | J28: =SUM(5000-I28) -> 5000 | K28: =CAR_06!U28 -> 0 | L28: =CAR_06!AC28 -> 0 | M28: =CAR_06!AK28 -> 0 | O28: JUN | P28: =CAR_07!H27 -> 0 | Q28: =SUM(5000-P28) -> 5000 | R28: =CAR_07!U28 -> 0 | S28: =CAR_07!AC28 -> 0 | T28: =CAR_07!AK28 -> 0 | V28: JUN | W28: =CAR_08!H27 -> 0 | X28: =SUM(5000-W28) -> 5000 | Y28: =CAR_08!U28 -> 0 | Z28: =CAR_08!AE28 -> 0 | AA28: =CAR_08!AN28 -> 0
A29: JUL | B29: =CAR_05!H31 -> 0 | C29: =SUM(5000-B29) -> 5000 | D29: =CAR_05!U32 -> 0 | E29: =CAR_05!AC32 -> 0 | F29: =CAR_05!AK32 -> 0 | H29: JUL | I29: =CAR_06!H31 -> 0 | J29: =SUM(5000-I29) -> 5000 | K29: =CAR_06!U32 -> 0 | L29: =CAR_06!AC32 -> 0 | M29: =CAR_06!AK32 -> 0 | O29: JUL | P29: =CAR_07!H31 -> 0 | Q29: =SUM(5000-P29) -> 5000 | R29: =CAR_07!U32 -> 0 | S29: =CAR_07!AC32 -> 0 | T29: =CAR_07!AK32 -> 0 | V29: JUL | W29: =CAR_08!H31 -> 0 | X29: =SUM(5000-W29) -> 5000 | Y29: =CAR_08!U32 -> 0 | Z29: =CAR_08!AE32 -> 0 | AA29: =CAR_08!AN32 -> 0
A30: AGO | B30: =CAR_05!H35 -> 0 | C30: =SUM(5000-B30) -> 5000 | D30: =CAR_05!U36 -> 0 | E30: =CAR_05!AC36 -> 0 | F30: =CAR_05!AK36 -> 0 | H30: AGO | I30: =CAR_06!H35 -> 0 | J30: =SUM(5000-I30) -> 5000 | K30: =CAR_06!U36 -> 0 | L30: =CAR_06!AC36 -> 0 | M30: =CAR_06!AK36 -> 0 | O30: AGO | P30: =CAR_07!H35 -> 0 | Q30: =SUM(5000-P30) -> 5000 | R30: =CAR_07!U36 -> 0 | S30: =CAR_07!AC36 -> 0 | T30: =CAR_07!AK36 -> 0 | V30: AGO | W30: =CAR_08!H35 -> 0 | X30: =SUM(5000-W30) -> 5000 | Y30: =CAR_08!U36 -> 0 | Z30: =CAR_08!AE36 -> 0 | AA30: =CAR_08!AN36 -> 0
A31: SET | B31: =CAR_05!H39 -> 0 | C31: =SUM(5000-B31) -> 5000 | D31: =CAR_05!U40 -> 0 | E31: =CAR_05!AC40 -> 0 | F31: =CAR_05!AK4 -> 0 | H31: SET | I31: =CAR_06!H39 -> 0 | J31: =SUM(5000-I31) -> 5000 | K31: =CAR_06!U40 -> 0 | L31: =CAR_06!AC40 -> 0 | M31: =CAR_06!AK40 -> 0 | O31: SET | P31: =CAR_07!H39 -> 0 | Q31: =SUM(5000-P31) -> 5000 | R31: =CAR_07!U40 -> 0 | S31: =CAR_07!AC40 -> 0 | T31: =CAR_07!AK40 -> 0 | V31: SET | W31: =CAR_08!H39 -> 0 | X31: =SUM(5000-W31) -> 5000 | Y31: =CAR_08!U40 -> 0 | Z31: =CAR_08!AE40 -> 0 | AA31: =CAR_08!AN40 -> 0
A32: OUT | B32: =CAR_05!H43 -> 0 | C32: =SUM(5000-B32) -> 5000 | D32: =CAR_05!U44 -> 0 | E32: =CAR_05!AC44 -> 0 | F32: =CAR_05!AK44 -> 0 | H32: OUT | I32: =CAR_06!H43 -> 0 | J32: =SUM(5000-I32) -> 5000 | K32: =CAR_06!U44 -> 0 | L32: =CAR_06!AC44 -> 0 | M32: =CAR_06!AK44 -> 0 | O32: OUT | P32: =CAR_07!H43 -> 0 | Q32: =SUM(5000-P32) -> 5000 | R32: =CAR_07!U44 -> 0 | S32: =CAR_07!AC44 -> 0 | T32: =CAR_07!AK44 -> 0 | V32: OUT | W32: =CAR_08!H43 -> 0 | X32: =SUM(5000-W32) -> 5000 | Y32: =CAR_08!U44 -> 0 | Z32: =CAR_08!AE44 -> 0 | AA32: =CAR_08!AN44 -> 0
A33: NOV | B33: =CAR_05!H47 -> 0 | C33: =SUM(5000-B33) -> 5000 | D33: =CAR_05!U48 -> 0 | E33: =CAR_05!AC48 -> 0 | F33: =CAR_05!AK48 -> 0 | H33: NOV | I33: =CAR_06!H47 -> 0 | J33: =SUM(5000-I33) -> 5000 | K33: =CAR_06!U48 -> 0 | L33: =CAR_06!AC48 -> 0 | M33: =CAR_06!AK48 -> 0 | O33: NOV | P33: =CAR_07!H47 -> 0 | Q33: =SUM(5000-P33) -> 5000 | R33: =CAR_07!U48 -> 0 | S33: =CAR_07!AC48 -> 0 | T33: =CAR_07!AK48 -> 0 | V33: NOV | W33: =CAR_08!H47 -> 0 | X33: =SUM(5000-W33) -> 5000 | Y33: =CAR_08!U48 -> 0 | Z33: =CAR_08!AE48 -> 0 | AA33: =CAR_08!AN48 -> 0
A34: DEZ | B34: =CAR_05!H51 -> 0 | C34: =SUM(5000-B34) -> 5000 | D34: =CAR_05!U52 -> 0 | E34: =CAR_05!AC52 -> 0 | F34: =CAR_05!AK52 -> 0 | H34: DEZ | I34: =CAR_06!H51 -> 0 | J34: =SUM(5000-I34) -> 5000 | K34: =CAR_06!U52 -> 0 | L34: =CAR_06!AC52 -> 0 | M34: =CAR_06!AK52 -> 0 | O34: DEZ | P34: =CAR_07!H51 -> 0 | Q34: =SUM(5000-P34) -> 5000 | R34: =CAR_07!U52 -> 0 | S34: =CAR_07!AC52 -> 0 | T34: =CAR_07!AK52 -> 0 | V34: DEZ | W34: =CAR_08!H51 -> 0 | X34: =SUM(5000-W34) -> 5000 | Y34: =CAR_08!U52 -> 0 | Z34: =CAR_08!AE52 -> 0 | AA34: =CAR_08!AN52 -> 0
A36: TOTAL | B36: =SUM(B23:B34) -> 0 | D36: =SUM(D23:D34) -> 0 | E36: =SUM(E23:E34) -> 0 | F36: =SUM(F23:F34) -> 0 | H36: TOTAL | I36: =SUM(I23:I34) -> 0 | K36: =SUM(K23:K34) -> 0 | L36: =SUM(L23:L34) -> 0 | M36: =SUM(M23:M34) -> 0 | O36: TOTAL | P36: =SUM(P23:P34) -> 0 | R36: =SUM(R23:R34) -> 0 | S36: =SUM(S23:S34) -> 0 | T36: =SUM(T23:T34) -> 0 | V36: TOTAL | W36: =SUM(W23:W34) -> 0 | Y36: =SUM(Y23:Y34) -> 0 | Z36: =SUM(Z23:Z34) -> 0 | AA36: =SUM(AA23:AA34) -> 0
A37: SALDO KM | B37: =SUM(60000-B36) -> 60000 | H37: SALDO KM | I37: =SUM(60000-I36) -> 60000 | O37: SALDO KM | P37: =SUM(60000-P36) -> 60000 | V37: SALDO KM | W37: =SUM(60000-W36) -> 60000
B40: CAR_09 | I40: CAR_10 | P40: CAR_11 | W40: CAR_12
B41: KM | C41: KM MENSAL | D41: ABASTECIMENTO | E41: LAVA_RAPIDO | F41: BORRACHARIA | I41: KM | J41: KM MENSAL | K41: ABASTECIMENTO | L41: LAVA_RAPIDO | M41: BORRACHARIA | P41: KM | Q41: KM MENSAL | R41: ABASTECIMENTO | S41: LAVA_RAPIDO | T41: BORRACHARIA | W41: KM | X41: KM MENSAL | Y41: ABASTECIMENTO | Z41: LAVA_RAPIDO | AA41: BORRACHARIA
A42: JAN | H42: JAN | O42: JAN | V42: JAN
A43: FEV | B43: =CAR_09!H11 -> 0 | C43: =SUM(5000-B43) -> 5000 | D43: =CAR_09!U12 -> 0 | E43: =CAR_09!AE12 -> 0 | F43: =CAR_09!AN12 -> 0 | H43: FEV | I43: =CAR_10!H11 -> 0 | J43: =SUM(5000-I43) -> 5000 | K43: =CAR_10!U12 -> 0 | L43: =CAR_10!AE12 -> 0 | M43: =CAR_10!AN12 -> 0 | O43: FEV | P43: =CAR_11!H11 -> 0 | Q43: =SUM(5000-P43) -> 5000 | R43: =CAR_11!U12 -> 0 | S43: =CAR_11!AE12 -> 0 | T43: =CAR_11!AN12 -> 0 | V43: FEV | W43: =CAR_12!H11 -> 0 | X43: =SUM(5000-W43) -> 5000 | Y43: =CAR_12!U12 -> 0 | Z43: =CAR_12!AE12 -> 0 | AA43: =CAR_12!AN12 -> 0
A44: MAR | B44: =CAR_09!H15 -> 0 | C44: =SUM(5000-B44) -> 5000 | D44: =CAR_09!U16 -> 0 | E44: =CAR_09!AE16 -> 0 | F44: =CAR_09!AN16 -> 0 | H44: MAR | I44: =CAR_10!H15 -> 0 | J44: =SUM(5000-I44) -> 5000 | K44: =CAR_10!U16 -> 0 | L44: =CAR_10!AE16 -> 0 | M44: =CAR_10!AN16 -> 0 | O44: MAR | P44: =CAR_11!H15 -> 0 | Q44: =SUM(5000-P44) -> 5000 | R44: =CAR_11!U16 -> 0 | S44: =CAR_11!AE16 -> 0 | T44: =CAR_11!AN16 -> 0 | V44: MAR | W44: =CAR_12!H15 -> 0 | X44: =SUM(5000-W44) -> 5000 | Y44: =CAR_12!U16 -> 0 | Z44: =CAR_12!AE16 -> 0 | AA44: =CAR_12!AN16 -> 0
A45: ABR | B45: =CAR_09!H19 -> 0 | C45: =SUM(5000-B45) -> 5000 | D45: =CAR_09!U20 -> 0 | E45: =CAR_09!AE20 -> 0 | F45: =CAR_09!AN20 -> 0 | H45: ABR | I45: =CAR_10!H19 -> 0 | J45: =SUM(5000-I45) -> 5000 | K45: =CAR_10!U20 -> 0 | L45: =CAR_10!AE20 -> 0 | M45: =CAR_10!AN20 -> 0 | O45: ABR | P45: =CAR_11!H19 -> 0 | Q45: =SUM(5000-P45) -> 5000 | R45: =CAR_11!U20 -> 0 | S45: =CAR_11!AE20 -> 0 | T45: =CAR_11!AN20 -> 0 | V45: ABR | W45: =CAR_12!H19 -> 0 | X45: =SUM(5000-W45) -> 5000 | Y45: =CAR_12!U20 -> 0 | Z45: =CAR_12!AE20 -> 0 | AA45: =CAR_12!AN20 -> 0
A46: MAI | B46: =CAR_09!H23 -> 0 | C46: =SUM(5000-B46) -> 5000 | D46: =CAR_09!U24 -> 0 | E46: =CAR_09!AE24 -> 0 | F46: =CAR_09!AN24 -> 0 | H46: MAI | I46: =CAR_10!H23 -> 0 | J46: =SUM(5000-I46) -> 5000 | K46: =CAR_10!U24 -> 0 | L46: =CAR_10!AE24 -> 0 | M46: =CAR_10!AN24 -> 0 | O46: MAI | P46: =CAR_11!H23 -> 0 | Q46: =SUM(5000-P46) -> 5000 | R46: =CAR_11!U24 -> 0 | S46: =CAR_11!AE24 -> 0 | T46: =CAR_11!AN24 -> 0 | V46: MAI | W46: =CAR_12!H23 -> 0 | X46: =SUM(5000-W46) -> 5000 | Y46: =CAR_12!U24 -> 0 | Z46: =CAR_12!AE24 -> 0 | AA46: =CAR_12!AN24 -> 0
A47: JUN | B47: =CAR_09!H27 -> 0 | C47: =SUM(5000-B47) -> 5000 | D47: =CAR_09!U28 -> 0 | E47: =CAR_09!AE28 -> 0 | F47: =CAR_09!AN28 -> 0 | H47: JUN | I47: =CAR_10!H27 -> 0 | J47: =SUM(5000-I47) -> 5000 | K47: =CAR_10!U28 -> 0 | L47: =CAR_10!AE28 -> 0 | M47: =CAR_10!AN28 -> 0 | O47: JUN | P47: =CAR_11!H27 -> 0 | Q47: =SUM(5000-P47) -> 5000 | R47: =CAR_11!U28 -> 0 | S47: =CAR_11!AE28 -> 0 | T47: =CAR_11!AN28 -> 0 | V47: JUN | W47: =CAR_12!H27 -> 0 | X47: =SUM(5000-W47) -> 5000 | Y47: =CAR_12!U28 -> 0 | Z47: =CAR_12!AE28 -> 0 | AA47: =CAR_12!AN28 -> 0
...

Sheet ELIKESTH
A2: Veiculo | B2: HB20 | D2: Placa: | E2: TDT7A83 | H2: KM | I2: 6000
A3: Substituição (data) | D3: Placa: | H3: Modelo
A4: Contrato de Locação | B4: 3314.42 | D4: Rastreador | E4: 45 | H4: Data mob. | I4: 45852
A7: REGISTRO DE KM | J7: ABASTECIMENTO | AD7: LAVA_RAPIDO | AL7: BORRACHARIA
B9: Fevereiro | J9: Fevereiro | AD9: Fevereiro | AL9: Fevereiro
A10: KM (Rodados) | B10: 1ª Leitura | C10: 2ª Leitura | D10: 3ª Leitura | E10: 4ª Leitura | F10: 15 dias Rodados | G10: 30 dias Rodados | H10: Total Mensal | J10: DATA | AD10: DATA | AL10: DATA
F11: =SUM(C11-B11) -> 0 | G11: =SUM(E11-D11) -> 0 | H11: =SUM(F11:G11) -> 0 | J11: VALOR | AD11: VALOR | AL11: VALOR
W12: TOTAL | Z12: =SUM(K11:Z11) -> 0 | AI12: TOTAL | AJ12: =SUM(AE11:AJ11) -> 0 | AQ12: TOTAL | AR12: =SUM(AM11:AR11) -> 0
B13: Março | J13: Março | AD13: =J13 -> Março | AL13: =AD13 -> Março
A14: KM (Rodados) | B14: 1ª Leitura | C14: 2ª Leitura | D14: 3ª Leitura | E14: 4ª Leitura | F14: 15 dias Rodados | G14: 30 dias Rodados | H14: Total Mensal | J14: DATA | AD14: DATA | AL14: DATA
F15: =SUM(C15-B15) -> 0 | G15: =SUM(E15-D15) -> 0 | H15: =SUM(F15:G15) -> 0 | J15: VALOR | AD15: VALOR | AL15: VALOR
W16: TOTAL | Z16: =SUM(K15:Z15) -> 0 | AI16: TOTAL | AJ16: =SUM(AE15:AJ15) -> 0 | AQ16: TOTAL | AR16: =SUM(AM15:AR15) -> 0
B17: Abril | J17: Abril | AD17: =J17 -> Abril | AL17: =AD17 -> Abril
A18: KM (Rodados) | B18: 1ª Leitura | C18: 2ª Leitura | D18: 3ª Leitura | E18: 4ª Leitura | F18: 15 dias Rodados | G18: 30 dias Rodados | H18: Total Mensal | J18: DATA | AD18: DATA | AL18: DATA
F19: =SUM(C19-B19) -> 0 | G19: =SUM(E19-D19) -> 0 | H19: =SUM(F19:G19) -> 0 | J19: VALOR | AD19: VALOR | AL19: VALOR
W20: TOTAL | Z20: =SUM(K19:Z19) -> 0 | AI20: TOTAL | AJ20: =SUM(AE19:AJ19) -> 0 | AQ20: TOTAL | AR20: =SUM(AM19:AR19) -> 0
B21: Maio | J21: Maio | AD21: =J21 -> Maio | AL21: =AD21 -> Maio
A22: KM (Rodados) | B22: 1ª Leitura | C22: 2ª Leitura | D22: 3ª Leitura | E22: 4ª Leitura | F22: 15 dias Rodados | G22: 30 dias Rodados | H22: Total Mensal | J22: DATA | AD22: DATA | AL22: DATA
F23: =SUM(C23-B23) -> 0 | G23: =SUM(E23-D23) -> 0 | H23: =SUM(F23:G23) -> 0 | J23: VALOR | AD23: VALOR | AL23: VALOR
W24: TOTAL | Z24: =SUM(K23:Z23) -> 0 | AI24: TOTAL | AJ24: =SUM(AE23:AJ23) -> 0 | AQ24: TOTAL | AR24: =SUM(AM23:AR23) -> 0
B25: Junho | J25: Junho | AD25: =J25 -> Junho | AL25: =AD25 -> Junho
A26: KM (Rodados) | B26: 1ª Leitura | C26: 2ª Leitura | D26: 3ª Leitura | E26: 4ª Leitura | F26: 15 dias Rodados | G26: 30 dias Rodados | H26: Total Mensal | J26: DATA | AD26: DATA | AL26: DATA
F27: =SUM(C27-B27) -> 0 | G27: =SUM(E27-D27) -> 0 | H27: =SUM(F27:G27) -> 0 | J27: VALOR | AD27: VALOR | AL27: VALOR
W28: TOTAL | Z28: =SUM(K27:Z27) -> 0 | AI28: TOTAL | AJ28: =SUM(AE27:AJ27) -> 0 | AQ28: TOTAL | AR28: =SUM(AM27:AR27) -> 0
B29: Julho | J29: Julho | AD29: =J29 -> Julho | AL29: =AD29 -> Julho
A30: KM (Rodados) | B30: 1ª Leitura | C30: 2ª Leitura | D30: 3ª Leitura | E30: 4ª Leitura | F30: 15 dias Rodados | G30: 30 dias Rodados | H30: Total Mensal | J30: DATA | K30: 45855 | L30: 45856 | M30: 45857 | N30: 45860 | O30: 45861 | P30: 45862 | Q30: 45866 | R30: 45868 | S30: 45869 | AD30: DATA | AL30: DATA
D31: 3700 | E31: 8101 | F31: =SUM(C31-B31) -> 0 | G31: =SUM(E31-D31) -> 4401 | H31: =SUM(F31:G31) -> 4401 | J31: VALOR | K31: 224.55 | L31: 272.4 | M31: 299.96 | N31: 200.54 | O31: 302.09 | P31: 249.03 | Q31: 223.38 | R31: 200 | S31: 230 | AD31: VALOR | AL31: VALOR
W32: TOTAL | Z32: =SUM(K31:Z31) -> 2201.95 | AI32: TOTAL | AJ32: =SUM(AE31:AJ31) -> 0 | AQ32: TOTAL | AR32: =SUM(AM31:AR31) -> 0
B33: Agosto | J33: Agosto | AD33: =J33 -> Agosto | AL33: =AD33 -> Agosto
A34: KM (Rodados) | B34: 1ª Leitura | C34: 2ª Leitura | D34: 3ª Leitura | E34: 4ª Leitura | F34: 15 dias Rodados | G34: 30 dias Rodados | H34: Total Mensal | J34: DATA | K34: 45870 | L34: 45874 | M34: 45875 | N34: 45877 | O34: 45878 | P34: 45881 | Q34: 45882 | R34: 45884 | S34: 45888 | T34: 45889 | U34: 45891 | V34: 45892 | W34: 45895 | X34: 45897 | Y34: 45898 | AD34: DATA | AE34: 45871 | AF34: 45894 | AL34: DATA | AM34: 45875
B35: 8101 | C35: 12199 | D35: 12199 | E35: 15555 | F35: =SUM(C35-B35) -> 4098 | G35: =SUM(E35-D35) -> 3356 | H35: =SUM(F35:G35) -> 7454 | J35: VALOR | K35: 234.02 | L35: 238.88 | M35: 247.01 | N35: 210 | O35: 200 | P35: 210 | Q35: 274.8 | R35: 200 | S35: 261 | T35: 210 | U35: 195.03 | V35: 218 | W35: 220.02 | X35: 222.05 | Y35: 256.02 | AD35: VALOR | AE35: 55 | AF35: 55 | AL35: VALOR | AM35: 25
W36: TOTAL | Z36: =SUM(K35:Z35) -> 3396.83 | AI36: TOTAL | AJ36: =SUM(AE35:AJ35) -> 110 | AQ36: TOTAL | AR36: =SUM(AM35:AR35) -> 25
B37: Setembro | J37: Setembro | AD37: =J37 -> Setembro | AL37: =AD37 -> Setembro
A38: KM (Rodados) | B38: 1ª Leitura | C38: 2ª Leitura | D38: 3ª Leitura | E38: 4ª Leitura | F38: 15 dias Rodados | G38: 30 dias Rodados | H38: Total Mensal | J38: DATA | K38: 45901 | L38: 45903 | M38: 45904 | N38: 45906 | O38: 45909 | P38: 45910 | Q38: 45911 | R38: 45912 | S38: 45916 | T38: 45917 | U38: 45918 | V38: 45923 | W38: 45925 | X38: 45926 | Y38: 45927 | Z38: 45930 | AD38: DATA | AE38: 45919 | AL38: DATA | AM38: 45911
B39: 15555 | C39: 19016 | D39: 19016 | E39: 22794 | F39: =SUM(C39-B39) -> 3461 | G39: =SUM(E39-D39) -> 3778 | H39: =SUM(F39:G39) -> 7239 | J39: VALOR | K39: 213 | L39: 273.43 | M39: 230 | N39: 182.01 | O39: 205.01 | P39: 270 | Q39: 234.54 | R39: 219.46 | S39: 222.02 | T39: 219.02 | U39: 238.87 | V39: 235.86 | W39: 185.05 | X39: 214.01 | Y39: 215.01 | Z39: 210.06 | AD39: VALOR | AE39: 55 | AL39: VALOR | AM39: 40
W40: TOTAL | Z40: =SUM(K39:Z39) -> 3567.35 | AI40: TOTAL | AJ40: =SUM(AE39:AJ39) -> 55 | AQ40: TOTAL | AR40: =SUM(AM39:AR39) -> 40
B41: Outubro | J41: Outubro | AD41: =J41 -> Outubro | AL41: =AD41 -> Outubro
A42: KM (Rodados) | B42: 1ª Leitura | C42: 2ª Leitura | D42: 3ª Leitura | E42: 4ª Leitura | F42: 15 dias Rodados | G42: 30 dias Rodados | H42: Total Mensal | J42: DATA | K42: 45931 | L42: 45932 | M42: 45937 | N42: 45938 | O42: 45939 | P42: 45940 | Q42: 45944 | R42: 45945 | S42: 45946 | T42: 45947 | U42: 45951 | V42: 45952 | W42: 45953 | X42: 45957 | Y42: 45958 | Z42: 45959 | AA42: 45960 | AB42: 45961 | AD42: DATA | AE42: 45941 | AL42: DATA | AM42: 45941
B43: 22794 | C43: 26569 | D43: 26569 | E43: 30715 | F43: =SUM(C43-B43) -> 3775 | H43: =SUM(F43:G43) -> 3775 | J43: VALOR | K43: 273.83 | L43: 228.08 | M43: 224.99 | N43: 261.08 | O43: 119.85 | P43: 197.37 | Q43: 195.6 | R43: 232.04 | S43: 143.14 | T43: 230.04 | U43: 203 | V43: 225 | W43: 230.05 | X43: 214.04 | Y43: 186 | Z43: 223 | AA43: 150.02 | AB43: 199.02 | AD43: VALOR | AE43: 55 | AL43: VALOR | AM43: 30
W44: TOTAL | Z44: =SUM(K43:AB43) -> 3736.15 | AI44: TOTAL | AJ44: =SUM(AE43:AJ43) -> 55 | AQ44: TOTAL | AR44: =SUM(AM43:AR43) -> 30
...

Sheet CAR_02
A2: Veiculo | D2: Placa: | H2: Medição
A3: Substituição (data) | D3: Placa: | H3: Modelo
A4: Contrato de Locação | D4: Rastreador | H4: Data mob.
A7: REGISTRO DE KM | J7: ABASTECIMENTO | W7: LAVA_RAPIDO | AE7: BORRACHARIA
B9: Fevereiro | J9: Fevereiro | W9: Fevereiro | AE9: Fevereiro
A10: KM (Rodados) | B10: 1ª Leitura | C10: 2ª Leitura | D10: 3ª Leitura | E10: 4ª Leitura | F10: 15 dias Rodados | G10: 30 dias Rodados | H10: Total Mensal | J10: DATA | W10: DATA | AE10: DATA
F11: =SUM(C11-B11) -> 0 | G11: =SUM(E11-D11) -> 0 | H11: =SUM(F11:G11) -> 0 | J11: VALOR | W11: VALOR | AE11: VALOR
T12: TOTAL | U12: =SUM(K11:U11) -> 0 | AB12: TOTAL | AC12: =SUM(X11:AC11) -> 0 | AJ12: TOTAL | AK12: =SUM(AF11:AK11) -> 0
B13: Março | J13: Março | W13: =J13 -> Março | AE13: =W13 -> Março
A14: KM (Rodados) | B14: 1ª Leitura | C14: 2ª Leitura | D14: 3ª Leitura | E14: 4ª Leitura | F14: 15 dias Rodados | G14: 30 dias Rodados | H14: Total Mensal | J14: DATA | W14: DATA | AE14: DATA
F15: =SUM(C15-B15) -> 0 | G15: =SUM(E15-D15) -> 0 | H15: =SUM(F15:G15) -> 0 | J15: VALOR | W15: VALOR | AE15: VALOR
T16: TOTAL | U16: =SUM(K15:U15) -> 0 | AB16: TOTAL | AC16: =SUM(X15:AC15) -> 0 | AJ16: TOTAL | AK16: =SUM(AF15:AK15) -> 0
B17: Abril | J17: Abril | W17: =J17 -> Abril | AE17: =W17 -> Abril
A18: KM (Rodados) | B18: 1ª Leitura | C18: 2ª Leitura | D18: 3ª Leitura | E18: 4ª Leitura | F18: 15 dias Rodados | G18: 30 dias Rodados | H18: Total Mensal | J18: DATA | W18: DATA | AE18: DATA
F19: =SUM(C19-B19) -> 0 | G19: =SUM(E19-D19) -> 0 | H19: =SUM(F19:G19) -> 0 | J19: VALOR | W19: VALOR | AE19: VALOR
T20: TOTAL | U20: =SUM(K19:U19) -> 0 | AB20: TOTAL | AC20: =SUM(X19:AC19) -> 0 | AJ20: TOTAL | AK20: =SUM(AF19:AK19) -> 0
B21: Maio | J21: Maio | W21: =J21 -> Maio | AE21: =W21 -> Maio
A22: KM (Rodados) | B22: 1ª Leitura | C22: 2ª Leitura | D22: 3ª Leitura | E22: 4ª Leitura | F22: 15 dias Rodados | G22: 30 dias Rodados | H22: Total Mensal | J22: DATA | W22: DATA | AE22: DATA
F23: =SUM(C23-B23) -> 0 | G23: =SUM(E23-D23) -> 0 | H23: =SUM(F23:G23) -> 0 | J23: VALOR | W23: VALOR | AE23: VALOR
T24: TOTAL | U24: =SUM(K23:U23) -> 0 | AB24: TOTAL | AC24: =SUM(X23:AC23) -> 0 | AJ24: TOTAL | AK24: =SUM(AF23:AK23) -> 0
B25: Junho | J25: Junho | W25: =J25 -> Junho | AE25: =W25 -> Junho
A26: KM (Rodados) | B26: 1ª Leitura | C26: 2ª Leitura | D26: 3ª Leitura | E26: 4ª Leitura | F26: 15 dias Rodados | G26: 30 dias Rodados | H26: Total Mensal | J26: DATA | W26: DATA | AE26: DATA
F27: =SUM(C27-B27) -> 0 | G27: =SUM(E27-D27) -> 0 | H27: =SUM(F27:G27) -> 0 | J27: VALOR | W27: VALOR | AE27: VALOR
T28: TOTAL | U28: =SUM(K27:U27) -> 0 | AB28: TOTAL | AC28: =SUM(X27:AC27) -> 0 | AJ28: TOTAL | AK28: =SUM(AF27:AK27) -> 0
B29: Julho | J29: Julho | W29: =J29 -> Julho | AE29: =W29 -> Julho
A30: KM (Rodados) | B30: 1ª Leitura | C30: 2ª Leitura | D30: 3ª Leitura | E30: 4ª Leitura | F30: 15 dias Rodados | G30: 30 dias Rodados | H30: Total Mensal | J30: DATA | W30: DATA | AE30: DATA
F31: =SUM(C31-B31) -> 0 | G31: =SUM(E31-D31) -> 0 | H31: =SUM(F31:G31) -> 0 | J31: VALOR | W31: VALOR | AE31: VALOR
T32: TOTAL | U32: =SUM(K31:U31) -> 0 | AB32: TOTAL | AC32: =SUM(X31:AC31) -> 0 | AJ32: TOTAL | AK32: =SUM(AF31:AK31) -> 0
B33: Agosto | J33: Agosto | W33: =J33 -> Agosto | AE33: =W33 -> Agosto
A34: KM (Rodados) | B34: 1ª Leitura | C34: 2ª Leitura | D34: 3ª Leitura | E34: 4ª Leitura | F34: 15 dias Rodados | G34: 30 dias Rodados | H34: Total Mensal | J34: DATA | W34: DATA | AE34: DATA
F35: =SUM(C35-B35) -> 0 | G35: =SUM(E35-D35) -> 0 | H35: =SUM(F35:G35) -> 0 | J35: VALOR | W35: VALOR | AE35: VALOR
T36: TOTAL | U36: =SUM(K35:U35) -> 0 | AB36: TOTAL | AC36: =SUM(X35:AC35) -> 0 | AJ36: TOTAL | AK36: =SUM(AF35:AK35) -> 0
B37: Setembro | J37: Setembro | W37: =J37 -> Setembro | AE37: =W37 -> Setembro
A38: KM (Rodados) | B38: 1ª Leitura | C38: 2ª Leitura | D38: 3ª Leitura | E38: 4ª Leitura | F38: 15 dias Rodados | G38: 30 dias Rodados | H38: Total Mensal | J38: DATA | W38: DATA | AE38: DATA
F39: =SUM(C39-B39) -> 0 | G39: =SUM(E39-D39) -> 0 | H39: =SUM(F39:G39) -> 0 | J39: VALOR | W39: VALOR | AE39: VALOR
T40: TOTAL | U40: =SUM(K39:U39) -> 0 | AB40: TOTAL | AC40: =SUM(X39:AC39) -> 0 | AJ40: TOTAL | AK40: =SUM(AF39:AK39) -> 0
B41: Outubro | J41: Outubro | W41: =J41 -> Outubro | AE41: =W41 -> Outubro
A42: KM (Rodados) | B42: 1ª Leitura | C42: 2ª Leitura | D42: 3ª Leitura | E42: 4ª Leitura | F42: 15 dias Rodados | G42: 30 dias Rodados | H42: Total Mensal | J42: DATA | W42: DATA | AE42: DATA
F43: =SUM(C43-B43) -> 0 | G43: =SUM(E43-D43) -> 0 | H43: =SUM(F43:G43) -> 0 | J43: VALOR | W43: VALOR | AE43: VALOR
T44: TOTAL | U44: =SUM(K43:U43) -> 0 | AB44: TOTAL | AC44: =SUM(X43:AC43) -> 0 | AJ44: TOTAL | AK44: =SUM(AF43:AK43) -> 0
...

Sheet CAR_03
A2: Veiculo | D2: Placa: | H2: Medição
A3: Substituição (data) | D3: Placa: | H3: Modelo
A4: Contrato de Locação | D4: Rastreador | H4: Data mob.
A7: REGISTRO DE KM | J7: ABASTECIMENTO | W7: LAVA_RAPIDO | AE7: BORRACHARIA
B9: Fevereiro | J9: Fevereiro | W9: Fevereiro | AE9: Fevereiro
A10: KM (Rodados) | B10: 1ª Leitura | C10: 2ª Leitura | D10: 3ª Leitura | E10: 4ª Leitura | F10: 15 dias Rodados | G10: 30 dias Rodados | H10: Total Mensal | J10: DATA | W10: DATA | AE10: DATA
F11: =SUM(C11-B11) -> 0 | G11: =SUM(E11-D11) -> 0 | H11: =SUM(F11:G11) -> 0 | J11: VALOR | W11: VALOR | AE11: VALOR
T12: TOTAL | U12: =SUM(K11:U11) -> 0 | AB12: TOTAL | AC12: =SUM(X11:AC11) -> 0 | AJ12: TOTAL | AK12: =SUM(AF11:AK11) -> 0
B13: Março | J13: Março | W13: =J13 -> Março | AE13: =W13 -> Março
A14: KM (Rodados) | B14: 1ª Leitura | C14: 2ª Leitura | D14: 3ª Leitura | E14: 4ª Leitura | F14: 15 dias Rodados | G14: 30 dias Rodados | H14: Total Mensal | J14: DATA | W14: DATA | AE14: DATA
F15: =SUM(C15-B15) -> 0 | G15: =SUM(E15-D15) -> 0 | H15: =SUM(F15:G15) -> 0 | J15: VALOR | W15: VALOR | AE15: VALOR
T16: TOTAL | U16: =SUM(K15:U15) -> 0 | AB16: TOTAL | AC16: =SUM(X15:AC15) -> 0 | AJ16: TOTAL | AK16: =SUM(AF15:AK15) -> 0
B17: Abril | J17: Abril | W17: =J17 -> Abril | AE17: =W17 -> Abril
A18: KM (Rodados) | B18: 1ª Leitura | C18: 2ª Leitura | D18: 3ª Leitura | E18: 4ª Leitura | F18: 15 dias Rodados | G18: 30 dias Rodados | H18: Total Mensal | J18: DATA | W18: DATA | AE18: DATA
F19: =SUM(C19-B19) -> 0 | G19: =SUM(E19-D19) -> 0 | H19: =SUM(F19:G19) -> 0 | J19: VALOR | W19: VALOR | AE19: VALOR
T20: TOTAL | U20: =SUM(K19:U19) -> 0 | AB20: TOTAL | AC20: =SUM(X19:AC19) -> 0 | AJ20: TOTAL | AK20: =SUM(AF19:AK19) -> 0
B21: Maio | J21: Maio | W21: =J21 -> Maio | AE21: =W21 -> Maio
A22: KM (Rodados) | B22: 1ª Leitura | C22: 2ª Leitura | D22: 3ª Leitura | E22: 4ª Leitura | F22: 15 dias Rodados | G22: 30 dias Rodados | H22: Total Mensal | J22: DATA | W22: DATA | AE22: DATA
F23: =SUM(C23-B23) -> 0 | G23: =SUM(E23-D23) -> 0 | H23: =SUM(F23:G23) -> 0 | J23: VALOR | W23: VALOR | AE23: VALOR
T24: TOTAL | U24: =SUM(K23:U23) -> 0 | AB24: TOTAL | AC24: =SUM(X23:AC23) -> 0 | AJ24: TOTAL | AK24: =SUM(AF23:AK23) -> 0
B25: Junho | J25: Junho | W25: =J25 -> Junho | AE25: =W25 -> Junho
A26: KM (Rodados) | B26: 1ª Leitura | C26: 2ª Leitura | D26: 3ª Leitura | E26: 4ª Leitura | F26: 15 dias Rodados | G26: 30 dias Rodados | H26: Total Mensal | J26: DATA | W26: DATA | AE26: DATA
F27: =SUM(C27-B27) -> 0 | G27: =SUM(E27-D27) -> 0 | H27: =SUM(F27:G27) -> 0 | J27: VALOR | W27: VALOR | AE27: VALOR
T28: TOTAL | U28: =SUM(K27:U27) -> 0 | AB28: TOTAL | AC28: =SUM(X27:AC27) -> 0 | AJ28: TOTAL | AK28: =SUM(AF27:AK27) -> 0
B29: Julho | J29: Julho | W29: =J29 -> Julho | AE29: =W29 -> Julho
A30: KM (Rodados) | B30: 1ª Leitura | C30: 2ª Leitura | D30: 3ª Leitura | E30: 4ª Leitura | F30: 15 dias Rodados | G30: 30 dias Rodados | H30: Total Mensal | J30: DATA | W30: DATA | AE30: DATA
F31: =SUM(C31-B31) -> 0 | G31: =SUM(E31-D31) -> 0 | H31: =SUM(F31:G31) -> 0 | J31: VALOR | W31: VALOR | AE31: VALOR
T32: TOTAL | U32: =SUM(K31:U31) -> 0 | AB32: TOTAL | AC32: =SUM(X31:AC31) -> 0 | AJ32: TOTAL | AK32: =SUM(AF31:AK31) -> 0
B33: Agosto | J33: Agosto | W33: =J33 -> Agosto | AE33: =W33 -> Agosto
A34: KM (Rodados) | B34: 1ª Leitura | C34: 2ª Leitura | D34: 3ª Leitura | E34: 4ª Leitura | F34: 15 dias Rodados | G34: 30 dias Rodados | H34: Total Mensal | J34: DATA | W34: DATA | AE34: DATA
F35: =SUM(C35-B35) -> 0 | G35: =SUM(E35-D35) -> 0 | H35: =SUM(F35:G35) -> 0 | J35: VALOR | W35: VALOR | AE35: VALOR
T36: TOTAL | U36: =SUM(K35:U35) -> 0 | AB36: TOTAL | AC36: =SUM(X35:AC35) -> 0 | AJ36: TOTAL | AK36: =SUM(AF35:AK35) -> 0
B37: Setembro | J37: Setembro | W37: =J37 -> Setembro | AE37: =W37 -> Setembro
A38: KM (Rodados) | B38: 1ª Leitura | C38: 2ª Leitura | D38: 3ª Leitura | E38: 4ª Leitura | F38: 15 dias Rodados | G38: 30 dias Rodados | H38: Total Mensal | J38: DATA | W38: DATA | AE38: DATA
F39: =SUM(C39-B39) -> 0 | G39: =SUM(E39-D39) -> 0 | H39: =SUM(F39:G39) -> 0 | J39: VALOR | W39: VALOR | AE39: VALOR
T40: TOTAL | U40: =SUM(K39:U39) -> 0 | AB40: TOTAL | AC40: =SUM(X39:AC39) -> 0 | AJ40: TOTAL | AK40: =SUM(AF39:AK39) -> 0
