Workbook

Sheet RESUMO
A1: UFV IRAPURU - JANAUBA
B5: JAN | C5: FEV | D5: MAR | E5: ABR | F5: MAI | G5: JUN | H5: JUL | I5: AGO | J5: SET | K5: OUT | L5: NOV | M5: DEZ
A6: ABASTECIMENTO | B6: =SUM('Controle Central'!D4+'Controle Central'!K4+'Controle Central'!R4+'Controle Central'!Y4+'Controle Central'!D23+'Controle Central'!K23+'Controle Central'!R23+'Controle Central'!Y23+'Controle Central'!D42+'Controle Central'!K42+'Controle Central'!R42+'Controle Central'!Y42+'Controle Central'!D61+'Controle Central'!K61+'Controle Central'!R61+'Controle Central'!Y61+'Controle Central'!D80+'Controle Central'!K80+'Controle Central'!R80+'Controle Central'!Y80+'Controle Central'!D98+'Controle Central'!K98+'Controle Central'!R98+'Controle Central'!Y98+'Controle Central'!D116+'Controle Central'!K116+'Controle Central'!R116+'Controle Central'!Y116+'Controle Central'!D134+'Controle Central'!K134) -> 0 | C6: =SUM('Controle Central'!D5+'Controle Central'!K5+'Controle Central'!R5+'Controle Central'!Y5+'Controle Central'!D24+'Controle Central'!K24+'Controle Central'!R24+'Controle Central'!Y24+'Controle Central'!D43+'Controle Central'!K43+'Controle Central'!R43+'Controle Central'!Y43+'Controle Central'!D62+'Controle Central'!K62+'Controle Central'!R62+'Controle Central'!Y62+'Controle Central'!D81+'Controle Central'!K81+'Controle Central'!R81+'Controle Central'!D99+'Controle Central'!K99+'Controle Central'!R99+'Controle Central'!Y99+'Controle Central'!D117+'Controle Central'!K117+'Controle Central'!R117+'Controle Central'!Y117+'Controle Central'!D135+'Controle Central'!K135) -> #REF! | D6: =SUM('Controle Central'!D6+'Controle Central'!K6+'Controle Central'!R6+'Controle Central'!Y6+'Controle Central'!D25+'Controle Central'!K25+'Controle Central'!R25+'Controle Central'!Y25+'Controle Central'!D44+'Controle Central'!K44+'Controle Central'!R44+'Controle Central'!Y44+'Controle Central'!D63+'Controle Central'!K63+'Controle Central'!R63+'Controle Central'!Y63+'Controle Central'!D82+'Controle Central'!K82+'Controle Central'!R82+'Controle Central'!Y82+'Controle Central'!D100+'Controle Central'!K100+'Controle Central'!R100+'Controle Central'!Y100+'Controle Central'!D118+'Controle Central'!K118+'Controle Central'!R118+'Controle Central'!Y118+'Controle Central'!D136+'Controle Central'!K136) -> #REF! | E6: ='Controle Central'!D7+'Controle Central'!K7+'Controle Central'!R7+'Controle Central'!Y7+'Controle Central'!D26+'Controle Central'!K26+'Controle Central'!R26+'Controle Central'!Y26+'Controle Central'!D45+'Controle Central'!K45+'Controle Central'!R45+'Controle Central'!Y45+'Controle Central'!D64+'Controle Central'!K64+'Controle Central'!R64+'Controle Central'!D83+'Controle Central'!K83+'Controle Central'!R83+'Controle Central'!Y83+'Controle Central'!D101+'Controle Central'!K101+'Controle Central'!R101+'Controle Central'!Y101+'Controle Central'!D119+'Controle Central'!K119+'Controle Central'!R119+'Controle Central'!Y119+'Controle Central'!D137+'Controle Central'!K137 -> #REF! | F6: =SUM('Controle Central'!D8+'Controle Central'!K8+'Controle Central'!R8+'Controle Central'!Y8+'Controle Central'!D27+'Controle Central'!K27+'Controle Central'!R27+'Controle Central'!Y27+'Controle Central'!D46+'Controle Central'!K46+'Controle Central'!R46+'Controle Central'!Y46+'Controle Central'!D65+'Controle Central'!K65+'Controle Central'!R65+'Controle Central'!Y65+'Controle Central'!D84+'Controle Central'!K84+'Controle Central'!R84+'Controle Central'!Y84+'Controle Central'!D102+'Controle Central'!K102+'Controle Central'!R102+'Controle Central'!Y102+'Controle Central'!D120+'Controle Central'!K120+'Controle Central'!R120+'Controle Central'!Y120+'Controle Central'!D138+'Controle Central'!K138) -> #REF! | G6: =SUM('Controle Central'!D9+'Controle Central'!K9+'Controle Central'!R9+'Controle Central'!Y9+'Controle Central'!D28+'Controle Central'!K28+'Controle Central'!R28+'Controle Central'!Y28+'Controle Central'!D47+'Controle Central'!K47+'Controle Central'!R47+'Controle Central'!Y47+'Controle Central'!D66+'Controle Central'!K66+'Controle Central'!R66+'Controle Central'!Y66+'Controle Central'!D85+'Controle Central'!K85+'Controle Central'!R85+'Controle Central'!Y85+'Controle Central'!D103+'Controle Central'!K103+'Controle Central'!R103+'Controle Central'!Y103+'Controle Central'!D121+'Controle Central'!K121+'Controle Central'!R121+'Controle Central'!Y121+'Controle Central'!D139+'Controle Central'!K139) -> #REF! | H6: =SUM('Controle Central'!D10+'Controle Central'!K10+'Controle Central'!R10+'Controle Central'!Y10+'Controle Central'!D29+'Controle Central'!K29+'Controle Central'!R29+'Controle Central'!D48+'Controle Central'!K48+'Controle Central'!R48+'Controle Central'!Y48+'Controle Central'!D67+'Controle Central'!K67+'Controle Central'!R67+'Controle Central'!Y67+'Controle Central'!D86+'Controle Central'!K86+'Controle Central'!R86+'Controle Central'!Y86+'Controle Central'!D104+'Controle Central'!K104+'Controle Central'!R104+'Controle Central'!Y104+'Controle Central'!D122+'Controle Central'!K122+'Controle Central'!R122+'Controle Central'!Y122+'Controle Central'!D140+'Controle Central'!K140) -> #REF! | I6: =SUM('Controle Central'!D11+'Controle Central'!K11+'Controle Central'!R11+'Controle Central'!Y11+'Controle Central'!D30+'Controle Central'!K30+'Controle Central'!R30+'Controle Central'!Y30+'Controle Central'!D49+'Controle Central'!K49+'Controle Central'!R49+'Controle Central'!Y49+'Controle Central'!D68+'Controle Central'!K68+'Controle Central'!R68+'Controle Central'!Y68+'Controle Central'!D87+'Controle Central'!K87+'Controle Central'!R87+'Controle Central'!Y87+'Controle Central'!D105+'Controle Central'!K105+'Controle Central'!R105+'Controle Central'!Y105+'Controle Central'!D123+'Controle Central'!K123+'Controle Central'!R123+'Controle Central'!Y123+'Controle Central'!D141+'Controle Central'!K141) -> #REF! | J6: =SUM('Controle Central'!D12+'Controle Central'!K12+'Controle Central'!R12+'Controle Central'!Y12+'Controle Central'!D31+'Controle Central'!K31+'Controle Central'!R31+'Controle Central'!Y31+'Controle Central'!D50+'Controle Central'!K50+'Controle Central'!R50+'Controle Central'!Y50+'Controle Central'!D69+'Controle Central'!K69+'Controle Central'!R69+'Controle Central'!Y69+'Controle Central'!D88+'Controle Central'!K88+'Controle Central'!R88+'Controle Central'!Y88+'Controle Central'!D106+'Controle Central'!K106+'Controle Central'!R106+'Controle Central'!Y106+'Controle Central'!D124+'Controle Central'!K124+'Controle Central'!R124+'Controle Central'!Y124+'Controle Central'!D142+'Controle Central'!K142) -> #REF! | K6: =SUM('Controle Central'!D13+'Controle Central'!K13+'Controle Central'!R13+'Controle Central'!Y13+'Controle Central'!D32+'Controle Central'!K32+'Controle Central'!R32+'Controle Central'!Y32+'Controle Central'!D51+'Controle Central'!K51+'Controle Central'!R51+'Controle Central'!Y51+'Controle Central'!D70+'Controle Central'!K70+'Controle Central'!R70+'Controle Central'!Y70+'Controle Central'!D89+'Controle Central'!K89+'Controle Central'!R89+'Controle Central'!Y89+'Controle Central'!D107+'Controle Central'!K107+'Controle Central'!R107+'Controle Central'!Y107+'Controle Central'!D125+'Controle Central'!K125+'Controle Central'!R125+'Controle Central'!Y125+'Controle Central'!D143+'Controle Central'!K143) -> #REF! | L6: =SUM('Controle Central'!D14+'Controle Central'!K14+'Controle Central'!R14+'Controle Central'!Y14+'Controle Central'!D33+'Controle Central'!K33+'Controle Central'!R33+'Controle Central'!Y33+'Controle Central'!D52+'Controle Central'!K52+'Controle Central'!R52+'Controle Central'!Y52+'Controle Central'!D71+'Controle Central'!K71+'Controle Central'!R71+'Controle Central'!Y71+'Controle Central'!D90+'Controle Central'!K90+'Controle Central'!R90+'Controle Central'!Y90+'Controle Central'!D108+'Controle Central'!K108+'Controle Central'!R108+'Controle Central'!Y108+'Controle Central'!D126+'Controle Central'!K126+'Controle Central'!R126+'Controle Central'!Y126+'Controle Central'!D144+'Controle Central'!K144) -> #REF! | M6: =SUM('Controle Central'!D15+'Controle Central'!K15+'Controle Central'!R15+'Controle Central'!Y15+'Controle Central'!D34+'Controle Central'!K34+'Controle Central'!R34+'Controle Central'!Y34+'Controle Central'!D53+'Controle Central'!K53+'Controle Central'!R53+'Controle Central'!Y53+'Controle Central'!D72+'Controle Central'!K72+'Controle Central'!R72+'Controle Central'!Y72+'Controle Central'!D91+'Controle Central'!K91+'Controle Central'!R91+'Controle Central'!Y91+'Controle Central'!D109+'Controle Central'!K109+'Controle Central'!R109+'Controle Central'!Y109+'Controle Central'!D127+'Controle Central'!K127+'Controle Central'!R127+'Controle Central'!Y127+'Controle Central'!D145+'Controle Central'!K145) -> #REF!
C7: GASOLINA: 369,07 | D7: GASOLINA: 1.454,72 | E7: GASOLINA: 1.757,74 | F7: GASOLINA: 2.111,78 | G7: GASOLINA: 2.410,38 | H7: GASOLINA: 2.769,34 | I7: GASOLINA: 3.035,04 | J7: GASOLINA: 2.726,30
D8: ETANOL: 331,2 | E8: ETANOL: 461,44 | F8: ETANOL: 169,56 | G8: ETANOL: 172,99 | H8: ETANOL: 293,05 | I8: ETANOL: 296,64 | J8: ETANOL: 239,17
A10: LAVA_RAPIDO | B10: =SUM('Controle Central'!E4+'Controle Central'!L4+'Controle Central'!S4+'Controle Central'!Z4+'Controle Central'!E23+'Controle Central'!L23+'Controle Central'!S23+'Controle Central'!Z23+'Controle Central'!E42+'Controle Central'!L42+'Controle Central'!S42+'Controle Central'!Z42+'Controle Central'!E61+'Controle Central'!L61+'Controle Central'!S61+'Controle Central'!Z61+'Controle Central'!E80+'Controle Central'!L80+'Controle Central'!S80+'Controle Central'!Z80+'Controle Central'!E98+'Controle Central'!L98+'Controle Central'!S98+'Controle Central'!Z98+'Controle Central'!E116+'Controle Central'!L116+'Controle Central'!S116+'Controle Central'!Z116+'Controle Central'!E134+'Controle Central'!L134) -> 0 | C10: =SUM('Controle Central'!E5,'Controle Central'!L5,'Controle Central'!S5,'Controle Central'!Z5,'Controle Central'!E24,'Controle Central'!L24,'Controle Central'!S24,'Controle Central'!Z24,'Controle Central'!E43,'Controle Central'!L43,'Controle Central'!S43,'Controle Central'!Z43,'Controle Central'!E62,'Controle Central'!L62,'Controle Central'!S62,'Controle Central'!Z62,'Controle Central'!E81,'Controle Central'!L81,'Controle Central'!S81,'Controle Central'!Z81,'Controle Central'!E99,'Controle Central'!L99,'Controle Central'!S99,'Controle Central'!Z99,'Controle Central'!E117,'Controle Central'!L117,'Controle Central'!S117,'Controle Central'!Z117,'Controle Central'!E135,'Controle Central'!L135) -> #REF! | D10: =SUM('Controle Central'!E6,'Controle Central'!L6,'Controle Central'!S6,'Controle Central'!Z6,'Controle Central'!E25,'Controle Central'!L25,'Controle Central'!S25,'Controle Central'!Z25,'Controle Central'!E44,'Controle Central'!L44,'Controle Central'!S44,'Controle Central'!Z44,'Controle Central'!E63,'Controle Central'!L63,'Controle Central'!S63,'Controle Central'!Z63,'Controle Central'!E82,'Controle Central'!L82,'Controle Central'!S82,'Controle Central'!Z82,'Controle Central'!E100,'Controle Central'!L100,'Controle Central'!S100,'Controle Central'!Z100,'Controle Central'!E118,'Controle Central'!L118,'Controle Central'!S118,'Controle Central'!Z118,'Controle Central'!E136,'Controle Central'!L136) -> #REF! | E10: =SUM('Controle Central'!E7,'Controle Central'!L7,'Controle Central'!S7,'Controle Central'!Z7,'Controle Central'!E26,'Controle Central'!L26,'Controle Central'!S26,'Controle Central'!Z26,'Controle Central'!E45,'Controle Central'!L45,'Controle Central'!S45,'Controle Central'!Z45,'Controle Central'!E64,'Controle Central'!L64,'Controle Central'!S64,'Controle Central'!Z64,'Controle Central'!E83,'Controle Central'!L83,'Controle Central'!S83,'Controle Central'!Z83,'Controle Central'!E101,'Controle Central'!L101,'Controle Central'!S101,'Controle Central'!Z101,'Controle Central'!E119,'Controle Central'!L119,'Controle Central'!S119,'Controle Central'!Z119,'Controle Central'!E137,'Controle Central'!L137) -> #REF! | F10: =SUM('Controle Central'!E8,'Controle Central'!L8,'Controle Central'!S8,'Controle Central'!Z8,'Controle Central'!E27,'Controle Central'!L27,'Controle Central'!S27,'Controle Central'!Z27,'Controle Central'!E46,'Controle Central'!L46,'Controle Central'!S46,'Controle Central'!Z46,'Controle Central'!E65,'Controle Central'!L65,'Controle Central'!S65,'Controle Central'!Z65,'Controle Central'!E84,'Controle Central'!L84,'Controle Central'!S84,'Controle Central'!Z84,'Controle Central'!E102,'Controle Central'!L102,'Controle Central'!S102,'Controle Central'!Z102,'Controle Central'!E120,'Controle Central'!L120,'Controle Central'!S120,'Controle Central'!Z120,'Controle Central'!E138,'Controle Central'!L138) -> #REF! | G10: =SUM('Controle Central'!E9,'Controle Central'!L9,'Controle Central'!S9,'Controle Central'!Z9,'Controle Central'!E28,'Controle Central'!L28,'Controle Central'!S28,'Controle Central'!Z28,'Controle Central'!E47,'Controle Central'!L47,'Controle Central'!S47,'Controle Central'!Z47,'Controle Central'!E66,'Controle Central'!L66,'Controle Central'!S66,'Controle Central'!Z66,'Controle Central'!E85,'Controle Central'!L85,'Controle Central'!S85,'Controle Central'!Z85,'Controle Central'!E103,'Controle Central'!L103,'Controle Central'!S103,'Controle Central'!Z103,'Controle Central'!E121,'Controle Central'!L121,'Controle Central'!S121,'Controle Central'!Z121,'Controle Central'!E139+'Controle Central'!L139) -> #REF! | H10: =SUM('Controle Central'!E10,'Controle Central'!L10,'Controle Central'!S10,'Controle Central'!Z10,'Controle Central'!E29,'Controle Central'!L29,'Controle Central'!S29,'Controle Central'!Z29,'Controle Central'!E48,'Controle Central'!L48,'Controle Central'!S48,'Controle Central'!Z48,'Controle Central'!E67,'Controle Central'!L67,'Controle Central'!S67,'Controle Central'!Z67,'Controle Central'!E86,'Controle Central'!L86,'Controle Central'!S86,'Controle Central'!Z86,'Controle Central'!E104,'Controle Central'!L104,'Controle Central'!S104,'Controle Central'!Z104,'Controle Central'!E122,'Controle Central'!L122,'Controle Central'!S122,'Controle Central'!Z122,'Controle Central'!E140,'Controle Central'!L140) -> #REF! | I10: =SUM('Controle Central'!L11,'Controle Central'!S11,'Controle Central'!E11,'Controle Central'!Z11,'Controle Central'!Z30,'Controle Central'!S30,'Controle Central'!L30,'Controle Central'!E30,'Controle Central'!E49,'Controle Central'!L49,'Controle Central'!S49,'Controle Central'!Z49,'Controle Central'!Z68,'Controle Central'!S68,'Controle Central'!L68,'Controle Central'!E68,'Controle Central'!E87,'Controle Central'!L87,'Controle Central'!S87,'Controle Central'!Z87,'Controle Central'!Z105,'Controle Central'!Z123,'Controle Central'!S105,'Controle Central'!S123,'Controle Central'!L123,'Controle Central'!L105,'Controle Central'!E123,'Controle Central'!E105,'Controle Central'!E141,'Controle Central'!L141) -> #REF! | J10: =SUM('Controle Central'!E12,'Controle Central'!E31,'Controle Central'!L12,'Controle Central'!L31,'Controle Central'!S12,'Controle Central'!S31,'Controle Central'!Z12,'Controle Central'!Z31,'Controle Central'!Z50,'Controle Central'!Z69,'Controle Central'!S50,'Controle Central'!S69,'Controle Central'!L50,'Controle Central'!L69,'Controle Central'!E50,'Controle Central'!E69,'Controle Central'!E88,'Controle Central'!E106,'Controle Central'!L88,'Controle Central'!L106,'Controle Central'!S88,'Controle Central'!S106,'Controle Central'!Z88,'Controle Central'!Z106,'Controle Central'!Z124,'Controle Central'!S124,'Controle Central'!L124,'Controle Central'!E124,'Controle Central'!E142,'Controle Central'!L142) -> #REF! | K10: =SUM('Controle Central'!E13,'Controle Central'!L13,'Controle Central'!E32,'Controle Central'!L32,'Controle Central'!S13,'Controle Central'!S32,'Controle Central'!Z13,'Controle Central'!Z32,'Controle Central'!Z51,'Controle Central'!Z70,'Controle Central'!S51,'Controle Central'!S70,'Controle Central'!L51,'Controle Central'!L70,'Controle Central'!E51,'Controle Central'!E70,'Controle Central'!E89,'Controle Central'!E107,'Controle Central'!L89,'Controle Central'!L107,'Controle Central'!S89,'Controle Central'!S107,'Controle Central'!Z107,'Controle Central'!Z89,'Controle Central'!Z125,'Controle Central'!S125,'Controle Central'!L143,'Controle Central'!L125,'Controle Central'!E125,'Controle Central'!E143) -> #REF! | L10: =SUM('Controle Central'!E14,'Controle Central'!E33,'Controle Central'!L14,'Controle Central'!L33,'Controle Central'!S14,'Controle Central'!S33,'Controle Central'!Z14,'Controle Central'!Z33,'Controle Central'!Z52,'Controle Central'!Z71,'Controle Central'!S52,'Controle Central'!S71,'Controle Central'!L52,'Controle Central'!L71,'Controle Central'!E52,'Controle Central'!E71,'Controle Central'!E90,'Controle Central'!E108,'Controle Central'!L90,'Controle Central'!L108,'Controle Central'!S90,'Controle Central'!S108,'Controle Central'!Z90,'Controle Central'!Z108,'Controle Central'!Z126,'Controle Central'!S126,'Controle Central'!L126,'Controle Central'!L144,'Controle Central'!E126,'Controle Central'!E144) -> #REF! | M10: =SUM('Controle Central'!E15,'Controle Central'!E34,'Controle Central'!L15,'Controle Central'!L34,'Controle Central'!S15,'Controle Central'!S34,'Controle Central'!Z15,'Controle Central'!Z34,'Controle Central'!Z53,'Controle Central'!Z72,'Controle Central'!S53,'Controle Central'!S72,'Controle Central'!L53,'Controle Central'!L72,'Controle Central'!E53,'Controle Central'!E72,'Controle Central'!E91,'Controle Central'!E109,'Controle Central'!L91,'Controle Central'!L109,'Controle Central'!S91,'Controle Central'!S109,'Controle Central'!Z91,'Controle Central'!Z109,'Controle Central'!Z127,'Controle Central'!S127,'Controle Central'!L127,'Controle Central'!E127,'Controle Central'!E145,'Controle Central'!L145) -> #REF!
A12: BORRACHARIA | B12: =SUM('Controle Central'!F4,'Controle Central'!M4,'Controle Central'!M23,'Controle Central'!F23,'Controle Central'!T4,'Controle Central'!T23,'Controle Central'!AA4,'Controle Central'!AA23,'Controle Central'!AA61,'Controle Central'!AA42,'Controle Central'!T42,'Controle Central'!M42,'Controle Central'!M61,'Controle Central'!F61,'Controle Central'!F42,'Controle Central'!F98,'Controle Central'!F80,'Controle Central'!M80,'Controle Central'!M98,'Controle Central'!T80,'Controle Central'!T98,'Controle Central'!AA80,'Controle Central'!AA98,'Controle Central'!AA116,'Controle Central'!T116,'Controle Central'!M116,'Controle Central'!F116,'Controle Central'!F134,'Controle Central'!M134) -> 0 | C12: =SUM('Controle Central'!F5,'Controle Central'!F24,'Controle Central'!M5,'Controle Central'!M24,'Controle Central'!T24,'Controle Central'!T5,'Controle Central'!AA5,'Controle Central'!AA24,'Controle Central'!AA43,'Controle Central'!AA62,'Controle Central'!T43,'Controle Central'!T62,'Controle Central'!M43,'Controle Central'!M62,'Controle Central'!F43,'Controle Central'!F62,'Controle Central'!F81,'Controle Central'!F99,'Controle Central'!M99,'Controle Central'!M81,'Controle Central'!T99,'Controle Central'!T81,'Controle Central'!AA81,'Controle Central'!AA99,'Controle Central'!AA117,'Controle Central'!T117,'Controle Central'!M117,'Controle Central'!F117,'Controle Central'!F135,'Controle Central'!M135) -> #REF! | D12: =SUM('Controle Central'!F6,'Controle Central'!F25,'Controle Central'!M6,'Controle Central'!M25,'Controle Central'!T6,'Controle Central'!T25,'Controle Central'!AA25,'Controle Central'!AA6,'Controle Central'!AA44,'Controle Central'!AA63,'Controle Central'!T63,'Controle Central'!T44,'Controle Central'!M44,'Controle Central'!M63,'Controle Central'!F63,'Controle Central'!F44,'Controle Central'!F82,'Controle Central'!F100,'Controle Central'!M100,'Controle Central'!M82,'Controle Central'!T82,'Controle Central'!T100,'Controle Central'!AA100,'Controle Central'!AA82,'Controle Central'!AA118,'Controle Central'!T118,'Controle Central'!M118,'Controle Central'!M136,'Controle Central'!F118,'Controle Central'!F136) -> #REF! | E12: =SUM('Controle Central'!F7,'Controle Central'!F26,'Controle Central'!M26,'Controle Central'!M7,'Controle Central'!T7,'Controle Central'!T26,'Controle Central'!AA7,'Controle Central'!AA26,'Controle Central'!AA45,'Controle Central'!T45,'Controle Central'!AA64,'Controle Central'!T64,'Controle Central'!M45,'Controle Central'!M64,'Controle Central'!F45,'Controle Central'!F64,'Controle Central'!F83,'Controle Central'!F101,'Controle Central'!M83,'Controle Central'!M101,'Controle Central'!T83,'Controle Central'!T101,'Controle Central'!AA83,'Controle Central'!AA101,'Controle Central'!AA119,'Controle Central'!T119,'Controle Central'!M119,'Controle Central'!M137,'Controle Central'!F137,'Controle Central'!F119) -> #REF! | F12: =SUM('Controle Central'!F8,'Controle Central'!F27,'Controle Central'!M8,'Controle Central'!M27,'Controle Central'!T8,'Controle Central'!T27,'Controle Central'!AA27,'Controle Central'!AA8,'Controle Central'!AA46,'Controle Central'!AA65,'Controle Central'!T46,'Controle Central'!T65,'Controle Central'!M65,'Controle Central'!M46,'Controle Central'!F46,'Controle Central'!F65,'Controle Central'!F84,'Controle Central'!F102,'Controle Central'!M84,'Controle Central'!M102,'Controle Central'!T84,'Controle Central'!T102,'Controle Central'!AA84,'Controle Central'!AA102,'Controle Central'!AA120,'Controle Central'!T120,'Controle Central'!M120,'Controle Central'!M138,'Controle Central'!F120,'Controle Central'!F138) -> #REF! | G12: =SUM('Controle Central'!F9,'Controle Central'!F28,'Controle Central'!M9,'Controle Central'!M28,'Controle Central'!T9,'Controle Central'!T28,'Controle Central'!AA9,'Controle Central'!AA28,'Controle Central'!AA47,'Controle Central'!AA66,'Controle Central'!T47,'Controle Central'!T66,'Controle Central'!M47,'Controle Central'!M66,'Controle Central'!F47,'Controle Central'!F66,'Controle Central'!F85,'Controle Central'!F103,'Controle Central'!M85,'Controle Central'!M103,'Controle Central'!T85,'Controle Central'!T103,'Controle Central'!AA85,'Controle Central'!AA103,'Controle Central'!AA121,'Controle Central'!T121,'Controle Central'!M121,'Controle Central'!M139,'Controle Central'!F139) -> #REF! | H12: =SUM('Controle Central'!F10,'Controle Central'!F29,'Controle Central'!M10,'Controle Central'!M29,'Controle Central'!T10,'Controle Central'!T29,'Controle Central'!AA10,'Controle Central'!AA29,'Controle Central'!AA48,'Controle Central'!T48,'Controle Central'!AA67,'Controle Central'!T67,'Controle Central'!M48,'Controle Central'!M67,'Controle Central'!F48,'Controle Central'!F67,'Controle Central'!F86,'Controle Central'!F104,'Controle Central'!M104,'Controle Central'!M86,'Controle Central'!T86,'Controle Central'!T104,'Controle Central'!AA86,'Controle Central'!AA104,'Controle Central'!AA122,'Controle Central'!T122,'Controle Central'!M122,'Controle Central'!M140,'Controle Central'!F122,'Controle Central'!F140) -> #REF! | I12: =SUM('Controle Central'!F11,'Controle Central'!F30,'Controle Central'!M11,'Controle Central'!M30,'Controle Central'!T11,'Controle Central'!T30,'Controle Central'!AA11,'Controle Central'!AA30,'Controle Central'!AA49,'Controle Central'!AA68,'Controle Central'!T49,'Controle Central'!T68,'Controle Central'!M49,'Controle Central'!M68,'Controle Central'!F68,'Controle Central'!F49,'Controle Central'!F87,'Controle Central'!F105,'Controle Central'!M87,'Controle Central'!M105,'Controle Central'!T87,'Controle Central'!T105,'Controle Central'!AA87,'Controle Central'!AA105,'Controle Central'!AA123,'Controle Central'!T123,'Controle Central'!M123,'Controle Central'!M141,'Controle Central'!F123,'Controle Central'!F141) -> #REF! | J12: =SUM('Controle Central'!F12,'Controle Central'!F31,'Controle Central'!M12,'Controle Central'!M31,'Controle Central'!T12,'Controle Central'!T31,'Controle Central'!AA12,'Controle Central'!AA31,'Controle Central'!AA50,'Controle Central'!T50,'Controle Central'!T69,'Controle Central'!AA69,'Controle Central'!M50,'Controle Central'!M69,'Controle Central'!F69,'Controle Central'!F50,'Controle Central'!F88,'Controle Central'!F106,'Controle Central'!M88,'Controle Central'!M106,'Controle Central'!T88,'Controle Central'!T106,'Controle Central'!AA88,'Controle Central'!AA106,'Controle Central'!AA124,'Controle Central'!T124,'Controle Central'!M124,'Controle Central'!F124,'Controle Central'!F142,'Controle Central'!M142) -> #REF! | K12: =SUM('Controle Central'!F13,'Controle Central'!F32,'Controle Central'!M13,'Controle Central'!M32,'Controle Central'!T13,'Controle Central'!T32,'Controle Central'!AA13,'Controle Central'!AA32,'Controle Central'!AA51,'Controle Central'!T51,'Controle Central'!T70,'Controle Central'!AA70,'Controle Central'!M51,'Controle Central'!M70,'Controle Central'!F70,'Controle Central'!F51,'Controle Central'!F89,'Controle Central'!F107,'Controle Central'!M89,'Controle Central'!M107,'Controle Central'!T89,'Controle Central'!T107,'Controle Central'!AA107,'Controle Central'!AA89,'Controle Central'!AA125,'Controle Central'!T125,'Controle Central'!M125,'Controle Central'!F125,'Controle Central'!F143,'Controle Central'!M143) -> #REF! | L12: =SUM('Controle Central'!F14,'Controle Central'!M14,'Controle Central'!F33,'Controle Central'!M33,'Controle Central'!T14,'Controle Central'!T33,'Controle Central'!AA33,'Controle Central'!AA14,'Controle Central'!AA52,'Controle Central'!T52,'Controle Central'!M52,'Controle Central'!M71,'Controle Central'!T71,'Controle Central'!AA71,'Controle Central'!AA90,'Controle Central'!T90,'Controle Central'!M90,'Controle Central'!F90,'Controle Central'!F108,'Controle Central'!F126,'Controle Central'!M108,'Controle Central'!M126,'Controle Central'!T108,'Controle Central'!T126,'Controle Central'!AA108,'Controle Central'!AA126,'Controle Central'!M144,'Controle Central'!F144) -> #REF! | M12: =SUM('Controle Central'!F15,'Controle Central'!F34,'Controle Central'!M15,'Controle Central'!M34,'Controle Central'!T15,'Controle Central'!T34,'Controle Central'!AA15,'Controle Central'!AA34,'Controle Central'!AA53,'Controle Central'!T53,'Controle Central'!AA72,'Controle Central'!T72,'Controle Central'!M53,'Controle Central'!F53,'Controle Central'!F72,'Controle Central'!M72,'Controle Central'!F91,'Controle Central'!F109,'Controle Central'!M91,'Controle Central'!M109,'Controle Central'!T91,'Controle Central'!T109,'Controle Central'!AA91,'Controle Central'!AA109,'Controle Central'!AA127,'Controle Central'!T127,'Controle Central'!M127,'Controle Central'!M145,'Controle Central'!F127,'Controle Central'!F145) -> #REF!
B16: JAN | C16: FEV | D16: MAR | E16: ABR | F16: MAI | G16: JUN | H16: JUL | I16: AGO | J16: SET | K16: OUT | L16: NOV | M16: DEZ
A17: Medição | C17: 20800 | D17: 46800
A19: Contrato de Locação | C19: 9452 | D19: 21267
A21: Lucro Car's | B21: =B17-B19 -> 0 | C21: =C17-C19 -> 11348 | D21: =D17-D19 -> 25533 | E21: =E17-E19 -> 0 | F21: =F17-F19 -> 0 | G21: =G17-G19 -> 0 | H21: =H17-H19 -> 0 | I21: =I17-I19 -> 0 | ... M21: =M17-M19 -> 0

Sheet Controle Central
B2: Robson km contratual 5.000 | I2: Paulo km contratual 5000 | P2: Marco km contratual 5000 | W2: Ivnna km contratual 5000
B3: KM RODADO | C3: KM MENSAL | D3: ABASTECIMENTO | E3: LAVA_RAPIDO | F3: BORRACHARIA | I3: KM RODADO | J3: KM MENSAL | K3: ABASTECIMENTO | L3: LAVA_RAPIDO | M3: BORRACHARIA | P3: KM RODADO | Q3: KM MENSAL | R3: ABASTECIMENTO | S3: LAVA_RAPIDO | T3: BORRACHARIA | W3: KM RODADO | X3: KM MENSAL | Y3: ABASTECIMENTO | Z3: LAVA_RAPIDO | AA3: BORRACHARIA
A4: JAN | C4: 0 | D4: 0 | E4: 0 | F4: 0 | H4: JAN | J4: 0 | K4: 0 | L4: 0 | M4: 0 | O4: JAN | Q4: 0 | R4: 0 | S4: 0 | T4: 0 | V4: JAN | X4: 0 | Y4: 0 | Z4: 0 | AA4: 0
A5: FEV | B5: ='Robson-Devolv'!H12 -> 1314 | C5: =SUM(5000-B5) -> 3686 | D5: ='Robson-Devolv'!U13 -> 687.92 | E5: ='Robson-Devolv'!AC13 -> 0 | F5: ='Robson-Devolv'!AK13 -> 0 | H5: FEV | I5: ='Paulo - Desmob'!H11 -> 1572 | J5: =SUM(5000-I5) -> 3428 | K5: ='Paulo - Desmob'!U12 -> 704.42 | L5: ='Paulo - Desmob'!AC12 -> 0 | M5: ='Paulo - Desmob'!AK12 -> 0 | O5: FEV | P5: ='Marco - Desmob'!H11 -> 1218 | Q5: =SUM(5000-P5) -> 3782 | R5: ='Marco - Desmob'!U12 -> 610.74 | S5: ='Marco - Desmob'!AI12 -> 0 | T5: ='Marco - Desmob'!AR12 -> 0 | V5: FEV | W5: ='Ivnna-Desmob'!H11 -> 925 | X5: =SUM(5000-W5) -> 4075 | Y5: ='Ivnna-Desmob'!U12 -> 207.61 | Z5: ='Ivnna-Desmob'!AI12 -> 0 | AA5: ='Ivnna-Desmob'!AR12 -> 0
A6: MAR | B6: ='Robson-Devolv'!H16 -> 2994 | C6: =SUM(5000-B6) -> 2006 | D6: ='Robson-Devolv'!U17 -> 1346.74 | E6: ='Robson-Devolv'!AC17 -> 0 | F6: ='Robson-Devolv'!AK17 -> 0 | H6: MAR | I6: ='Paulo - Desmob'!H15 -> 3761 | J6: =SUM(5000-I6) -> 1239 | K6: ='Paulo - Desmob'!U16 -> 1959.56 | L6: ='Paulo - Desmob'!AC16 -> 0 | M6: ='Paulo - Desmob'!AK16 -> 0 | O6: MAR | P6: ='Marco - Desmob'!H15 -> 2279 | Q6: =SUM(5000-P6) -> 2721 | R6: ='Marco - Desmob'!U16 -> 706.46 | S6: ='Marco - Desmob'!AI16 -> 0 | T6: ='Marco - Desmob'!AR16 -> 0 | V6: MAR | W6: ='Ivnna-Desmob'!H15 -> 2685 | X6: =SUM(5000-W6) -> 2315 | Y6: ='Ivnna-Desmob'!U16 -> 1309.3 | Z6: ='Ivnna-Desmob'!AI16 -> 0 | AA6: ='Ivnna-Desmob'!AR16 -> 0
A7: ABR | B7: ='Robson-Devolv'!H20 -> 3086 | C7: =SUM(5000-B7) -> 1914 | D7: ='Robson-Devolv'!U21 -> 1268.57 | E7: ='Robson-Devolv'!AC21 -> 80 | F7: ='Robson-Devolv'!AK21 -> 0 | H7: ABR | I7: ='Paulo - Desmob'!H19 -> 2185 | J7: =SUM(5000-I7) -> 2815 | K7: ='Paulo - Desmob'!U20 -> 1147.02 | L7: ='Paulo - Desmob'!AC20 -> 80 | M7: ='Paulo - Desmob'!AK20 -> 0 | O7: ABR | P7: ='Marco - Desmob'!H19 -> 2628 | Q7: =SUM(5000-P7) -> 2372 | R7: ='Marco - Desmob'!U20 -> 1242.98 | S7: ='Marco - Desmob'!AI20 -> 0 | T7: ='Marco - Desmob'!AR20 -> 0 | V7: ABR | W7: ='Ivnna-Desmob'!H19 -> 3094 | X7: =SUM(5000-W7) -> 1906 | Y7: ='Ivnna-Desmob'!U20 -> 1226.75 | Z7: ='Ivnna-Desmob'!AI20 -> 0 | AA7: ='Ivnna-Desmob'!AR20 -> 0
A8: MAI | B8: ='Robson-Devolv'!H24 -> 2498 | C8: =SUM(5000-B8) -> 2502 | D8: ='Robson-Devolv'!U25 -> 870.52 | E8: ='Robson-Devolv'!AC25 -> 80 | F8: ='Robson-Devolv'!AK25 -> 0 | H8: MAI | I8: ='Paulo - Desmob'!H23 -> 3015 | J8: =SUM(5000-I8) -> 1985 | K8: ='Paulo - Desmob'!U24 -> 1794.06 | L8: ='Paulo - Desmob'!AC24 -> 80 | M8: ='Paulo - Desmob'!AK24 -> 0 | O8: MAI | P8: ='Marco - Desmob'!H23 -> 3170 | Q8: =SUM(5000-P8) -> 1830 | R8: ='Marco - Desmob'!U24 -> 1300.91 | S8: ='Marco - Desmob'!AC24 -> 160 | T8: ='Marco - Desmob'!AR24 -> 0 | V8: MAI | W8: ='Ivnna-Desmob'!H23 -> 2882 | X8: =SUM(5000-W8) -> 2118 | Y8: ='Ivnna-Desmob'!U24 -> 959.72 | Z8: ='Ivnna-Desmob'!AC24 -> 130 | AA8: ='Ivnna-Desmob'!AR24 -> 0
A9: JUN | B9: ='Robson-Devolv'!H28 -> 2729 | C9: =SUM(5000-B9) -> 2271 | D9: ='Robson-Devolv'!U29 -> 1312.59 | E9: ='Robson-Devolv'!AC29 -> 160 | F9: ='Robson-Devolv'!AK29 -> 0 | H9: JUN | I9: ='Paulo - Desmob'!H27 -> 4452 | J9: =SUM(5000-I9) -> 548 | K9: ='Paulo - Desmob'!U28 -> 1862.81 | L9: ='Paulo - Desmob'!AC28 -> 240 | M9: ='Robson-Devolv'!AK29 -> 0 | O9: JUN | P9: ='Marco - Desmob'!H27 -> 2928 | Q9: =SUM(5000-P9) -> 2072 | R9: ='Marco - Desmob'!U28 -> 1021.22 | S9: ='Marco - Desmob'!AI28 -> 0 | T9: ='Marco - Desmob'!AR28 -> 0 | V9: JUN | W9: ='Ivnna-Desmob'!H27 -> 2722 | X9: =SUM(5000-W9) -> 2278 | Y9: ='Ivnna-Desmob'!U28 -> 1244.86 | Z9: ='Ivnna-Desmob'!AI28 -> 0 | AA9: ='Ivnna-Desmob'!AR28 -> 0
A10: JUL | B10: ='Robson-Devolv'!H32 -> 2667 | C10: =SUM(5000-B10) -> 2333 | D10: ='Robson-Devolv'!U33 -> 1564.22 | E10: ='Robson-Devolv'!AC33 -> 135 | F10: ='Robson-Devolv'!AK33 -> 0 | H10: JUL | I10: ='Paulo - Desmob'!H31 -> 2031 | J10: =SUM(5000-I10) -> 2969 | K10: ='Paulo - Desmob'!U32 -> 1169.63 | L10: ='Paulo - Desmob'!AC32 -> 160 | M10: ='Paulo - Desmob'!AK32 -> 0 | O10: JUL | P10: ='Marco - Desmob'!H31 -> 2251 | Q10: =SUM(5000-P10) -> 2749 | R10: ='Marco - Desmob'!U32 -> 962.33 | S10: ='Marco - Desmob'!AC32 -> 140 | T10: ='Marco - Desmob'!AR32 -> 0 | V10: JUL | W10: ='Ivnna-Desmob'!H31 -> 3246 | X10: =SUM(5000-W10) -> 1754 | Y10: ='Ivnna-Desmob'!U32 -> 1338.32 | Z10: ='Ivnna-Desmob'!AC32 -> 220 | AA10: ='Ivnna-Desmob'!AR32 -> 0
A11: AGO | B11: ='Robson-Devolv'!H36 -> 1483 | C11: =SUM(5000-B11) -> 3517 | D11: ='Robson-Devolv'!U37 -> 1342.94 | E11: ='Robson-Devolv'!AC37 -> 215 | F11: ='Robson-Devolv'!AK37 -> 0 | H11: AGO | I11: ='Paulo - Desmob'!H35 -> 3925 | J11: =SUM(5000-I11) -> 1075 | K11: ='Paulo - Desmob'!U36 -> 2240.32 | L11: ='Paulo - Desmob'!AC36 -> 240 | M11: ='Paulo - Desmob'!AK36 -> 0 | O11: AGO | P11: ='Marco - Desmob'!H35 -> 0 | Q11: =SUM(5000-P11) -> 5000 | R11: ='Marco - Desmob'!U36 -> 360.84 | S11: ='Marco - Desmob'!AC36 -> 80 | T11: ='Marco - Desmob'!AR36 -> 0 | V11: AGO | W11: ='Ivnna-Desmob'!H35 -> 2843 | X11: =SUM(5000-W11) -> 2157 | Y11: ='Ivnna-Desmob'!U36 -> 1166.75 | Z11: ='Ivnna-Desmob'!AC36 -> 240 | AA11: ='Ivnna-Desmob'!AR36 -> 0
A12: SET | B12: ='Robson-Devolv'!H40 -> 2886 | C12: =SUM(5000-B12) -> 2114 | D12: ='Robson-Devolv'!U41 -> 1243.68 | E12: ='Robson-Devolv'!AC41 -> 75 | F12: ='Robson-Devolv'!AK41 -> 0 | H12: SET | I12: ='Paulo - Desmob'!H39 -> 3284 | J12: =SUM(5000-I12) -> 1716 | K12: ='Paulo - Desmob'!U40 -> 1698.73 | L12: ='Paulo - Desmob'!AC40 -> 75 | M12: ='Paulo - Desmob'!AK40 -> 0 | O12: SET | P12: ='Marco - Desmob'!H35 -> 0 | Q12: =SUM(5000-P12) -> 5000 | R12: ='Marco - Desmob'!Z40 -> 0 | S12: ='Marco - Desmob'!AI40 -> 0 | T12: ='Marco - Desmob'!AR40 -> 0 | V12: SET | W12: ='Ivnna-Desmob'!H39 -> 2747 | X12: =SUM(5000-W12) -> 2253 | Y12: ='Ivnna-Desmob'!U40 -> 1028.47 | Z12: ='Ivnna-Desmob'!AI40 -> 0 | AA12: ='Ivnna-Desmob'!AR40 -> 0
A13: OUT | B13: ='Robson-Devolv'!H44 -> 0 | C13: =SUM(5000-B13) -> 5000 | D13: ='Robson-Devolv'!U45 -> 1710.74 | E13: ='Robson-Devolv'!AC45 -> 75 | F13: ='Robson-Devolv'!AK45 -> 0 | H13: OUT | I13: ='Paulo - Desmob'!H43 -> 1136 | J13: =SUM(5000-I13) -> 3864 | K13: ='Paulo - Desmob'!U44 -> 2080.72 | L13: ='Paulo - Desmob'!AC44 -> 80 | M13: ='Paulo - Desmob'!AK44 -> 0 | O13: OUT | P13: ='Marco - Desmob'!H39 -> 0 | Q13: =SUM(5000-P13) -> 5000 | R13: ='Marco - Desmob'!Z44 -> 0 | S13: ='Marco - Desmob'!AI44 -> 0 | T13: ='Marco - Desmob'!AR44 -> 0 | V13: OUT | W13: ='Ivnna-Desmob'!H43 -> 3063 | X13: =SUM(5000-W13) -> 1937 | Y13: ='Ivnna-Desmob'!Z44 -> 0 | Z13: ='Ivnna-Desmob'!AI44 -> 0 | AA13: ='Ivnna-Desmob'!AR44 -> 0
A14: NOV | B14: ='Robson-Devolv'!H48 -> 1393 | C14: =SUM(5000-B14) -> 3607 | D14: ='Robson-Devolv'!U49 -> 408.9 | E14: ='Robson-Devolv'!AC49 -> 0 | F14: ='Robson-Devolv'!AK49 -> 0 | H14: NOV | I14: ='Paulo - Desmob'!H47 -> 2954 | J14: =SUM(5000-I14) -> 2046 | K14: ='Paulo - Desmob'!U48 -> 464.24 | L14: ='Paulo - Desmob'!AC48 -> 0 | M14: ='Paulo - Desmob'!AK48 -> 0 | O14: NOV | P14: ='Marco - Desmob'!H43 -> 0 | Q14: =SUM(5000-P14) -> 5000 | R14: ='Marco - Desmob'!Z48 -> 0 | S14: ='Marco - Desmob'!AI48 -> 0 | T14: ='Marco - Desmob'!AR48 -> 0 | V14: NOV | W14: ='Ivnna-Desmob'!H47 -> 1068 | X14: =SUM(5000-W14) -> 3932 | Y14: ='Ivnna-Desmob'!Z48 -> 0 | Z14: ='Ivnna-Desmob'!AI48 -> 0 | AA14: ='Ivnna-Desmob'!AR48 -> 0
A15: DEZ | B15: ='Robson-Devolv'!H52 -> 2696 | C15: =SUM(5000-B15) -> 2304 | D15: ='Robson-Devolv'!U53 -> 0 | E15: ='Robson-Devolv'!AC53 -> 0 | F15: ='Robson-Devolv'!AK53 -> 0 | H15: DEZ | I15: ='Paulo - Desmob'!H51 -> 2082 | J15: =SUM(5000-I15) -> 2918 | K15: ='Paulo - Desmob'!U52 -> 0 | L15: ='Paulo - Desmob'!AC48 -> 0 | M15: ='Paulo - Desmob'!AK48 -> 0 | O15: DEZ | P15: ='Marco - Desmob'!H47 -> 0 | Q15: =SUM(5000-P15) -> 5000 | R15: ='Marco - Desmob'!Z52 -> 0 | S15: ='Marco - Desmob'!AI48 -> 0 | T15: ='Marco - Desmob'!AR52 -> 0 | V15: DEZ | W15: ='Ivnna-Desmob'!H51 -> 1515 | X15: =SUM(5000-W15) -> 3485 | Y15: ='Ivnna-Desmob'!Z52 -> 0 | Z15: ='Ivnna-Desmob'!AI52 -> 0 | AA15: ='Ivnna-Desmob'!AR52 -> 0
A17: TOTAL | B17: =SUM(B4:B15) -> 23746 | D17: =SUM(D4:D15) -> 11756.82 | E17: =SUM(E4:E15) -> 820 | F17: =SUM(F4:F15) -> 0 | H17: TOTAL | I17: =SUM(I4:I15) -> 30397 | K17: =SUM(K4:K15) -> 15121.51 | L17: =SUM(L4:L15) -> 955 | M17: =SUM(M4:M15) -> 0 | O17: TOTAL | P17: =SUM(P4:P15) -> 14474 | R17: =SUM(R4:R15) -> 6205.48 | S17: =SUM(S4:S15) -> 380 | T17: =SUM(T4:T15) -> 0 | V17: TOTAL | W17: =SUM(W4:W15) -> 26790 | Y17: =SUM(Y4:Y15) -> 8481.78 | Z17: =SUM(Z4:Z15) -> 590 | AA17: =SUM(AA4:AA15) -> 0
A18: SALDO KM | B18: =SUM(60000-B17) -> 36254 | H18: SALDO KM | I18: =SUM(60000-I17) -> 29603 | O18: SALDO KM | P18: =SUM(60000-P17) -> 45526 | V18: SALDO KM | W18: =SUM(60000-W17) -> 33210
B21: Thiago km contratual 5000 | I21: Adalberto km contratual 5000 | P21: Danilo km contratual 5000 | W21: Jacques km contratual 5000
B22: KM RODADO | C22: KM MENSAL | D22: ABASTECIMENTO | E22: LAVA_RAPIDO | F22: BORRACHARIA | I22: KM RODADO | J22: KM MENSAL | K22: ABASTECIMENTO | L22: LAVA_RAPIDO | M22: BORRACHARIA | P22: KM RODADO | Q22: KM MENSAL | R22: ABASTECIMENTO | S22: LAVA_RAPIDO | T22: BORRACHARIA | W22: KM RODADO | X22: KM MENSAL | Y22: ABASTECIMENTO | Z22: LAVA_RAPIDO | AA22: BORRACHARIA
A23: JAN | C23: 0 | D23: 0 | E23: 0 | F23: 0 | H23: JAN | J23: 0 | K23: 0 | L23: 0 | M23: 0 | O23: JAN | Q23: 0 | R23: 0 | S23: 0 | T23: 0 | V23: JAN | X23: 0 | Y23: 0 | Z23: 0 | AA23: 0
A24: FEV | B24: ='Rodolfo - Desmob'!H11 -> 0 | C24: =SUM(5000-B24) -> 5000 | D24: ='Rodolfo - Desmob'!U12 -> 0 | E24: ='Rodolfo - Desmob'!AC12 -> 0 | F24: ='Rodolfo - Desmob'!AK12 -> 0 | H24: FEV | I24: ='Chris-Desmob'!H11 -> 0 | J24: =SUM(5000-I24) -> 5000 | K24: ='Chris-Desmob'!U12 -> 0 | L24: ='Chris-Desmob'!AC12 -> 0 | M24: ='Chris-Desmob'!AK12 -> 0 | O24: FEV | P24: ='Igor-Desmob'!H11 -> 0 | Q24: =SUM(5000-P24) -> 5000 | R24: ='Igor-Desmob'!U12 -> 0 | S24: ='Igor-Desmob'!AC12 -> 0 | T24: ='Igor-Desmob'!AK12 -> 0 | V24: FEV | W24: ='Jacques - desmob'!H11 -> 0 | X24: =SUM(5000-W24) -> 5000 | Y24: ='Jacques - desmob'!U12 -> 0 | Z24: ='Jacques - desmob'!AC12 -> 0 | AA24: ='Jacques - desmob'!AK12 -> 0
A25: MAR | B25: ='Rodolfo - Desmob'!H15 -> 3002 | C25: =SUM(5000-B25) -> 1998 | D25: ='Rodolfo - Desmob'!U16 -> 1198.73 | E25: ='Rodolfo - Desmob'!AC16 -> 0 | F25: ='Rodolfo - Desmob'!AK16 -> 0 | H25: MAR | I25: ='Chris-Desmob'!H15 -> 2709 | J25: =SUM(5000-I25) -> 2291 | K25: ='Chris-Desmob'!U16 -> 1195.48 | L25: ='Chris-Desmob'!AC16 -> 0 | M25: ='Chris-Desmob'!AK16 -> 0 | O25: MAR | P25: ='Igor-Desmob'!H15 -> 3812 | Q25: =SUM(5000-P25) -> 1188 | R25: ='Igor-Desmob'!U16 -> 1754.35 | S25: ='Igor-Desmob'!AC16 -> 0 | T25: ='Igor-Desmob'!AK16 -> 0 | V25: MAR | W25: ='Jacques - desmob'!H15 -> 1967 | X25: =SUM(5000-W25) -> 3033 | Y25: ='Jacques - desmob'!U16 -> 544.78 | Z25: ='Jacques - desmob'!AC16 -> 0 | AA25: ='Jacques - desmob'!AK16 -> 0
A26: ABR | B26: ='Rodolfo - Desmob'!H19 -> 3082 | C26: =SUM(5000-B26) -> 1918 | D26: ='Rodolfo - Desmob'!U20 -> 1713.29 | E26: ='Rodolfo - Desmob'!AC20 -> 160 | F26: ='Rodolfo - Desmob'!AK20 -> 0 | H26: ABR | I26: ='Chris-Desmob'!H19 -> 2746 | J26: =SUM(5000-I26) -> 2254 | K26: ='Chris-Desmob'!U20 -> 1178.23 | L26: ='Chris-Desmob'!AC20 -> 80 | M26: ='Chris-Desmob'!AK20 -> 0 | O26: ABR | P26: ='Igor-Desmob'!H19 -> 3444 | Q26: =SUM(5000-P26) -> 1556 | R26: ='Igor-Desmob'!U20 -> 1735.07 | S26: ='Igor-Desmob'!AC20 -> 0 | T26: ='Igor-Desmob'!AK20 -> 0 | V26: ABR | W26: ='Jacques - desmob'!H19 -> 3475 | X26: =SUM(5000-W26) -> 1525 | Y26: ='Jacques - desmob'!U20 -> 1170.58 | Z26: ='Jacques - desmob'!AC20 -> 0 | AA26: ='Jacques - desmob'!AK200 -> 0
A27: MAI | B27: ='Rodolfo - Desmob'!H23 -> 2723 | C27: =SUM(5000-B27) -> 2277 | D27: ='Rodolfo - Desmob'!U24 -> 1347.94 | E27: ='Rodolfo - Desmob'!AC24 -> 160 | F27: ='Rodolfo - Desmob'!AK24 -> 0 | H27: MAI | I27: ='Chris-Desmob'!H23 -> 2577 | J27: =SUM(5000-I27) -> 2423 | K27: ='Chris-Desmob'!U24 -> 1295.99 | L27: ='Chris-Desmob'!AC24 -> 80 | M27: ='Chris-Desmob'!AK24 -> 0 | O27: MAI | P27: ='Igor-Desmob'!H23 -> 2939 | Q27: =SUM(5000-P27) -> 2061 | R27: ='Igor-Desmob'!U24 -> 1469.93 | S27: ='Igor-Desmob'!AC24 -> 290 | T27: ='Igor-Desmob'!AK24 -> 0 | V27: MAI | W27: ='Jacques - desmob'!H23 -> 2806 | X27: =SUM(5000-W27) -> 2194 | Y27: ='Jacques - desmob'!U24 -> 713.11 | Z27: ='Jacques - desmob'!AC24 -> 80 | AA27: ='Jacques - desmob'!AK24 -> 0
A28: JUN | B28: ='Rodolfo - Desmob'!H27 -> 3052 | C28: =SUM(5000-B28) -> 1948 | D28: ='Rodolfo - Desmob'!U28 -> 1486.9 | E28: ='Rodolfo - Desmob'!AC24 -> 160 | F28: ='Rodolfo - Desmob'!AK28 -> 0 | H28: JUN | I28: ='Chris-Desmob'!H27 -> 2121 | J28: =SUM(5000-I28) -> 2879 | K28: ='Chris-Desmob'!U28 -> 1240.85 | L28: ='Chris-Desmob'!AC28 -> 80 | M28: ='Chris-Desmob'!AK28 -> 0 | O28: JUN | P28: ='Igor-Desmob'!H27 -> 3082 | Q28: =SUM(5000-P28) -> 1918 | R28: ='Igor-Desmob'!U28 -> 1657.74 | S28: ='Igor-Desmob'!AC24 -> 290 | T28: ='Igor-Desmob'!AK28 -> 0 | V28: JUN | W28: ='Jacques - desmob'!H27 -> 0 | X28: =SUM(5000-W28) -> 5000 | Y28: ='Jacques - desmob'!U28 -> 0 | Z28: ='Jacques - desmob'!AC28 -> 0 | AA28: ='Jacques - desmob'!AK28 -> 0
A29: JUL | B29: ='Rodolfo - Desmob'!H31 -> 2611 | C29: =SUM(5000-B29) -> 2389 | D29: ='Rodolfo - Desmob'!U32 -> 1779.48 | E29: ='Rodolfo - Desmob'!AC32 -> 160 | F29: ='Rodolfo - Desmob'!AK32 -> 0 | H29: JUL | I29: ='Chris-Desmob'!H31 -> 2535 | J29: =SUM(5000-I29) -> 2465 | K29: ='Chris-Desmob'!U32 -> 1403.15 | L29: ='Chris-Desmob'!AC32 -> 215 | M29: ='Chris-Desmob'!AK32 -> 0 | O29: JUL | P29: ='Igor-Desmob'!H31 -> 3873 | Q29: =SUM(5000-P29) -> 1127 | R29: ='Igor-Desmob'!U32 -> 1689.01 | S29: ='Igor-Desmob'!AC32 -> 295 | T29: ='Igor-Desmob'!AK32 -> 0 | V29: JUL | W29: ='Jacques - desmob'!H31 -> 0 | X29: =SUM(5000-W29) -> 5000 | Y29: ='Jacques - desmob'!U32 -> 0 | Z29: ='Jacques - desmob'!AC32 -> 0 | AA29: ='Jacques - desmob'!AK32 -> 0
A30: AGO | B30: ='Rodolfo - Desmob'!H35 -> 2181 | C30: =SUM(5000-B30) -> 2819 | D30: ='Rodolfo - Desmob'!U36 -> 1516.86 | E30: ='Rodolfo - Desmob'!AC36 -> 135 | F30: ='Rodolfo - Desmob'!AK36 -> 0 | H30: AGO | I30: ='Chris-Desmob'!H35 -> 2327 | J30: =SUM(5000-I30) -> 2673 | K30: ='Chris-Desmob'!U36 -> 1129.75 | L30: ='Chris-Desmob'!AC36 -> 200 | M30: ='Chris-Desmob'!AK36 -> 0 | O30: AGO | P30: ='Igor-Desmob'!H35 -> 4548 | Q30: =SUM(5000-P30) -> 452 | R30: ='Igor-Desmob'!U36 -> 2037.19 | S30: ='Igor-Desmob'!AC36 -> 215 | T30: ='Igor-Desmob'!AK36 -> 0 | V30: AGO | W30: ='Jacques - desmob'!H35 -> 0 | X30: =SUM(5000-W30) -> 5000 | Y30: ='Jacques - desmob'!U36 -> 0 | Z30: ='Jacques - desmob'!AC36 -> 0 | AA30: ='Jacques - desmob'!AK36 -> 0
A31: SET | B31: ='Rodolfo - Desmob'!H39 -> 2654 | C31: =SUM(5000-B31) -> 2346 | D31: ='Rodolfo - Desmob'!U40 -> 1491.29 | E31: ='Rodolfo - Desmob'!AC40 -> 210 | F31: ='Rodolfo - Desmob'!AK4 -> 0 | H31: SET | I31: ='Chris-Desmob'!H39 -> 2288 | J31: =SUM(5000-I31) -> 2712 | K31: ='Chris-Desmob'!U40 -> 953.2 | L31: ='Chris-Desmob'!AC40 -> 155 | M31: ='Chris-Desmob'!AK40 -> 50 | O31: SET | P31: ='Igor-Desmob'!H39 -> 3731 | Q31: =SUM(5000-P31) -> 1269 | R31: ='Igor-Desmob'!U40 -> 1939.82 | S31: ='Igor-Desmob'!AC40 -> 155 | T31: ='Igor-Desmob'!AK40 -> 0 | V31: SET | W31: ='Jacques - desmob'!H39 -> 0 | X31: =SUM(5000-W31) -> 5000 | Y31: ='Jacques - desmob'!U40 -> 0 | Z31: ='Jacques - desmob'!AC40 -> 0 | AA31: ='Jacques - desmob'!AK40 -> 0
A32: OUT | B32: ='Rodolfo - Desmob'!H43 -> -8031 | C32: =SUM(5000-B32) -> 13031 | D32: ='Rodolfo - Desmob'!U44 -> 1712.65 | E32: ='Rodolfo - Desmob'!AC44 -> 0 | F32: ='Rodolfo - Desmob'!AK44 -> 0 | H32: OUT | I32: ='Chris-Desmob'!H43 -> 1404 | J32: =SUM(5000-I32) -> 3596 | K32: ='Chris-Desmob'!U44 -> 1212.89 | L32: ='Chris-Desmob'!AC44 -> 75 | M32: ='Chris-Desmob'!AK44 -> 0 | O32: OUT | P32: ='Igor-Desmob'!H43 -> 4373 | Q32: =SUM(5000-P32) -> 627 | R32: ='Igor-Desmob'!U44 -> 2335.23 | S32: ='Igor-Desmob'!AC44 -> 150 | T32: ='Igor-Desmob'!AK44 -> 0 | V32: OUT | W32: ='Jacques - desmob'!H43 -> 0 | X32: =SUM(5000-W32) -> 5000 | Y32: ='Jacques - desmob'!U44 -> 0 | Z32: ='Jacques - desmob'!AC44 -> 0 | AA32: ='Jacques - desmob'!AK44 -> 0
A33: NOV | B33: ='Rodolfo - Desmob'!H47 -> 0 | C33: =SUM(5000-B33) -> 5000 | D33: ='Rodolfo - Desmob'!U48 -> 337.2 | E33: ='Rodolfo - Desmob'!AC48 -> 0 | F33: ='Rodolfo - Desmob'!AK48 -> 0 | H33: NOV | I33: ='Chris-Desmob'!H47 -> 3329 | J33: =SUM(5000-I33) -> 1671 | K33: ='Chris-Desmob'!U48 -> 242.5 | L33: ='Chris-Desmob'!AC48 -> 0 | M33: ='Chris-Desmob'!AK48 -> 0 | O33: NOV | P33: ='Igor-Desmob'!H47 -> 3532 | Q33: =SUM(5000-P33) -> 1468 | R33: ='Igor-Desmob'!U48 -> 752.94 | S33: ='Igor-Desmob'!AC48 -> 0 | T33: ='Igor-Desmob'!AK48 -> 0 | V33: NOV | W33: ='Jacques - desmob'!H47 -> 0 | X33: =SUM(5000-W33) -> 5000 | Y33: ='Jacques - desmob'!U48 -> 0 | Z33: ='Jacques - desmob'!AC48 -> 0 | AA33: ='Jacques - desmob'!AK48 -> 0
A34: DEZ | B34: ='Rodolfo - Desmob'!H51 -> 0 | C34: =SUM(5000-B34) -> 5000 | D34: ='Rodolfo - Desmob'!U52 -> 0 | E34: ='Rodolfo - Desmob'!AC52 -> 0 | F34: ='Rodolfo - Desmob'!AK52 -> 0 | H34: DEZ | I34: ='Chris-Desmob'!H51 -> 1706 | J34: =SUM(5000-I34) -> 3294 | K34: ='Chris-Desmob'!U52 -> 824.95 | L34: ='Chris-Desmob'!AC52 -> 0 | M34: ='Chris-Desmob'!AK52 -> 0 | O34: DEZ | P34: ='Igor-Desmob'!H51 -> 764 | Q34: =SUM(5000-P34) -> 4236 | R34: ='Igor-Desmob'!U52 -> 0 | S34: ='Igor-Desmob'!AC52 -> 0 | T34: ='Igor-Desmob'!AK52 -> 0 | V34: DEZ | W34: ='Jacques - desmob'!H51 -> 0 | X34: =SUM(5000-W34) -> 5000 | Y34: ='Jacques - desmob'!U52 -> 0 | Z34: ='Jacques - desmob'!AC52 -> 0 | AA34: ='Jacques - desmob'!AK52 -> 0
A36: TOTAL | B36: =SUM(B23:B34) -> 11274 | D36: =SUM(D23:D34) -> 12584.34 | E36: =SUM(E23:E34) -> 985 | F36: =SUM(F23:F34) -> 0 | H36: TOTAL | I36: =SUM(I23:I34) -> 23742 | K36: =SUM(K23:K34) -> 10676.99 | L36: =SUM(L23:L34) -> 885 | M36: =SUM(M23:M34) -> 50 | O36: TOTAL | P36: =SUM(P23:P34) -> 34098 | R36: =SUM(R23:R34) -> 15371.28 | S36: =SUM(S23:S34) -> 1395 | T36: =SUM(T23:T34) -> 0 | V36: TOTAL | W36: =SUM(W23:W34) -> 8248 | Y36: =SUM(Y23:Y34) -> 2428.47 | Z36: =SUM(Z23:Z34) -> 80 | AA36: =SUM(AA23:AA34) -> 0
A37: SALDO KM | B37: =SUM(60000-B36) -> 48726 | H37: SALDO KM | I37: =SUM(60000-I36) -> 36258 | O37: SALDO KM | P37: =SUM(60000-P36) -> 25902 | V37: SALDO KM | W37: =SUM(60000-W36) -> 51752
B40: Illichi km contratual 5000 | I40: Wagner km contratual 5000 | P40: Devaldo km contratual 5000 | W40: Antonio Flavio km contratual 5000
B41: KM | C41: KM MENSAL | D41: ABASTECIMENTO | E41: LAVA_RAPIDO | F41: BORRACHARIA | I41: KM | J41: KM MENSAL | K41: ABASTECIMENTO | L41: LAVA_RAPIDO | M41: BORRACHARIA | P41: KM | Q41: KM MENSAL | R41: ABASTECIMENTO | S41: LAVA_RAPIDO | T41: BORRACHARIA | W41: KM | X41: KM MENSAL | Y41: ABASTECIMENTO | Z41: LAVA_RAPIDO | AA41: BORRACHARIA
A42: JAN | H42: JAN | O42: JAN | V42: JAN
A43: FEV | B43: ='Illichi_Wesley-Desmob'!H11 -> 0 | C43: =SUM(5000-B43) -> 5000 | D43: ='Illichi_Wesley-Desmob'!U12 -> 0 | E43: ='Illichi_Wesley-Desmob'!AC12 -> 0 | F43: ='Illichi_Wesley-Desmob'!AK12 -> 0 | H43: FEV | I43: ='Wagner-Desmob'!H11 -> 0 | J43: =SUM(5000-I43) -> 5000 | K43: ='Wagner-Desmob'!U12 -> 0 | L43: ='Wagner-Desmob'!AE12 -> 0 | M43: ='Wagner-Desmob'!AN12 -> 0 | O43: FEV | P43: ='Devaldo-Desmob'!H11 -> 0 | Q43: =SUM(5000-P43) -> 5000 | R43: ='Devaldo-Desmob'!U12 -> 0 | S43: ='Devaldo-Desmob'!AE12 -> 0 | T43: ='Devaldo-Desmob'!AN12 -> 0 | V43: FEV | W43: ='Antonio Flavio-Desmob'!H14 -> 0 | X43: =SUM(5000-W43) -> 5000 | Y43: ='Antonio Flavio-Desmob'!U15 -> 0 | Z43: ='Antonio Flavio-Desmob'!AE15 -> 0 | AA43: ='Antonio Flavio-Desmob'!AN15 -> 0
A44: MAR | B44: ='Illichi_Wesley-Desmob'!H15 -> 149 | C44: =SUM(5000-B44) -> 4851 | D44: ='Illichi_Wesley-Desmob'!U16 -> 0 | E44: ='Illichi_Wesley-Desmob'!AC16 -> 0 | F44: ='Illichi_Wesley-Desmob'!AK16 -> 0 | H44: MAR | I44: ='Wagner-Desmob'!H15 -> 0 | J44: =SUM(5000-I44) -> 5000 | K44: ='Wagner-Desmob'!U16 -> 0 | L44: ='Wagner-Desmob'!AE16 -> 0 | M44: ='Wagner-Desmob'!AN16 -> 0 | O44: MAR | P44: ='Devaldo-Desmob'!H15 -> 0 | Q44: =SUM(5000-P44) -> 5000 | R44: ='Devaldo-Desmob'!U16 -> 0 | S44: ='Devaldo-Desmob'!AE16 -> 0 | T44: ='Devaldo-Desmob'!AN16 -> 0 | V44: MAR | W44: ='Antonio Flavio-Desmob'!H18 -> 0 | X44: =SUM(5000-W44) -> 5000 | Y44: ='Antonio Flavio-Desmob'!U19 -> 0 | Z44: ='Antonio Flavio-Desmob'!AE19 -> 0 | AA44: ='Antonio Flavio-Desmob'!AN19 -> 0
A45: ABR | B45: ='Illichi_Wesley-Desmob'!H19 -> 3335 | C45: =SUM(5000-B45) -> 1665 | D45: ='Illichi_Wesley-Desmob'!U20 -> 1469.27 | E45: ='Illichi_Wesley-Desmob'!AC20 -> 80 | F45: ='Illichi_Wesley-Desmob'!AK20 -> 0 | H45: ABR | I45: ='Wagner-Desmob'!H19 -> 0 | J45: =SUM(5000-I45) -> 5000 | K45: ='Wagner-Desmob'!U20 -> 186.41 | L45: ='Wagner-Desmob'!AE20 -> 0 | M45: ='Wagner-Desmob'!AN20 -> 0 | O45: ABR | P45: ='Devaldo-Desmob'!H19 -> 0 | Q45: =SUM(5000-P45) -> 5000 | R45: ='Devaldo-Desmob'!U20 -> 0 | S45: ='Devaldo-Desmob'!AE20 -> 0 | T45: ='Devaldo-Desmob'!AN20 -> 0 | V45: ABR | W45: ='Antonio Flavio-Desmob'!H22 -> 0 | X45: =SUM(5000-W45) -> 5000 | Y45: ='Antonio Flavio-Desmob'!U23 -> 0 | Z45: ='Antonio Flavio-Desmob'!AE23 -> 0 | AA45: ='Antonio Flavio-Desmob'!AN23 -> 0
A46: MAI | B46: ='Illichi_Wesley-Desmob'!H23 -> 2518 | C46: =SUM(5000-B46) -> 2482 | D46: ='Illichi_Wesley-Desmob'!U24 -> 1028.72 | E46: ='Illichi_Wesley-Desmob'!AC24 -> 160 | F46: ='Illichi_Wesley-Desmob'!AK24 -> 0 | H46: MAI | I46: ='Wagner-Desmob'!H23 -> 3418 | J46: =SUM(5000-I46) -> 1582 | K46: ='Wagner-Desmob'!U24 -> 1036.27 | L46: ='Wagner-Desmob'!AE24 -> 0 | M46: ='Wagner-Desmob'!AN24 -> 0 | O46: MAI | P46: ='Devaldo-Desmob'!H23 -> 3005 | Q46: =SUM(5000-P46) -> 1995 | R46: ='Devaldo-Desmob'!U24 -> 1351.61 | S46: ='Devaldo-Desmob'!AE24 -> 0 | T46: ='Devaldo-Desmob'!AN24 -> 0 | V46: MAI | W46: ='Antonio Flavio-Desmob'!H26 -> 573 | X46: =SUM(5000-W46) -> 4427 | Y46: ='Antonio Flavio-Desmob'!U27 -> 192.14 | Z46: ='Antonio Flavio-Desmob'!AE27 -> 0 | AA46: ='Antonio Flavio-Desmob'!AN27 -> 0
A47: JUN | B47: ='Illichi_Wesley-Desmob'!H27 -> 0 | C47: =SUM(5000-B47) -> 5000 | D47: ='Illichi_Wesley-Desmob'!U28 -> 934.01 | E47: ='Illichi_Wesley-Desmob'!AC28 -> 80 | F47: ='Illichi_Wesley-Desmob'!AK28 -> 0 | H47: JUN | I47: ='Wagner-Desmob'!H27 -> 3419 | J47: =SUM(5000-I47) -> 1581 | K47: ='Wagner-Desmob'!U28 -> 1572.8 | L47: ='Wagner-Desmob'!AE28 -> 320 | M47: ='Wagner-Desmob'!AN28 -> 0 | O47: JUN | P47: ='Devaldo-Desmob'!H27 -> 2584 | Q47: =SUM(5000-P47) -> 2416 | R47: ='Devaldo-Desmob'!U28 -> 1366.57 | S47: ='Devaldo-Desmob'!AE28 -> 0 | T47: ='Devaldo-Desmob'!AN28 -> 0 | V47: JUN | W47: ='Antonio Flavio-Desmob'!H30 -> 1814 | X47: =SUM(5000-W47) -> 3186 | Y47: ='Antonio Flavio-Desmob'!U31 -> 957.52 | Z47: ='Antonio Flavio-Desmob'!AE31 -> 160 | AA47: ='Antonio Flavio-Desmob'!AN31 -> 0
...

Sheet Leandro
A2: Veiculo | B2: Polo | D2: Placa: | E2: TJA7B20 | H2: km | I2: 3000
A3: Troca de Condutor | B3: 46167 | D3: Placa: | E3: TJA7B20 | H3: Consutores | I3: Wendel para Leandro
A4: Substituição Veículo | D4: Placa: | H4: Modelo
A5: Contrato de Locação | B5: 2484 | D5: Rastreador | E5: Unidas - 3s | H5: Data Desmob | I5: 46131
A8: REGISTRO DE KM | J8: ABASTECIMENTO | W8: LAVA_RAPIDO | AF8: BORRACHARIA
B10: Fevereiro | J10: Fevereiro | W10: Fevereiro | AF10: Fevereiro
A11: KM (Rodados) | B11: 1ª Leitura | C11: 2ª Leitura | D11: 3ª Leitura | E11: 4ª Leitura | F11: 15 dias Rodados | G11: 30 dias Rodados | H11: Total Mensal | J11: DATA | W11: DATA | AF11: DATA
F12: =SUM(C12-B12) -> 0 | G12: =SUM(E12-D12) -> 0 | H12: =SUM(F12:G12) -> 0 | J12: VALOR | W12: VALOR | AF12: VALOR
T13: TOTAL | U13: =SUM(K12:U12) -> 0 | AB13: TOTAL | AC13: =SUM(X12:AC12) -> 0 | AK13: TOTAL | AL13: =SUM(AG12:AL12) -> 0
B14: Março | J14: Março | W14: =J14 -> Março | AF14: =W14 -> Março
A15: KM (Rodados) | B15: 1ª Leitura | C15: 2ª Leitura | D15: 3ª Leitura | E15: 4ª Leitura | F15: 15 dias Rodados | G15: 30 dias Rodados | H15: Total Mensal | J15: DATA | W15: DATA | AF15: DATA
F16: =SUM(C16-B16) -> 0 | G16: =SUM(E16-D16) -> 0 | H16: =SUM(F16:G16) -> 0 | J16: VALOR | W16: VALOR | AF16: VALOR
T17: TOTAL | U17: =SUM(K16:U16) -> 0 | AB17: TOTAL | AC17: =SUM(X16:AC16) -> 0 | AK17: TOTAL | AL17: =SUM(AG16:AL16) -> 0
B18: Abril | J18: Abril | W18: =J18 -> Abril | AF18: =W18 -> Abril
A19: KM (Rodados) | B19: 1ª Leitura | C19: 2ª Leitura | D19: 3ª Leitura | E19: 4ª Leitura | F19: 15 dias Rodados | G19: 30 dias Rodados | H19: Total Mensal | J19: DATA | W19: DATA | AF19: DATA
D20: 51696 | E20: 53114 | F20: =SUM(C20-B20) -> 0 | G20: =SUM(E20-D20) -> 1418 | H20: =SUM(F20:G20) -> 1418 | J20: VALOR | W20: VALOR | AF20: VALOR
T21: TOTAL | U21: =SUM(K20:U20) -> 0 | AB21: TOTAL | AC21: =SUM(X20:AC20) -> 0 | AK21: TOTAL | AL21: =SUM(AG20:AL20) -> 0
B22: Maio | J22: Maio | W22: =J22 -> Maio | AF22: =W22 -> Maio
A23: KM (Rodados) | B23: 1ª Leitura | C23: 2ª Leitura | D23: 3ª Leitura | E23: 4ª Leitura | F23: 15 dias Rodados | G23: 30 dias Rodados | H23: Total Mensal | J23: DATA | W23: DATA | AF23: DATA
B24: 53114 | E24: 56409 | F24: =SUM(C24-B24) -> -53114 | G24: =SUM(E24-D24) -> 56409 | H24: =SUM(F24:G24) -> 3295 | J24: VALOR | W24: VALOR | AF24: VALOR
T25: TOTAL | U25: =SUM(K24:U24) -> 0 | AB25: TOTAL | AC25: =SUM(X24:AC24) -> 0 | AK25: TOTAL | AL25: =SUM(AG24:AL24) -> 0
B26: Junho | J26: Junho | W26: =J26 -> Junho | AF26: =W26 -> Junho
A27: KM (Rodados) | B27: 1ª Leitura | C27: 2ª Leitura | D27: 3ª Leitura | E27: 4ª Leitura | F27: 15 dias Rodados | G27: 30 dias Rodados | H27: Total Mensal | J27: DATA | W27: DATA | AF27: DATA
F28: =SUM(C28-B28) -> 0 | G28: =SUM(E28-D28) -> 0 | H28: =SUM(F28:G28) -> 0 | J28: VALOR | W28: VALOR | AF28: VALOR
T29: TOTAL | U29: =SUM(K28:U28) -> 0 | AB29: TOTAL | AC29: =SUM(X28:AC28) -> 0 | AK29: TOTAL | AL29: =SUM(AG28:AL28) -> 0
B30: Julho | J30: Julho | W30: =J30 -> Julho | AF30: =W30 -> Julho
A31: KM (Rodados) | B31: 1ª Leitura | C31: 2ª Leitura | D31: 3ª Leitura | E31: 4ª Leitura | F31: 15 dias Rodados | G31: 30 dias Rodados | H31: Total Mensal | J31: DATA | W31: DATA | AF31: DATA
F32: =SUM(C32-B32) -> 0 | G32: =SUM(E32-D32) -> 0 | H32: =SUM(F32:G32) -> 0 | J32: VALOR | W32: VALOR | AF32: VALOR
T33: TOTAL | U33: =SUM(K32:U32) -> 0 | AB33: TOTAL | AC33: =SUM(X32:AC32) -> 0 | AK33: TOTAL | AL33: =SUM(AG32:AL32) -> 0
B34: Agosto | J34: Agosto | W34: =J34 -> Agosto | AF34: =W34 -> Agosto
A35: KM (Rodados) | B35: 1ª Leitura | C35: 2ª Leitura | D35: 3ª Leitura | E35: 4ª Leitura | F35: 15 dias Rodados | G35: 30 dias Rodados | H35: Total Mensal | J35: DATA | W35: DATA | AF35: DATA
F36: =SUM(C36-B36) -> 0 | G36: =SUM(E36-D36) -> 0 | H36: =SUM(F36:G36) -> 0 | J36: VALOR | W36: VALOR | AF36: VALOR
T37: TOTAL | U37: =SUM(K36:U36) -> 0 | AB37: TOTAL | AC37: =SUM(X36:AC36) -> 0 | AK37: TOTAL | AL37: =SUM(AG36:AL36) -> 0
B38: Setembro | J38: Setembro | W38: =J38 -> Setembro | AF38: =W38 -> Setembro
A39: KM (Rodados) | B39: 1ª Leitura | C39: 2ª Leitura | D39: 3ª Leitura | E39: 4ª Leitura | F39: 15 dias Rodados | G39: 30 dias Rodados | H39: Total Mensal | J39: DATA | W39: DATA | AF39: DATA
F40: =SUM(C40-B40) -> 0 | G40: =SUM(E40-D40) -> 0 | H40: =SUM(F40:G40) -> 0 | J40: VALOR | W40: VALOR | AF40: VALOR
T41: TOTAL | U41: =SUM(K40:U40) -> 0 | AB41: TOTAL | AC41: =SUM(X40:AC40) -> 0 | AK41: TOTAL | AL41: =SUM(AG40:AL40) -> 0
B42: Outubro | J42: Outubro | W42: =J42 -> Outubro | AF42: =W42 -> Outubro
A43: KM (Rodados) | B43: 1ª Leitura | C43: 2ª Leitura | D43: 3ª Leitura | E43: 4ª Leitura | F43: 15 dias Rodados | G43: 30 dias Rodados | H43: Total Mensal | J43: DATA | W43: DATA | AF43: DATA
F44: =SUM(C44-B44) -> 0 | G44: =SUM(E44-D44) -> 0 | H44: =SUM(F44:G44) -> 0 | J44: VALOR | W44: VALOR | AF44: VALOR
...

Sheet Helen
A2: Veiculo | B2: Argo | D2: Placa: | E2: TZL9C64 | H2: km | I2: 3000
A3: Troca de Condutor | B3: 46182 | D3: Placa: | E3: TZL9C64 | H3: Consutores | I3: Alain para Helen
A5: Contrato de Locação | B5: 2606.08 | D5: Rastreador | E5: unidas 3s | H5: Data Desmob | I5: 46179
A8: REGISTRO DE KM | J8: ABASTECIMENTO | Y8: LAVA_RAPIDO | AH8: BORRACHARIA
B10: Fevereiro | J10: Fevereiro | Y10: Fevereiro | AH10: Fevereiro
A11: KM (Rodados) | B11: 1ª Leitura | C11: 2ª Leitura | D11: 3ª Leitura | E11: 4ª Leitura | F11: 15 dias Rodados | G11: 30 dias Rodados | H11: Total Mensal | J11: DATA | Y11: DATA | AH11: DATA
F12: =SUM(C12-B12) -> 0 | G12: =SUM(E12-D12) -> 0 | H12: =SUM(F12:G12) -> 0 | J12: VALOR | Y12: VALOR | AH12: VALOR
T13: TOTAL | U13: =SUM(K12:U12) -> 0 | AD13: TOTAL | AE13: =SUM(Z12:AE12) -> 0 | AM13: TOTAL | AN13: =SUM(AI12:AN12) -> 0
B14: Março | J14: Março | Y14: =J14 -> Março | AH14: =Y14 -> Março
A15: KM (Rodados) | B15: 1ª Leitura | C15: 2ª Leitura | D15: 3ª Leitura | E15: 4ª Leitura | F15: 15 dias Rodados | G15: 30 dias Rodados | H15: Total Mensal | J15: DATA | Y15: DATA | AH15: DATA
F16: =SUM(C16-B16) -> 0 | G16: =SUM(E16-D16) -> 0 | H16: =SUM(F16:G16) -> 0 | J16: VALOR | Y16: VALOR | AH16: VALOR
T17: TOTAL | U17: =SUM(K16:U16) -> 0 | AD17: TOTAL | AE17: =SUM(Z16:AE16) -> 0 | AM17: TOTAL | AN17: =SUM(AI16:AN16) -> 0
B18: Abril | J18: Abril | Y18: =J18 -> Abril | AH18: =Y18 -> Abril
A19: KM (Rodados) | B19: 1ª Leitura | C19: 2ª Leitura | D19: 3ª Leitura | E19: 4ª Leitura | F19: 15 dias Rodados | G19: 30 dias Rodados | H19: Total Mensal | J19: DATA | Y19: DATA | AH19: DATA
F20: =SUM(C20-B20) -> 0 | G20: =SUM(E20-D20) -> 0 | H20: =SUM(F20:G20) -> 0 | J20: VALOR | Y20: VALOR | AH20: VALOR
T21: TOTAL | U21: =SUM(K20:U20) -> 0 | AD21: TOTAL | AE21: =SUM(Z20:AE20) -> 0 | AM21: TOTAL | AN21: =SUM(AI20:AN20) -> 0
B22: Maio | J22: Maio | Y22: =J22 -> Maio | AH22: =Y22 -> Maio
A23: KM (Rodados) | B23: 1ª Leitura | C23: 2ª Leitura | D23: 3ª Leitura | E23: 4ª Leitura | F23: 15 dias Rodados | G23: 30 dias Rodados | H23: Total Mensal | J23: DATA | Y23: DATA | AH23: DATA
F24: =SUM(C24-B24) -> 0 | G24: =SUM(E24-D24) -> 0 | H24: =SUM(F24:G24) -> 0 | J24: VALOR | Y24: VALOR | AH24: VALOR
T25: TOTAL | U25: =SUM(K24:U24) -> 0 | AD25: TOTAL | AE25: =SUM(Z24:AE24) -> 0 | AM25: TOTAL | AN25: =SUM(AI24:AN24) -> 0
B26: Junho | J26: Junho | Y26: =J26 -> Junho | AH26: =Y26 -> Junho
A27: KM (Rodados) | B27: 1ª Leitura | C27: 2ª Leitura | D27: 3ª Leitura | E27: 4ª Leitura | F27: 15 dias Rodados | G27: 30 dias Rodados | H27: Total Mensal | J27: DATA | Y27: DATA | AH27: DATA
B28: 20 | F28: =SUM(C28-B28) -> -20 | G28: =SUM(E28-D28) -> 0 | H28: =SUM(F28:G28) -> -20 | J28: VALOR | Y28: VALOR | AH28: VALOR
T29: TOTAL | U29: =SUM(K28:U28) -> 0 | AD29: TOTAL | AE29: =SUM(Z28:AE28) -> 0 | AM29: TOTAL | AN29: =SUM(AI28:AN28) -> 0
B30: Julho | J30: Julho | Y30: =J30 -> Julho | AH30: =Y30 -> Julho
A31: KM (Rodados) | B31: 1ª Leitura | C31: 2ª Leitura | D31: 3ª Leitura | E31: 4ª Leitura | F31: 15 dias Rodados | G31: 30 dias Rodados | H31: Total Mensal | J31: DATA | Y31: DATA | AH31: DATA
F32: =SUM(C32-B32) -> 0 | G32: =SUM(E32-D32) -> 0 | H32: =SUM(F32:G32) -> 0 | J32: VALOR | Y32: VALOR | AH32: VALOR
T33: TOTAL | U33: =SUM(K32:U32) -> 0 | AD33: TOTAL | AE33: =SUM(Z32:AE32) -> 0 | AM33: TOTAL | AN33: =SUM(AI32:AN32) -> 0
B34: Agosto | J34: Agosto | Y34: =J34 -> Agosto | AH34: =Y34 -> Agosto
A35: KM (Rodados) | B35: 1ª Leitura | C35: 2ª Leitura | D35: 3ª Leitura | E35: 4ª Leitura | F35: 15 dias Rodados | G35: 30 dias Rodados | H35: Total Mensal | J35: DATA | Y35: DATA | AH35: DATA
F36: =SUM(C36-B36) -> 0 | G36: =SUM(E36-D36) -> 0 | H36: =SUM(F36:G36) -> 0 | J36: VALOR | Y36: VALOR | AH36: VALOR
T37: TOTAL | U37: =SUM(K36:U36) -> 0 | AD37: TOTAL | AE37: =SUM(Z36:AE36) -> 0 | AM37: TOTAL | AN37: =SUM(AI36:AN36) -> 0
B38: Setembro | J38: Setembro | Y38: =J38 -> Setembro | AH38: =Y38 -> Setembro
A39: KM (Rodados) | B39: 1ª Leitura | C39: 2ª Leitura | D39: 3ª Leitura | E39: 4ª Leitura | F39: 15 dias Rodados | G39: 30 dias Rodados | H39: Total Mensal | J39: DATA | Y39: DATA | AH39: DATA
F40: =SUM(C40-B40) -> 0 | G40: =SUM(E40-D40) -> 0 | H40: =SUM(F40:G40) -> 0 | J40: VALOR | Y40: VALOR | AH40: VALOR
T41: TOTAL | U41: =SUM(K40:U40) -> 0 | AD41: TOTAL | AE41: =SUM(Z40:AE40) -> 0 | AM41: TOTAL | AN41: =SUM(AI40:AN40) -> 0
B42: Outubro | J42: Outubro | Y42: =J42 -> Outubro | AH42: =Y42 -> Outubro
A43: KM (Rodados) | B43: 1ª Leitura | C43: 2ª Leitura | D43: 3ª Leitura | E43: 4ª Leitura | F43: 15 dias Rodados | G43: 30 dias Rodados | H43: Total Mensal | J43: DATA | Y43: DATA | AH43: DATA
F44: =SUM(C44-B44) -> 0 | G44: =SUM(E44-D44) -> 0 | H44: =SUM(F44:G44) -> 0 | J44: VALOR | Y44: VALOR | AH44: VALOR
T45: TOTAL | U45: =SUM(K44:U44) -> 0 | AD45: TOTAL | AE45: =SUM(Z44:AE44) -> 0 | AM45: TOTAL | AN45: =SUM(AI44:AN44) -> 0
...

Sheet Robson-Desmob
A2: Veiculo | B2: Argo | D2: Placa: | E2: TCU0B50 | H2: KM | I2: 3000
A3: Troca de Condutor | B3: 46122 | D3: Placa: | E3: TCU0B50 | H3: Condutores | I3: Robson para Leandro
