Workbook

Sheet RESUMO
A1: SUSTENTABILIDADE
B5: JAN | C5: FEV | D5: MAR | E5: ABR | F5: MAI | G5: JUN | H5: JUL | I5: AGO | J5: SET | K5: OUT | L5: NOV | M5: DEZ
A6: ABASTECIMENTO | B6: =SUM('Controle Central'!D4+'Controle Central'!K4+'Controle Central'!R4+'Controle Central'!Y4+'Controle Central'!D23+'Controle Central'!K23+'Controle Central'!R23+'Controle Central'!Y23+'Controle Central'!D42+'Controle Central'!K42+'Controle Central'!R42+'Controle Central'!Y42+'Controle Central'!D61+'Controle Central'!K61+'Controle Central'!R61+'Controle Central'!Y61+'Controle Central'!D80+'Controle Central'!K80+'Controle Central'!R80+'Controle Central'!Y80+'Controle Central'!D98+'Controle Central'!K98+'Controle Central'!R98+'Controle Central'!Y98+'Controle Central'!D116+'Controle Central'!K116+'Controle Central'!R116+'Controle Central'!Y116+'Controle Central'!D134+'Controle Central'!K134) -> 0 | C6: =SUM('Controle Central'!D5+'Controle Central'!K5+'Controle Central'!R5+'Controle Central'!Y5+'Controle Central'!D24+'Controle Central'!K24+'Controle Central'!R24+'Controle Central'!Y24+'Controle Central'!D43+'Controle Central'!K43+'Controle Central'!R43+'Controle Central'!Y43+'Controle Central'!D62+'Controle Central'!K62+'Controle Central'!R62+'Controle Central'!Y62+'Controle Central'!D81+'Controle Central'!K81+'Controle Central'!R81+'Controle Central'!D99+'Controle Central'!K99+'Controle Central'!R99+'Controle Central'!Y99+'Controle Central'!D117+'Controle Central'!K117+'Controle Central'!R117+'Controle Central'!Y117+'Controle Central'!D135+'Controle Central'!K135) -> 0 | D6: =SUM('Controle Central'!D6+'Controle Central'!K6+'Controle Central'!R6+'Controle Central'!Y6+'Controle Central'!D25+'Controle Central'!K25+'Controle Central'!R25+'Controle Central'!Y25+'Controle Central'!D44+'Controle Central'!K44+'Controle Central'!R44+'Controle Central'!Y44+'Controle Central'!D63+'Controle Central'!K63+'Controle Central'!R63+'Controle Central'!Y63+'Controle Central'!D82+'Controle Central'!K82+'Controle Central'!R82+'Controle Central'!Y82+'Controle Central'!D100+'Controle Central'!K100+'Controle Central'!R100+'Controle Central'!Y100+'Controle Central'!D118+'Controle Central'!K118+'Controle Central'!R118+'Controle Central'!Y118+'Controle Central'!D136+'Controle Central'!K136) -> 0 | E6: ='Controle Central'!D7+'Controle Central'!K7+'Controle Central'!R7+'Controle Central'!Y7+'Controle Central'!D26+'Controle Central'!K26+'Controle Central'!R26+'Controle Central'!Y26+'Controle Central'!D45+'Controle Central'!K45+'Controle Central'!R45+'Controle Central'!Y45+'Controle Central'!D64+'Controle Central'!K64+'Controle Central'!R64+'Controle Central'!D83+'Controle Central'!K83+'Controle Central'!R83+'Controle Central'!Y83+'Controle Central'!D101+'Controle Central'!K101+'Controle Central'!R101+'Controle Central'!Y101+'Controle Central'!D119+'Controle Central'!K119+'Controle Central'!R119+'Controle Central'!Y119+'Controle Central'!D137+'Controle Central'!K137 -> 737.98 | F6: =SUM('Controle Central'!D8+'Controle Central'!K8+'Controle Central'!R8+'Controle Central'!Y8+'Controle Central'!D27+'Controle Central'!K27+'Controle Central'!R27+'Controle Central'!Y27+'Controle Central'!D46+'Controle Central'!K46+'Controle Central'!R46+'Controle Central'!Y46+'Controle Central'!D65+'Controle Central'!K65+'Controle Central'!R65+'Controle Central'!Y65+'Controle Central'!D84+'Controle Central'!K84+'Controle Central'!R84+'Controle Central'!Y84+'Controle Central'!D102+'Controle Central'!K102+'Controle Central'!R102+'Controle Central'!Y102+'Controle Central'!D120+'Controle Central'!K120+'Controle Central'!R120+'Controle Central'!Y120+'Controle Central'!D138+'Controle Central'!K138) -> 0 | G6: =SUM('Controle Central'!D9+'Controle Central'!K9+'Controle Central'!R9+'Controle Central'!Y9+'Controle Central'!D28+'Controle Central'!K28+'Controle Central'!R28+'Controle Central'!Y28+'Controle Central'!D47+'Controle Central'!K47+'Controle Central'!R47+'Controle Central'!Y47+'Controle Central'!D66+'Controle Central'!K66+'Controle Central'!R66+'Controle Central'!Y66+'Controle Central'!D85+'Controle Central'!K85+'Controle Central'!R85+'Controle Central'!Y85+'Controle Central'!D103+'Controle Central'!K103+'Controle Central'!R103+'Controle Central'!Y103+'Controle Central'!D121+'Controle Central'!K121+'Controle Central'!R121+'Controle Central'!Y121+'Controle Central'!D139+'Controle Central'!K139) -> 1012.19 | H6: =SUM('Controle Central'!D10+'Controle Central'!K10+'Controle Central'!R10+'Controle Central'!Y10+'Controle Central'!D29+'Controle Central'!K29+'Controle Central'!R29+'Controle Central'!D48+'Controle Central'!K48+'Controle Central'!R48+'Controle Central'!Y48+'Controle Central'!D67+'Controle Central'!K67+'Controle Central'!R67+'Controle Central'!Y67+'Controle Central'!D86+'Controle Central'!K86+'Controle Central'!R86+'Controle Central'!Y86+'Controle Central'!D104+'Controle Central'!K104+'Controle Central'!R104+'Controle Central'!Y104+'Controle Central'!D122+'Controle Central'!K122+'Controle Central'!R122+'Controle Central'!Y122+'Controle Central'!D140+'Controle Central'!K140) -> 1477.52 | I6: =SUM('Controle Central'!D11+'Controle Central'!K11+'Controle Central'!R11+'Controle Central'!Y11+'Controle Central'!D30+'Controle Central'!K30+'Controle Central'!R30+'Controle Central'!Y30+'Controle Central'!D49+'Controle Central'!K49+'Controle Central'!R49+'Controle Central'!Y49+'Controle Central'!D68+'Controle Central'!K68+'Controle Central'!R68+'Controle Central'!Y68+'Controle Central'!D87+'Controle Central'!K87+'Controle Central'!R87+'Controle Central'!Y87+'Controle Central'!D105+'Controle Central'!K105+'Controle Central'!R105+'Controle Central'!Y105+'Controle Central'!D123+'Controle Central'!K123+'Controle Central'!R123+'Controle Central'!Y123+'Controle Central'!D141+'Controle Central'!K141) -> 816.96 | J6: =SUM('Controle Central'!D12+'Controle Central'!K12+'Controle Central'!R12+'Controle Central'!Y12+'Controle Central'!D31+'Controle Central'!K31+'Controle Central'!R31+'Controle Central'!Y31+'Controle Central'!D50+'Controle Central'!K50+'Controle Central'!R50+'Controle Central'!Y50+'Controle Central'!D69+'Controle Central'!K69+'Controle Central'!R69+'Controle Central'!Y69+'Controle Central'!D88+'Controle Central'!K88+'Controle Central'!R88+'Controle Central'!Y88+'Controle Central'!D106+'Controle Central'!K106+'Controle Central'!R106+'Controle Central'!Y106+'Controle Central'!D124+'Controle Central'!K124+'Controle Central'!R124+'Controle Central'!Y124+'Controle Central'!D142+'Controle Central'!K142) -> 1008.69 | K6: =SUM('Controle Central'!D13+'Controle Central'!K13+'Controle Central'!R13+'Controle Central'!Y13+'Controle Central'!D32+'Controle Central'!K32+'Controle Central'!R32+'Controle Central'!Y32+'Controle Central'!D51+'Controle Central'!K51+'Controle Central'!R51+'Controle Central'!Y51+'Controle Central'!D70+'Controle Central'!K70+'Controle Central'!R70+'Controle Central'!Y70+'Controle Central'!D89+'Controle Central'!K89+'Controle Central'!R89+'Controle Central'!Y89+'Controle Central'!D107+'Controle Central'!K107+'Controle Central'!R107+'Controle Central'!Y107+'Controle Central'!D125+'Controle Central'!K125+'Controle Central'!R125+'Controle Central'!Y125+'Controle Central'!D143+'Controle Central'!K143) -> 1957.41 | L6: =SUM('Controle Central'!D14+'Controle Central'!K14+'Controle Central'!R14+'Controle Central'!Y14+'Controle Central'!D33+'Controle Central'!K33+'Controle Central'!R33+'Controle Central'!Y33+'Controle Central'!D52+'Controle Central'!K52+'Controle Central'!R52+'Controle Central'!Y52+'Controle Central'!D71+'Controle Central'!K71+'Controle Central'!R71+'Controle Central'!Y71+'Controle Central'!D90+'Controle Central'!K90+'Controle Central'!R90+'Controle Central'!Y90+'Controle Central'!D108+'Controle Central'!K108+'Controle Central'!R108+'Controle Central'!Y108+'Controle Central'!D126+'Controle Central'!K126+'Controle Central'!R126+'Controle Central'!Y126+'Controle Central'!D144+'Controle Central'!K144) -> 1649.99 | M6: =SUM('Controle Central'!D15+'Controle Central'!K15+'Controle Central'!R15+'Controle Central'!Y15+'Controle Central'!D34+'Controle Central'!K34+'Controle Central'!R34+'Controle Central'!Y34+'Controle Central'!D53+'Controle Central'!K53+'Controle Central'!R53+'Controle Central'!Y53+'Controle Central'!D72+'Controle Central'!K72+'Controle Central'!R72+'Controle Central'!Y72+'Controle Central'!D91+'Controle Central'!K91+'Controle Central'!R91+'Controle Central'!Y91+'Controle Central'!D109+'Controle Central'!K109+'Controle Central'!R109+'Controle Central'!Y109+'Controle Central'!D127+'Controle Central'!K127+'Controle Central'!R127+'Controle Central'!Y127+'Controle Central'!D145+'Controle Central'!K145) -> 1210.64
A8: LAVA_RAPIDO | B8: =SUM('Controle Central'!E4+'Controle Central'!L4+'Controle Central'!S4+'Controle Central'!Z4+'Controle Central'!E23+'Controle Central'!L23+'Controle Central'!S23+'Controle Central'!Z23+'Controle Central'!E42+'Controle Central'!L42+'Controle Central'!S42+'Controle Central'!Z42+'Controle Central'!E61+'Controle Central'!L61+'Controle Central'!S61+'Controle Central'!Z61+'Controle Central'!E80+'Controle Central'!L80+'Controle Central'!S80+'Controle Central'!Z80+'Controle Central'!E98+'Controle Central'!L98+'Controle Central'!S98+'Controle Central'!Z98+'Controle Central'!E116+'Controle Central'!L116+'Controle Central'!S116+'Controle Central'!Z116+'Controle Central'!E134+'Controle Central'!L134) -> 0 | C8: =SUM('Controle Central'!E5,'Controle Central'!L5,'Controle Central'!S5,'Controle Central'!Z5,'Controle Central'!E24,'Controle Central'!L24,'Controle Central'!S24,'Controle Central'!Z24,'Controle Central'!E43,'Controle Central'!L43,'Controle Central'!S43,'Controle Central'!Z43,'Controle Central'!E62,'Controle Central'!L62,'Controle Central'!S62,'Controle Central'!Z62,'Controle Central'!E81,'Controle Central'!L81,'Controle Central'!S81,'Controle Central'!Z81,'Controle Central'!E99,'Controle Central'!L99,'Controle Central'!S99,'Controle Central'!Z99,'Controle Central'!E117,'Controle Central'!L117,'Controle Central'!S117,'Controle Central'!Z117,'Controle Central'!E135,'Controle Central'!L135) -> 0 | D8: =SUM('Controle Central'!E6,'Controle Central'!L6,'Controle Central'!S6,'Controle Central'!Z6,'Controle Central'!E25,'Controle Central'!L25,'Controle Central'!S25,'Controle Central'!Z25,'Controle Central'!E44,'Controle Central'!L44,'Controle Central'!S44,'Controle Central'!Z44,'Controle Central'!E63,'Controle Central'!L63,'Controle Central'!S63,'Controle Central'!Z63,'Controle Central'!E82,'Controle Central'!L82,'Controle Central'!S82,'Controle Central'!Z82,'Controle Central'!E100,'Controle Central'!L100,'Controle Central'!S100,'Controle Central'!Z100,'Controle Central'!E118,'Controle Central'!L118,'Controle Central'!S118,'Controle Central'!Z118,'Controle Central'!E136,'Controle Central'!L136) -> 0 | E8: =SUM('Controle Central'!E7,'Controle Central'!L7,'Controle Central'!S7,'Controle Central'!Z7,'Controle Central'!E26,'Controle Central'!L26,'Controle Central'!S26,'Controle Central'!Z26,'Controle Central'!E45,'Controle Central'!L45,'Controle Central'!S45,'Controle Central'!Z45,'Controle Central'!E64,'Controle Central'!L64,'Controle Central'!S64,'Controle Central'!Z64,'Controle Central'!E83,'Controle Central'!L83,'Controle Central'!S83,'Controle Central'!Z83,'Controle Central'!E101,'Controle Central'!L101,'Controle Central'!S101,'Controle Central'!Z101,'Controle Central'!E119,'Controle Central'!L119,'Controle Central'!S119,'Controle Central'!Z119,'Controle Central'!E137,'Controle Central'!L137) -> 0 | F8: =SUM('Controle Central'!E8,'Controle Central'!L8,'Controle Central'!S8,'Controle Central'!Z8,'Controle Central'!E27,'Controle Central'!L27,'Controle Central'!S27,'Controle Central'!Z27,'Controle Central'!E46,'Controle Central'!L46,'Controle Central'!S46,'Controle Central'!Z46,'Controle Central'!E65,'Controle Central'!L65,'Controle Central'!S65,'Controle Central'!Z65,'Controle Central'!E84,'Controle Central'!L84,'Controle Central'!S84,'Controle Central'!Z84,'Controle Central'!E102,'Controle Central'!L102,'Controle Central'!S102,'Controle Central'!Z102,'Controle Central'!E120,'Controle Central'!L120,'Controle Central'!S120,'Controle Central'!Z120,'Controle Central'!E138,'Controle Central'!L138) -> 0 | G8: =SUM('Controle Central'!E9,'Controle Central'!L9,'Controle Central'!S9,'Controle Central'!Z9,'Controle Central'!E28,'Controle Central'!L28,'Controle Central'!S28,'Controle Central'!Z28,'Controle Central'!E47,'Controle Central'!L47,'Controle Central'!S47,'Controle Central'!Z47,'Controle Central'!E66,'Controle Central'!L66,'Controle Central'!S66,'Controle Central'!Z66,'Controle Central'!E85,'Controle Central'!L85,'Controle Central'!S85,'Controle Central'!Z85,'Controle Central'!E103,'Controle Central'!L103,'Controle Central'!S103,'Controle Central'!Z103,'Controle Central'!E121,'Controle Central'!L121,'Controle Central'!S121,'Controle Central'!Z121,'Controle Central'!E139+'Controle Central'!L139) -> 0 | H8: =SUM('Controle Central'!E10,'Controle Central'!L10,'Controle Central'!S10,'Controle Central'!Z10,'Controle Central'!E29,'Controle Central'!L29,'Controle Central'!S29,'Controle Central'!Z29,'Controle Central'!E48,'Controle Central'!L48,'Controle Central'!S48,'Controle Central'!Z48,'Controle Central'!E67,'Controle Central'!L67,'Controle Central'!S67,'Controle Central'!Z67,'Controle Central'!E86,'Controle Central'!L86,'Controle Central'!S86,'Controle Central'!Z86,'Controle Central'!E104,'Controle Central'!L104,'Controle Central'!S104,'Controle Central'!Z104,'Controle Central'!E122,'Controle Central'!L122,'Controle Central'!S122,'Controle Central'!Z122,'Controle Central'!E140,'Controle Central'!L140) -> 0 | I8: =SUM('Controle Central'!L11,'Controle Central'!S11,'Controle Central'!E11,'Controle Central'!Z11,'Controle Central'!Z30,'Controle Central'!S30,'Controle Central'!L30,'Controle Central'!E30,'Controle Central'!E49,'Controle Central'!L49,'Controle Central'!S49,'Controle Central'!Z49,'Controle Central'!Z68,'Controle Central'!S68,'Controle Central'!L68,'Controle Central'!E68,'Controle Central'!E87,'Controle Central'!L87,'Controle Central'!S87,'Controle Central'!Z87,'Controle Central'!Z105,'Controle Central'!Z123,'Controle Central'!S105,'Controle Central'!S123,'Controle Central'!L123,'Controle Central'!L105,'Controle Central'!E123,'Controle Central'!E105,'Controle Central'!E141,'Controle Central'!L141) -> 0 | J8: =SUM('Controle Central'!E12,'Controle Central'!E31,'Controle Central'!L12,'Controle Central'!L31,'Controle Central'!S12,'Controle Central'!S31,'Controle Central'!Z12,'Controle Central'!Z31,'Controle Central'!Z50,'Controle Central'!Z69,'Controle Central'!S50,'Controle Central'!S69,'Controle Central'!L50,'Controle Central'!L69,'Controle Central'!E50,'Controle Central'!E69,'Controle Central'!E88,'Controle Central'!E106,'Controle Central'!L88,'Controle Central'!L106,'Controle Central'!S88,'Controle Central'!S106,'Controle Central'!Z88,'Controle Central'!Z106,'Controle Central'!Z124,'Controle Central'!S124,'Controle Central'!L124,'Controle Central'!E124,'Controle Central'!E142,'Controle Central'!L142) -> 0 | K8: =SUM('Controle Central'!E13,'Controle Central'!L13,'Controle Central'!E32,'Controle Central'!L32,'Controle Central'!S13,'Controle Central'!S32,'Controle Central'!Z13,'Controle Central'!Z32,'Controle Central'!Z51,'Controle Central'!Z70,'Controle Central'!S51,'Controle Central'!S70,'Controle Central'!L51,'Controle Central'!L70,'Controle Central'!E51,'Controle Central'!E70,'Controle Central'!E89,'Controle Central'!E107,'Controle Central'!L89,'Controle Central'!L107,'Controle Central'!S89,'Controle Central'!S107,'Controle Central'!Z107,'Controle Central'!Z89,'Controle Central'!Z125,'Controle Central'!S125,'Controle Central'!L143,'Controle Central'!L125,'Controle Central'!E125,'Controle Central'!E143) -> 0 | L8: =SUM('Controle Central'!E14,'Controle Central'!E33,'Controle Central'!L14,'Controle Central'!L33,'Controle Central'!S14,'Controle Central'!S33,'Controle Central'!Z14,'Controle Central'!Z33,'Controle Central'!Z52,'Controle Central'!Z71,'Controle Central'!S52,'Controle Central'!S71,'Controle Central'!L52,'Controle Central'!L71,'Controle Central'!E52,'Controle Central'!E71,'Controle Central'!E90,'Controle Central'!E108,'Controle Central'!L90,'Controle Central'!L108,'Controle Central'!S90,'Controle Central'!S108,'Controle Central'!Z90,'Controle Central'!Z108,'Controle Central'!Z126,'Controle Central'!S126,'Controle Central'!L126,'Controle Central'!L144,'Controle Central'!E126,'Controle Central'!E144) -> 0 | M8: =SUM('Controle Central'!E15,'Controle Central'!E34,'Controle Central'!L15,'Controle Central'!L34,'Controle Central'!S15,'Controle Central'!S34,'Controle Central'!Z15,'Controle Central'!Z34,'Controle Central'!Z53,'Controle Central'!Z72,'Controle Central'!S53,'Controle Central'!S72,'Controle Central'!L53,'Controle Central'!L72,'Controle Central'!E53,'Controle Central'!E72,'Controle Central'!E91,'Controle Central'!E109,'Controle Central'!L91,'Controle Central'!L109,'Controle Central'!S91,'Controle Central'!S109,'Controle Central'!Z91,'Controle Central'!Z109,'Controle Central'!Z127,'Controle Central'!S127,'Controle Central'!L127,'Controle Central'!E127,'Controle Central'!E145,'Controle Central'!L145) -> 0
A10: BORRACHARIA | B10: =SUM('Controle Central'!F4,'Controle Central'!M4,'Controle Central'!M23,'Controle Central'!F23,'Controle Central'!T4,'Controle Central'!T23,'Controle Central'!AA4,'Controle Central'!AA23,'Controle Central'!AA61,'Controle Central'!AA42,'Controle Central'!T42,'Controle Central'!M42,'Controle Central'!M61,'Controle Central'!F61,'Controle Central'!F42,'Controle Central'!F98,'Controle Central'!F80,'Controle Central'!M80,'Controle Central'!M98,'Controle Central'!T80,'Controle Central'!T98,'Controle Central'!AA80,'Controle Central'!AA98,'Controle Central'!AA116,'Controle Central'!T116,'Controle Central'!M116,'Controle Central'!F116,'Controle Central'!F134,'Controle Central'!M134) -> 0 | C10: =SUM('Controle Central'!F5,'Controle Central'!F24,'Controle Central'!M5,'Controle Central'!M24,'Controle Central'!T24,'Controle Central'!T5,'Controle Central'!AA5,'Controle Central'!AA24,'Controle Central'!AA43,'Controle Central'!AA62,'Controle Central'!T43,'Controle Central'!T62,'Controle Central'!M43,'Controle Central'!M62,'Controle Central'!F43,'Controle Central'!F62,'Controle Central'!F81,'Controle Central'!F99,'Controle Central'!M99,'Controle Central'!M81,'Controle Central'!T99,'Controle Central'!T81,'Controle Central'!AA81,'Controle Central'!AA99,'Controle Central'!AA117,'Controle Central'!T117,'Controle Central'!M117,'Controle Central'!F117,'Controle Central'!F135,'Controle Central'!M135) -> 0 | D10: =SUM('Controle Central'!F6,'Controle Central'!F25,'Controle Central'!M6,'Controle Central'!M25,'Controle Central'!T6,'Controle Central'!T25,'Controle Central'!AA25,'Controle Central'!AA6,'Controle Central'!AA44,'Controle Central'!AA63,'Controle Central'!T63,'Controle Central'!T44,'Controle Central'!M44,'Controle Central'!M63,'Controle Central'!F63,'Controle Central'!F44,'Controle Central'!F82,'Controle Central'!F100,'Controle Central'!M100,'Controle Central'!M82,'Controle Central'!T82,'Controle Central'!T100,'Controle Central'!AA100,'Controle Central'!AA82,'Controle Central'!AA118,'Controle Central'!T118,'Controle Central'!M118,'Controle Central'!M136,'Controle Central'!F118,'Controle Central'!F136) -> 0 | E10: =SUM('Controle Central'!F7,'Controle Central'!F26,'Controle Central'!M26,'Controle Central'!M7,'Controle Central'!T7,'Controle Central'!T26,'Controle Central'!AA7,'Controle Central'!AA26,'Controle Central'!AA45,'Controle Central'!T45,'Controle Central'!AA64,'Controle Central'!T64,'Controle Central'!M45,'Controle Central'!M64,'Controle Central'!F45,'Controle Central'!F64,'Controle Central'!F83,'Controle Central'!F101,'Controle Central'!M83,'Controle Central'!M101,'Controle Central'!T83,'Controle Central'!T101,'Controle Central'!AA83,'Controle Central'!AA101,'Controle Central'!AA119,'Controle Central'!T119,'Controle Central'!M119,'Controle Central'!M137,'Controle Central'!F137,'Controle Central'!F119) -> 0 | F10: =SUM('Controle Central'!F8,'Controle Central'!F27,'Controle Central'!M8,'Controle Central'!M27,'Controle Central'!T8,'Controle Central'!T27,'Controle Central'!AA27,'Controle Central'!AA8,'Controle Central'!AA46,'Controle Central'!AA65,'Controle Central'!T46,'Controle Central'!T65,'Controle Central'!M65,'Controle Central'!M46,'Controle Central'!F46,'Controle Central'!F65,'Controle Central'!F84,'Controle Central'!F102,'Controle Central'!M84,'Controle Central'!M102,'Controle Central'!T84,'Controle Central'!T102,'Controle Central'!AA84,'Controle Central'!AA102,'Controle Central'!AA120,'Controle Central'!T120,'Controle Central'!M120,'Controle Central'!M138,'Controle Central'!F120,'Controle Central'!F138) -> 0 | G10: =SUM('Controle Central'!F9,'Controle Central'!F28,'Controle Central'!M9,'Controle Central'!M28,'Controle Central'!T9,'Controle Central'!T28,'Controle Central'!AA9,'Controle Central'!AA28,'Controle Central'!AA47,'Controle Central'!AA66,'Controle Central'!T47,'Controle Central'!T66,'Controle Central'!M47,'Controle Central'!M66,'Controle Central'!F47,'Controle Central'!F66,'Controle Central'!F85,'Controle Central'!F103,'Controle Central'!M85,'Controle Central'!M103,'Controle Central'!T85,'Controle Central'!T103,'Controle Central'!AA85,'Controle Central'!AA103,'Controle Central'!AA121,'Controle Central'!T121,'Controle Central'!M121,'Controle Central'!M139,'Controle Central'!F139) -> 0 | H10: =SUM('Controle Central'!F10,'Controle Central'!F29,'Controle Central'!M10,'Controle Central'!M29,'Controle Central'!T10,'Controle Central'!T29,'Controle Central'!AA10,'Controle Central'!AA29,'Controle Central'!AA48,'Controle Central'!T48,'Controle Central'!AA67,'Controle Central'!T67,'Controle Central'!M48,'Controle Central'!M67,'Controle Central'!F48,'Controle Central'!F67,'Controle Central'!F86,'Controle Central'!F104,'Controle Central'!M104,'Controle Central'!M86,'Controle Central'!T86,'Controle Central'!T104,'Controle Central'!AA86,'Controle Central'!AA104,'Controle Central'!AA122,'Controle Central'!T122,'Controle Central'!M122,'Controle Central'!M140,'Controle Central'!F122,'Controle Central'!F140) -> 0 | I10: =SUM('Controle Central'!F11,'Controle Central'!F30,'Controle Central'!M11,'Controle Central'!M30,'Controle Central'!T11,'Controle Central'!T30,'Controle Central'!AA11,'Controle Central'!AA30,'Controle Central'!AA49,'Controle Central'!AA68,'Controle Central'!T49,'Controle Central'!T68,'Controle Central'!M49,'Controle Central'!M68,'Controle Central'!F68,'Controle Central'!F49,'Controle Central'!F87,'Controle Central'!F105,'Controle Central'!M87,'Controle Central'!M105,'Controle Central'!T87,'Controle Central'!T105,'Controle Central'!AA87,'Controle Central'!AA105,'Controle Central'!AA123,'Controle Central'!T123,'Controle Central'!M123,'Controle Central'!M141,'Controle Central'!F123,'Controle Central'!F141) -> 0 | J10: =SUM('Controle Central'!F12,'Controle Central'!F31,'Controle Central'!M12,'Controle Central'!M31,'Controle Central'!T12,'Controle Central'!T31,'Controle Central'!AA12,'Controle Central'!AA31,'Controle Central'!AA50,'Controle Central'!T50,'Controle Central'!T69,'Controle Central'!AA69,'Controle Central'!M50,'Controle Central'!M69,'Controle Central'!F69,'Controle Central'!F50,'Controle Central'!F88,'Controle Central'!F106,'Controle Central'!M88,'Controle Central'!M106,'Controle Central'!T88,'Controle Central'!T106,'Controle Central'!AA88,'Controle Central'!AA106,'Controle Central'!AA124,'Controle Central'!T124,'Controle Central'!M124,'Controle Central'!F124,'Controle Central'!F142,'Controle Central'!M142) -> 0 | K10: =SUM('Controle Central'!F13,'Controle Central'!F32,'Controle Central'!M13,'Controle Central'!M32,'Controle Central'!T13,'Controle Central'!T32,'Controle Central'!AA13,'Controle Central'!AA32,'Controle Central'!AA51,'Controle Central'!T51,'Controle Central'!T70,'Controle Central'!AA70,'Controle Central'!M51,'Controle Central'!M70,'Controle Central'!F70,'Controle Central'!F51,'Controle Central'!F89,'Controle Central'!F107,'Controle Central'!M89,'Controle Central'!M107,'Controle Central'!T89,'Controle Central'!T107,'Controle Central'!AA107,'Controle Central'!AA89,'Controle Central'!AA125,'Controle Central'!T125,'Controle Central'!M125,'Controle Central'!F125,'Controle Central'!F143,'Controle Central'!M143) -> 0 | L10: =SUM('Controle Central'!F14,'Controle Central'!M14,'Controle Central'!F33,'Controle Central'!M33,'Controle Central'!T14,'Controle Central'!T33,'Controle Central'!AA33,'Controle Central'!AA14,'Controle Central'!AA52,'Controle Central'!T52,'Controle Central'!M52,'Controle Central'!M71,'Controle Central'!T71,'Controle Central'!AA71,'Controle Central'!AA90,'Controle Central'!T90,'Controle Central'!M90,'Controle Central'!F90,'Controle Central'!F108,'Controle Central'!F126,'Controle Central'!M108,'Controle Central'!M126,'Controle Central'!T108,'Controle Central'!T126,'Controle Central'!AA108,'Controle Central'!AA126,'Controle Central'!M144,'Controle Central'!F144) -> 0 | M10: =SUM('Controle Central'!F15,'Controle Central'!F34,'Controle Central'!M15,'Controle Central'!M34,'Controle Central'!T15,'Controle Central'!T34,'Controle Central'!AA15,'Controle Central'!AA34,'Controle Central'!AA53,'Controle Central'!T53,'Controle Central'!AA72,'Controle Central'!T72,'Controle Central'!M53,'Controle Central'!F53,'Controle Central'!F72,'Controle Central'!M72,'Controle Central'!F91,'Controle Central'!F109,'Controle Central'!M91,'Controle Central'!M109,'Controle Central'!T91,'Controle Central'!T109,'Controle Central'!AA91,'Controle Central'!AA109,'Controle Central'!AA127,'Controle Central'!T127,'Controle Central'!M127,'Controle Central'!M145,'Controle Central'!F127,'Controle Central'!F145) -> 0
B14: JAN | C14: FEV | D14: MAR | E14: ABR | F14: MAI | G14: JUN | H14: JUL | I14: AGO | J14: SET | K14: OUT | L14: NOV | M14: DEZ
A15: Medição
A17: Contrato de Locação
A19: Lucro Car's | B19: =B15-B17 -> 0 | C19: =C15-C17 -> 0 | D19: =D15-D17 -> 0 | E19: =E15-E17 -> 0 | F19: =F15-F17 -> 0 | G19: =G15-G17 -> 0 | H19: =H15-H17 -> 0 | I19: =I15-I17 -> 0 | ... M19: =M15-M17 -> 0

Sheet Controle Central
B2: ERIKA | I2: JOSEANE | P2: ALIRE | W2: LUCIANE
B3: KM RODADO | C3: KM MENSAL | D3: ABASTECIMENTO | E3: LAVA_RAPIDO | F3: BORRACHARIA | I3: KM RODADO | J3: KM MENSAL | K3: ABASTECIMENTO | L3: LAVA_RAPIDO | M3: BORRACHARIA | P3: KM RODADO | Q3: KM MENSAL | R3: ABASTECIMENTO | S3: LAVA_RAPIDO | T3: BORRACHARIA | W3: KM RODADO | X3: KM MENSAL | Y3: ABASTECIMENTO | Z3: LAVA_RAPIDO | AA3: BORRACHARIA
A4: JAN | C4: 0 | D4: 0 | E4: 0 | F4: 0 | H4: JAN | J4: 0 | K4: 0 | L4: 0 | M4: 0 | O4: JAN | Q4: 0 | R4: 0 | S4: 0 | T4: 0 | V4: JAN | X4: 0 | Y4: 0 | Z4: 0 | AA4: 0
A5: FEV | B5: ='Erika - desmob'!H11 -> 0 | C5: =SUM(5000-B5) -> 5000 | D5: ='Erika - desmob'!U12 -> 0 | E5: ='Erika - desmob'!AC12 -> 0 | F5: ='Erika - desmob'!AK12 -> 0 | H5: FEV | I5: ='Eucilene-Desmob'!H12 -> 0 | J5: =SUM(5000-I5) -> 5000 | K5: ='Eucilene-Desmob'!U13 -> 0 | L5: ='Eucilene-Desmob'!AC13 -> 0 | M5: ='Eucilene-Desmob'!AK13 -> 0 | O5: FEV | P5: =Alire!H12 -> 0 | Q5: =SUM(5000-P5) -> 5000 | R5: =Alire!U13 -> 0 | S5: =Alire!AI13 -> 0 | T5: =Alire!AR13 -> 0 | V5: FEV | W5: ='Luciane-Desmob'!H11 -> 0 | X5: =SUM(5000-W5) -> 5000 | Y5: ='Luciane-Desmob'!U12 -> 0 | Z5: ='Luciane-Desmob'!AI12 -> 0 | AA5: ='Luciane-Desmob'!AR12 -> 0
A6: MAR | B6: ='Erika - desmob'!H15 -> 0 | C6: =SUM(5000-B6) -> 5000 | D6: ='Erika - desmob'!U16 -> 0 | E6: ='Erika - desmob'!AC16 -> 0 | F6: ='Erika - desmob'!AK16 -> 0 | H6: MAR | I6: ='Eucilene-Desmob'!H16 -> 0 | J6: =SUM(5000-I6) -> 5000 | K6: ='Eucilene-Desmob'!U17 -> 0 | L6: ='Eucilene-Desmob'!AC17 -> 0 | M6: ='Eucilene-Desmob'!AK17 -> 0 | O6: MAR | P6: =Alire!H16 -> 0 | Q6: =SUM(5000-P6) -> 5000 | R6: =Alire!U17 -> 0 | S6: =Alire!AI17 -> 0 | T6: =Alire!AR17 -> 0 | V6: MAR | W6: ='Luciane-Desmob'!H15 -> 0 | X6: =SUM(5000-W6) -> 5000 | Y6: ='Luciane-Desmob'!U16 -> 0 | Z6: ='Luciane-Desmob'!AI16 -> 0 | AA6: ='Luciane-Desmob'!AR16 -> 0
A7: ABR | B7: ='Erika - desmob'!H19 -> 2261 | C7: =SUM(5000-B7) -> 2739 | D7: ='Erika - desmob'!U20 -> 0 | E7: ='Erika - desmob'!AC20 -> 0 | F7: ='Erika - desmob'!AK20 -> 0 | H7: ABR | I7: ='Eucilene-Desmob'!H20 -> 4660 | J7: =SUM(5000-I7) -> 340 | K7: ='Eucilene-Desmob'!U21 -> 737.98 | L7: ='Eucilene-Desmob'!AC21 -> 0 | M7: ='Eucilene-Desmob'!AK21 -> 0 | O7: ABR | P7: =Alire!H20 -> 1671 | Q7: =SUM(5000-P7) -> 3329 | R7: =Alire!Z21 -> 0 | S7: =Alire!AI21 -> 0 | T7: =Alire!AR21 -> 0 | V7: ABR | W7: ='Luciane-Desmob'!H19 -> 2763 | X7: =SUM(5000-W7) -> 2237 | Y7: ='Luciane-Desmob'!Z20 -> 0 | Z7: ='Luciane-Desmob'!AI20 -> 0 | AA7: ='Luciane-Desmob'!AR20 -> 0
A8: MAI | B8: ='Erika - desmob'!H23 -> 0 | C8: =SUM(5000-B8) -> 5000 | D8: ='Erika - desmob'!U24 -> 0 | E8: ='Erika - desmob'!AC24 -> 0 | F8: ='Erika - desmob'!AK24 -> 0 | H8: MAI | I8: ='Eucilene-Desmob'!H24 -> 1000 | J8: =SUM(5000-I8) -> 4000 | K8: ='Eucilene-Desmob'!U25 -> 0 | L8: ='Eucilene-Desmob'!AC25 -> 0 | M8: ='Eucilene-Desmob'!AK25 -> 0 | O8: MAI | P8: =Alire!H24 -> 1587 | Q8: =SUM(5000-P8) -> 3413 | R8: =Alire!Z25 -> 0 | S8: =Alire!AI25 -> 0 | T8: =Alire!AR25 -> 0 | V8: MAI | W8: ='Luciane-Desmob'!H23 -> 2047 | X8: =SUM(5000-W8) -> 2953 | Y8: ='Luciane-Desmob'!Z24 -> 0 | Z8: ='Luciane-Desmob'!AI24 -> 0 | AA8: ='Luciane-Desmob'!AR24 -> 0
A9: JUN | B9: ='Erika - desmob'!H27 -> 0 | C9: =SUM(5000-B9) -> 5000 | D9: ='Erika - desmob'!U28 -> 0 | E9: ='Erika - desmob'!AC28 -> 0 | F9: ='Erika - desmob'!AK28 -> 0 | H9: JUN | I9: ='Eucilene-Desmob'!H28 -> 1422 | J9: =SUM(5000-I9) -> 3578 | K9: ='Eucilene-Desmob'!U29 -> 0 | L9: ='Eucilene-Desmob'!AC29 -> 0 | M9: ='Erika - desmob'!AK28 -> 0 | O9: JUN | P9: =Alire!H28 -> 1848 | Q9: =SUM(5000-P9) -> 3152 | R9: =Alire!Z29 -> 0 | S9: =Alire!AI29 -> 0 | T9: =Alire!AR29 -> 0 | V9: JUN | W9: ='Luciane-Desmob'!H27 -> 2017 | X9: =SUM(5000-W9) -> 2983 | Y9: ='Luciane-Desmob'!Z28 -> 0 | Z9: ='Luciane-Desmob'!AI28 -> 0 | AA9: ='Luciane-Desmob'!AR28 -> 0
A10: JUL | B10: ='Erika - desmob'!H31 -> 0 | C10: =SUM(5000-B10) -> 5000 | D10: ='Erika - desmob'!U32 -> 0 | E10: ='Erika - desmob'!AC32 -> 0 | F10: ='Erika - desmob'!AK32 -> 0 | H10: JUL | I10: ='Eucilene-Desmob'!H32 -> 2970 | J10: =SUM(5000-I10) -> 2030 | K10: ='Eucilene-Desmob'!U33 -> 0 | L10: ='Eucilene-Desmob'!AC33 -> 0 | M10: ='Eucilene-Desmob'!AK33 -> 0 | O10: JUL | P10: =Alire!H32 -> 776 | Q10: =SUM(5000-P10) -> 4224 | R10: =Alire!Z33 -> 0 | S10: =Alire!AI33 -> 0 | T10: =Alire!AR33 -> 0 | V10: JUL | W10: ='Luciane-Desmob'!H31 -> 2387 | X10: =SUM(5000-W10) -> 2613 | Y10: ='Luciane-Desmob'!Z32 -> 0 | Z10: ='Luciane-Desmob'!AI32 -> 0 | AA10: ='Luciane-Desmob'!AR32 -> 0
A11: AGO | B11: ='Erika - desmob'!H35 -> 0 | C11: =SUM(5000-B11) -> 5000 | D11: ='Erika - desmob'!U36 -> 0 | E11: ='Erika - desmob'!AC36 -> 0 | F11: ='Erika - desmob'!AK36 -> 0 | H11: AGO | I11: ='Eucilene-Desmob'!H36 -> 2564 | J11: =SUM(5000-I11) -> 2436 | K11: ='Eucilene-Desmob'!U37 -> 0 | L11: ='Eucilene-Desmob'!AC37 -> 0 | M11: ='Eucilene-Desmob'!AK37 -> 0 | O11: AGO | P11: =Alire!H36 -> 1839 | Q11: =SUM(5000-P11) -> 3161 | R11: =Alire!Z37 -> 0 | S11: =Alire!AI37 -> 0 | T11: =Alire!AR37 -> 0 | V11: AGO | W11: ='Luciane-Desmob'!H35 -> 1984 | X11: =SUM(5000-W11) -> 3016 | Y11: ='Luciane-Desmob'!Z36 -> 0 | Z11: ='Luciane-Desmob'!AI36 -> 0 | AA11: ='Luciane-Desmob'!AR36 -> 0
A12: SET | B12: ='Erika - desmob'!H39 -> 0 | C12: =SUM(5000-B12) -> 5000 | D12: ='Erika - desmob'!U40 -> 0 | E12: ='Erika - desmob'!AC40 -> 0 | F12: ='Erika - desmob'!AK40 -> 0 | H12: SET | I12: ='Eucilene-Desmob'!H40 -> 1624 | J12: =SUM(5000-I12) -> 3376 | K12: ='Eucilene-Desmob'!U41 -> 0 | L12: ='Eucilene-Desmob'!AC41 -> 0 | M12: ='Eucilene-Desmob'!AK41 -> 0 | O12: SET | P12: =Alire!H36 -> 1839 | Q12: =SUM(5000-P12) -> 3161 | R12: =Alire!Z41 -> 0 | S12: =Alire!AI41 -> 0 | T12: =Alire!AR41 -> 0 | V12: SET | W12: ='Luciane-Desmob'!H39 -> 2089 | X12: =SUM(5000-W12) -> 2911 | Y12: ='Luciane-Desmob'!Z40 -> 0 | Z12: ='Luciane-Desmob'!AI40 -> 0 | AA12: ='Luciane-Desmob'!AR40 -> 0
A13: OUT | B13: ='Erika - desmob'!H43 -> 0 | C13: =SUM(5000-B13) -> 5000 | D13: ='Erika - desmob'!U44 -> 0 | E13: ='Erika - desmob'!AC44 -> 0 | F13: ='Erika - desmob'!AK44 -> 0 | H13: OUT | I13: ='Eucilene-Desmob'!H44 -> 0 | J13: =SUM(5000-I13) -> 5000 | K13: ='Eucilene-Desmob'!U45 -> 0 | L13: ='Eucilene-Desmob'!AC45 -> 0 | M13: ='Eucilene-Desmob'!AK45 -> 0 | O13: OUT | P13: =Alire!H40 -> 1446 | Q13: =SUM(5000-P13) -> 3554 | R13: =Alire!Z45 -> 0 | S13: =Alire!AI45 -> 0 | T13: =Alire!AR45 -> 0 | V13: OUT | W13: ='Luciane-Desmob'!H43 -> 1714 | X13: =SUM(5000-W13) -> 3286 | Y13: ='Luciane-Desmob'!Z44 -> 0 | Z13: ='Luciane-Desmob'!AI44 -> 0 | AA13: ='Luciane-Desmob'!AR44 -> 0
A14: NOV | B14: ='Erika - desmob'!H47 -> 0 | C14: =SUM(5000-B14) -> 5000 | D14: ='Erika - desmob'!U48 -> 0 | E14: ='Erika - desmob'!AC48 -> 0 | F14: ='Erika - desmob'!AK48 -> 0 | H14: NOV | I14: ='Eucilene-Desmob'!H48 -> 0 | J14: =SUM(5000-I14) -> 5000 | K14: ='Eucilene-Desmob'!U49 -> 0 | L14: ='Eucilene-Desmob'!AC49 -> 0 | M14: ='Eucilene-Desmob'!AK49 -> 0 | O14: NOV | P14: =Alire!H44 -> 1609 | Q14: =SUM(5000-P14) -> 3391 | R14: =Alire!Z49 -> 0 | S14: =Alire!AI49 -> 0 | T14: =Alire!AR49 -> 0 | V14: NOV | W14: ='Luciane-Desmob'!H47 -> 1538 | X14: =SUM(5000-W14) -> 3462 | Y14: ='Luciane-Desmob'!Z48 -> 0 | Z14: ='Luciane-Desmob'!AI48 -> 0 | AA14: ='Luciane-Desmob'!AR48 -> 0
A15: DEZ | B15: ='Erika - desmob'!H51 -> 0 | C15: =SUM(5000-B15) -> 5000 | D15: ='Erika - desmob'!U52 -> 0 | E15: ='Erika - desmob'!AC52 -> 0 | F15: ='Erika - desmob'!AK52 -> 0 | H15: DEZ | I15: ='Eucilene-Desmob'!H52 -> 1343 | J15: =SUM(5000-I15) -> 3657 | K15: ='Eucilene-Desmob'!U53 -> 0 | L15: ='Eucilene-Desmob'!AC49 -> 0 | M15: ='Eucilene-Desmob'!AK49 -> 0 | O15: DEZ | P15: =Alire!H48 -> 1125 | Q15: =SUM(5000-P15) -> 3875 | R15: =Alire!Z53 -> 0 | S15: =Alire!AI49 -> 0 | T15: =Alire!AR53 -> 0 | V15: DEZ | W15: ='Luciane-Desmob'!H51 -> 1322 | X15: =SUM(5000-W15) -> 3678 | Y15: ='Luciane-Desmob'!Z52 -> 0 | Z15: ='Luciane-Desmob'!AI52 -> 0 | AA15: ='Luciane-Desmob'!AR52 -> 0
A17: TOTAL | B17: =SUM(B4:B15) -> 2261 | D17: =SUM(D4:D15) -> 0 | E17: =SUM(E4:E15) -> 0 | F17: =SUM(F4:F15) -> 0 | H17: TOTAL | I17: =SUM(I4:I15) -> 15583 | K17: =SUM(K4:K15) -> 737.98 | L17: =SUM(L4:L15) -> 0 | M17: =SUM(M4:M15) -> 0 | O17: TOTAL | P17: =SUM(P4:P15) -> 13740 | R17: =SUM(R4:R15) -> 0 | S17: =SUM(S4:S15) -> 0 | T17: =SUM(T4:T15) -> 0 | V17: TOTAL | W17: =SUM(W4:W15) -> 17861 | Y17: =SUM(Y4:Y15) -> 0 | Z17: =SUM(Z4:Z15) -> 0 | AA17: =SUM(AA4:AA15) -> 0
A18: SALDO KM | B18: =SUM(60000-B17) -> 57739 | H18: SALDO KM | I18: =SUM(60000-I17) -> 44417 | O18: SALDO KM | P18: =SUM(60000-P17) -> 46260 | V18: SALDO KM | W18: =SUM(60000-W17) -> 42139
B21: CAR_05 | I21: CAR_06 | P21: CAR_07 | W21: CAR_08
B22: KM RODADO | C22: KM MENSAL | D22: ABASTECIMENTO | E22: LAVA_RAPIDO | F22: BORRACHARIA | I22: KM RODADO | J22: KM MENSAL | K22: ABASTECIMENTO | L22: LAVA_RAPIDO | M22: BORRACHARIA | P22: KM RODADO | Q22: KM MENSAL | R22: ABASTECIMENTO | S22: LAVA_RAPIDO | T22: BORRACHARIA | W22: KM RODADO | X22: KM MENSAL | Y22: ABASTECIMENTO | Z22: LAVA_RAPIDO | AA22: BORRACHARIA
A23: JAN | C23: 0 | D23: 0 | E23: 0 | F23: 0 | H23: JAN | J23: 0 | K23: 0 | L23: 0 | M23: 0 | O23: JAN | Q23: 0 | R23: 0 | S23: 0 | T23: 0 | V23: JAN | X23: 0 | Y23: 0 | Z23: 0 | AA23: 0
A24: FEV | B24: ='Tayonara-Desmob'!H11 -> 0 | C24: =SUM(5000-B24) -> 5000 | D24: ='Tayonara-Desmob'!U12 -> 0 | E24: ='Tayonara-Desmob'!AC12 -> 0 | F24: ='Tayonara-Desmob'!AK12 -> 0 | H24: FEV | I24: ='Eucilene-Desmobi'!H11 -> 0 | J24: =SUM(5000-I24) -> 5000 | K24: ='Eucilene-Desmobi'!U12 -> 0 | L24: ='Eucilene-Desmobi'!AC12 -> 0 | M24: ='Eucilene-Desmobi'!AK12 -> 0 | O24: FEV | P24: =Tayonara!H11 -> 0 | Q24: =SUM(5000-P24) -> 5000 | R24: =Tayonara!U12 -> 0 | S24: =Tayonara!AC12 -> 0 | T24: =Tayonara!AK12 -> 0 | V24: FEV | W24: =CAR_08!H11 -> 0 | X24: =SUM(5000-W24) -> 5000 | Y24: =CAR_08!U12 -> 0 | Z24: =CAR_08!AE12 -> 0 | AA24: =CAR_08!AN12 -> 0
A25: MAR | B25: ='Tayonara-Desmob'!H15 -> 0 | C25: =SUM(5000-B25) -> 5000 | D25: ='Tayonara-Desmob'!U16 -> 0 | E25: ='Tayonara-Desmob'!AC16 -> 0 | F25: ='Tayonara-Desmob'!AK16 -> 0 | H25: MAR | I25: ='Eucilene-Desmobi'!H15 -> 0 | J25: =SUM(5000-I25) -> 5000 | K25: ='Eucilene-Desmobi'!U16 -> 0 | L25: ='Eucilene-Desmobi'!AC16 -> 0 | M25: ='Eucilene-Desmobi'!AK16 -> 0 | O25: MAR | P25: =Tayonara!H15 -> 2243 | Q25: =SUM(5000-P25) -> 2757 | R25: =Tayonara!U16 -> 0 | S25: =Tayonara!AC16 -> 0 | T25: =Tayonara!AK16 -> 0 | V25: MAR | W25: =CAR_08!H15 -> 0 | X25: =SUM(5000-W25) -> 5000 | Y25: =CAR_08!U16 -> 0 | Z25: =CAR_08!AE16 -> 0 | AA25: =CAR_08!AN16 -> 0
A26: ABR | B26: ='Tayonara-Desmob'!H19 -> 0 | C26: =SUM(5000-B26) -> 5000 | D26: ='Tayonara-Desmob'!U20 -> 0 | E26: ='Tayonara-Desmob'!AC20 -> 0 | F26: ='Tayonara-Desmob'!AK20 -> 0 | H26: ABR | I26: ='Eucilene-Desmobi'!H19 -> 0 | J26: =SUM(5000-I26) -> 5000 | K26: ='Eucilene-Desmobi'!U20 -> 0 | L26: ='Eucilene-Desmobi'!AC20 -> 0 | M26: ='Eucilene-Desmobi'!AK20 -> 0 | O26: ABR | P26: =Tayonara!H19 -> 1368 | Q26: =SUM(5000-P26) -> 3632 | R26: =Tayonara!U20 -> 0 | S26: =Tayonara!AC20 -> 0 | T26: =Tayonara!AK20 -> 0 | V26: ABR | W26: =CAR_08!H19 -> 0 | X26: =SUM(5000-W26) -> 5000 | Y26: =CAR_08!U200 -> 0 | Z26: =CAR_08!AE20 -> 0 | AA26: =CAR_08!AN200 -> 0
A27: MAI | B27: ='Tayonara-Desmob'!H23 -> 0 | C27: =SUM(5000-B27) -> 5000 | D27: ='Tayonara-Desmob'!U24 -> 0 | E27: ='Tayonara-Desmob'!AC24 -> 0 | F27: ='Tayonara-Desmob'!AK24 -> 0 | H27: MAI | I27: ='Eucilene-Desmobi'!H23 -> 0 | J27: =SUM(5000-I27) -> 5000 | K27: ='Eucilene-Desmobi'!U24 -> 0 | L27: ='Eucilene-Desmobi'!AC24 -> 0 | M27: ='Eucilene-Desmobi'!AK24 -> 0 | O27: MAI | P27: =Tayonara!H23 -> 1728 | Q27: =SUM(5000-P27) -> 3272 | R27: =Tayonara!U24 -> 0 | S27: =Tayonara!AC24 -> 0 | T27: =Tayonara!AK24 -> 0 | V27: MAI | W27: =CAR_08!H23 -> 0 | X27: =SUM(5000-W27) -> 5000 | Y27: =CAR_08!U24 -> 0 | Z27: =CAR_08!AE24 -> 0 | AA27: =CAR_08!AN24 -> 0
A28: JUN | B28: ='Tayonara-Desmob'!H27 -> 1806 | C28: =SUM(5000-B28) -> 3194 | D28: ='Tayonara-Desmob'!U28 -> 1012.19 | E28: ='Tayonara-Desmob'!AC28 -> 0 | F28: ='Tayonara-Desmob'!AK28 -> 0 | H28: JUN | I28: ='Eucilene-Desmobi'!H27 -> 0 | J28: =SUM(5000-I28) -> 5000 | K28: ='Eucilene-Desmobi'!U28 -> 0 | L28: ='Eucilene-Desmobi'!AC28 -> 0 | M28: ='Eucilene-Desmobi'!AK28 -> 0 | O28: JUN | P28: =Tayonara!H27 -> 0 | Q28: =SUM(5000-P28) -> 5000 | R28: =Tayonara!U28 -> 0 | S28: =Tayonara!AC28 -> 0 | T28: =Tayonara!AK28 -> 0 | V28: JUN | W28: =CAR_08!H27 -> 0 | X28: =SUM(5000-W28) -> 5000 | Y28: =CAR_08!U28 -> 0 | Z28: =CAR_08!AE28 -> 0 | AA28: =CAR_08!AN28 -> 0
A29: JUL | B29: ='Tayonara-Desmob'!H31 -> 2372 | C29: =SUM(5000-B29) -> 2628 | D29: ='Tayonara-Desmob'!U32 -> 1477.52 | E29: ='Tayonara-Desmob'!AC32 -> 0 | F29: ='Tayonara-Desmob'!AK32 -> 0 | H29: JUL | I29: ='Eucilene-Desmobi'!H31 -> 0 | J29: =SUM(5000-I29) -> 5000 | K29: ='Eucilene-Desmobi'!U32 -> 0 | L29: ='Eucilene-Desmobi'!AC32 -> 0 | M29: ='Eucilene-Desmobi'!AK32 -> 0 | O29: JUL | P29: =Tayonara!H31 -> 0 | Q29: =SUM(5000-P29) -> 5000 | R29: =Tayonara!U32 -> 0 | S29: =Tayonara!AC32 -> 0 | T29: =Tayonara!AK32 -> 0 | V29: JUL | W29: =CAR_08!H31 -> 0 | X29: =SUM(5000-W29) -> 5000 | Y29: =CAR_08!U32 -> 0 | Z29: =CAR_08!AE32 -> 0 | AA29: =CAR_08!AN32 -> 0
A30: AGO | B30: ='Tayonara-Desmob'!H35 -> 1433 | C30: =SUM(5000-B30) -> 3567 | D30: ='Tayonara-Desmob'!U36 -> 816.96 | E30: ='Tayonara-Desmob'!AC36 -> 0 | F30: ='Tayonara-Desmob'!AK36 -> 0 | H30: AGO | I30: ='Eucilene-Desmobi'!H35 -> 0 | J30: =SUM(5000-I30) -> 5000 | K30: ='Eucilene-Desmobi'!U36 -> 0 | L30: ='Eucilene-Desmobi'!AC36 -> 0 | M30: ='Eucilene-Desmobi'!AK36 -> 0 | O30: AGO | P30: =Tayonara!H35 -> 0 | Q30: =SUM(5000-P30) -> 5000 | R30: =Tayonara!U36 -> 0 | S30: =Tayonara!AC36 -> 0 | T30: =Tayonara!AK36 -> 0 | V30: AGO | W30: =CAR_08!H35 -> 0 | X30: =SUM(5000-W30) -> 5000 | Y30: =CAR_08!U36 -> 0 | Z30: =CAR_08!AE36 -> 0 | AA30: =CAR_08!AN36 -> 0
A31: SET | B31: ='Tayonara-Desmob'!H39 -> 1521 | C31: =SUM(5000-B31) -> 3479 | D31: ='Tayonara-Desmob'!U40 -> 1008.69 | E31: ='Tayonara-Desmob'!AC40 -> 0 | F31: ='Tayonara-Desmob'!AK4 -> 0 | H31: SET | I31: ='Eucilene-Desmobi'!H39 -> 664 | J31: =SUM(5000-I31) -> 4336 | K31: ='Eucilene-Desmobi'!U40 -> 0 | L31: ='Eucilene-Desmobi'!AC40 -> 0 | M31: ='Eucilene-Desmobi'!AK40 -> 0 | O31: SET | P31: =Tayonara!H39 -> 0 | Q31: =SUM(5000-P31) -> 5000 | R31: =Tayonara!U40 -> 0 | S31: =Tayonara!AC40 -> 0 | T31: =Tayonara!AK40 -> 0 | V31: SET | W31: =CAR_08!H39 -> 0 | X31: =SUM(5000-W31) -> 5000 | Y31: =CAR_08!U40 -> 0 | Z31: =CAR_08!AE40 -> 0 | AA31: =CAR_08!AN40 -> 0
A32: OUT | B32: ='Tayonara-Desmob'!H43 -> 1801 | C32: =SUM(5000-B32) -> 3199 | D32: ='Tayonara-Desmob'!U44 -> 1092.18 | E32: ='Tayonara-Desmob'!AC44 -> 0 | F32: ='Tayonara-Desmob'!AK44 -> 0 | H32: OUT | I32: ='Eucilene-Desmobi'!H43 -> 1269 | J32: =SUM(5000-I32) -> 3731 | K32: ='Eucilene-Desmobi'!U44 -> 865.23 | L32: ='Eucilene-Desmobi'!AC44 -> 0 | M32: ='Eucilene-Desmobi'!AK44 -> 0 | O32: OUT | P32: =Tayonara!H43 -> 0 | Q32: =SUM(5000-P32) -> 5000 | R32: =Tayonara!U44 -> 0 | S32: =Tayonara!AC44 -> 0 | T32: =Tayonara!AK44 -> 0 | V32: OUT | W32: =CAR_08!H43 -> 0 | X32: =SUM(5000-W32) -> 5000 | Y32: =CAR_08!U44 -> 0 | Z32: =CAR_08!AE44 -> 0 | AA32: =CAR_08!AN44 -> 0
A33: NOV | B33: ='Tayonara-Desmob'!H47 -> 2227 | C33: =SUM(5000-B33) -> 2773 | D33: ='Tayonara-Desmob'!U48 -> 1137.79 | E33: ='Tayonara-Desmob'!AC48 -> 0 | F33: ='Tayonara-Desmob'!AK48 -> 0 | H33: NOV | I33: ='Eucilene-Desmobi'!H47 -> 955 | J33: =SUM(5000-I33) -> 4045 | K33: ='Eucilene-Desmobi'!U48 -> 512.2 | L33: ='Eucilene-Desmobi'!AC48 -> 0 | M33: ='Eucilene-Desmobi'!AK48 -> 0 | O33: NOV | P33: =Tayonara!H47 -> 0 | Q33: =SUM(5000-P33) -> 5000 | R33: =Tayonara!U48 -> 0 | S33: =Tayonara!AC48 -> 0 | T33: =Tayonara!AK48 -> 0 | V33: NOV | W33: =CAR_08!H47 -> 0 | X33: =SUM(5000-W33) -> 5000 | Y33: =CAR_08!U48 -> 0 | Z33: =CAR_08!AE48 -> 0 | AA33: =CAR_08!AN48 -> 0
A34: DEZ | B34: ='Tayonara-Desmob'!H51 -> 1548 | C34: =SUM(5000-B34) -> 3452 | D34: ='Tayonara-Desmob'!U52 -> 972.64 | E34: ='Tayonara-Desmob'!AC52 -> 0 | F34: ='Tayonara-Desmob'!AK52 -> 0 | H34: DEZ | I34: ='Eucilene-Desmobi'!H51 -> 1576 | J34: =SUM(5000-I34) -> 3424 | K34: ='Eucilene-Desmobi'!U52 -> 238 | L34: ='Eucilene-Desmobi'!AC52 -> 0 | M34: ='Eucilene-Desmobi'!AK52 -> 0 | O34: DEZ | P34: =Tayonara!H51 -> 0 | Q34: =SUM(5000-P34) -> 5000 | R34: =Tayonara!U52 -> 0 | S34: =Tayonara!AC52 -> 0 | T34: =Tayonara!AK52 -> 0 | V34: DEZ | W34: =CAR_08!H51 -> 0 | X34: =SUM(5000-W34) -> 5000 | Y34: =CAR_08!U52 -> 0 | Z34: =CAR_08!AE52 -> 0 | AA34: =CAR_08!AN52 -> 0
A36: TOTAL | B36: =SUM(B23:B34) -> 12708 | D36: =SUM(D23:D34) -> 7517.97 | E36: =SUM(E23:E34) -> 0 | F36: =SUM(F23:F34) -> 0 | H36: TOTAL | I36: =SUM(I23:I34) -> 4464 | K36: =SUM(K23:K34) -> 1615.43 | L36: =SUM(L23:L34) -> 0 | M36: =SUM(M23:M34) -> 0 | O36: TOTAL | P36: =SUM(P23:P34) -> 5339 | R36: =SUM(R23:R34) -> 0 | S36: =SUM(S23:S34) -> 0 | T36: =SUM(T23:T34) -> 0 | V36: TOTAL | W36: =SUM(W23:W34) -> 0 | Y36: =SUM(Y23:Y34) -> 0 | Z36: =SUM(Z23:Z34) -> 0 | AA36: =SUM(AA23:AA34) -> 0
A37: SALDO KM | B37: =SUM(60000-B36) -> 47292 | H37: SALDO KM | I37: =SUM(60000-I36) -> 55536 | O37: SALDO KM | P37: =SUM(60000-P36) -> 54661 | V37: SALDO KM | W37: =SUM(60000-W36) -> 60000
B40: CAR_09 | I40: CAR_10 | P40: CAR_11 | W40: CAR_12
B41: KM | C41: KM MENSAL | D41: ABASTECIMENTO | E41: LAVA_RAPIDO | F41: BORRACHARIA | I41: KM | J41: KM MENSAL | K41: ABASTECIMENTO | L41: LAVA_RAPIDO | M41: BORRACHARIA | P41: KM | Q41: KM MENSAL | R41: ABASTECIMENTO | S41: LAVA_RAPIDO | T41: BORRACHARIA | W41: KM | X41: KM MENSAL | Y41: ABASTECIMENTO | Z41: LAVA_RAPIDO | AA41: BORRACHARIA
A42: JAN | H42: JAN | O42: JAN | V42: JAN
A43: FEV | B43: =CAR_09!H11 -> 0 | C43: =SUM(5000-B43) -> 5000 | D43: =CAR_09!U12 -> 0 | E43: =CAR_09!AE12 -> 0 | F43: =CAR_09!AN12 -> 0 | H43: FEV | I43: =CAR_10!H11 -> 4460 | J43: =SUM(5000-I43) -> 540 | K43: =CAR_10!U12 -> 0 | L43: =CAR_10!AE12 -> 0 | M43: =CAR_10!AN12 -> 0 | O43: FEV | P43: =CAR_11!H11 -> 0 | Q43: =SUM(5000-P43) -> 5000 | R43: =CAR_11!U12 -> 0 | S43: =CAR_11!AE12 -> 0 | T43: =CAR_11!AN12 -> 0 | V43: FEV | W43: =CAR_12!H11 -> 0 | X43: =SUM(5000-W43) -> 5000 | Y43: =CAR_12!U12 -> 0 | Z43: =CAR_12!AE12 -> 0 | AA43: =CAR_12!AN12 -> 0
A44: MAR | B44: =CAR_09!H15 -> 0 | C44: =SUM(5000-B44) -> 5000 | D44: =CAR_09!U16 -> 0 | E44: =CAR_09!AE16 -> 0 | F44: =CAR_09!AN16 -> 0 | H44: MAR | I44: =CAR_10!H15 -> 4460 | J44: =SUM(5000-I44) -> 540 | K44: =CAR_10!U16 -> 0 | L44: =CAR_10!AE16 -> 0 | M44: =CAR_10!AN16 -> 0 | O44: MAR | P44: =CAR_11!H15 -> 0 | Q44: =SUM(5000-P44) -> 5000 | R44: =CAR_11!U16 -> 0 | S44: =CAR_11!AE16 -> 0 | T44: =CAR_11!AN16 -> 0 | V44: MAR | W44: =CAR_12!H15 -> 0 | X44: =SUM(5000-W44) -> 5000 | Y44: =CAR_12!U16 -> 0 | Z44: =CAR_12!AE16 -> 0 | AA44: =CAR_12!AN16 -> 0
A45: ABR | B45: =CAR_09!H19 -> 0 | C45: =SUM(5000-B45) -> 5000 | D45: =CAR_09!U20 -> 0 | E45: =CAR_09!AE20 -> 0 | F45: =CAR_09!AN20 -> 0 | H45: ABR | I45: =CAR_10!H19 -> 4460 | J45: =SUM(5000-I45) -> 540 | K45: =CAR_10!U20 -> 0 | L45: =CAR_10!AE20 -> 0 | M45: =CAR_10!AN20 -> 0 | O45: ABR | P45: =CAR_11!H19 -> 0 | Q45: =SUM(5000-P45) -> 5000 | R45: =CAR_11!U20 -> 0 | S45: =CAR_11!AE20 -> 0 | T45: =CAR_11!AN20 -> 0 | V45: ABR | W45: =CAR_12!H19 -> 0 | X45: =SUM(5000-W45) -> 5000 | Y45: =CAR_12!U20 -> 0 | Z45: =CAR_12!AE20 -> 0 | AA45: =CAR_12!AN20 -> 0
A46: MAI | B46: =CAR_09!H23 -> 0 | C46: =SUM(5000-B46) -> 5000 | D46: =CAR_09!U24 -> 0 | E46: =CAR_09!AE24 -> 0 | F46: =CAR_09!AN24 -> 0 | H46: MAI | I46: =CAR_10!H23 -> 0 | J46: =SUM(5000-I46) -> 5000 | K46: =CAR_10!U24 -> 0 | L46: =CAR_10!AE24 -> 0 | M46: =CAR_10!AN24 -> 0 | O46: MAI | P46: =CAR_11!H23 -> 0 | Q46: =SUM(5000-P46) -> 5000 | R46: =CAR_11!U24 -> 0 | S46: =CAR_11!AE24 -> 0 | T46: =CAR_11!AN24 -> 0 | V46: MAI | W46: =CAR_12!H23 -> 0 | X46: =SUM(5000-W46) -> 5000 | Y46: =CAR_12!U24 -> 0 | Z46: =CAR_12!AE24 -> 0 | AA46: =CAR_12!AN24 -> 0
A47: JUN | B47: =CAR_09!H27 -> 0 | C47: =SUM(5000-B47) -> 5000 | D47: =CAR_09!U28 -> 0 | E47: =CAR_09!AE28 -> 0 | F47: =CAR_09!AN28 -> 0 | H47: JUN | I47: =CAR_10!H27 -> 0 | J47: =SUM(5000-I47) -> 5000 | K47: =CAR_10!U28 -> 0 | L47: =CAR_10!AE28 -> 0 | M47: =CAR_10!AN28 -> 0 | O47: JUN | P47: =CAR_11!H27 -> 0 | Q47: =SUM(5000-P47) -> 5000 | R47: =CAR_11!U28 -> 0 | S47: =CAR_11!AE28 -> 0 | T47: =CAR_11!AN28 -> 0 | V47: JUN | W47: =CAR_12!H27 -> 0 | X47: =SUM(5000-W47) -> 5000 | Y47: =CAR_12!U28 -> 0 | Z47: =CAR_12!AE28 -> 0 | AA47: =CAR_12!AN28 -> 0
...

Sheet Alire
A2: Veiculo | B2: TCROSS | D2: Placa: | E2: EGK2E03 | H2: km | I2: 3000
A3: Substituição | B3: 45883 | D3: Placa: | E3: TEL5D67 | H3: Modelo | I3: Tracker
A4: Substituição | B4: 46088 | D4: Placa: | E4: TEL2B29 | H4: Modelo | I4: Tracker
A5: Contrato de Locação | B5: 3837 | D5: Rastreador | E5: 50 | H5: Data mob. | I5: 45384
A8: REGISTRO DE KM | J8: ABASTECIMENTO | W8: LAVA_RAPIDO | AE8: BORRACHARIA
B10: Fevereiro | J10: Fevereiro | W10: Fevereiro | AE10: Fevereiro
A11: KM (Rodados) | B11: 1ª Leitura | C11: 2ª Leitura | D11: 3ª Leitura | E11: 4ª Leitura | F11: 15 dias Rodados | G11: 30 dias Rodados | H11: Total Mensal | J11: DATA | W11: DATA | AE11: DATA
F12: =SUM(C12-B12) -> 0 | G12: =SUM(E12-D12) -> 0 | H12: =SUM(F12:G12) -> 0 | J12: VALOR | W12: VALOR | AE12: VALOR
T13: TOTAL | U13: =SUM(K12:U12) -> 0 | AB13: TOTAL | AC13: =SUM(X12:AC12) -> 0 | AJ13: TOTAL | AK13: =SUM(AF12:AK12) -> 0
B14: Março | J14: Março | W14: =J14 -> Março | AE14: =W14 -> Março
A15: KM (Rodados) | B15: 1ª Leitura | C15: 2ª Leitura | D15: 3ª Leitura | E15: 4ª Leitura | F15: 15 dias Rodados | G15: 30 dias Rodados | H15: Total Mensal | J15: DATA | W15: DATA | AE15: DATA
F16: =SUM(C16-B16) -> 0 | G16: =SUM(E16-D16) -> 0 | H16: =SUM(F16:G16) -> 0 | J16: VALOR | W16: VALOR | AE16: VALOR
T17: TOTAL | U17: =SUM(K16:U16) -> 0 | AB17: TOTAL | AC17: =SUM(X16:AC16) -> 0 | AJ17: TOTAL | AK17: =SUM(AF16:AK16) -> 0
B18: Abril | J18: Abril | W18: =J18 -> Abril | AE18: =W18 -> Abril
A19: KM (Rodados) | B19: 1ª Leitura | C19: 2ª Leitura | D19: 3ª Leitura | E19: 4ª Leitura | F19: 15 dias Rodados | G19: 30 dias Rodados | H19: Total Mensal | J19: DATA | W19: DATA | AE19: DATA
B20: 31054 | E20: 32725 | F20: =SUM(C20-B20) -> -31054 | G20: =SUM(E20-D20) -> 32725 | H20: =SUM(F20:G20) -> 1671 | J20: VALOR | W20: VALOR | AE20: VALOR
T21: TOTAL | U21: =SUM(K20:U20) -> 0 | AB21: TOTAL | AC21: =SUM(X20:AC20) -> 0 | AJ21: TOTAL | AK21: =SUM(AF20:AK20) -> 0
B22: Maio | J22: Maio | W22: =J22 -> Maio | AE22: =W22 -> Maio
A23: KM (Rodados) | B23: 1ª Leitura | C23: 2ª Leitura | D23: 3ª Leitura | E23: 4ª Leitura | F23: 15 dias Rodados | G23: 30 dias Rodados | H23: Total Mensal | J23: DATA | W23: DATA | AE23: DATA
B24: 32725 | E24: 34312 | F24: =SUM(C24-B24) -> -32725 | G24: =SUM(E24-D24) -> 34312 | H24: =SUM(F24:G24) -> 1587 | J24: VALOR | W24: VALOR | AE24: VALOR
T25: TOTAL | U25: =SUM(K24:U24) -> 0 | AB25: TOTAL | AC25: =SUM(X24:AC24) -> 0 | AJ25: TOTAL | AK25: =SUM(AF24:AK24) -> 0
B26: Junho | J26: Junho | W26: =J26 -> Junho | AE26: =W26 -> Junho
A27: KM (Rodados) | B27: 1ª Leitura | C27: 2ª Leitura | D27: 3ª Leitura | E27: 4ª Leitura | F27: 15 dias Rodados | G27: 30 dias Rodados | H27: Total Mensal | J27: DATA | W27: DATA | AE27: DATA
B28: 34312 | E28: 36160 | F28: =SUM(C28-B28) -> -34312 | G28: =SUM(E28-D28) -> 36160 | H28: =SUM(F28:G28) -> 1848 | J28: VALOR | W28: VALOR | AE28: VALOR
T29: TOTAL | U29: =SUM(K28:U28) -> 0 | AB29: TOTAL | AC29: =SUM(X28:AC28) -> 0 | AJ29: TOTAL | AK29: =SUM(AF28:AK28) -> 0
B30: Julho | J30: Julho | W30: =J30 -> Julho | AE30: =W30 -> Julho
A31: KM (Rodados) | B31: 1ª Leitura | C31: 2ª Leitura | D31: 3ª Leitura | E31: 4ª Leitura | F31: 15 dias Rodados | G31: 30 dias Rodados | H31: Total Mensal | J31: DATA | W31: DATA | AE31: DATA
B32: 36160 | E32: 36936 | F32: =SUM(C32-B32) -> -36160 | G32: =SUM(E32-D32) -> 36936 | H32: =SUM(F32:G32) -> 776 | J32: VALOR | W32: VALOR | AE32: VALOR
T33: TOTAL | U33: =SUM(K32:U32) -> 0 | AB33: TOTAL | AC33: =SUM(X32:AC32) -> 0 | AJ33: TOTAL | AK33: =SUM(AF32:AK32) -> 0
B34: Agosto | J34: Agosto | W34: =J34 -> Agosto | AE34: =W34 -> Agosto
A35: KM (Rodados) | B35: 1ª Leitura | C35: 2ª Leitura | D35: 3ª Leitura | E35: 4ª Leitura | F35: 15 dias Rodados | G35: 30 dias Rodados | H35: Total Mensal | J35: DATA | W35: DATA | AE35: DATA
B36: 36936 | E36: 38775 | F36: =SUM(C36-B36) -> -36936 | G36: =SUM(E36-D36) -> 38775 | H36: =SUM(F36:G36) -> 1839 | J36: VALOR | W36: VALOR | AE36: VALOR
T37: TOTAL | U37: =SUM(K36:U36) -> 0 | AB37: TOTAL | AC37: =SUM(X36:AC36) -> 0 | AJ37: TOTAL | AK37: =SUM(AF36:AK36) -> 0
B38: Setembro | J38: Setembro | W38: =J38 -> Setembro | AE38: =W38 -> Setembro
A39: KM (Rodados) | B39: 1ª Leitura | C39: 2ª Leitura | D39: 3ª Leitura | E39: 4ª Leitura | F39: 15 dias Rodados | G39: 30 dias Rodados | H39: Total Mensal | J39: DATA | W39: DATA | AE39: DATA
B40: 38775 | E40: 40221 | F40: =SUM(C40-B40) -> -38775 | G40: =SUM(E40-D40) -> 40221 | H40: =SUM(F40:G40) -> 1446 | J40: VALOR | W40: VALOR | AE40: VALOR
T41: TOTAL | U41: =SUM(K40:U40) -> 0 | AB41: TOTAL | AC41: =SUM(X40:AC40) -> 0 | AJ41: TOTAL | AK41: =SUM(AF40:AK40) -> 0
B42: Outubro | J42: Outubro | W42: =J42 -> Outubro | AE42: =W42 -> Outubro
A43: KM (Rodados) | B43: 1ª Leitura | C43: 2ª Leitura | D43: 3ª Leitura | E43: 4ª Leitura | F43: 15 dias Rodados | G43: 30 dias Rodados | H43: Total Mensal | J43: DATA | W43: DATA | AE43: DATA
B44: 40221 | E44: 41830 | F44: =SUM(C44-B44) -> -40221 | G44: =SUM(E44-D44) -> 41830 | H44: =SUM(F44:G44) -> 1609 | J44: VALOR | W44: VALOR | AE44: VALOR
...

Sheet Tayonara
A2: Veiculo | B2: 46086 | D2: Placa: | E2: UFL3I50 | H2: km | I2: 3000
A4: Contrato de Locação | D4: Rastreador | E4: 50 | H4: Data mob. | I4: 46086
A7: REGISTRO DE KM | J7: ABASTECIMENTO | W7: LAVA_RAPIDO | AE7: BORRACHARIA
B9: Fevereiro | J9: Fevereiro | W9: Fevereiro | AE9: Fevereiro
A10: KM (Rodados) | B10: 1ª Leitura | C10: 2ª Leitura | D10: 3ª Leitura | E10: 4ª Leitura | F10: 15 dias Rodados | G10: 30 dias Rodados | H10: Total Mensal | J10: DATA | W10: DATA | AE10: DATA
F11: =SUM(C11-B11) -> 0 | G11: =SUM(E11-D11) -> 0 | H11: =SUM(F11:G11) -> 0 | J11: VALOR | W11: VALOR | AE11: VALOR
T12: TOTAL | U12: =SUM(K11:U11) -> 0 | AB12: TOTAL | AC12: =SUM(X11:AC11) -> 0 | AJ12: TOTAL | AK12: =SUM(AF11:AK11) -> 0
B13: Março | J13: Março | W13: =J13 -> Março | AE13: =W13 -> Março
A14: KM (Rodados) | B14: 1ª Leitura | C14: 2ª Leitura | D14: 3ª Leitura | E14: 4ª Leitura | F14: 15 dias Rodados | G14: 30 dias Rodados | H14: Total Mensal | J14: DATA | W14: DATA | AE14: DATA
B15: 2109 | E15: 4352 | F15: =SUM(C15-B15) -> -2109 | G15: =SUM(E15-D15) -> 4352 | H15: =SUM(F15:G15) -> 2243 | J15: VALOR | W15: VALOR | AE15: VALOR
T16: TOTAL | U16: =SUM(K15:U15) -> 0 | AB16: TOTAL | AC16: =SUM(X15:AC15) -> 0 | AJ16: TOTAL | AK16: =SUM(AF15:AK15) -> 0
B17: Abril | J17: Abril | W17: =J17 -> Abril | AE17: =W17 -> Abril
A18: KM (Rodados) | B18: 1ª Leitura | C18: 2ª Leitura | D18: 3ª Leitura | E18: 4ª Leitura | F18: 15 dias Rodados | G18: 30 dias Rodados | H18: Total Mensal | J18: DATA | W18: DATA | AE18: DATA
B19: 4352 | E19: 5720 | F19: =SUM(C19-B19) -> -4352 | G19: =SUM(E19-D19) -> 5720 | H19: =SUM(F19:G19) -> 1368 | J19: VALOR | W19: VALOR | AE19: VALOR
T20: TOTAL | U20: =SUM(K19:U19) -> 0 | AB20: TOTAL | AC20: =SUM(X19:AC19) -> 0 | AJ20: TOTAL | AK20: =SUM(AF19:AK19) -> 0
B21: Maio | J21: Maio | W21: =J21 -> Maio | AE21: =W21 -> Maio
A22: KM (Rodados) | B22: 1ª Leitura | C22: 2ª Leitura | D22: 3ª Leitura | E22: 4ª Leitura | F22: 15 dias Rodados | G22: 30 dias Rodados | H22: Total Mensal | J22: DATA | W22: DATA | AE22: DATA
B23: 5720 | E23: 7448 | F23: =SUM(C23-B23) -> -5720 | G23: =SUM(E23-D23) -> 7448 | H23: =SUM(F23:G23) -> 1728 | J23: VALOR | W23: VALOR | AE23: VALOR
T24: TOTAL | U24: =SUM(K23:U23) -> 0 | AB24: TOTAL | AC24: =SUM(X23:AC23) -> 0 | AJ24: TOTAL | AK24: =SUM(AF23:AK23) -> 0
B25: Junho | J25: Junho | W25: =J25 -> Junho | AE25: =W25 -> Junho
A26: KM (Rodados) | B26: 1ª Leitura | C26: 2ª Leitura | D26: 3ª Leitura | E26: 4ª Leitura | F26: 15 dias Rodados | G26: 30 dias Rodados | H26: Total Mensal | J26: DATA | W26: DATA | AE26: DATA
F27: =SUM(C27-B27) -> 0 | G27: =SUM(E27-D27) -> 0 | H27: =SUM(F27:G27) -> 0 | J27: VALOR | W27: VALOR | AE27: VALOR
T28: TOTAL | U28: =SUM(K27:U27) -> 0 | AB28: TOTAL | AC28: =SUM(X27:AC27) -> 0 | AJ28: TOTAL | AK28: =SUM(AF27:AK27) -> 0
B29: Julho | J29: Julho | W29: =J29 -> Julho | AE29: =W29 -> Julho
A30: KM (Rodados) | B30: 1ª Leitura | C30: 2ª Leitura | D30: 3ª Leitura | E30: 4ª Leitura | F30: 15 dias Rodados | G30: 30 dias Rodados | H30: Total Mensal | J30: DATA | W30: DATA | AE30: DATA
F31: =SUM(C31-B31) -> 0 | G31: =SUM(E31-D31) -> 0 | H31: =SUM(F31:G31) -> 0 | J31: VALOR | W31: VALOR | AE31: VALOR
T32: TOTAL | U32: =SUM(K31:U31) -> 0 | AB32: TOTAL | AC32: =SUM(X31:AC31) -> 0 | AJ32: TOTAL | AK32: =SUM(AF31:AK31) -> 0
B33: Agosto | J33: Agosto | W33: =J33 -> Agosto | AE33: =W33 -> Agosto
A34: KM (Rodados) | B34: 1ª Leitura | C34: 2ª Leitura | D34: 3ª Leitura | E34: 4ª Leitura | F34: 15 dias Rodados | G34: 30 dias Rodados | H34: Total Mensal | J34: DATA | W34: DATA | AE34: DATA
F35: =SUM(C35-B35) -> 0 | G35: =SUM(E35-D35) -> 0 | H35: =SUM(F35:G35) -> 0 | J35: VALOR | W35: VALOR | AE35: VALOR
T36: TOTAL | U36: =SUM(K35:U35) -> 0 | AB36: TOTAL | AC36: =SUM(X35:AC35) -> 0 | AJ36: TOTAL | AK36: =SUM(AF35:AK35) -> 0
B37: Setembro | J37: Setembro | W37: =J37 -> Setembro | AE37: =W37 -> Setembro
A38: KM (Rodados) | B38: 1ª Leitura | C38: 2ª Leitura | D38: 3ª Leitura | E38: 4ª Leitura | F38: 15 dias Rodados | G38: 30 dias Rodados | H38: Total Mensal | J38: DATA | W38: DATA | AE38: DATA
F39: =SUM(C39-B39) -> 0 | G39: =SUM(E39-D39) -> 0 | H39: =SUM(F39:G39) -> 0 | J39: VALOR | W39: VALOR | AE39: VALOR
T40: TOTAL | U40: =SUM(K39:U39) -> 0 | AB40: TOTAL | AC40: =SUM(X39:AC39) -> 0 | AJ40: TOTAL | AK40: =SUM(AF39:AK39) -> 0
B41: Outubro | J41: Outubro | W41: =J41 -> Outubro | AE41: =W41 -> Outubro
A42: KM (Rodados) | B42: 1ª Leitura | C42: 2ª Leitura | D42: 3ª Leitura | E42: 4ª Leitura | F42: 15 dias Rodados | G42: 30 dias Rodados | H42: Total Mensal | J42: DATA | W42: DATA | AE42: DATA
F43: =SUM(C43-B43) -> 0 | G43: =SUM(E43-D43) -> 0 | H43: =SUM(F43:G43) -> 0 | J43: VALOR | W43: VALOR | AE43: VALOR
T44: TOTAL | U44: =SUM(K43:U43) -> 0 | AB44: TOTAL | AC44: =SUM(X43:AC43) -> 0 | AJ44: TOTAL | AK44: =SUM(AF43:AK43) -> 0
B45: Novembro | J45: Novembro | W45: =J45 -> Novembro | AE45: =W45 -> Novembro
...

Sheet Tayonara-Desmob
A2: Veiculo | B2: Renegade | D2: Placa: | E2: TEJ8H62 | H2: KM | I2: 3000
A4: Contrato de Locação | B4: 4039.73 | D4: Rastreador | E4: 45 | H4: Data mob. | I4: 45810 | J4: Data Desmob. | K4: 46086
A7: REGISTRO DE KM | J7: ABASTECIMENTO | W7: LAVA_RAPIDO | AE7: BORRACHARIA
B9: Fevereiro | J9: Fevereiro | W9: Fevereiro | AE9: Fevereiro
A10: KM (Rodados) | B10: 1ª Leitura | C10: 2ª Leitura | D10: 3ª Leitura | E10: 4ª Leitura | F10: 15 dias Rodados | G10: 30 dias Rodados | H10: Total Mensal | J10: DATA | W10: DATA | AE10: DATA
F11: =SUM(C11-B11) -> 0 | G11: =SUM(E11-D11) -> 0 | H11: =SUM(F11:G11) -> 0 | J11: VALOR | W11: VALOR | AE11: VALOR
T12: TOTAL | U12: =SUM(K11:U11) -> 0 | AB12: TOTAL | AC12: =SUM(X11:AC11) -> 0 | AJ12: TOTAL | AK12: =SUM(AF11:AK11) -> 0
B13: Março | J13: Março | W13: =J13 -> Março | AE13: =W13 -> Março
A14: KM (Rodados) | B14: 1ª Leitura | C14: 2ª Leitura | D14: 3ª Leitura | E14: 4ª Leitura | F14: 15 dias Rodados | G14: 30 dias Rodados | H14: Total Mensal | J14: DATA | W14: DATA | AE14: DATA
F15: =SUM(C15-B15) -> 0 | G15: =SUM(E15-D15) -> 0 | H15: =SUM(F15:G15) -> 0 | J15: VALOR | W15: VALOR | AE15: VALOR
T16: TOTAL | U16: =SUM(K15:U15) -> 0 | AB16: TOTAL | AC16: =SUM(X15:AC15) -> 0 | AJ16: TOTAL | AK16: =SUM(AF15:AK15) -> 0
B17: Abril | J17: Abril | W17: =J17 -> Abril | AE17: =W17 -> Abril
A18: KM (Rodados) | B18: 1ª Leitura | C18: 2ª Leitura | D18: 3ª Leitura | E18: 4ª Leitura | F18: 15 dias Rodados | G18: 30 dias Rodados | H18: Total Mensal | J18: DATA | W18: DATA | AE18: DATA
F19: =SUM(C19-B19) -> 0 | G19: =SUM(E19-D19) -> 0 | H19: =SUM(F19:G19) -> 0 | J19: VALOR | W19: VALOR | AE19: VALOR
T20: TOTAL | U20: =SUM(K19:U19) -> 0 | AB20: TOTAL | AC20: =SUM(X19:AC19) -> 0 | AJ20: TOTAL | AK20: =SUM(AF19:AK19) -> 0
B21: Maio | J21: Maio | W21: =J21 -> Maio | AE21: =W21 -> Maio
A22: KM (Rodados) | B22: 1ª Leitura | C22: 2ª Leitura | D22: 3ª Leitura | E22: 4ª Leitura | F22: 15 dias Rodados | G22: 30 dias Rodados | H22: Total Mensal | J22: DATA | W22: DATA | AE22: DATA
F23: =SUM(C23-B23) -> 0 | G23: =SUM(E23-D23) -> 0 | H23: =SUM(F23:G23) -> 0 | J23: VALOR | W23: VALOR | AE23: VALOR
T24: TOTAL | U24: =SUM(K23:U23) -> 0 | AB24: TOTAL | AC24: =SUM(X23:AC23) -> 0 | AJ24: TOTAL | AK24: =SUM(AF23:AK23) -> 0
B25: Junho | J25: Junho | W25: =J25 -> Junho | AE25: =W25 -> Junho
A26: KM (Rodados) | B26: 1ª Leitura | C26: 2ª Leitura | D26: 3ª Leitura | E26: 4ª Leitura | F26: 15 dias Rodados | G26: 30 dias Rodados | H26: Total Mensal | J26: DATA | K26: 45813 | L26: 45817 | M26: 45821 | N26: 45835 | W26: DATA | AE26: DATA
B27: 26 | C27: 1165 | D27: 1165 | E27: 1832 | F27: =SUM(C27-B27) -> 1139 | G27: =SUM(E27-D27) -> 667 | H27: =SUM(F27:G27) -> 1806 | J27: VALOR | K27: 232.71 | L27: 225.52 | M27: 302 | N27: 251.96 | W27: VALOR | AE27: VALOR
T28: TOTAL | U28: =SUM(K27:U27) -> 1012.19 | AB28: TOTAL | AC28: =SUM(X27:AC27) -> 0 | AJ28: TOTAL | AK28: =SUM(AF27:AK27) -> 0
B29: Julho | J29: Julho | W29: =J29 -> Julho | AE29: =W29 -> Julho
A30: KM (Rodados) | B30: 1ª Leitura | C30: 2ª Leitura | D30: 3ª Leitura | E30: 4ª Leitura | F30: 15 dias Rodados | G30: 30 dias Rodados | H30: Total Mensal | J30: DATA | K30: 45841 | L30: 45847 | M30: 45853 | N30: 45860 | O30: 45863 | P30: 45868 | W30: DATA | AE30: DATA
