Workbook

Sheet RESUMO
A1: CGN RUSSAS
B5: JAN | C5: FEV | D5: MAR | E5: ABR | F5: MAI | G5: JUN | H5: JUL | I5: AGO | J5: SET | K5: OUT | L5: NOV | M5: DEZ
A6: ABASTECIMENTO | B6: =SUM('Controle Central'!D4+'Controle Central'!K4+'Controle Central'!R4+'Controle Central'!Y4+'Controle Central'!D23+'Controle Central'!K23+'Controle Central'!R23+'Controle Central'!Y23+'Controle Central'!D42+'Controle Central'!K42+'Controle Central'!R42+'Controle Central'!Y42+'Controle Central'!D61+'Controle Central'!K61+'Controle Central'!R61+'Controle Central'!Y61+'Controle Central'!D80+'Controle Central'!K80+'Controle Central'!R80+'Controle Central'!Y80+'Controle Central'!D98+'Controle Central'!K98+'Controle Central'!R98+'Controle Central'!Y98+'Controle Central'!D116+'Controle Central'!K116+'Controle Central'!R116+'Controle Central'!Y116+'Controle Central'!D134+'Controle Central'!K134) -> 0 | C6: =SUM('Controle Central'!D5+'Controle Central'!K5+'Controle Central'!R5+'Controle Central'!Y5+'Controle Central'!D24+'Controle Central'!K24+'Controle Central'!R24+'Controle Central'!Y24+'Controle Central'!D43+'Controle Central'!K43+'Controle Central'!R43+'Controle Central'!Y43+'Controle Central'!D62+'Controle Central'!K62+'Controle Central'!R62+'Controle Central'!Y62+'Controle Central'!D81+'Controle Central'!K81+'Controle Central'!R81+'Controle Central'!D99+'Controle Central'!K99+'Controle Central'!R99+'Controle Central'!Y99+'Controle Central'!D117+'Controle Central'!K117+'Controle Central'!R117+'Controle Central'!Y117+'Controle Central'!D135+'Controle Central'!K135) -> 0 | D6: =SUM('Controle Central'!D6+'Controle Central'!K6+'Controle Central'!R6+'Controle Central'!Y6+'Controle Central'!D25+'Controle Central'!K25+'Controle Central'!R25+'Controle Central'!Y25+'Controle Central'!D44+'Controle Central'!K44+'Controle Central'!R44+'Controle Central'!Y44+'Controle Central'!D63+'Controle Central'!K63+'Controle Central'!R63+'Controle Central'!Y63+'Controle Central'!D82+'Controle Central'!K82+'Controle Central'!R82+'Controle Central'!Y82+'Controle Central'!D100+'Controle Central'!K100+'Controle Central'!R100+'Controle Central'!Y100+'Controle Central'!D118+'Controle Central'!K118+'Controle Central'!R118+'Controle Central'!Y118+'Controle Central'!D136+'Controle Central'!K136) -> 0 | E6: ='Controle Central'!D7+'Controle Central'!K7+'Controle Central'!R7+'Controle Central'!Y7+'Controle Central'!D26+'Controle Central'!K26+'Controle Central'!R26+'Controle Central'!Y26+'Controle Central'!D45+'Controle Central'!K45+'Controle Central'!R45+'Controle Central'!Y45+'Controle Central'!D64+'Controle Central'!K64+'Controle Central'!R64+'Controle Central'!D83+'Controle Central'!K83+'Controle Central'!R83+'Controle Central'!Y83+'Controle Central'!D101+'Controle Central'!K101+'Controle Central'!R101+'Controle Central'!Y101+'Controle Central'!D119+'Controle Central'!K119+'Controle Central'!R119+'Controle Central'!Y119+'Controle Central'!D137+'Controle Central'!K137 -> 1511.42 | F6: =SUM('Controle Central'!D8+'Controle Central'!K8+'Controle Central'!R8+'Controle Central'!Y8+'Controle Central'!D27+'Controle Central'!K27+'Controle Central'!R27+'Controle Central'!Y27+'Controle Central'!D46+'Controle Central'!K46+'Controle Central'!R46+'Controle Central'!Y46+'Controle Central'!D65+'Controle Central'!K65+'Controle Central'!R65+'Controle Central'!Y65+'Controle Central'!D84+'Controle Central'!K84+'Controle Central'!R84+'Controle Central'!Y84+'Controle Central'!D102+'Controle Central'!K102+'Controle Central'!R102+'Controle Central'!Y102+'Controle Central'!D120+'Controle Central'!K120+'Controle Central'!R120+'Controle Central'!Y120+'Controle Central'!D138+'Controle Central'!K138) -> 6032.75 | G6: =SUM('Controle Central'!D9+'Controle Central'!K9+'Controle Central'!R9+'Controle Central'!Y9+'Controle Central'!D28+'Controle Central'!K28+'Controle Central'!R28+'Controle Central'!Y28+'Controle Central'!D47+'Controle Central'!K47+'Controle Central'!R47+'Controle Central'!Y47+'Controle Central'!D66+'Controle Central'!K66+'Controle Central'!R66+'Controle Central'!Y66+'Controle Central'!D85+'Controle Central'!K85+'Controle Central'!R85+'Controle Central'!Y85+'Controle Central'!D103+'Controle Central'!K103+'Controle Central'!R103+'Controle Central'!Y103+'Controle Central'!D121+'Controle Central'!K121+'Controle Central'!R121+'Controle Central'!Y121+'Controle Central'!D139+'Controle Central'!K139) -> 6591.72 | H6: =SUM('Controle Central'!D10+'Controle Central'!K10+'Controle Central'!R10+'Controle Central'!Y10+'Controle Central'!D29+'Controle Central'!K29+'Controle Central'!R29+'Controle Central'!D48+'Controle Central'!K48+'Controle Central'!R48+'Controle Central'!Y48+'Controle Central'!D67+'Controle Central'!K67+'Controle Central'!R67+'Controle Central'!Y67+'Controle Central'!D86+'Controle Central'!K86+'Controle Central'!R86+'Controle Central'!Y86+'Controle Central'!D104+'Controle Central'!K104+'Controle Central'!R104+'Controle Central'!Y104+'Controle Central'!D122+'Controle Central'!K122+'Controle Central'!R122+'Controle Central'!Y122+'Controle Central'!D140+'Controle Central'!K140) -> 6249.96 | I6: =SUM('Controle Central'!D11+'Controle Central'!K11+'Controle Central'!R11+'Controle Central'!Y11+'Controle Central'!D30+'Controle Central'!K30+'Controle Central'!R30+'Controle Central'!Y30+'Controle Central'!D49+'Controle Central'!K49+'Controle Central'!R49+'Controle Central'!Y49+'Controle Central'!D68+'Controle Central'!K68+'Controle Central'!R68+'Controle Central'!Y68+'Controle Central'!D87+'Controle Central'!K87+'Controle Central'!R87+'Controle Central'!Y87+'Controle Central'!D105+'Controle Central'!K105+'Controle Central'!R105+'Controle Central'!Y105+'Controle Central'!D123+'Controle Central'!K123+'Controle Central'!R123+'Controle Central'!Y123+'Controle Central'!D141+'Controle Central'!K141) -> 6340.37 | J6: =SUM('Controle Central'!D12+'Controle Central'!K12+'Controle Central'!R12+'Controle Central'!Y12+'Controle Central'!D31+'Controle Central'!K31+'Controle Central'!R31+'Controle Central'!Y31+'Controle Central'!D50+'Controle Central'!K50+'Controle Central'!R50+'Controle Central'!Y50+'Controle Central'!D69+'Controle Central'!K69+'Controle Central'!R69+'Controle Central'!Y69+'Controle Central'!D88+'Controle Central'!K88+'Controle Central'!R88+'Controle Central'!Y88+'Controle Central'!D106+'Controle Central'!K106+'Controle Central'!R106+'Controle Central'!Y106+'Controle Central'!D124+'Controle Central'!K124+'Controle Central'!R124+'Controle Central'!Y124+'Controle Central'!D142+'Controle Central'!K142) -> 6726.59 | K6: =SUM('Controle Central'!D13+'Controle Central'!K13+'Controle Central'!R13+'Controle Central'!Y13+'Controle Central'!D32+'Controle Central'!K32+'Controle Central'!R32+'Controle Central'!Y32+'Controle Central'!D51+'Controle Central'!K51+'Controle Central'!R51+'Controle Central'!Y51+'Controle Central'!D70+'Controle Central'!K70+'Controle Central'!R70+'Controle Central'!Y70+'Controle Central'!D89+'Controle Central'!K89+'Controle Central'!R89+'Controle Central'!Y89+'Controle Central'!D107+'Controle Central'!K107+'Controle Central'!R107+'Controle Central'!Y107+'Controle Central'!D125+'Controle Central'!K125+'Controle Central'!R125+'Controle Central'!Y125+'Controle Central'!D143+'Controle Central'!K143) -> 11899.47 | L6: =SUM('Controle Central'!D14+'Controle Central'!K14+'Controle Central'!R14+'Controle Central'!Y14+'Controle Central'!D33+'Controle Central'!K33+'Controle Central'!R33+'Controle Central'!Y33+'Controle Central'!D52+'Controle Central'!K52+'Controle Central'!R52+'Controle Central'!Y52+'Controle Central'!D71+'Controle Central'!K71+'Controle Central'!R71+'Controle Central'!Y71+'Controle Central'!D90+'Controle Central'!K90+'Controle Central'!R90+'Controle Central'!Y90+'Controle Central'!D108+'Controle Central'!K108+'Controle Central'!R108+'Controle Central'!Y108+'Controle Central'!D126+'Controle Central'!K126+'Controle Central'!R126+'Controle Central'!Y126+'Controle Central'!D144+'Controle Central'!K144) -> 3917.66 | M6: =SUM('Controle Central'!D15+'Controle Central'!K15+'Controle Central'!R15+'Controle Central'!Y15+'Controle Central'!D34+'Controle Central'!K34+'Controle Central'!R34+'Controle Central'!Y34+'Controle Central'!D53+'Controle Central'!K53+'Controle Central'!R53+'Controle Central'!Y53+'Controle Central'!D72+'Controle Central'!K72+'Controle Central'!R72+'Controle Central'!Y72+'Controle Central'!D91+'Controle Central'!K91+'Controle Central'!R91+'Controle Central'!Y91+'Controle Central'!D109+'Controle Central'!K109+'Controle Central'!R109+'Controle Central'!Y109+'Controle Central'!D127+'Controle Central'!K127+'Controle Central'!R127+'Controle Central'!Y127+'Controle Central'!D145+'Controle Central'!K145) -> 3076.49
A8: LAVA_RAPIDO | B8: =SUM('Controle Central'!E4+'Controle Central'!L4+'Controle Central'!S4+'Controle Central'!Z4+'Controle Central'!E23+'Controle Central'!L23+'Controle Central'!S23+'Controle Central'!Z23+'Controle Central'!E42+'Controle Central'!L42+'Controle Central'!S42+'Controle Central'!Z42+'Controle Central'!E61+'Controle Central'!L61+'Controle Central'!S61+'Controle Central'!Z61+'Controle Central'!E80+'Controle Central'!L80+'Controle Central'!S80+'Controle Central'!Z80+'Controle Central'!E98+'Controle Central'!L98+'Controle Central'!S98+'Controle Central'!Z98+'Controle Central'!E116+'Controle Central'!L116+'Controle Central'!S116+'Controle Central'!Z116+'Controle Central'!E134+'Controle Central'!L134) -> 0 | C8: =SUM('Controle Central'!E5,'Controle Central'!L5,'Controle Central'!S5,'Controle Central'!Z5,'Controle Central'!E24,'Controle Central'!L24,'Controle Central'!S24,'Controle Central'!Z24,'Controle Central'!E43,'Controle Central'!L43,'Controle Central'!S43,'Controle Central'!Z43,'Controle Central'!E62,'Controle Central'!L62,'Controle Central'!S62,'Controle Central'!Z62,'Controle Central'!E81,'Controle Central'!L81,'Controle Central'!S81,'Controle Central'!Z81,'Controle Central'!E99,'Controle Central'!L99,'Controle Central'!S99,'Controle Central'!Z99,'Controle Central'!E117,'Controle Central'!L117,'Controle Central'!S117,'Controle Central'!Z117,'Controle Central'!E135,'Controle Central'!L135) -> 0 | D8: =SUM('Controle Central'!E6,'Controle Central'!L6,'Controle Central'!S6,'Controle Central'!Z6,'Controle Central'!E25,'Controle Central'!L25,'Controle Central'!S25,'Controle Central'!Z25,'Controle Central'!E44,'Controle Central'!L44,'Controle Central'!S44,'Controle Central'!Z44,'Controle Central'!E63,'Controle Central'!L63,'Controle Central'!S63,'Controle Central'!Z63,'Controle Central'!E82,'Controle Central'!L82,'Controle Central'!S82,'Controle Central'!Z82,'Controle Central'!E100,'Controle Central'!L100,'Controle Central'!S100,'Controle Central'!Z100,'Controle Central'!E118,'Controle Central'!L118,'Controle Central'!S118,'Controle Central'!Z118,'Controle Central'!E136,'Controle Central'!L136) -> 0 | E8: =SUM('Controle Central'!E7,'Controle Central'!L7,'Controle Central'!S7,'Controle Central'!Z7,'Controle Central'!E26,'Controle Central'!L26,'Controle Central'!S26,'Controle Central'!Z26,'Controle Central'!E45,'Controle Central'!L45,'Controle Central'!S45,'Controle Central'!Z45,'Controle Central'!E64,'Controle Central'!L64,'Controle Central'!S64,'Controle Central'!Z64,'Controle Central'!E83,'Controle Central'!L83,'Controle Central'!S83,'Controle Central'!Z83,'Controle Central'!E101,'Controle Central'!L101,'Controle Central'!S101,'Controle Central'!Z101,'Controle Central'!E119,'Controle Central'!L119,'Controle Central'!S119,'Controle Central'!Z119,'Controle Central'!E137,'Controle Central'!L137) -> 0 | F8: =SUM('Controle Central'!E8,'Controle Central'!L8,'Controle Central'!S8,'Controle Central'!Z8,'Controle Central'!E27,'Controle Central'!L27,'Controle Central'!S27,'Controle Central'!Z27,'Controle Central'!E46,'Controle Central'!L46,'Controle Central'!S46,'Controle Central'!Z46,'Controle Central'!E65,'Controle Central'!L65,'Controle Central'!S65,'Controle Central'!Z65,'Controle Central'!E84,'Controle Central'!L84,'Controle Central'!S84,'Controle Central'!Z84,'Controle Central'!E102,'Controle Central'!L102,'Controle Central'!S102,'Controle Central'!Z102,'Controle Central'!E120,'Controle Central'!L120,'Controle Central'!S120,'Controle Central'!Z120,'Controle Central'!E138,'Controle Central'!L138) -> 0 | G8: =SUM('Controle Central'!E9,'Controle Central'!L9,'Controle Central'!S9,'Controle Central'!Z9,'Controle Central'!E28,'Controle Central'!L28,'Controle Central'!S28,'Controle Central'!Z28,'Controle Central'!E47,'Controle Central'!L47,'Controle Central'!S47,'Controle Central'!Z47,'Controle Central'!E66,'Controle Central'!L66,'Controle Central'!S66,'Controle Central'!Z66,'Controle Central'!E85,'Controle Central'!L85,'Controle Central'!S85,'Controle Central'!Z85,'Controle Central'!E103,'Controle Central'!L103,'Controle Central'!S103,'Controle Central'!Z103,'Controle Central'!E121,'Controle Central'!L121,'Controle Central'!S121,'Controle Central'!Z121,'Controle Central'!E139+'Controle Central'!L139) -> 250 | H8: =SUM('Controle Central'!E10,'Controle Central'!L10,'Controle Central'!S10,'Controle Central'!Z10,'Controle Central'!E29,'Controle Central'!L29,'Controle Central'!S29,'Controle Central'!Z29,'Controle Central'!E48,'Controle Central'!L48,'Controle Central'!S48,'Controle Central'!Z48,'Controle Central'!E67,'Controle Central'!L67,'Controle Central'!S67,'Controle Central'!Z67,'Controle Central'!E86,'Controle Central'!L86,'Controle Central'!S86,'Controle Central'!Z86,'Controle Central'!E104,'Controle Central'!L104,'Controle Central'!S104,'Controle Central'!Z104,'Controle Central'!E122,'Controle Central'!L122,'Controle Central'!S122,'Controle Central'!Z122,'Controle Central'!E140,'Controle Central'!L140) -> 550 | I8: =SUM('Controle Central'!L11,'Controle Central'!S11,'Controle Central'!E11,'Controle Central'!Z11,'Controle Central'!Z30,'Controle Central'!S30,'Controle Central'!L30,'Controle Central'!E30,'Controle Central'!E49,'Controle Central'!L49,'Controle Central'!S49,'Controle Central'!Z49,'Controle Central'!Z68,'Controle Central'!S68,'Controle Central'!L68,'Controle Central'!E68,'Controle Central'!E87,'Controle Central'!L87,'Controle Central'!S87,'Controle Central'!Z87,'Controle Central'!Z105,'Controle Central'!Z123,'Controle Central'!S105,'Controle Central'!S123,'Controle Central'!L123,'Controle Central'!L105,'Controle Central'!E123,'Controle Central'!E105,'Controle Central'!E141,'Controle Central'!L141) -> 300 | J8: =SUM('Controle Central'!E12,'Controle Central'!E31,'Controle Central'!L12,'Controle Central'!L31,'Controle Central'!S12,'Controle Central'!S31,'Controle Central'!Z12,'Controle Central'!Z31,'Controle Central'!Z50,'Controle Central'!Z69,'Controle Central'!S50,'Controle Central'!S69,'Controle Central'!L50,'Controle Central'!L69,'Controle Central'!E50,'Controle Central'!E69,'Controle Central'!E88,'Controle Central'!E106,'Controle Central'!L88,'Controle Central'!L106,'Controle Central'!S88,'Controle Central'!S106,'Controle Central'!Z88,'Controle Central'!Z106,'Controle Central'!Z124,'Controle Central'!S124,'Controle Central'!L124,'Controle Central'!E124,'Controle Central'!E142,'Controle Central'!L142) -> 400 | K8: =SUM('Controle Central'!E13,'Controle Central'!L13,'Controle Central'!E32,'Controle Central'!L32,'Controle Central'!S13,'Controle Central'!S32,'Controle Central'!Z13,'Controle Central'!Z32,'Controle Central'!Z51,'Controle Central'!Z70,'Controle Central'!S51,'Controle Central'!S70,'Controle Central'!L51,'Controle Central'!L70,'Controle Central'!E51,'Controle Central'!E70,'Controle Central'!E89,'Controle Central'!E107,'Controle Central'!L89,'Controle Central'!L107,'Controle Central'!S89,'Controle Central'!S107,'Controle Central'!Z107,'Controle Central'!Z89,'Controle Central'!Z125,'Controle Central'!S125,'Controle Central'!L143,'Controle Central'!L125,'Controle Central'!E125,'Controle Central'!E143) -> 200 | L8: =SUM('Controle Central'!E14,'Controle Central'!E33,'Controle Central'!L14,'Controle Central'!L33,'Controle Central'!S14,'Controle Central'!S33,'Controle Central'!Z14,'Controle Central'!Z33,'Controle Central'!Z52,'Controle Central'!Z71,'Controle Central'!S52,'Controle Central'!S71,'Controle Central'!L52,'Controle Central'!L71,'Controle Central'!E52,'Controle Central'!E71,'Controle Central'!E90,'Controle Central'!E108,'Controle Central'!L90,'Controle Central'!L108,'Controle Central'!S90,'Controle Central'!S108,'Controle Central'!Z90,'Controle Central'!Z108,'Controle Central'!Z126,'Controle Central'!S126,'Controle Central'!L126,'Controle Central'!L144,'Controle Central'!E126,'Controle Central'!E144) -> 0 | M8: =SUM('Controle Central'!E15,'Controle Central'!E34,'Controle Central'!L15,'Controle Central'!L34,'Controle Central'!S15,'Controle Central'!S34,'Controle Central'!Z15,'Controle Central'!Z34,'Controle Central'!Z53,'Controle Central'!Z72,'Controle Central'!S53,'Controle Central'!S72,'Controle Central'!L53,'Controle Central'!L72,'Controle Central'!E53,'Controle Central'!E72,'Controle Central'!E91,'Controle Central'!E109,'Controle Central'!L91,'Controle Central'!L109,'Controle Central'!S91,'Controle Central'!S109,'Controle Central'!Z91,'Controle Central'!Z109,'Controle Central'!Z127,'Controle Central'!S127,'Controle Central'!L127,'Controle Central'!E127,'Controle Central'!E145,'Controle Central'!L145) -> 0
A10: BORRACHARIA | B10: =SUM('Controle Central'!F4,'Controle Central'!M4,'Controle Central'!M23,'Controle Central'!F23,'Controle Central'!T4,'Controle Central'!T23,'Controle Central'!AA4,'Controle Central'!AA23,'Controle Central'!AA61,'Controle Central'!AA42,'Controle Central'!T42,'Controle Central'!M42,'Controle Central'!M61,'Controle Central'!F61,'Controle Central'!F42,'Controle Central'!F98,'Controle Central'!F80,'Controle Central'!M80,'Controle Central'!M98,'Controle Central'!T80,'Controle Central'!T98,'Controle Central'!AA80,'Controle Central'!AA98,'Controle Central'!AA116,'Controle Central'!T116,'Controle Central'!M116,'Controle Central'!F116,'Controle Central'!F134,'Controle Central'!M134) -> 0 | C10: =SUM('Controle Central'!F5,'Controle Central'!F24,'Controle Central'!M5,'Controle Central'!M24,'Controle Central'!T24,'Controle Central'!T5,'Controle Central'!AA5,'Controle Central'!AA24,'Controle Central'!AA43,'Controle Central'!AA62,'Controle Central'!T43,'Controle Central'!T62,'Controle Central'!M43,'Controle Central'!M62,'Controle Central'!F43,'Controle Central'!F62,'Controle Central'!F81,'Controle Central'!F99,'Controle Central'!M99,'Controle Central'!M81,'Controle Central'!T99,'Controle Central'!T81,'Controle Central'!AA81,'Controle Central'!AA99,'Controle Central'!AA117,'Controle Central'!T117,'Controle Central'!M117,'Controle Central'!F117,'Controle Central'!F135,'Controle Central'!M135) -> 0 | D10: =SUM('Controle Central'!F6,'Controle Central'!F25,'Controle Central'!M6,'Controle Central'!M25,'Controle Central'!T6,'Controle Central'!T25,'Controle Central'!AA25,'Controle Central'!AA6,'Controle Central'!AA44,'Controle Central'!AA63,'Controle Central'!T63,'Controle Central'!T44,'Controle Central'!M44,'Controle Central'!M63,'Controle Central'!F63,'Controle Central'!F44,'Controle Central'!F82,'Controle Central'!F100,'Controle Central'!M100,'Controle Central'!M82,'Controle Central'!T82,'Controle Central'!T100,'Controle Central'!AA100,'Controle Central'!AA82,'Controle Central'!AA118,'Controle Central'!T118,'Controle Central'!M118,'Controle Central'!M136,'Controle Central'!F118,'Controle Central'!F136) -> 0 | E10: =SUM('Controle Central'!F7,'Controle Central'!F26,'Controle Central'!M26,'Controle Central'!M7,'Controle Central'!T7,'Controle Central'!T26,'Controle Central'!AA7,'Controle Central'!AA26,'Controle Central'!AA45,'Controle Central'!T45,'Controle Central'!AA64,'Controle Central'!T64,'Controle Central'!M45,'Controle Central'!M64,'Controle Central'!F45,'Controle Central'!F64,'Controle Central'!F83,'Controle Central'!F101,'Controle Central'!M83,'Controle Central'!M101,'Controle Central'!T83,'Controle Central'!T101,'Controle Central'!AA83,'Controle Central'!AA101,'Controle Central'!AA119,'Controle Central'!T119,'Controle Central'!M119,'Controle Central'!M137,'Controle Central'!F137,'Controle Central'!F119) -> 0 | F10: =SUM('Controle Central'!F8,'Controle Central'!F27,'Controle Central'!M8,'Controle Central'!M27,'Controle Central'!T8,'Controle Central'!T27,'Controle Central'!AA27,'Controle Central'!AA8,'Controle Central'!AA46,'Controle Central'!AA65,'Controle Central'!T46,'Controle Central'!T65,'Controle Central'!M65,'Controle Central'!M46,'Controle Central'!F46,'Controle Central'!F65,'Controle Central'!F84,'Controle Central'!F102,'Controle Central'!M84,'Controle Central'!M102,'Controle Central'!T84,'Controle Central'!T102,'Controle Central'!AA84,'Controle Central'!AA102,'Controle Central'!AA120,'Controle Central'!T120,'Controle Central'!M120,'Controle Central'!M138,'Controle Central'!F120,'Controle Central'!F138) -> 0 | G10: =SUM('Controle Central'!F9,'Controle Central'!F28,'Controle Central'!M9,'Controle Central'!M28,'Controle Central'!T9,'Controle Central'!T28,'Controle Central'!AA9,'Controle Central'!AA28,'Controle Central'!AA47,'Controle Central'!AA66,'Controle Central'!T47,'Controle Central'!T66,'Controle Central'!M47,'Controle Central'!M66,'Controle Central'!F47,'Controle Central'!F66,'Controle Central'!F85,'Controle Central'!F103,'Controle Central'!M85,'Controle Central'!M103,'Controle Central'!T85,'Controle Central'!T103,'Controle Central'!AA85,'Controle Central'!AA103,'Controle Central'!AA121,'Controle Central'!T121,'Controle Central'!M121,'Controle Central'!M139,'Controle Central'!F139) -> 0 | H10: =SUM('Controle Central'!F10,'Controle Central'!F29,'Controle Central'!M10,'Controle Central'!M29,'Controle Central'!T10,'Controle Central'!T29,'Controle Central'!AA10,'Controle Central'!AA29,'Controle Central'!AA48,'Controle Central'!T48,'Controle Central'!AA67,'Controle Central'!T67,'Controle Central'!M48,'Controle Central'!M67,'Controle Central'!F48,'Controle Central'!F67,'Controle Central'!F86,'Controle Central'!F104,'Controle Central'!M104,'Controle Central'!M86,'Controle Central'!T86,'Controle Central'!T104,'Controle Central'!AA86,'Controle Central'!AA104,'Controle Central'!AA122,'Controle Central'!T122,'Controle Central'!M122,'Controle Central'!M140,'Controle Central'!F122,'Controle Central'!F140) -> 0 | I10: =SUM('Controle Central'!F11,'Controle Central'!F30,'Controle Central'!M11,'Controle Central'!M30,'Controle Central'!T11,'Controle Central'!T30,'Controle Central'!AA11,'Controle Central'!AA30,'Controle Central'!AA49,'Controle Central'!AA68,'Controle Central'!T49,'Controle Central'!T68,'Controle Central'!M49,'Controle Central'!M68,'Controle Central'!F68,'Controle Central'!F49,'Controle Central'!F87,'Controle Central'!F105,'Controle Central'!M87,'Controle Central'!M105,'Controle Central'!T87,'Controle Central'!T105,'Controle Central'!AA87,'Controle Central'!AA105,'Controle Central'!AA123,'Controle Central'!T123,'Controle Central'!M123,'Controle Central'!M141,'Controle Central'!F123,'Controle Central'!F141) -> 0 | J10: =SUM('Controle Central'!F12,'Controle Central'!F31,'Controle Central'!M12,'Controle Central'!M31,'Controle Central'!T12,'Controle Central'!T31,'Controle Central'!AA12,'Controle Central'!AA31,'Controle Central'!AA50,'Controle Central'!T50,'Controle Central'!T69,'Controle Central'!AA69,'Controle Central'!M50,'Controle Central'!M69,'Controle Central'!F69,'Controle Central'!F50,'Controle Central'!F88,'Controle Central'!F106,'Controle Central'!M88,'Controle Central'!M106,'Controle Central'!T88,'Controle Central'!T106,'Controle Central'!AA88,'Controle Central'!AA106,'Controle Central'!AA124,'Controle Central'!T124,'Controle Central'!M124,'Controle Central'!F124,'Controle Central'!F142,'Controle Central'!M142) -> 0 | K10: =SUM('Controle Central'!F13,'Controle Central'!F32,'Controle Central'!M13,'Controle Central'!M32,'Controle Central'!T13,'Controle Central'!T32,'Controle Central'!AA13,'Controle Central'!AA32,'Controle Central'!AA51,'Controle Central'!T51,'Controle Central'!T70,'Controle Central'!AA70,'Controle Central'!M51,'Controle Central'!M70,'Controle Central'!F70,'Controle Central'!F51,'Controle Central'!F89,'Controle Central'!F107,'Controle Central'!M89,'Controle Central'!M107,'Controle Central'!T89,'Controle Central'!T107,'Controle Central'!AA107,'Controle Central'!AA89,'Controle Central'!AA125,'Controle Central'!T125,'Controle Central'!M125,'Controle Central'!F125,'Controle Central'!F143,'Controle Central'!M143) -> 0 | L10: =SUM('Controle Central'!F14,'Controle Central'!M14,'Controle Central'!F33,'Controle Central'!M33,'Controle Central'!T14,'Controle Central'!T33,'Controle Central'!AA33,'Controle Central'!AA14,'Controle Central'!AA52,'Controle Central'!T52,'Controle Central'!M52,'Controle Central'!M71,'Controle Central'!T71,'Controle Central'!AA71,'Controle Central'!AA90,'Controle Central'!T90,'Controle Central'!M90,'Controle Central'!F90,'Controle Central'!F108,'Controle Central'!F126,'Controle Central'!M108,'Controle Central'!M126,'Controle Central'!T108,'Controle Central'!T126,'Controle Central'!AA108,'Controle Central'!AA126,'Controle Central'!M144,'Controle Central'!F144) -> 0 | M10: =SUM('Controle Central'!F15,'Controle Central'!F34,'Controle Central'!M15,'Controle Central'!M34,'Controle Central'!T15,'Controle Central'!T34,'Controle Central'!AA15,'Controle Central'!AA34,'Controle Central'!AA53,'Controle Central'!T53,'Controle Central'!AA72,'Controle Central'!T72,'Controle Central'!M53,'Controle Central'!F53,'Controle Central'!F72,'Controle Central'!M72,'Controle Central'!F91,'Controle Central'!F109,'Controle Central'!M91,'Controle Central'!M109,'Controle Central'!T91,'Controle Central'!T109,'Controle Central'!AA91,'Controle Central'!AA109,'Controle Central'!AA127,'Controle Central'!T127,'Controle Central'!M127,'Controle Central'!M145,'Controle Central'!F127,'Controle Central'!F145) -> 0
B14: JAN | C14: FEV | D14: MAR | E14: ABR | F14: MAI | G14: JUN | H14: JUL | I14: AGO | J14: SET | K14: OUT | L14: NOV | M14: DEZ
A15: Medição
A17: Contrato de Locação
A19: Lucro Car's | B19: =B15-B17 -> 0 | C19: =C15-C17 -> 0 | D19: =D15-D17 -> 0 | E19: =E15-E17 -> 0 | F19: =F15-F17 -> 0 | G19: =G15-G17 -> 0 | H19: =H15-H17 -> 0 | I19: =I15-I17 -> 0 | ... M19: =M15-M17 -> 0

Sheet Controle Central
B2: Carlos Eduardo km contratado 6000 | I2: Eliomar km contratado 5000 | P2: André km contrato 4500 | W2: Jairo km contratado 4500
B3: KM RODADO | C3: KM MENSAL | D3: ABASTECIMENTO | E3: LAVA_RAPIDO | F3: BORRACHARIA | I3: KM RODADO | J3: KM MENSAL | K3: ABASTECIMENTO | L3: LAVA_RAPIDO | M3: BORRACHARIA | P3: KM RODADO | Q3: KM MENSAL | R3: ABASTECIMENTO | S3: LAVA_RAPIDO | T3: BORRACHARIA | W3: KM RODADO | X3: KM MENSAL | Y3: ABASTECIMENTO | Z3: LAVA_RAPIDO | AA3: BORRACHARIA
A4: JAN | C4: 0 | D4: 0 | E4: 0 | F4: 0 | H4: JAN | I4: 0 | J4: 5000 | K4: 0 | L4: 0 | M4: 0 | O4: JAN | P4: 0 | Q4: 4500 | R4: 0 | S4: 0 | T4: 0 | V4: JAN | W4: 0 | X4: 4500 | Y4: 0 | Z4: 0 | AA4: 0
A5: FEV | B5: ='Jonatas-Devol '!H11 -> 0 | C5: =SUM(6000-B5) -> 6000 | D5: ='Jonatas-Devol '!U12 -> 0 | E5: ='Jonatas-Devol '!AC12 -> 0 | F5: ='Jonatas-Devol '!AK12 -> 0 | H5: FEV | I5: ='Eliomar-Desmob'!H11 -> 0 | J5: =SUM(5000-I5) -> 5000 | K5: ='Eliomar-Desmob'!U12 -> 0 | L5: ='Eliomar-Desmob'!AC12 -> 0 | M5: ='Eliomar-Desmob'!AK12 -> 0 | O5: FEV | P5: ='Filipe-Desmob'!H11 -> 0 | Q5: 4500 | R5: ='Filipe-Desmob'!U12 -> 0 | S5: ='Filipe-Desmob'!AI12 -> 0 | T5: ='Filipe-Desmob'!AR12 -> 0 | V5: FEV | W5: ='Jairo - Desmob'!H11 -> 0 | X5: 4500 | Y5: ='Jairo - Desmob'!U12 -> 0 | Z5: ='Jairo - Desmob'!AI12 -> 0 | AA5: ='Jairo - Desmob'!AR12 -> 0
A6: MAR | B6: ='Jonatas-Devol '!H15 -> 0 | C6: =SUM(6000-B6) -> 6000 | D6: ='Jonatas-Devol '!U16 -> 0 | E6: ='Jonatas-Devol '!AC16 -> 0 | F6: ='Jonatas-Devol '!AK16 -> 0 | H6: MAR | I6: ='Eliomar-Desmob'!H15 -> 0 | J6: =SUM(5000-I6) -> 5000 | K6: ='Eliomar-Desmob'!U16 -> 0 | L6: ='Eliomar-Desmob'!AC16 -> 0 | M6: ='Eliomar-Desmob'!AK16 -> 0 | O6: MAR | P6: ='Filipe-Desmob'!H15 -> 0 | Q6: 4500 | R6: ='Filipe-Desmob'!U16 -> 0 | S6: ='Filipe-Desmob'!AI16 -> 0 | T6: ='Filipe-Desmob'!AR16 -> 0 | V6: MAR | W6: ='Jairo - Desmob'!H15 -> 0 | X6: 4500 | Y6: ='Jairo - Desmob'!U16 -> 0 | Z6: ='Jairo - Desmob'!AI16 -> 0 | AA6: ='Jairo - Desmob'!AR16 -> 0
A7: ABR | B7: ='Jonatas-Devol '!H19 -> 1113 | C7: =SUM(6000-B7) -> 4887 | D7: ='Jonatas-Devol '!U20 -> 617.7 | E7: ='Jonatas-Devol '!AC20 -> 0 | F7: ='Jonatas-Devol '!AK20 -> 0 | H7: ABR | I7: ='Eliomar-Desmob'!H19 -> 1449 | J7: =SUM(5000-I7) -> 3551 | K7: ='Eliomar-Desmob'!U20 -> 893.72 | L7: ='Eliomar-Desmob'!AC20 -> 0 | M7: ='Eliomar-Desmob'!AK20 -> 0 | O7: ABR | P7: ='Filipe-Desmob'!H19 -> 0 | Q7: 4500 | R7: ='Filipe-Desmob'!U20 -> 0 | S7: ='Filipe-Desmob'!AI20 -> 0 | T7: ='Filipe-Desmob'!AR20 -> 0 | V7: ABR | W7: ='Jairo - Desmob'!H19 -> 0 | X7: 4500 | Y7: ='Jairo - Desmob'!Z20 -> 0 | Z7: ='Jairo - Desmob'!AI20 -> 0 | AA7: ='Jairo - Desmob'!AR20 -> 0
A8: MAI | B8: ='Jonatas-Devol '!H23 -> 240 | C8: =SUM(6000-B8) -> 5760 | D8: ='Jonatas-Devol '!U24 -> 926.06 | E8: ='Jonatas-Devol '!AC24 -> 0 | F8: ='Jonatas-Devol '!AK24 -> 0 | H8: MAI | I8: ='Eliomar-Desmob'!H23 -> 1074 | J8: =SUM(5000-I8) -> 3926 | K8: ='Eliomar-Desmob'!U24 -> 599.76 | L8: ='Eliomar-Desmob'!AC24 -> 0 | M8: ='Eliomar-Desmob'!AK24 -> 0 | O8: MAI | P8: ='Filipe-Desmob'!H23 -> 3121 | Q8: =SUM(4500-P8) -> 1379 | R8: ='Filipe-Desmob'!U24 -> 1344.6 | S8: ='Filipe-Desmob'!AI24 -> 0 | T8: ='Filipe-Desmob'!AR24 -> 0 | V8: MAI | W8: ='Jairo - Desmob'!H23 -> 1210 | X8: 4500 | Y8: ='Jairo - Desmob'!U24 -> 628.9 | Z8: ='Jairo - Desmob'!AI24 -> 0 | AA8: ='Jairo - Desmob'!AR24 -> 0
A9: JUN | B9: ='Jonatas-Devol '!H27 -> 1103 | C9: =SUM(6000-B9) -> 4897 | D9: ='Jonatas-Devol '!U28 -> 401.35 | E9: ='Jonatas-Devol '!AC28 -> 50 | F9: ='Jonatas-Devol '!AK28 -> 0 | H9: JUN | I9: ='Eliomar-Desmob'!H27 -> 1640 | J9: =SUM(5000-I9) -> 3360 | K9: ='Eliomar-Desmob'!U28 -> 803.25 | L9: ='Eliomar-Desmob'!AC28 -> 50 | M9: ='Jonatas-Devol '!AK28 -> 0 | O9: JUN | P9: ='Filipe-Desmob'!H27 -> 3391 | Q9: 4500 | R9: ='Filipe-Desmob'!U28 -> 1813.12 | S9: ='Filipe-Desmob'!AI28 -> 0 | T9: ='Filipe-Desmob'!AR28 -> 0 | V9: JUN | W9: ='Jairo - Desmob'!H27 -> 1213 | X9: 4500 | Y9: ='Jairo - Desmob'!U28 -> 690.93 | Z9: ='Jairo - Desmob'!AI28 -> 0 | AA9: ='Jairo - Desmob'!AR28 -> 0
A10: JUL | B10: ='Jonatas-Devol '!H31 -> 2070 | C10: =SUM(6000-B10) -> 3930 | D10: ='Jonatas-Devol '!U32 -> 697.91 | E10: ='Jonatas-Devol '!AC32 -> 100 | F10: ='Jonatas-Devol '!AK32 -> 0 | H10: JUL | I10: ='Eliomar-Desmob'!H31 -> 876 | J10: =SUM(5000-I10) -> 4124 | K10: ='Eliomar-Desmob'!U32 -> 584.74 | L10: ='Eliomar-Desmob'!AC32 -> 100 | M10: ='Eliomar-Desmob'!AK32 -> 0 | O10: JUL | P10: ='Filipe-Desmob'!H31 -> 3720 | Q10: 4500 | R10: ='Filipe-Desmob'!U32 -> 1813.41 | S10: ='Filipe-Desmob'!AI32 -> 0 | T10: ='Filipe-Desmob'!AR32 -> 0 | V10: JUL | W10: ='Jairo - Desmob'!H31 -> 1223 | X10: 4500 | Y10: ='Jairo - Desmob'!Z32 -> 0 | Z10: ='Jairo - Desmob'!AI32 -> 0 | AA10: ='Jairo - Desmob'!AR32 -> 0
A11: AGO | B11: ='Jonatas-Devol '!H35 -> 1825 | C11: =SUM(6000-B11) -> 4175 | D11: ='Jonatas-Devol '!U36 -> 1429.48 | E11: ='Jonatas-Devol '!AC36 -> 100 | F11: ='Jonatas-Devol '!AK36 -> 0 | H11: AGO | I11: ='Eliomar-Desmob'!H35 -> 1406 | J11: =SUM(5000-I11) -> 3594 | K11: ='Eliomar-Desmob'!U36 -> 865.11 | L11: ='Eliomar-Desmob'!AC36 -> 100 | M11: ='Eliomar-Desmob'!AK36 -> 0 | O11: AGO | P11: ='Filipe-Desmob'!H35 -> 3285 | Q11: 4500 | R11: ='Filipe-Desmob'!U36 -> 1784.36 | S11: ='Filipe-Desmob'!AI36 -> 0 | T11: ='Filipe-Desmob'!AR36 -> 0 | V11: AGO | W11: ='Jairo - Desmob'!H35 -> 0 | X11: 4500 | Y11: ='Jairo - Desmob'!Z36 -> 0 | Z11: ='Jairo - Desmob'!AI36 -> 0 | AA11: ='Jairo - Desmob'!AR36 -> 0
A12: SET | B12: ='Jonatas-Devol '!H39 -> 2540 | C12: =SUM(6000-B12) -> 3460 | D12: ='Jonatas-Devol '!U40 -> 1743.24 | E12: ='Jonatas-Devol '!AC40 -> 100 | F12: ='Jonatas-Devol '!AK40 -> 0 | H12: SET | I12: ='Eliomar-Desmob'!H39 -> 2427 | J12: =SUM(5000-I12) -> 2573 | K12: ='Eliomar-Desmob'!U40 -> 701.01 | L12: ='Eliomar-Desmob'!AC40 -> 100 | M12: ='Eliomar-Desmob'!AK40 -> 0 | O12: SET | P12: ='Filipe-Desmob'!H35 -> 3285 | Q12: 4500 | R12: ='Filipe-Desmob'!U40 -> 1006.83 | S12: ='Filipe-Desmob'!AI40 -> 0 | T12: ='Filipe-Desmob'!AR40 -> 0 | V12: SET | W12: ='Jairo - Desmob'!H39 -> 0 | X12: 4500 | Y12: ='Jairo - Desmob'!Z40 -> 0 | Z12: ='Jairo - Desmob'!AI40 -> 0 | AA12: ='Jairo - Desmob'!AR40 -> 0
A13: OUT | B13: ='Jonatas-Devol '!H43 -> 3769 | C13: =SUM(6000-B13) -> 2231 | D13: ='Jonatas-Devol '!U44 -> 2380.29 | E13: ='Jonatas-Devol '!AC44 -> 50 | F13: ='Jonatas-Devol '!AK44 -> 0 | H13: OUT | I13: ='Eliomar-Desmob'!H43 -> 1559 | J13: =SUM(5000-I13) -> 3441 | K13: ='Eliomar-Desmob'!U44 -> 1041.17 | L13: ='Eliomar-Desmob'!AC44 -> 50 | M13: ='Eliomar-Desmob'!AK44 -> 0 | O13: OUT | P13: ='Filipe-Desmob'!H39 -> 1176 | Q13: 4500 | R13: ='Filipe-Desmob'!U44 -> 1146.91 | S13: ='Filipe-Desmob'!AI44 -> 0 | T13: ='Filipe-Desmob'!AR44 -> 0 | V13: OUT | W13: ='Jairo - Desmob'!H43 -> 0 | X13: 4500 | Y13: ='Jairo - Desmob'!Z44 -> 0 | Z13: ='Jairo - Desmob'!AI44 -> 0 | AA13: ='Jairo - Desmob'!AR44 -> 0
A14: NOV | B14: ='Jonatas-Devol '!H47 -> 3220 | C14: =SUM(6000-B14) -> 2780 | D14: ='Jonatas-Devol '!U48 -> 743.84 | E14: ='Jonatas-Devol '!AC48 -> 0 | F14: ='Jonatas-Devol '!AK48 -> 0 | H14: NOV | I14: ='Eliomar-Desmob'!H47 -> 1335 | J14: =SUM(5000-I14) -> 3665 | K14: ='Eliomar-Desmob'!U48 -> 538.31 | L14: ='Eliomar-Desmob'!AC48 -> 0 | M14: ='Eliomar-Desmob'!AK48 -> 0 | O14: NOV | P14: ='Filipe-Desmob'!H43 -> 1641 | Q14: 4500 | R14: ='Filipe-Desmob'!U48 -> 571.58 | S14: ='Filipe-Desmob'!AI48 -> 0 | T14: ='Filipe-Desmob'!AR48 -> 0 | V14: NOV | W14: ='Jairo - Desmob'!H47 -> 0 | X14: 4500 | Y14: ='Jairo - Desmob'!Z48 -> 0 | Z14: ='Jairo - Desmob'!AI48 -> 0 | AA14: ='Jairo - Desmob'!AR48 -> 0
A15: DEZ | B15: ='Jonatas-Devol '!H51 -> 2730 | C15: =SUM(6000-B15) -> 3270 | D15: ='Jonatas-Devol '!U52 -> 555.46 | E15: ='Jonatas-Devol '!AC52 -> 0 | F15: ='Jonatas-Devol '!AK52 -> 0 | H15: DEZ | I15: ='Eliomar-Desmob'!H51 -> 1180 | J15: =SUM(5000-I15) -> 3820 | K15: ='Eliomar-Desmob'!U52 -> 255.84 | L15: ='Eliomar-Desmob'!AC48 -> 0 | M15: ='Eliomar-Desmob'!AK48 -> 0 | O15: DEZ | P15: ='Filipe-Desmob'!H47 -> 0 | Q15: 4500 | R15: ='Filipe-Desmob'!U52 -> 0 | S15: ='Filipe-Desmob'!AI48 -> 0 | T15: ='Filipe-Desmob'!AR52 -> 0 | V15: DEZ | W15: ='Jairo - Desmob'!H51 -> 0 | X15: 4500 | Y15: ='Jairo - Desmob'!Z52 -> 0 | Z15: ='Jairo - Desmob'!AI52 -> 0 | AA15: ='Jairo - Desmob'!AR52 -> 0
A17: TOTAL | B17: =SUM(B4:B15) -> 18610 | D17: =SUM(D4:D15) -> 9495.33 | E17: =SUM(E4:E15) -> 400 | F17: =SUM(F4:F15) -> 0 | H17: TOTAL | I17: =SUM(I4:I15) -> 12946 | K17: =SUM(K4:K15) -> 6282.91 | L17: =SUM(L4:L15) -> 400 | M17: =SUM(M4:M15) -> 0 | O17: TOTAL | P17: =SUM(P4:P15) -> 19619 | R17: =SUM(R4:R15) -> 9480.81 | S17: =SUM(S4:S15) -> 0 | T17: =SUM(T4:T15) -> 0 | V17: TOTAL | W17: =SUM(W4:W15) -> 3646 | Y17: =SUM(Y4:Y15) -> 1319.83 | Z17: =SUM(Z4:Z15) -> 0 | AA17: =SUM(AA4:AA15) -> 0
A18: SALDO KM | B18: =SUM(72000-B17) -> 53390 | H18: SALDO KM | I18: =SUM(54000-I17) -> 41054 | O18: SALDO KM | P18: =SUM(54000-P17) -> 34381 | V18: SALDO KM | W18: =SUM(54000-W17) -> 50354
B21: Eric km contratado 4500 | I21: Jonatas | P21: Rogerio | W21: Filipe
B22: KM RODADO | C22: KM MENSAL | D22: ABASTECIMENTO | E22: LAVA_RAPIDO | F22: BORRACHARIA | I22: KM RODADO | J22: KM MENSAL | K22: ABASTECIMENTO | L22: LAVA_RAPIDO | M22: BORRACHARIA | P22: KM RODADO | Q22: KM MENSAL | R22: ABASTECIMENTO | S22: LAVA_RAPIDO | T22: BORRACHARIA | W22: KM RODADO | X22: KM MENSAL | Y22: ABASTECIMENTO | Z22: LAVA_RAPIDO | AA22: BORRACHARIA
A23: JAN | B23: 0 | C23: 4500 | D23: 0 | E23: 0 | F23: 0 | H23: JAN | J23: 0 | K23: 0 | L23: 0 | M23: 0 | O23: JAN | Q23: 0 | R23: 0 | S23: 0 | T23: 0 | V23: JAN | X23: 0 | Y23: 0 | Z23: 0 | AA23: 0
A24: FEV | B24: =' Eric - Desmob'!H11 -> 0 | C24: 4500 | D24: =' Eric - Desmob'!U12 -> 0 | E24: =' Eric - Desmob'!AC12 -> 0 | F24: =' Eric - Desmob'!AK12 -> 0 | H24: FEV | I24: ='Carlos Eduardo - Desmob'!H11 -> 0 | J24: =SUM(5000-I24) -> 5000 | K24: ='Carlos Eduardo - Desmob'!U12 -> 0 | L24: ='Carlos Eduardo - Desmob'!AC12 -> 0 | M24: ='Carlos Eduardo - Desmob'!AK12 -> 0 | O24: FEV | P24: ='Rogerio - Devol'!H11 -> 0 | Q24: =SUM(5000-P24) -> 5000 | R24: ='Rogerio - Devol'!U12 -> 0 | S24: ='Rogerio - Devol'!AC12 -> 0 | T24: ='Rogerio - Devol'!AK12 -> 0 | V24: FEV | W24: ='Filipe - Desmob'!H11 -> 0 | X24: =SUM(5000-W24) -> 5000 | Y24: ='Filipe - Desmob'!U12 -> 0 | Z24: ='Filipe - Desmob'!AE12 -> 0 | AA24: ='Filipe - Desmob'!AN12 -> 0
A25: MAR | B25: =' Eric - Desmob'!H15 -> 0 | C25: 4500 | D25: =' Eric - Desmob'!U16 -> 0 | E25: =' Eric - Desmob'!AC16 -> 0 | F25: =' Eric - Desmob'!AK16 -> 0 | H25: MAR | I25: ='Carlos Eduardo - Desmob'!H15 -> 0 | J25: =SUM(5000-I25) -> 5000 | K25: ='Carlos Eduardo - Desmob'!U16 -> 0 | L25: ='Carlos Eduardo - Desmob'!AC16 -> 0 | M25: ='Carlos Eduardo - Desmob'!AK16 -> 0 | O25: MAR | P25: ='Rogerio - Devol'!H15 -> 0 | Q25: =SUM(5000-P25) -> 5000 | R25: ='Rogerio - Devol'!U16 -> 0 | S25: ='Rogerio - Devol'!AC16 -> 0 | T25: ='Rogerio - Devol'!AK16 -> 0 | V25: MAR | W25: ='Filipe - Desmob'!H15 -> 0 | X25: =SUM(5000-W25) -> 5000 | Y25: ='Filipe - Desmob'!U16 -> 0 | Z25: ='Filipe - Desmob'!AE16 -> 0 | AA25: ='Filipe - Desmob'!AN16 -> 0
A26: ABR | B26: =' Eric - Desmob'!H19 -> 0 | C26: 4500 | D26: =' Eric - Desmob'!U20 -> 0 | E26: =' Eric - Desmob'!AC20 -> 0 | F26: =' Eric - Desmob'!AK20 -> 0 | H26: ABR | I26: ='Carlos Eduardo - Desmob'!H19 -> 0 | J26: =SUM(5000-I26) -> 5000 | K26: ='Carlos Eduardo - Desmob'!U20 -> 0 | L26: ='Carlos Eduardo - Desmob'!AC20 -> 0 | M26: ='Carlos Eduardo - Desmob'!AK20 -> 0 | O26: ABR | P26: ='Rogerio - Devol'!H19 -> 0 | Q26: =SUM(5000-P26) -> 5000 | R26: ='Rogerio - Devol'!U20 -> 0 | S26: ='Rogerio - Devol'!AC20 -> 0 | T26: ='Rogerio - Devol'!AK20 -> 0 | V26: ABR | W26: ='Filipe - Desmob'!H19 -> 0 | X26: =SUM(5000-W26) -> 5000 | Y26: ='Filipe - Desmob'!U200 -> 0 | Z26: ='Filipe - Desmob'!AE20 -> 0 | AA26: ='Filipe - Desmob'!AN200 -> 0
A27: MAI | B27: =' Eric - Desmob'!H23 -> 1385 | C27: 4500 | D27: =' Eric - Desmob'!U24 -> 530.97 | E27: =' Eric - Desmob'!AC24 -> 0 | F27: =' Eric - Desmob'!AK24 -> 0 | H27: MAI | I27: ='Carlos Eduardo - Desmob'!H23 -> 1968 | J27: =SUM(5000-I27) -> 3032 | K27: ='Carlos Eduardo - Desmob'!U24 -> 1277.24 | L27: ='Carlos Eduardo - Desmob'!AC24 -> 0 | M27: ='Carlos Eduardo - Desmob'!AK24 -> 0 | O27: MAI | P27: ='Rogerio - Devol'!H23 -> 3469 | Q27: =SUM(5000-P27) -> 1531 | R27: ='Rogerio - Devol'!U24 -> 725.22 | S27: ='Rogerio - Devol'!AC24 -> 0 | T27: ='Rogerio - Devol'!AK24 -> 0 | V27: MAI | W27: ='Filipe - Desmob'!H23 -> 0 | X27: =SUM(5000-W27) -> 5000 | Y27: ='Filipe - Desmob'!U24 -> 0 | Z27: ='Filipe - Desmob'!AE24 -> 0 | AA27: ='Filipe - Desmob'!AN24 -> 0
A28: JUN | B28: =' Eric - Desmob'!H27 -> 1310 | C28: 4500 | D28: =' Eric - Desmob'!U28 -> 521.85 | E28: =' Eric - Desmob'!AC28 -> 50 | F28: =' Eric - Desmob'!AK28 -> 0 | H28: JUN | I28: ='Carlos Eduardo - Desmob'!H27 -> 2130 | J28: =SUM(5000-I28) -> 2870 | K28: ='Carlos Eduardo - Desmob'!U28 -> 1558.15 | L28: ='Carlos Eduardo - Desmob'!AC28 -> 50 | M28: ='Carlos Eduardo - Desmob'!AK28 -> 0 | O28: JUN | P28: ='Rogerio - Devol'!H27 -> 1030 | Q28: =SUM(5000-P28) -> 3970 | R28: ='Rogerio - Devol'!U28 -> 803.07 | S28: ='Rogerio - Devol'!AC28 -> 50 | T28: ='Rogerio - Devol'!AK28 -> 0 | V28: JUN | W28: ='Filipe - Desmob'!H27 -> 0 | X28: =SUM(5000-W28) -> 5000 | Y28: ='Filipe - Desmob'!U28 -> 0 | Z28: ='Filipe - Desmob'!AE28 -> 0 | AA28: ='Filipe - Desmob'!AN28 -> 0
A29: JUL | B29: =' Eric - Desmob'!H31 -> 1472 | C29: 4500 | D29: =' Eric - Desmob'!U32 -> 850.08 | E29: =' Eric - Desmob'!AC32 -> 100 | F29: =' Eric - Desmob'!AK32 -> 0 | H29: JUL | I29: ='Carlos Eduardo - Desmob'!H31 -> 2171 | J29: =SUM(5000-I29) -> 2829 | K29: ='Carlos Eduardo - Desmob'!U32 -> 1376.46 | L29: ='Carlos Eduardo - Desmob'!AC32 -> 150 | M29: ='Carlos Eduardo - Desmob'!AK32 -> 0 | O29: JUL | P29: ='Rogerio - Devol'!H31 -> 1519 | Q29: =SUM(5000-P29) -> 3481 | R29: ='Rogerio - Devol'!U32 -> 927.36 | S29: ='Rogerio - Devol'!AC32 -> 100 | T29: ='Rogerio - Devol'!AK32 -> 0 | V29: JUL | W29: ='Filipe - Desmob'!H31 -> 0 | X29: =SUM(5000-W29) -> 5000 | Y29: ='Filipe - Desmob'!U32 -> 0 | Z29: ='Filipe - Desmob'!AE32 -> 0 | AA29: ='Filipe - Desmob'!AN32 -> 0
A30: AGO | B30: =' Eric - Desmob'!H35 -> -41063 | C30: 4500 | D30: =' Eric - Desmob'!U36 -> 490 | E30: =' Eric - Desmob'!AC36 -> 50 | F30: =' Eric - Desmob'!AK36 -> 0 | H30: AGO | I30: ='Carlos Eduardo - Desmob'!H35 -> 0 | J30: =SUM(5000-I30) -> 5000 | K30: ='Carlos Eduardo - Desmob'!U36 -> 305 | L30: ='Carlos Eduardo - Desmob'!AC36 -> 0 | M30: ='Carlos Eduardo - Desmob'!AK36 -> 0 | O30: AGO | P30: ='Rogerio - Devol'!H35 -> 0 | Q30: =SUM(5000-P30) -> 5000 | R30: ='Rogerio - Devol'!U36 -> 754.56 | S30: ='Rogerio - Devol'!AC36 -> 0 | T30: ='Rogerio - Devol'!AK36 -> 0 | V30: AGO | W30: ='Filipe - Desmob'!H35 -> 28233 | X30: =SUM(5000-W30) -> -23233 | Y30: ='Filipe - Desmob'!U36 -> 711.86 | Z30: ='Filipe - Desmob'!AE36 -> 50 | AA30: ='Filipe - Desmob'!AN36 -> 0
A31: SET | B31: =' Eric - Desmob'!H39 -> 0 | C31: 4500 | D31: =' Eric - Desmob'!U40 -> 0 | E31: =' Eric - Desmob'!AC40 -> 0 | F31: =' Eric - Desmob'!AK4 -> 0 | H31: SET | I31: ='Carlos Eduardo - Desmob'!H39 -> 0 | J31: =SUM(5000-I31) -> 5000 | K31: ='Carlos Eduardo - Desmob'!U40 -> 0 | L31: ='Carlos Eduardo - Desmob'!AC40 -> 0 | M31: ='Carlos Eduardo - Desmob'!AK40 -> 0 | O31: SET | P31: ='Rogerio - Devol'!H39 -> 581 | Q31: =SUM(5000-P31) -> 4419 | R31: ='Rogerio - Devol'!U40 -> 747.74 | S31: ='Rogerio - Devol'!AC40 -> 100 | T31: ='Rogerio - Devol'!AK40 -> 0 | V31: SET | W31: ='Filipe - Desmob'!H39 -> 0 | X31: =SUM(5000-W31) -> 5000 | Y31: ='Filipe - Desmob'!U40 -> 206.3 | Z31: ='Filipe - Desmob'!AE40 -> 50 | AA31: ='Filipe - Desmob'!AN40 -> 0
A32: OUT | B32: =' Eric - Desmob'!H43 -> 0 | C32: 4500 | D32: =' Eric - Desmob'!U44 -> 0 | E32: =' Eric - Desmob'!AC44 -> 0 | F32: =' Eric - Desmob'!AK44 -> 0 | H32: OUT | I32: ='Carlos Eduardo - Desmob'!H43 -> 0 | J32: =SUM(5000-I32) -> 5000 | K32: ='Carlos Eduardo - Desmob'!U44 -> 0 | L32: ='Carlos Eduardo - Desmob'!AC44 -> 0 | M32: ='Carlos Eduardo - Desmob'!AK44 -> 0 | O32: OUT | P32: ='Rogerio - Devol'!H43 -> 2841 | Q32: =SUM(5000-P32) -> 2159 | R32: ='Rogerio - Devol'!U44 -> 1565.85 | S32: ='Rogerio - Devol'!AC44 -> 0 | T32: ='Rogerio - Devol'!AK44 -> 0 | V32: OUT | W32: ='Filipe - Desmob'!H43 -> 0 | X32: =SUM(5000-W32) -> 5000 | Y32: ='Filipe - Desmob'!U44 -> 0 | Z32: ='Filipe - Desmob'!AE44 -> 0 | AA32: ='Filipe - Desmob'!AN44 -> 0
A33: NOV | B33: =' Eric - Desmob'!H47 -> 0 | C33: 4500 | D33: =' Eric - Desmob'!U48 -> 0 | E33: =' Eric - Desmob'!AC48 -> 0 | F33: =' Eric - Desmob'!AK48 -> 0 | H33: NOV | I33: ='Carlos Eduardo - Desmob'!H47 -> 0 | J33: =SUM(5000-I33) -> 5000 | K33: ='Carlos Eduardo - Desmob'!U48 -> 0 | L33: ='Carlos Eduardo - Desmob'!AC48 -> 0 | M33: ='Carlos Eduardo - Desmob'!AK48 -> 0 | O33: NOV | P33: ='Rogerio - Devol'!H47 -> 1040 | Q33: =SUM(5000-P33) -> 3960 | R33: ='Rogerio - Devol'!U48 -> 245.01 | S33: ='Rogerio - Devol'!AC48 -> 0 | T33: ='Rogerio - Devol'!AK48 -> 0 | V33: NOV | W33: ='Filipe - Desmob'!H47 -> 0 | X33: =SUM(5000-W33) -> 5000 | Y33: ='Filipe - Desmob'!U48 -> 0 | Z33: ='Filipe - Desmob'!AE48 -> 0 | AA33: ='Filipe - Desmob'!AN48 -> 0
A34: DEZ | B34: =' Eric - Desmob'!H51 -> 0 | C34: 4500 | D34: =' Eric - Desmob'!U52 -> 0 | E34: =' Eric - Desmob'!AC52 -> 0 | F34: =' Eric - Desmob'!AK52 -> 0 | H34: DEZ | I34: ='Carlos Eduardo - Desmob'!H51 -> 0 | J34: =SUM(5000-I34) -> 5000 | K34: ='Carlos Eduardo - Desmob'!U52 -> 0 | L34: ='Carlos Eduardo - Desmob'!AC52 -> 0 | M34: ='Carlos Eduardo - Desmob'!AK52 -> 0 | O34: DEZ | P34: ='Rogerio - Devol'!H51 -> 1373 | Q34: =SUM(5000-P34) -> 3627 | R34: ='Rogerio - Devol'!U52 -> 508.04 | S34: ='Rogerio - Devol'!AC52 -> 0 | T34: ='Rogerio - Devol'!AK52 -> 0 | V34: DEZ | W34: ='Filipe - Desmob'!H51 -> 0 | X34: =SUM(5000-W34) -> 5000 | Y34: ='Filipe - Desmob'!U52 -> 0 | Z34: ='Filipe - Desmob'!AE52 -> 0 | AA34: ='Filipe - Desmob'!AN52 -> 0
A36: TOTAL | B36: =SUM(B23:B34) -> -36896 | D36: =SUM(D23:D34) -> 2392.9 | E36: =SUM(E23:E34) -> 200 | F36: =SUM(F23:F34) -> 0 | H36: TOTAL | I36: =SUM(I23:I34) -> 6269 | K36: =SUM(K23:K34) -> 4516.85 | L36: =SUM(L23:L34) -> 200 | M36: =SUM(M23:M34) -> 0 | O36: TOTAL | P36: =SUM(P23:P34) -> 11853 | R36: =SUM(R23:R34) -> 6276.85 | S36: =SUM(S23:S34) -> 250 | T36: =SUM(T23:T34) -> 0 | V36: TOTAL | W36: =SUM(W23:W34) -> 28233 | Y36: =SUM(Y23:Y34) -> 918.16 | Z36: =SUM(Z23:Z34) -> 100 | AA36: =SUM(AA23:AA34) -> 0
A37: SALDO KM | B37: =SUM(54000-B36) -> 90896 | H37: SALDO KM | I37: =SUM(60000-I36) -> 53731 | O37: SALDO KM | P37: =SUM(60000-P36) -> 48147 | V37: SALDO KM | W37: =SUM(60000-W36) -> 31767
B40: André Gadelha | I40: Felipe-Daniel | P40: Ademir | W40: Jerfferson
B41: KM | C41: KM MENSAL | D41: ABASTECIMENTO | E41: LAVA_RAPIDO | F41: BORRACHARIA | I41: KM | J41: KM MENSAL | K41: ABASTECIMENTO | L41: LAVA_RAPIDO | M41: BORRACHARIA | P41: KM | Q41: KM MENSAL | R41: ABASTECIMENTO | S41: LAVA_RAPIDO | T41: BORRACHARIA | W41: KM | X41: KM MENSAL | Y41: ABASTECIMENTO | Z41: LAVA_RAPIDO | AA41: BORRACHARIA
A42: JAN | H42: JAN | O42: JAN | V42: JAN
A43: FEV | B43: ='André-Desmob'!H14 -> 0 | C43: =SUM(5000-B43) -> 5000 | D43: ='André-Desmob'!U15 -> 0 | E43: ='André-Desmob'!AE15 -> 0 | F43: ='André-Desmob'!AN15 -> 0 | H43: FEV | I43: ='Felipe Silva-Mob.CGN Lapa'!H11 -> 0 | J43: =SUM(5000-I43) -> 5000 | K43: ='Felipe Silva-Mob.CGN Lapa'!U12 -> 0 | L43: ='Felipe Silva-Mob.CGN Lapa'!AE12 -> 0 | M43: ='Felipe Silva-Mob.CGN Lapa'!AN12 -> 0 | O43: FEV | P43: ='Ademir-Desmob'!H11 -> 0 | Q43: =SUM(5000-P43) -> 5000 | R43: ='Ademir-Desmob'!U12 -> 0 | S43: ='Ademir-Desmob'!AE12 -> 0 | T43: ='Ademir-Desmob'!AN12 -> 0 | V43: FEV | W43: ='Jerfferson '!H12 -> 0 | X43: =SUM(5000-W43) -> 5000 | Y43: ='Jerfferson '!U13 -> 0 | Z43: ='Jerfferson '!AE13 -> 0 | AA43: ='Jerfferson '!AN13 -> 0
A44: MAR | B44: ='André-Desmob'!H18 -> 0 | C44: =SUM(5000-B44) -> 5000 | D44: ='André-Desmob'!U19 -> 0 | E44: ='André-Desmob'!AE19 -> 0 | F44: ='André-Desmob'!AN19 -> 0 | H44: MAR | I44: ='Felipe Silva-Mob.CGN Lapa'!H15 -> 0 | J44: =SUM(5000-I44) -> 5000 | K44: ='Felipe Silva-Mob.CGN Lapa'!U16 -> 0 | L44: ='Felipe Silva-Mob.CGN Lapa'!AE16 -> 0 | M44: ='Felipe Silva-Mob.CGN Lapa'!AN16 -> 0 | O44: MAR | P44: ='Ademir-Desmob'!H15 -> 0 | Q44: =SUM(5000-P44) -> 5000 | R44: ='Ademir-Desmob'!U16 -> 0 | S44: ='Ademir-Desmob'!AE16 -> 0 | T44: ='Ademir-Desmob'!AN16 -> 0 | V44: MAR | W44: ='Jerfferson '!H16 -> 0 | X44: =SUM(5000-W44) -> 5000 | Y44: ='Jerfferson '!U17 -> 0 | Z44: ='Jerfferson '!AE17 -> 0 | AA44: ='Jerfferson '!AN17 -> 0
A45: ABR | B45: ='André-Desmob'!H22 -> 0 | C45: =SUM(5000-B45) -> 5000 | D45: ='André-Desmob'!U23 -> 0 | E45: ='André-Desmob'!AE23 -> 0 | F45: ='André-Desmob'!AN23 -> 0 | H45: ABR | I45: ='Felipe Silva-Mob.CGN Lapa'!H19 -> 0 | J45: =SUM(5000-I45) -> 5000 | K45: ='Felipe Silva-Mob.CGN Lapa'!U20 -> 0 | L45: ='Felipe Silva-Mob.CGN Lapa'!AE20 -> 0 | M45: ='Felipe Silva-Mob.CGN Lapa'!AN20 -> 0 | O45: ABR | P45: ='Ademir-Desmob'!H19 -> 0 | Q45: =SUM(5000-P45) -> 5000 | R45: ='Ademir-Desmob'!U20 -> 0 | S45: ='Ademir-Desmob'!AE20 -> 0 | T45: ='Ademir-Desmob'!AN20 -> 0 | V45: ABR | W45: ='Jerfferson '!H20 -> 0 | X45: =SUM(5000-W45) -> 5000 | Y45: ='Jerfferson '!U21 -> 0 | Z45: ='Jerfferson '!AE21 -> 0 | AA45: ='Jerfferson '!AN21 -> 0
A46: MAI | B46: ='André-Desmob'!H26 -> 0 | C46: =SUM(5000-B46) -> 5000 | D46: ='André-Desmob'!U27 -> 0 | E46: ='André-Desmob'!AE27 -> 0 | F46: ='André-Desmob'!AN27 -> 0 | H46: MAI | I46: ='Felipe Silva-Mob.CGN Lapa'!H23 -> 0 | J46: =SUM(5000-I46) -> 5000 | K46: ='Felipe Silva-Mob.CGN Lapa'!U24 -> 0 | L46: ='Felipe Silva-Mob.CGN Lapa'!AE24 -> 0 | M46: ='Felipe Silva-Mob.CGN Lapa'!AN24 -> 0 | O46: MAI | P46: ='Ademir-Desmob'!H23 -> 0 | Q46: =SUM(5000-P46) -> 5000 | R46: ='Ademir-Desmob'!U24 -> 0 | S46: ='Ademir-Desmob'!AE24 -> 0 | T46: ='Ademir-Desmob'!AN24 -> 0 | V46: MAI | W46: ='Jerfferson '!H24 -> 0 | X46: =SUM(5000-W46) -> 5000 | Y46: ='Jerfferson '!U25 -> 0 | Z46: ='Jerfferson '!AE25 -> 0 | AA46: ='Jerfferson '!AN25 -> 0
A47: JUN | B47: ='André-Desmob'!H30 -> 0 | C47: =SUM(5000-B47) -> 5000 | D47: ='André-Desmob'!U31 -> 0 | E47: ='André-Desmob'!AE31 -> 0 | F47: ='André-Desmob'!AN31 -> 0 | H47: JUN | I47: ='Felipe Silva-Mob.CGN Lapa'!H27 -> 0 | J47: =SUM(5000-I47) -> 5000 | K47: ='Felipe Silva-Mob.CGN Lapa'!U28 -> 0 | L47: ='Felipe Silva-Mob.CGN Lapa'!AE28 -> 0 | M47: ='Felipe Silva-Mob.CGN Lapa'!AN28 -> 0 | O47: JUN | P47: ='Ademir-Desmob'!H27 -> 0 | Q47: =SUM(5000-P47) -> 5000 | R47: ='Ademir-Desmob'!U28 -> 0 | S47: ='Ademir-Desmob'!AE28 -> 0 | T47: ='Ademir-Desmob'!AN28 -> 0 | V47: JUN | W47: ='Jerfferson '!H28 -> 0 | X47: =SUM(5000-W47) -> 5000 | Y47: ='Jerfferson '!U29 -> 0 | Z47: ='Jerfferson '!AE29 -> 0 | AA47: ='Jerfferson '!AN29 -> 0
...

Sheet Eliomar
A2: Veiculo | B2: Renegade | D2: Placa: | E2: TXZ1G54 | H2: km | I2: 5000
A3: Substituição Veículo | D3: Placa: | H3: Modelo
A4: Contrato de Locação | B4: 4335.99 | D4: Rastreador | E4: Unidas - 3S | H4: Data Mob | I4: 46121
A7: REGISTRO DE KM | J7: ABASTECIMENTO | Y7: LAVA_RAPIDO | AH7: BORRACHARIA
B9: Fevereiro | J9: Fevereiro | Y9: Fevereiro | AH9: Fevereiro
A10: KM (Rodados) | B10: 1ª Leitura | C10: 2ª Leitura | D10: 3ª Leitura | E10: 4ª Leitura | F10: 15 dias Rodados | G10: 30 dias Rodados | H10: Total Mensal | J10: DATA | Y10: DATA | AH10: DATA
F11: =SUM(C11-B11) -> 0 | G11: =SUM(E11-D11) -> 0 | H11: =SUM(F11:G11) -> 0 | J11: VALOR | Y11: VALOR | AH11: VALOR
T12: TOTAL | U12: =SUM(K11:U11) -> 0 | AD12: TOTAL | AE12: =SUM(Z11:AE11) -> 0 | AM12: TOTAL | AN12: =SUM(AI11:AN11) -> 0
B13: Março | J13: Março | Y13: =J13 -> Março | AH13: =Y13 -> Março
A14: KM (Rodados) | B14: 1ª Leitura | C14: 2ª Leitura | D14: 3ª Leitura | E14: 4ª Leitura | F14: 15 dias Rodados | G14: 30 dias Rodados | H14: Total Mensal | J14: DATA | Y14: DATA | AH14: DATA
F15: =SUM(C15-B15) -> 0 | G15: =SUM(E15-D15) -> 0 | H15: =SUM(F15:G15) -> 0 | J15: VALOR | Y15: VALOR | AH15: VALOR
T16: TOTAL | U16: =SUM(K15:U15) -> 0 | AD16: TOTAL | AE16: =SUM(Z15:AE15) -> 0 | AM16: TOTAL | AN16: =SUM(AI15:AN15) -> 0
B17: Abril | J17: Abril | Y17: =J17 -> Abril | AH17: =Y17 -> Abril
A18: KM (Rodados) | B18: 1ª Leitura | C18: 2ª Leitura | D18: 3ª Leitura | E18: 4ª Leitura | F18: 15 dias Rodados | G18: 30 dias Rodados | H18: Total Mensal | J18: DATA | Y18: DATA | AH18: DATA
B19: 8307 | E19: 10586 | F19: =SUM(C19-B19) -> -8307 | G19: =SUM(E19-D19) -> 10586 | H19: =SUM(F19:G19) -> 2279 | J19: VALOR | Y19: VALOR | AH19: VALOR
T20: TOTAL | U20: =SUM(K19:U19) -> 0 | AD20: TOTAL | AE20: =SUM(Z19:AE19) -> 0 | AM20: TOTAL | AN20: =SUM(AI19:AN19) -> 0
B21: Maio | J21: Maio | Y21: =J21 -> Maio | AH21: =Y21 -> Maio
A22: KM (Rodados) | B22: 1ª Leitura | C22: 2ª Leitura | D22: 3ª Leitura | E22: 4ª Leitura | F22: 15 dias Rodados | G22: 30 dias Rodados | H22: Total Mensal | J22: DATA | Y22: DATA | AH22: DATA
B23: 10586 | E23: 13060 | F23: =SUM(C23-B23) -> -10586 | G23: =SUM(E23-D23) -> 13060 | H23: =SUM(F23:G23) -> 2474 | J23: VALOR | Y23: VALOR | AH23: VALOR
T24: TOTAL | U24: =SUM(K23:U23) -> 0 | AD24: TOTAL | AE24: =SUM(Z23:AE23) -> 0 | AM24: TOTAL | AN24: =SUM(AI23:AN23) -> 0
B25: Junho | J25: Junho | Y25: =J25 -> Junho | AH25: =Y25 -> Junho
A26: KM (Rodados) | B26: 1ª Leitura | C26: 2ª Leitura | D26: 3ª Leitura | E26: 4ª Leitura | F26: 15 dias Rodados | G26: 30 dias Rodados | H26: Total Mensal | J26: DATA | Y26: DATA | AH26: DATA
F27: =SUM(C27-B27) -> 0 | G27: =SUM(E27-D27) -> 0 | H27: =SUM(F27:G27) -> 0 | J27: VALOR | Y27: VALOR | AH27: VALOR
T28: TOTAL | U28: =SUM(K27:U27) -> 0 | AD28: TOTAL | AE28: =SUM(Z27:AE27) -> 0 | AM28: TOTAL | AN28: =SUM(AI27:AN27) -> 0
B29: Julho | J29: Julho | Y29: =J29 -> Julho | AH29: =Y29 -> Julho
A30: KM (Rodados) | B30: 1ª Leitura | C30: 2ª Leitura | D30: 3ª Leitura | E30: 4ª Leitura | F30: 15 dias Rodados | G30: 30 dias Rodados | H30: Total Mensal | J30: DATA | Y30: DATA | AH30: DATA
F31: =SUM(C31-B31) -> 0 | G31: =SUM(E31-D31) -> 0 | H31: =SUM(F31:G31) -> 0 | J31: VALOR | Y31: VALOR | AH31: VALOR
T32: TOTAL | U32: =SUM(K31:U31) -> 0 | AD32: TOTAL | AE32: =SUM(Z31:AE31) -> 0 | AM32: TOTAL | AN32: =SUM(AI31:AN31) -> 0
B33: Agosto | J33: Agosto | Y33: =J33 -> Agosto | AH33: =Y33 -> Agosto
A34: KM (Rodados) | B34: 1ª Leitura | C34: 2ª Leitura | D34: 3ª Leitura | E34: 4ª Leitura | F34: 15 dias Rodados | G34: 30 dias Rodados | H34: Total Mensal | J34: DATA | Y34: DATA | AH34: DATA
F35: =SUM(C35-B35) -> 0 | G35: =SUM(E35-D35) -> 0 | H35: =SUM(F35:G35) -> 0 | J35: VALOR | Y35: VALOR | AH35: VALOR
T36: TOTAL | U36: =SUM(K35:U35) -> 0 | AD36: TOTAL | AE36: =SUM(Z35:AE35) -> 0 | AM36: TOTAL | AN36: =SUM(AI35:AN35) -> 0
B37: Setembro | J37: Setembro | Y37: =J37 -> Setembro | AH37: =Y37 -> Setembro
A38: KM (Rodados) | B38: 1ª Leitura | C38: 2ª Leitura | D38: 3ª Leitura | E38: 4ª Leitura | F38: 15 dias Rodados | G38: 30 dias Rodados | H38: Total Mensal | J38: DATA | Y38: DATA | AH38: DATA
F39: =SUM(C39-B39) -> 0 | G39: =SUM(E39-D39) -> 0 | H39: =SUM(F39:G39) -> 0 | J39: VALOR | Y39: VALOR | AH39: VALOR
T40: TOTAL | U40: =SUM(K39:U39) -> 0 | AD40: TOTAL | AE40: =SUM(Z39:AE39) -> 0 | AM40: TOTAL | AN40: =SUM(AI39:AN39) -> 0
B41: Outubro | J41: Outubro | Y41: =J41 -> Outubro | AH41: =Y41 -> Outubro
A42: KM (Rodados) | B42: 1ª Leitura | C42: 2ª Leitura | D42: 3ª Leitura | E42: 4ª Leitura | F42: 15 dias Rodados | G42: 30 dias Rodados | H42: Total Mensal | J42: DATA | Y42: DATA | AH42: DATA
F43: =SUM(C43-B43) -> 0 | G43: =SUM(E43-D43) -> 0 | H43: =SUM(F43:G43) -> 0 | J43: VALOR | Y43: VALOR | AH43: VALOR
T44: TOTAL | U44: =SUM(K43:U43) -> 0 | AD44: TOTAL | AE44: =SUM(Z43:AE43) -> 0 | AM44: TOTAL | AN44: =SUM(AI43:AN43) -> 0
...

Sheet Jerfferson 
A2: Veiculo | B2: TRACKER | D2: Placa: | E2: TCB9G87 | H2: km | I2: 4500
A3: Substituição Veículo | B3: 45677 | D3: Placa: | E3: SUI0E07 | H3: Modelo | I3: T-Cross
A4: Substituição Veículo 2 | B4: 46136 | D4: Placa: | E4: TEL5C58 | H4: Modelo | I4: Tracker
A5: Contrato de Locação | B5: 4144 | D5: Rastreador | E5: 50 | H5: Data Mob | I5: 45677
A8: REGISTRO DE KM | J8: ABASTECIMENTO | Y8: LAVA_RAPIDO | AH8: BORRACHARIA
B10: Fevereiro | J10: Fevereiro | Y10: Fevereiro | AH10: Fevereiro
A11: KM (Rodados) | B11: 1ª Leitura | C11: 2ª Leitura | D11: 3ª Leitura | E11: 4ª Leitura | F11: 15 dias Rodados | G11: 30 dias Rodados | H11: Total Mensal | J11: DATA | Y11: DATA | AH11: DATA
F12: =SUM(C12-B12) -> 0 | G12: =SUM(E12-D12) -> 0 | H12: =SUM(F12:G12) -> 0 | J12: VALOR | Y12: VALOR | AH12: VALOR
T13: TOTAL | U13: =SUM(K12:U12) -> 0 | AD13: TOTAL | AE13: =SUM(Z12:AE12) -> 0 | AM13: TOTAL | AN13: =SUM(AI12:AN12) -> 0
B14: Março | J14: Março | Y14: =J14 -> Março | AH14: =Y14 -> Março
A15: KM (Rodados) | B15: 1ª Leitura | C15: 2ª Leitura | D15: 3ª Leitura | E15: 4ª Leitura | F15: 15 dias Rodados | G15: 30 dias Rodados | H15: Total Mensal | J15: DATA | Y15: DATA | AH15: DATA
F16: =SUM(C16-B16) -> 0 | G16: =SUM(E16-D16) -> 0 | H16: =SUM(F16:G16) -> 0 | J16: VALOR | Y16: VALOR | AH16: VALOR
T17: TOTAL | U17: =SUM(K16:U16) -> 0 | AD17: TOTAL | AE17: =SUM(Z16:AE16) -> 0 | AM17: TOTAL | AN17: =SUM(AI16:AN16) -> 0
B18: Abril | J18: Abril | Y18: =J18 -> Abril | AH18: =Y18 -> Abril
A19: KM (Rodados) | B19: 1ª Leitura | C19: 2ª Leitura | D19: 3ª Leitura | E19: 4ª Leitura | F19: 15 dias Rodados | G19: 30 dias Rodados | H19: Total Mensal | J19: DATA | Y19: DATA | AH19: DATA
F20: =SUM(C20-B20) -> 0 | G20: =SUM(E20-D20) -> 0 | H20: =SUM(F20:G20) -> 0 | J20: VALOR | Y20: VALOR | AH20: VALOR
T21: TOTAL | U21: =SUM(K20:U20) -> 0 | AD21: TOTAL | AE21: =SUM(Z20:AE20) -> 0 | AM21: TOTAL | AN21: =SUM(AI20:AN20) -> 0
B22: Maio | J22: Maio | Y22: =J22 -> Maio | AH22: =Y22 -> Maio
A23: KM (Rodados) | B23: 1ª Leitura | C23: 2ª Leitura | D23: 3ª Leitura | E23: 4ª Leitura | F23: 15 dias Rodados | G23: 30 dias Rodados | H23: Total Mensal | J23: DATA | Y23: DATA | AH23: DATA
F24: =SUM(C24-B24) -> 0 | G24: =SUM(E24-D24) -> 0 | H24: =SUM(F24:G24) -> 0 | J24: VALOR | Y24: VALOR | AH24: VALOR
T25: TOTAL | U25: =SUM(K24:U24) -> 0 | AD25: TOTAL | AE25: =SUM(Z24:AE24) -> 0 | AM25: TOTAL | AN25: =SUM(AI24:AN24) -> 0
B26: Junho | J26: Junho | Y26: =J26 -> Junho | AH26: =Y26 -> Junho
A27: KM (Rodados) | B27: 1ª Leitura | C27: 2ª Leitura | D27: 3ª Leitura | E27: 4ª Leitura | F27: 15 dias Rodados | G27: 30 dias Rodados | H27: Total Mensal | J27: DATA | Y27: DATA | AH27: DATA
F28: =SUM(C28-B28) -> 0 | G28: =SUM(E28-D28) -> 0 | H28: =SUM(F28:G28) -> 0 | J28: VALOR | Y28: VALOR | AH28: VALOR
T29: TOTAL | U29: =SUM(K28:U28) -> 0 | AD29: TOTAL | AE29: =SUM(Z28:AE28) -> 0 | AM29: TOTAL | AN29: =SUM(AI28:AN28) -> 0
B30: Julho | J30: Julho | Y30: =J30 -> Julho | AH30: =Y30 -> Julho
A31: KM (Rodados) | B31: 1ª Leitura | C31: 2ª Leitura | D31: 3ª Leitura | E31: 4ª Leitura | F31: 15 dias Rodados | G31: 30 dias Rodados | H31: Total Mensal | J31: DATA | Y31: DATA | AH31: DATA
F32: =SUM(C32-B32) -> 0 | G32: =SUM(E32-D32) -> 0 | H32: =SUM(F32:G32) -> 0 | J32: VALOR | Y32: VALOR | AH32: VALOR
T33: TOTAL | U33: =SUM(K32:U32) -> 0 | AD33: TOTAL | AE33: =SUM(Z32:AE32) -> 0 | AM33: TOTAL | AN33: =SUM(AI32:AN32) -> 0
B34: Agosto | J34: Agosto | Y34: =J34 -> Agosto | AH34: =Y34 -> Agosto
A35: KM (Rodados) | B35: 1ª Leitura | C35: 2ª Leitura | D35: 3ª Leitura | E35: 4ª Leitura | F35: 15 dias Rodados | G35: 30 dias Rodados | H35: Total Mensal | J35: DATA | Y35: DATA | AH35: DATA
F36: =SUM(C36-B36) -> 0 | G36: =SUM(E36-D36) -> 0 | H36: =SUM(F36:G36) -> 0 | J36: VALOR | Y36: VALOR | AH36: VALOR
T37: TOTAL | U37: =SUM(K36:U36) -> 0 | AD37: TOTAL | AE37: =SUM(Z36:AE36) -> 0 | AM37: TOTAL | AN37: =SUM(AI36:AN36) -> 0
B38: Setembro | J38: Setembro | Y38: =J38 -> Setembro | AH38: =Y38 -> Setembro
A39: KM (Rodados) | B39: 1ª Leitura | C39: 2ª Leitura | D39: 3ª Leitura | E39: 4ª Leitura | F39: 15 dias Rodados | G39: 30 dias Rodados | H39: Total Mensal | J39: DATA | K39: 45560 | L39: 45594 | Y39: DATA | Z39: 45548 | AH39: DATA
B40: 2900 | E40: 5740 | F40: =SUM(C40-B40) -> -2900 | G40: =SUM(E40-D40) -> 5740 | H40: =SUM(F40:G40) -> 2840 | J40: VALOR | K40: 177.93 | L40: 217.61 | Y40: VALOR | Z40: 50 | AH40: VALOR
T41: TOTAL | U41: =SUM(K40:U40) -> 395.54 | AD41: TOTAL | AE41: =SUM(Z40:AE40) -> 50 | AM41: TOTAL | AN41: =SUM(AI40:AN40) -> 0
B42: Outubro | J42: Outubro | Y42: =J42 -> Outubro | AH42: =Y42 -> Outubro
A43: KM (Rodados) | B43: 1ª Leitura | C43: 2ª Leitura | D43: 3ª Leitura | E43: 4ª Leitura | F43: 15 dias Rodados | G43: 30 dias Rodados | H43: Total Mensal | J43: DATA | K43: 45566 | L43: 40453 | M43: 45570 | N43: 45573 | O43: 45575 | P43: 45577 | Q43: 45580 | R43: 45582 | S43: 45584 | T43: 45589 | U43: 45596 | Y43: DATA | Z43: 45568 | AH43: DATA
B44: 5740 | E44: 7591 | F44: =SUM(C44-B44) -> -5740 | G44: =SUM(E44-D44) -> 7591 | H44: =SUM(F44:G44) -> 1851 | J44: VALOR | K44: 239.6 | L44: 218.89 | M44: 127.01 | N44: 223.83 | O44: 113.47 | P44: 122.04 | Q44: 223.89 | R44: 122.59 | S44: 116.48 | T44: 197.71 | U44: 116.19 | Y44: VALOR | Z44: 50 | AH44: VALOR
...

Sheet Eliomar-Desmob
A2: Veiculo | B2: TCROSS | D2: Placa: | E2: SIJ3F45 | H2: KM | I2: 5000
A4: Contrato de Locação | B4: 4335.99 | D4: Rastreador | E4: 50 | H4: Data mob. | I4: 45390 | J4: Data Desmob. | K4: 46090
A7: REGISTRO DE KM | J7: ABASTECIMENTO | W7: LAVA_RAPIDO | AE7: BORRACHARIA
B9: Fevereiro | J9: Fevereiro | W9: Fevereiro | AE9: Fevereiro
A10: KM (Rodados) | B10: 1ª Leitura | C10: 2ª Leitura | D10: 3ª Leitura | E10: 4ª Leitura | F10: 15 dias Rodados | G10: 30 dias Rodados | H10: Total Mensal | J10: DATA | W10: DATA | AE10: DATA
F11: =SUM(C11-B11) -> 0 | G11: =SUM(E11-D11) -> 0 | H11: =SUM(F11:G11) -> 0 | J11: VALOR | W11: VALOR | AE11: VALOR
T12: TOTAL | U12: =SUM(K11:U11) -> 0 | AB12: TOTAL | AC12: =SUM(X11:AC11) -> 0 | AJ12: TOTAL | AK12: =SUM(AF11:AK11) -> 0
