Workbook

Sheet RESUMO
A1: UFV RIACHO
B5: JAN | C5: FEV | D5: MAR | E5: ABR | F5: MAI | G5: JUN | H5: JUL | I5: AGO | J5: SET | K5: OUT | L5: NOV | M5: DEZ
A6: ABASTECIMENTO | B6: =SUM('Controle Central'!D4+'Controle Central'!K4+'Controle Central'!R4+'Controle Central'!Y4+'Controle Central'!D23+'Controle Central'!K23+'Controle Central'!R23+'Controle Central'!Y23+'Controle Central'!D42+'Controle Central'!K42+'Controle Central'!R42+'Controle Central'!Y42+'Controle Central'!D61+'Controle Central'!K61+'Controle Central'!R61+'Controle Central'!Y61+'Controle Central'!D80+'Controle Central'!K80+'Controle Central'!R80+'Controle Central'!Y80+'Controle Central'!D98+'Controle Central'!K98+'Controle Central'!R98+'Controle Central'!Y98+'Controle Central'!D116+'Controle Central'!K116+'Controle Central'!R116+'Controle Central'!Y116+'Controle Central'!D134+'Controle Central'!K134) -> 0 | C6: =SUM('Controle Central'!D5+'Controle Central'!K5+'Controle Central'!R5+'Controle Central'!Y5+'Controle Central'!D24+'Controle Central'!K24+'Controle Central'!R24+'Controle Central'!Y24+'Controle Central'!D43+'Controle Central'!K43+'Controle Central'!R43+'Controle Central'!Y43+'Controle Central'!D62+'Controle Central'!K62+'Controle Central'!R62+'Controle Central'!Y62+'Controle Central'!D81+'Controle Central'!K81+'Controle Central'!R81+'Controle Central'!D99+'Controle Central'!K99+'Controle Central'!R99+'Controle Central'!Y99+'Controle Central'!D117+'Controle Central'!K117+'Controle Central'!R117+'Controle Central'!Y117+'Controle Central'!D135+'Controle Central'!K135) -> 4181.93 | D6: =SUM('Controle Central'!D6+'Controle Central'!K6+'Controle Central'!R6+'Controle Central'!Y6+'Controle Central'!D25+'Controle Central'!K25+'Controle Central'!R25+'Controle Central'!Y25+'Controle Central'!D44+'Controle Central'!K44+'Controle Central'!R44+'Controle Central'!Y44+'Controle Central'!D63+'Controle Central'!K63+'Controle Central'!R63+'Controle Central'!Y63+'Controle Central'!D82+'Controle Central'!K82+'Controle Central'!R82+'Controle Central'!Y82+'Controle Central'!D100+'Controle Central'!K100+'Controle Central'!R100+'Controle Central'!Y100+'Controle Central'!D118+'Controle Central'!K118+'Controle Central'!R118+'Controle Central'!Y118+'Controle Central'!D136+'Controle Central'!K136) -> 4045.79 | E6: ='Controle Central'!D7+'Controle Central'!K7+'Controle Central'!R7+'Controle Central'!Y7+'Controle Central'!D26+'Controle Central'!K26+'Controle Central'!R26+'Controle Central'!Y26+'Controle Central'!D45+'Controle Central'!K45+'Controle Central'!R45+'Controle Central'!Y45+'Controle Central'!D64+'Controle Central'!K64+'Controle Central'!R64+'Controle Central'!D83+'Controle Central'!K83+'Controle Central'!R83+'Controle Central'!Y83+'Controle Central'!D101+'Controle Central'!K101+'Controle Central'!R101+'Controle Central'!Y101+'Controle Central'!D119+'Controle Central'!K119+'Controle Central'!R119+'Controle Central'!Y119+'Controle Central'!D137+'Controle Central'!K137 -> 2208.94 | F6: =SUM('Controle Central'!D8+'Controle Central'!K8+'Controle Central'!R8+'Controle Central'!Y8+'Controle Central'!D27+'Controle Central'!K27+'Controle Central'!R27+'Controle Central'!Y27+'Controle Central'!D46+'Controle Central'!K46+'Controle Central'!R46+'Controle Central'!Y46+'Controle Central'!D65+'Controle Central'!K65+'Controle Central'!R65+'Controle Central'!Y65+'Controle Central'!D84+'Controle Central'!K84+'Controle Central'!R84+'Controle Central'!Y84+'Controle Central'!D102+'Controle Central'!K102+'Controle Central'!R102+'Controle Central'!Y102+'Controle Central'!D120+'Controle Central'!K120+'Controle Central'!R120+'Controle Central'!Y120+'Controle Central'!D138+'Controle Central'!K138) -> 2104.71 | G6: =SUM('Controle Central'!D9+'Controle Central'!K9+'Controle Central'!R9+'Controle Central'!Y9+'Controle Central'!D28+'Controle Central'!K28+'Controle Central'!R28+'Controle Central'!Y28+'Controle Central'!D47+'Controle Central'!K47+'Controle Central'!R47+'Controle Central'!Y47+'Controle Central'!D66+'Controle Central'!K66+'Controle Central'!R66+'Controle Central'!Y66+'Controle Central'!D85+'Controle Central'!K85+'Controle Central'!R85+'Controle Central'!Y85+'Controle Central'!D103+'Controle Central'!K103+'Controle Central'!R103+'Controle Central'!Y103+'Controle Central'!D121+'Controle Central'!K121+'Controle Central'!R121+'Controle Central'!Y121+'Controle Central'!D139+'Controle Central'!K139) -> 2237.94 | H6: =SUM('Controle Central'!D10+'Controle Central'!K10+'Controle Central'!R10+'Controle Central'!Y10+'Controle Central'!D29+'Controle Central'!K29+'Controle Central'!R29+'Controle Central'!D48+'Controle Central'!K48+'Controle Central'!R48+'Controle Central'!Y48+'Controle Central'!D67+'Controle Central'!K67+'Controle Central'!R67+'Controle Central'!Y67+'Controle Central'!D86+'Controle Central'!K86+'Controle Central'!R86+'Controle Central'!Y86+'Controle Central'!D104+'Controle Central'!K104+'Controle Central'!R104+'Controle Central'!Y104+'Controle Central'!D122+'Controle Central'!K122+'Controle Central'!R122+'Controle Central'!Y122+'Controle Central'!D140+'Controle Central'!K140) -> 3314.66 | I6: =SUM('Controle Central'!D11+'Controle Central'!K11+'Controle Central'!R11+'Controle Central'!Y11+'Controle Central'!D30+'Controle Central'!K30+'Controle Central'!R30+'Controle Central'!Y30+'Controle Central'!D49+'Controle Central'!K49+'Controle Central'!R49+'Controle Central'!Y49+'Controle Central'!D68+'Controle Central'!K68+'Controle Central'!R68+'Controle Central'!Y68+'Controle Central'!D87+'Controle Central'!K87+'Controle Central'!R87+'Controle Central'!Y87+'Controle Central'!D105+'Controle Central'!K105+'Controle Central'!R105+'Controle Central'!Y105+'Controle Central'!D123+'Controle Central'!K123+'Controle Central'!R123+'Controle Central'!Y123+'Controle Central'!D141+'Controle Central'!K141) -> 2693.66 | J6: =SUM('Controle Central'!D12+'Controle Central'!K12+'Controle Central'!R12+'Controle Central'!Y12+'Controle Central'!D31+'Controle Central'!K31+'Controle Central'!R31+'Controle Central'!Y31+'Controle Central'!D50+'Controle Central'!K50+'Controle Central'!R50+'Controle Central'!Y50+'Controle Central'!D69+'Controle Central'!K69+'Controle Central'!R69+'Controle Central'!Y69+'Controle Central'!D88+'Controle Central'!K88+'Controle Central'!R88+'Controle Central'!Y88+'Controle Central'!D106+'Controle Central'!K106+'Controle Central'!R106+'Controle Central'!Y106+'Controle Central'!D124+'Controle Central'!K124+'Controle Central'!R124+'Controle Central'!Y124+'Controle Central'!D142+'Controle Central'!K142) -> 2720.56 | K6: =SUM('Controle Central'!D13+'Controle Central'!K13+'Controle Central'!R13+'Controle Central'!Y13+'Controle Central'!D32+'Controle Central'!K32+'Controle Central'!R32+'Controle Central'!Y32+'Controle Central'!D51+'Controle Central'!K51+'Controle Central'!R51+'Controle Central'!Y51+'Controle Central'!D70+'Controle Central'!K70+'Controle Central'!R70+'Controle Central'!Y70+'Controle Central'!D89+'Controle Central'!K89+'Controle Central'!R89+'Controle Central'!Y89+'Controle Central'!D107+'Controle Central'!K107+'Controle Central'!R107+'Controle Central'!Y107+'Controle Central'!D125+'Controle Central'!K125+'Controle Central'!R125+'Controle Central'!Y125+'Controle Central'!D143+'Controle Central'!K143) -> 2087.61 | L6: =SUM('Controle Central'!D14+'Controle Central'!K14+'Controle Central'!R14+'Controle Central'!Y14+'Controle Central'!D33+'Controle Central'!K33+'Controle Central'!R33+'Controle Central'!Y33+'Controle Central'!D52+'Controle Central'!K52+'Controle Central'!R52+'Controle Central'!Y52+'Controle Central'!D71+'Controle Central'!K71+'Controle Central'!R71+'Controle Central'!Y71+'Controle Central'!D90+'Controle Central'!K90+'Controle Central'!R90+'Controle Central'!Y90+'Controle Central'!D108+'Controle Central'!K108+'Controle Central'!R108+'Controle Central'!Y108+'Controle Central'!D126+'Controle Central'!K126+'Controle Central'!R126+'Controle Central'!Y126+'Controle Central'!D144+'Controle Central'!K144) -> 2469.71 | M6: =SUM('Controle Central'!D15+'Controle Central'!K15+'Controle Central'!R15+'Controle Central'!Y15+'Controle Central'!D34+'Controle Central'!K34+'Controle Central'!R34+'Controle Central'!Y34+'Controle Central'!D53+'Controle Central'!K53+'Controle Central'!R53+'Controle Central'!Y53+'Controle Central'!D72+'Controle Central'!K72+'Controle Central'!R72+'Controle Central'!Y72+'Controle Central'!D91+'Controle Central'!K91+'Controle Central'!R91+'Controle Central'!Y91+'Controle Central'!D109+'Controle Central'!K109+'Controle Central'!R109+'Controle Central'!Y109+'Controle Central'!D127+'Controle Central'!K127+'Controle Central'!R127+'Controle Central'!Y127+'Controle Central'!D145+'Controle Central'!K145) -> 2665.21
A8: LAVA_RAPIDO | B8: =SUM('Controle Central'!E4+'Controle Central'!L4+'Controle Central'!S4+'Controle Central'!Z4+'Controle Central'!E23+'Controle Central'!L23+'Controle Central'!S23+'Controle Central'!Z23+'Controle Central'!E42+'Controle Central'!L42+'Controle Central'!S42+'Controle Central'!Z42+'Controle Central'!E61+'Controle Central'!L61+'Controle Central'!S61+'Controle Central'!Z61+'Controle Central'!E80+'Controle Central'!L80+'Controle Central'!S80+'Controle Central'!Z80+'Controle Central'!E98+'Controle Central'!L98+'Controle Central'!S98+'Controle Central'!Z98+'Controle Central'!E116+'Controle Central'!L116+'Controle Central'!S116+'Controle Central'!Z116+'Controle Central'!E134+'Controle Central'!L134) -> 0 | C8: =SUM('Controle Central'!E5,'Controle Central'!L5,'Controle Central'!S5,'Controle Central'!Z5,'Controle Central'!E24,'Controle Central'!L24,'Controle Central'!S24,'Controle Central'!Z24,'Controle Central'!E43,'Controle Central'!L43,'Controle Central'!S43,'Controle Central'!Z43,'Controle Central'!E62,'Controle Central'!L62,'Controle Central'!S62,'Controle Central'!Z62,'Controle Central'!E81,'Controle Central'!L81,'Controle Central'!S81,'Controle Central'!Z81,'Controle Central'!E99,'Controle Central'!L99,'Controle Central'!S99,'Controle Central'!Z99,'Controle Central'!E117,'Controle Central'!L117,'Controle Central'!S117,'Controle Central'!Z117,'Controle Central'!E135,'Controle Central'!L135) -> 60 | D8: =SUM('Controle Central'!E6,'Controle Central'!L6,'Controle Central'!S6,'Controle Central'!Z6,'Controle Central'!E25,'Controle Central'!L25,'Controle Central'!S25,'Controle Central'!Z25,'Controle Central'!E44,'Controle Central'!L44,'Controle Central'!S44,'Controle Central'!Z44,'Controle Central'!E63,'Controle Central'!L63,'Controle Central'!S63,'Controle Central'!Z63,'Controle Central'!E82,'Controle Central'!L82,'Controle Central'!S82,'Controle Central'!Z82,'Controle Central'!E100,'Controle Central'!L100,'Controle Central'!S100,'Controle Central'!Z100,'Controle Central'!E118,'Controle Central'!L118,'Controle Central'!S118,'Controle Central'!Z118,'Controle Central'!E136,'Controle Central'!L136) -> 460 | E8: =SUM('Controle Central'!E7,'Controle Central'!L7,'Controle Central'!S7,'Controle Central'!Z7,'Controle Central'!E26,'Controle Central'!L26,'Controle Central'!S26,'Controle Central'!Z26,'Controle Central'!E45,'Controle Central'!L45,'Controle Central'!S45,'Controle Central'!Z45,'Controle Central'!E64,'Controle Central'!L64,'Controle Central'!S64,'Controle Central'!Z64,'Controle Central'!E83,'Controle Central'!L83,'Controle Central'!S83,'Controle Central'!Z83,'Controle Central'!E101,'Controle Central'!L101,'Controle Central'!S101,'Controle Central'!Z101,'Controle Central'!E119,'Controle Central'!L119,'Controle Central'!S119,'Controle Central'!Z119,'Controle Central'!E137,'Controle Central'!L137) -> 0 | F8: =SUM('Controle Central'!E8,'Controle Central'!L8,'Controle Central'!S8,'Controle Central'!Z8,'Controle Central'!E27,'Controle Central'!L27,'Controle Central'!S27,'Controle Central'!Z27,'Controle Central'!E46,'Controle Central'!L46,'Controle Central'!S46,'Controle Central'!Z46,'Controle Central'!E65,'Controle Central'!L65,'Controle Central'!S65,'Controle Central'!Z65,'Controle Central'!E84,'Controle Central'!L84,'Controle Central'!S84,'Controle Central'!Z84,'Controle Central'!E102,'Controle Central'!L102,'Controle Central'!S102,'Controle Central'!Z102,'Controle Central'!E120,'Controle Central'!L120,'Controle Central'!S120,'Controle Central'!Z120,'Controle Central'!E138,'Controle Central'!L138) -> 0 | G8: =SUM('Controle Central'!E9,'Controle Central'!L9,'Controle Central'!S9,'Controle Central'!Z9,'Controle Central'!E28,'Controle Central'!L28,'Controle Central'!S28,'Controle Central'!Z28,'Controle Central'!E47,'Controle Central'!L47,'Controle Central'!S47,'Controle Central'!Z47,'Controle Central'!E66,'Controle Central'!L66,'Controle Central'!S66,'Controle Central'!Z66,'Controle Central'!E85,'Controle Central'!L85,'Controle Central'!S85,'Controle Central'!Z85,'Controle Central'!E103,'Controle Central'!L103,'Controle Central'!S103,'Controle Central'!Z103,'Controle Central'!E121,'Controle Central'!L121,'Controle Central'!S121,'Controle Central'!Z121,'Controle Central'!E139+'Controle Central'!L139) -> 0 | H8: =SUM('Controle Central'!E10,'Controle Central'!L10,'Controle Central'!S10,'Controle Central'!Z10,'Controle Central'!E29,'Controle Central'!L29,'Controle Central'!S29,'Controle Central'!Z29,'Controle Central'!E48,'Controle Central'!L48,'Controle Central'!S48,'Controle Central'!Z48,'Controle Central'!E67,'Controle Central'!L67,'Controle Central'!S67,'Controle Central'!Z67,'Controle Central'!E86,'Controle Central'!L86,'Controle Central'!S86,'Controle Central'!Z86,'Controle Central'!E104,'Controle Central'!L104,'Controle Central'!S104,'Controle Central'!Z104,'Controle Central'!E122,'Controle Central'!L122,'Controle Central'!S122,'Controle Central'!Z122,'Controle Central'!E140,'Controle Central'!L140) -> 0 | I8: =SUM('Controle Central'!L11,'Controle Central'!S11,'Controle Central'!E11,'Controle Central'!Z11,'Controle Central'!Z30,'Controle Central'!S30,'Controle Central'!L30,'Controle Central'!E30,'Controle Central'!E49,'Controle Central'!L49,'Controle Central'!S49,'Controle Central'!Z49,'Controle Central'!Z68,'Controle Central'!S68,'Controle Central'!L68,'Controle Central'!E68,'Controle Central'!E87,'Controle Central'!L87,'Controle Central'!S87,'Controle Central'!Z87,'Controle Central'!Z105,'Controle Central'!Z123,'Controle Central'!S105,'Controle Central'!S123,'Controle Central'!L123,'Controle Central'!L105,'Controle Central'!E123,'Controle Central'!E105,'Controle Central'!E141,'Controle Central'!L141) -> 0 | J8: =SUM('Controle Central'!E12,'Controle Central'!E31,'Controle Central'!L12,'Controle Central'!L31,'Controle Central'!S12,'Controle Central'!S31,'Controle Central'!Z12,'Controle Central'!Z31,'Controle Central'!Z50,'Controle Central'!Z69,'Controle Central'!S50,'Controle Central'!S69,'Controle Central'!L50,'Controle Central'!L69,'Controle Central'!E50,'Controle Central'!E69,'Controle Central'!E88,'Controle Central'!E106,'Controle Central'!L88,'Controle Central'!L106,'Controle Central'!S88,'Controle Central'!S106,'Controle Central'!Z88,'Controle Central'!Z106,'Controle Central'!Z124,'Controle Central'!S124,'Controle Central'!L124,'Controle Central'!E124,'Controle Central'!E142,'Controle Central'!L142) -> 0 | K8: =SUM('Controle Central'!E13,'Controle Central'!L13,'Controle Central'!E32,'Controle Central'!L32,'Controle Central'!S13,'Controle Central'!S32,'Controle Central'!Z13,'Controle Central'!Z32,'Controle Central'!Z51,'Controle Central'!Z70,'Controle Central'!S51,'Controle Central'!S70,'Controle Central'!L51,'Controle Central'!L70,'Controle Central'!E51,'Controle Central'!E70,'Controle Central'!E89,'Controle Central'!E107,'Controle Central'!L89,'Controle Central'!L107,'Controle Central'!S89,'Controle Central'!S107,'Controle Central'!Z107,'Controle Central'!Z89,'Controle Central'!Z125,'Controle Central'!S125,'Controle Central'!L143,'Controle Central'!L125,'Controle Central'!E125,'Controle Central'!E143) -> 0 | L8: =SUM('Controle Central'!E14,'Controle Central'!E33,'Controle Central'!L14,'Controle Central'!L33,'Controle Central'!S14,'Controle Central'!S33,'Controle Central'!Z14,'Controle Central'!Z33,'Controle Central'!Z52,'Controle Central'!Z71,'Controle Central'!S52,'Controle Central'!S71,'Controle Central'!L52,'Controle Central'!L71,'Controle Central'!E52,'Controle Central'!E71,'Controle Central'!E90,'Controle Central'!E108,'Controle Central'!L90,'Controle Central'!L108,'Controle Central'!S90,'Controle Central'!S108,'Controle Central'!Z90,'Controle Central'!Z108,'Controle Central'!Z126,'Controle Central'!S126,'Controle Central'!L126,'Controle Central'!L144,'Controle Central'!E126,'Controle Central'!E144) -> 0 | M8: =SUM('Controle Central'!E15,'Controle Central'!E34,'Controle Central'!L15,'Controle Central'!L34,'Controle Central'!S15,'Controle Central'!S34,'Controle Central'!Z15,'Controle Central'!Z34,'Controle Central'!Z53,'Controle Central'!Z72,'Controle Central'!S53,'Controle Central'!S72,'Controle Central'!L53,'Controle Central'!L72,'Controle Central'!E53,'Controle Central'!E72,'Controle Central'!E91,'Controle Central'!E109,'Controle Central'!L91,'Controle Central'!L109,'Controle Central'!S91,'Controle Central'!S109,'Controle Central'!Z91,'Controle Central'!Z109,'Controle Central'!Z127,'Controle Central'!S127,'Controle Central'!L127,'Controle Central'!E127,'Controle Central'!E145,'Controle Central'!L145) -> 0
A10: BORRACHARIA | B10: =SUM('Controle Central'!F4,'Controle Central'!M4,'Controle Central'!M23,'Controle Central'!F23,'Controle Central'!T4,'Controle Central'!T23,'Controle Central'!AA4,'Controle Central'!AA23,'Controle Central'!AA61,'Controle Central'!AA42,'Controle Central'!T42,'Controle Central'!M42,'Controle Central'!M61,'Controle Central'!F61,'Controle Central'!F42,'Controle Central'!F98,'Controle Central'!F80,'Controle Central'!M80,'Controle Central'!M98,'Controle Central'!T80,'Controle Central'!T98,'Controle Central'!AA80,'Controle Central'!AA98,'Controle Central'!AA116,'Controle Central'!T116,'Controle Central'!M116,'Controle Central'!F116,'Controle Central'!F134,'Controle Central'!M134) -> 0 | C10: =SUM('Controle Central'!F5,'Controle Central'!F24,'Controle Central'!M5,'Controle Central'!M24,'Controle Central'!T24,'Controle Central'!T5,'Controle Central'!AA5,'Controle Central'!AA24,'Controle Central'!AA43,'Controle Central'!AA62,'Controle Central'!T43,'Controle Central'!T62,'Controle Central'!M43,'Controle Central'!M62,'Controle Central'!F43,'Controle Central'!F62,'Controle Central'!F81,'Controle Central'!F99,'Controle Central'!M99,'Controle Central'!M81,'Controle Central'!T99,'Controle Central'!T81,'Controle Central'!AA81,'Controle Central'!AA99,'Controle Central'!AA117,'Controle Central'!T117,'Controle Central'!M117,'Controle Central'!F117,'Controle Central'!F135,'Controle Central'!M135) -> 0 | D10: =SUM('Controle Central'!F6,'Controle Central'!F25,'Controle Central'!M6,'Controle Central'!M25,'Controle Central'!T6,'Controle Central'!T25,'Controle Central'!AA25,'Controle Central'!AA6,'Controle Central'!AA44,'Controle Central'!AA63,'Controle Central'!T63,'Controle Central'!T44,'Controle Central'!M44,'Controle Central'!M63,'Controle Central'!F63,'Controle Central'!F44,'Controle Central'!F82,'Controle Central'!F100,'Controle Central'!M100,'Controle Central'!M82,'Controle Central'!T82,'Controle Central'!T100,'Controle Central'!AA100,'Controle Central'!AA82,'Controle Central'!AA118,'Controle Central'!T118,'Controle Central'!M118,'Controle Central'!M136,'Controle Central'!F118,'Controle Central'!F136) -> 0 | E10: =SUM('Controle Central'!F7,'Controle Central'!F26,'Controle Central'!M26,'Controle Central'!M7,'Controle Central'!T7,'Controle Central'!T26,'Controle Central'!AA7,'Controle Central'!AA26,'Controle Central'!AA45,'Controle Central'!T45,'Controle Central'!AA64,'Controle Central'!T64,'Controle Central'!M45,'Controle Central'!M64,'Controle Central'!F45,'Controle Central'!F64,'Controle Central'!F83,'Controle Central'!F101,'Controle Central'!M83,'Controle Central'!M101,'Controle Central'!T83,'Controle Central'!T101,'Controle Central'!AA83,'Controle Central'!AA101,'Controle Central'!AA119,'Controle Central'!T119,'Controle Central'!M119,'Controle Central'!M137,'Controle Central'!F137,'Controle Central'!F119) -> 0 | F10: =SUM('Controle Central'!F8,'Controle Central'!F27,'Controle Central'!M8,'Controle Central'!M27,'Controle Central'!T8,'Controle Central'!T27,'Controle Central'!AA27,'Controle Central'!AA8,'Controle Central'!AA46,'Controle Central'!AA65,'Controle Central'!T46,'Controle Central'!T65,'Controle Central'!M65,'Controle Central'!M46,'Controle Central'!F46,'Controle Central'!F65,'Controle Central'!F84,'Controle Central'!F102,'Controle Central'!M84,'Controle Central'!M102,'Controle Central'!T84,'Controle Central'!T102,'Controle Central'!AA84,'Controle Central'!AA102,'Controle Central'!AA120,'Controle Central'!T120,'Controle Central'!M120,'Controle Central'!M138,'Controle Central'!F120,'Controle Central'!F138) -> 0 | G10: =SUM('Controle Central'!F9,'Controle Central'!F28,'Controle Central'!M9,'Controle Central'!M28,'Controle Central'!T9,'Controle Central'!T28,'Controle Central'!AA9,'Controle Central'!AA28,'Controle Central'!AA47,'Controle Central'!AA66,'Controle Central'!T47,'Controle Central'!T66,'Controle Central'!M47,'Controle Central'!M66,'Controle Central'!F47,'Controle Central'!F66,'Controle Central'!F85,'Controle Central'!F103,'Controle Central'!M85,'Controle Central'!M103,'Controle Central'!T85,'Controle Central'!T103,'Controle Central'!AA85,'Controle Central'!AA103,'Controle Central'!AA121,'Controle Central'!T121,'Controle Central'!M121,'Controle Central'!M139,'Controle Central'!F139) -> 0 | H10: =SUM('Controle Central'!F10,'Controle Central'!F29,'Controle Central'!M10,'Controle Central'!M29,'Controle Central'!T10,'Controle Central'!T29,'Controle Central'!AA10,'Controle Central'!AA29,'Controle Central'!AA48,'Controle Central'!T48,'Controle Central'!AA67,'Controle Central'!T67,'Controle Central'!M48,'Controle Central'!M67,'Controle Central'!F48,'Controle Central'!F67,'Controle Central'!F86,'Controle Central'!F104,'Controle Central'!M104,'Controle Central'!M86,'Controle Central'!T86,'Controle Central'!T104,'Controle Central'!AA86,'Controle Central'!AA104,'Controle Central'!AA122,'Controle Central'!T122,'Controle Central'!M122,'Controle Central'!M140,'Controle Central'!F122,'Controle Central'!F140) -> 0 | I10: =SUM('Controle Central'!F11,'Controle Central'!F30,'Controle Central'!M11,'Controle Central'!M30,'Controle Central'!T11,'Controle Central'!T30,'Controle Central'!AA11,'Controle Central'!AA30,'Controle Central'!AA49,'Controle Central'!AA68,'Controle Central'!T49,'Controle Central'!T68,'Controle Central'!M49,'Controle Central'!M68,'Controle Central'!F68,'Controle Central'!F49,'Controle Central'!F87,'Controle Central'!F105,'Controle Central'!M87,'Controle Central'!M105,'Controle Central'!T87,'Controle Central'!T105,'Controle Central'!AA87,'Controle Central'!AA105,'Controle Central'!AA123,'Controle Central'!T123,'Controle Central'!M123,'Controle Central'!M141,'Controle Central'!F123,'Controle Central'!F141) -> 0 | J10: =SUM('Controle Central'!F12,'Controle Central'!F31,'Controle Central'!M12,'Controle Central'!M31,'Controle Central'!T12,'Controle Central'!T31,'Controle Central'!AA12,'Controle Central'!AA31,'Controle Central'!AA50,'Controle Central'!T50,'Controle Central'!T69,'Controle Central'!AA69,'Controle Central'!M50,'Controle Central'!M69,'Controle Central'!F69,'Controle Central'!F50,'Controle Central'!F88,'Controle Central'!F106,'Controle Central'!M88,'Controle Central'!M106,'Controle Central'!T88,'Controle Central'!T106,'Controle Central'!AA88,'Controle Central'!AA106,'Controle Central'!AA124,'Controle Central'!T124,'Controle Central'!M124,'Controle Central'!F124,'Controle Central'!F142,'Controle Central'!M142) -> 0 | K10: =SUM('Controle Central'!F13,'Controle Central'!F32,'Controle Central'!M13,'Controle Central'!M32,'Controle Central'!T13,'Controle Central'!T32,'Controle Central'!AA13,'Controle Central'!AA32,'Controle Central'!AA51,'Controle Central'!T51,'Controle Central'!T70,'Controle Central'!AA70,'Controle Central'!M51,'Controle Central'!M70,'Controle Central'!F70,'Controle Central'!F51,'Controle Central'!F89,'Controle Central'!F107,'Controle Central'!M89,'Controle Central'!M107,'Controle Central'!T89,'Controle Central'!T107,'Controle Central'!AA107,'Controle Central'!AA89,'Controle Central'!AA125,'Controle Central'!T125,'Controle Central'!M125,'Controle Central'!F125,'Controle Central'!F143,'Controle Central'!M143) -> 0 | L10: =SUM('Controle Central'!F14,'Controle Central'!M14,'Controle Central'!F33,'Controle Central'!M33,'Controle Central'!T14,'Controle Central'!T33,'Controle Central'!AA33,'Controle Central'!AA14,'Controle Central'!AA52,'Controle Central'!T52,'Controle Central'!M52,'Controle Central'!M71,'Controle Central'!T71,'Controle Central'!AA71,'Controle Central'!AA90,'Controle Central'!T90,'Controle Central'!M90,'Controle Central'!F90,'Controle Central'!F108,'Controle Central'!F126,'Controle Central'!M108,'Controle Central'!M126,'Controle Central'!T108,'Controle Central'!T126,'Controle Central'!AA108,'Controle Central'!AA126,'Controle Central'!M144,'Controle Central'!F144) -> 0 | M10: =SUM('Controle Central'!F15,'Controle Central'!F34,'Controle Central'!M15,'Controle Central'!M34,'Controle Central'!T15,'Controle Central'!T34,'Controle Central'!AA15,'Controle Central'!AA34,'Controle Central'!AA53,'Controle Central'!T53,'Controle Central'!AA72,'Controle Central'!T72,'Controle Central'!M53,'Controle Central'!F53,'Controle Central'!F72,'Controle Central'!M72,'Controle Central'!F91,'Controle Central'!F109,'Controle Central'!M91,'Controle Central'!M109,'Controle Central'!T91,'Controle Central'!T109,'Controle Central'!AA91,'Controle Central'!AA109,'Controle Central'!AA127,'Controle Central'!T127,'Controle Central'!M127,'Controle Central'!M145,'Controle Central'!F127,'Controle Central'!F145) -> 0
B14: JAN | C14: FEV | D14: MAR | E14: ABR | F14: MAI | G14: JUN | H14: JUL | I14: AGO | J14: SET | K14: OUT | L14: NOV | M14: DEZ
A15: Medição
A17: Contrato de Locação
A19: Lucro Car's | B19: =B15-B17 -> 0 | C19: =C15-C17 -> 0 | D19: =D15-D17 -> 0 | E19: =E15-E17 -> 0 | F19: =F15-F17 -> 0 | G19: =G15-G17 -> 0 | H19: =H15-H17 -> 0 | I19: =I15-I17 -> 0 | ... M19: =M15-M17 -> 0

Sheet Controle Central
B2: CAR_01 | I2: CAR_02 | P2: CAR_03 | W2: CAR_04
B3: KM RODADO | C3: KM MENSAL | D3: ABASTECIMENTO | E3: LAVA_RAPIDO | F3: BORRACHARIA | I3: KM RODADO | J3: KM MENSAL | K3: ABASTECIMENTO | L3: LAVA_RAPIDO | M3: BORRACHARIA | P3: KM RODADO | Q3: KM MENSAL | R3: ABASTECIMENTO | S3: LAVA_RAPIDO | T3: BORRACHARIA | W3: KM RODADO | X3: KM MENSAL | Y3: ABASTECIMENTO | Z3: LAVA_RAPIDO | AA3: BORRACHARIA
A4: JAN | C4: 0 | D4: 0 | E4: 0 | F4: 0 | H4: JAN | J4: 0 | K4: 0 | L4: 0 | M4: 0 | O4: JAN | Q4: 0 | R4: 0 | S4: 0 | T4: 0 | V4: JAN | X4: 0 | Y4: 0 | Z4: 0 | AA4: 0
A5: FEV | B5: ='Ualace-Desmob'!H13 -> 0 | C5: =SUM(5000-B5) -> 5000 | D5: ='Ualace-Desmob'!U14 -> 0 | E5: ='Ualace-Desmob'!AC14 -> 0 | F5: ='Ualace-Desmob'!AK14 -> 0 | H5: FEV | I5: ='André Plácido-Desmob'!H16 -> 1828 | J5: =SUM(5000-I5) -> 3172 | K5: ='André Plácido-Desmob'!U17 -> 962.7 | L5: ='André Plácido-Desmob'!AC17 -> 60 | M5: ='André Plácido-Desmob'!AK17 -> 0 | O5: FEV | P5: ='Wendel Matias-Desmob'!H14 -> 1843 | Q5: =SUM(5000-P5) -> 3157 | R5: ='Wendel Matias-Desmob'!U15 -> 1156.78 | S5: ='Wendel Matias-Desmob'!AI15 -> 0 | T5: ='Wendel Matias-Desmob'!AR15 -> 0 | V5: FEV | W5: ='Ednei-Desmob'!H14 -> 1588 | X5: =SUM(5000-W5) -> 3412 | Y5: ='Ednei-Desmob'!U15 -> 1154.69 | Z5: ='Ednei-Desmob'!AI15 -> 0 | AA5: ='Ednei-Desmob'!AR15 -> 0
A6: MAR | B6: ='Ualace-Desmob'!H17 -> 0 | C6: =SUM(5000-B6) -> 5000 | D6: ='Ualace-Desmob'!U18 -> 0 | E6: ='Ualace-Desmob'!AC18 -> 0 | F6: ='Ualace-Desmob'!AK18 -> 0 | H6: MAR | I6: ='André Plácido-Desmob'!H20 -> 1857 | J6: =SUM(5000-I6) -> 3143 | K6: ='André Plácido-Desmob'!U21 -> 792.09 | L6: ='André Plácido-Desmob'!AC21 -> 240 | M6: ='André Plácido-Desmob'!AK21 -> 0 | O6: MAR | P6: ='Wendel Matias-Desmob'!H18 -> 1069 | Q6: =SUM(5000-P6) -> 3931 | R6: ='Wendel Matias-Desmob'!U19 -> 816.11 | S6: ='Wendel Matias-Desmob'!AI19 -> 0 | T6: ='Wendel Matias-Desmob'!AR19 -> 0 | V6: MAR | W6: ='Ednei-Desmob'!H18 -> 925 | X6: =SUM(5000-W6) -> 4075 | Y6: ='Ednei-Desmob'!U19 -> 644.32 | Z6: ='Ednei-Desmob'!AI19 -> 0 | AA6: ='Ednei-Desmob'!AR19 -> 0
A7: ABR | B7: ='Ualace-Desmob'!H21 -> 0 | C7: =SUM(5000-B7) -> 5000 | D7: ='Ualace-Desmob'!U22 -> 0 | E7: ='Ualace-Desmob'!AC22 -> 0 | F7: ='Ualace-Desmob'!AK22 -> 0 | H7: ABR | I7: ='André Plácido-Desmob'!H24 -> 257 | J7: =SUM(5000-I7) -> 4743 | K7: ='André Plácido-Desmob'!U25 -> 0 | L7: ='André Plácido-Desmob'!AC25 -> 0 | M7: ='André Plácido-Desmob'!AK25 -> 0 | O7: ABR | P7: ='Wendel Matias-Desmob'!H22 -> 1649 | Q7: =SUM(5000-P7) -> 3351 | R7: ='Wendel Matias-Desmob'!Z23 -> 0 | S7: ='Wendel Matias-Desmob'!AI23 -> 0 | T7: ='Wendel Matias-Desmob'!AR23 -> 0 | V7: ABR | W7: ='Ednei-Desmob'!H22 -> 1461 | X7: =SUM(5000-W7) -> 3539 | Y7: ='Ednei-Desmob'!Z23 -> 0 | Z7: ='Ednei-Desmob'!AI23 -> 0 | AA7: ='Ednei-Desmob'!AR23 -> 0
A8: MAI | B8: ='Ualace-Desmob'!H25 -> 0 | C8: =SUM(5000-B8) -> 5000 | D8: ='Ualace-Desmob'!U26 -> 0 | E8: ='Ualace-Desmob'!AC26 -> 0 | F8: ='Ualace-Desmob'!AK26 -> 0 | H8: MAI | I8: ='André Plácido-Desmob'!H28 -> 2297 | J8: =SUM(5000-I8) -> 2703 | K8: ='André Plácido-Desmob'!U29 -> 0 | L8: ='André Plácido-Desmob'!AC29 -> 0 | M8: ='André Plácido-Desmob'!AK29 -> 0 | O8: MAI | P8: ='Wendel Matias-Desmob'!H26 -> 876 | Q8: =SUM(5000-P8) -> 4124 | R8: ='Wendel Matias-Desmob'!Z27 -> 0 | S8: ='Wendel Matias-Desmob'!AI27 -> 0 | T8: ='Wendel Matias-Desmob'!AR27 -> 0 | V8: MAI | W8: ='Ednei-Desmob'!H26 -> 1515 | X8: =SUM(5000-W8) -> 3485 | Y8: ='Ednei-Desmob'!Z27 -> 0 | Z8: ='Ednei-Desmob'!AI27 -> 0 | AA8: ='Ednei-Desmob'!AR27 -> 0
A9: JUN | B9: ='Ualace-Desmob'!H29 -> 0 | C9: =SUM(5000-B9) -> 5000 | D9: ='Ualace-Desmob'!U30 -> 0 | E9: ='Ualace-Desmob'!AC30 -> 0 | F9: ='Ualace-Desmob'!AK30 -> 0 | H9: JUN | I9: ='André Plácido-Desmob'!H32 -> 1355 | J9: =SUM(5000-I9) -> 3645 | K9: ='André Plácido-Desmob'!U33 -> 407.55 | L9: ='André Plácido-Desmob'!AC33 -> 0 | M9: ='Ualace-Desmob'!AK30 -> 0 | O9: JUN | P9: ='Wendel Matias-Desmob'!H30 -> 1648 | Q9: =SUM(5000-P9) -> 3352 | R9: ='Wendel Matias-Desmob'!Z31 -> 0 | S9: ='Wendel Matias-Desmob'!AI31 -> 0 | T9: ='Wendel Matias-Desmob'!AR31 -> 0 | V9: JUN | W9: ='Ednei-Desmob'!H30 -> 1696 | X9: =SUM(5000-W9) -> 3304 | Y9: ='Ednei-Desmob'!Z31 -> 0 | Z9: ='Ednei-Desmob'!AI31 -> 0 | AA9: ='Ednei-Desmob'!AR31 -> 0
A10: JUL | B10: ='Ualace-Desmob'!H33 -> 0 | C10: =SUM(5000-B10) -> 5000 | D10: ='Ualace-Desmob'!U34 -> 0 | E10: ='Ualace-Desmob'!AC34 -> 0 | F10: ='Ualace-Desmob'!AK34 -> 0 | H10: JUL | I10: ='André Plácido-Desmob'!H36 -> 1498 | J10: =SUM(5000-I10) -> 3502 | K10: ='André Plácido-Desmob'!U37 -> 859.81 | L10: ='André Plácido-Desmob'!AC37 -> 0 | M10: ='André Plácido-Desmob'!AK37 -> 0 | O10: JUL | P10: ='Wendel Matias-Desmob'!H34 -> 1821 | Q10: =SUM(5000-P10) -> 3179 | R10: ='Wendel Matias-Desmob'!Z35 -> 0 | S10: ='Wendel Matias-Desmob'!AI35 -> 0 | T10: ='Wendel Matias-Desmob'!AR35 -> 0 | V10: JUL | W10: ='Ednei-Desmob'!H34 -> 1816 | X10: =SUM(5000-W10) -> 3184 | Y10: ='Ednei-Desmob'!Z35 -> 0 | Z10: ='Ednei-Desmob'!AI35 -> 0 | AA10: ='Ednei-Desmob'!AR35 -> 0
A11: AGO | B11: ='Ualace-Desmob'!H37 -> 0 | C11: =SUM(5000-B11) -> 5000 | D11: ='Ualace-Desmob'!U38 -> 0 | E11: ='Ualace-Desmob'!AC38 -> 0 | F11: ='Ualace-Desmob'!AK38 -> 0 | H11: AGO | I11: ='André Plácido-Desmob'!H40 -> 1090 | J11: =SUM(5000-I11) -> 3910 | K11: ='André Plácido-Desmob'!U41 -> 966.28 | L11: ='André Plácido-Desmob'!AC41 -> 0 | M11: ='André Plácido-Desmob'!AK41 -> 0 | O11: AGO | P11: ='Wendel Matias-Desmob'!H38 -> 964 | Q11: =SUM(5000-P11) -> 4036 | R11: ='Wendel Matias-Desmob'!Z39 -> 0 | S11: ='Wendel Matias-Desmob'!AI39 -> 0 | T11: ='Wendel Matias-Desmob'!AR39 -> 0 | V11: AGO | W11: ='Ednei-Desmob'!H38 -> 2021 | X11: =SUM(5000-W11) -> 2979 | Y11: ='Ednei-Desmob'!Z39 -> 0 | Z11: ='Ednei-Desmob'!AI39 -> 0 | AA11: ='Ednei-Desmob'!AR39 -> 0
A12: SET | B12: ='Ualace-Desmob'!H41 -> 0 | C12: =SUM(5000-B12) -> 5000 | D12: ='Ualace-Desmob'!U42 -> 0 | E12: ='Ualace-Desmob'!AC42 -> 0 | F12: ='Ualace-Desmob'!AK42 -> 0 | H12: SET | I12: ='André Plácido-Desmob'!H44 -> 1335 | J12: =SUM(5000-I12) -> 3665 | K12: ='André Plácido-Desmob'!U45 -> 723.78 | L12: ='André Plácido-Desmob'!AC45 -> 0 | M12: ='André Plácido-Desmob'!AK45 -> 0 | O12: SET | P12: ='Wendel Matias-Desmob'!H38 -> 964 | Q12: =SUM(5000-P12) -> 4036 | R12: ='Wendel Matias-Desmob'!Z43 -> 0 | S12: ='Wendel Matias-Desmob'!AI43 -> 0 | T12: ='Wendel Matias-Desmob'!AR43 -> 0 | V12: SET | W12: ='Ednei-Desmob'!H42 -> 1648 | X12: =SUM(5000-W12) -> 3352 | Y12: ='Ednei-Desmob'!Z43 -> 0 | Z12: ='Ednei-Desmob'!AI43 -> 0 | AA12: ='Ednei-Desmob'!AR43 -> 0
A13: OUT | B13: ='Ualace-Desmob'!H45 -> 726 | C13: =SUM(5000-B13) -> 4274 | D13: ='Ualace-Desmob'!U46 -> 0 | E13: ='Ualace-Desmob'!AC46 -> 0 | F13: ='Ualace-Desmob'!AK46 -> 0 | H13: OUT | I13: ='André Plácido-Desmob'!H48 -> 2624 | J13: =SUM(5000-I13) -> 2376 | K13: ='André Plácido-Desmob'!U49 -> 643.44 | L13: ='André Plácido-Desmob'!AC49 -> 0 | M13: ='André Plácido-Desmob'!AK49 -> 0 | O13: OUT | P13: ='Wendel Matias-Desmob'!H42 -> 1939 | Q13: =SUM(5000-P13) -> 3061 | R13: ='Wendel Matias-Desmob'!Z47 -> 0 | S13: ='Wendel Matias-Desmob'!AI47 -> 0 | T13: ='Wendel Matias-Desmob'!AR47 -> 0 | V13: OUT | W13: ='Ednei-Desmob'!H46 -> 1564 | X13: =SUM(5000-W13) -> 3436 | Y13: ='Ednei-Desmob'!Z47 -> 0 | Z13: ='Ednei-Desmob'!AI47 -> 0 | AA13: ='Ednei-Desmob'!AR47 -> 0
A14: NOV | B14: ='Ualace-Desmob'!H49 -> 3829 | C14: =SUM(5000-B14) -> 1171 | D14: ='Ualace-Desmob'!U50 -> 0 | E14: ='Ualace-Desmob'!AC50 -> 0 | F14: ='Ualace-Desmob'!AK50 -> 0 | H14: NOV | I14: ='André Plácido-Desmob'!H52 -> 896 | J14: =SUM(5000-I14) -> 4104 | K14: ='André Plácido-Desmob'!U53 -> 400.06 | L14: ='André Plácido-Desmob'!AC53 -> 0 | M14: ='André Plácido-Desmob'!AK53 -> 0 | O14: NOV | P14: ='Wendel Matias-Desmob'!H46 -> 2022 | Q14: =SUM(5000-P14) -> 2978 | R14: ='Wendel Matias-Desmob'!Z51 -> 0 | S14: ='Wendel Matias-Desmob'!AI51 -> 0 | T14: ='Wendel Matias-Desmob'!AR51 -> 0 | V14: NOV | W14: ='Ednei-Desmob'!H50 -> 1462 | X14: =SUM(5000-W14) -> 3538 | Y14: ='Ednei-Desmob'!Z51 -> 0 | Z14: ='Ednei-Desmob'!AI51 -> 0 | AA14: ='Ednei-Desmob'!AR51 -> 0
A15: DEZ | B15: ='Ualace-Desmob'!H53 -> 1771 | C15: =SUM(5000-B15) -> 3229 | D15: ='Ualace-Desmob'!U54 -> 1384.87 | E15: ='Ualace-Desmob'!AC54 -> 0 | F15: ='Ualace-Desmob'!AK54 -> 0 | H15: DEZ | I15: ='André Plácido-Desmob'!H56 -> 719 | J15: =SUM(5000-I15) -> 4281 | K15: ='André Plácido-Desmob'!U57 -> 500.31 | L15: ='André Plácido-Desmob'!AC53 -> 0 | M15: ='André Plácido-Desmob'!AK53 -> 0 | O15: DEZ | P15: ='Wendel Matias-Desmob'!H50 -> 1848 | Q15: =SUM(5000-P15) -> 3152 | R15: ='Wendel Matias-Desmob'!Z55 -> 0 | S15: ='Wendel Matias-Desmob'!AI51 -> 0 | T15: ='Wendel Matias-Desmob'!AR55 -> 0 | V15: DEZ | W15: ='Ednei-Desmob'!H54 -> 1564 | X15: =SUM(5000-W15) -> 3436 | Y15: ='Ednei-Desmob'!Z55 -> 0 | Z15: ='Ednei-Desmob'!AI55 -> 0 | AA15: ='Ednei-Desmob'!AR55 -> 0
A17: TOTAL | B17: =SUM(B4:B15) -> 6326 | D17: =SUM(D4:D15) -> 1384.87 | E17: =SUM(E4:E15) -> 0 | F17: =SUM(F4:F15) -> 0 | H17: TOTAL | I17: =SUM(I4:I15) -> 15756 | K17: =SUM(K4:K15) -> 6256.02 | L17: =SUM(L4:L15) -> 300 | M17: =SUM(M4:M15) -> 0 | O17: TOTAL | P17: =SUM(P4:P15) -> 16643 | R17: =SUM(R4:R15) -> 1972.89 | S17: =SUM(S4:S15) -> 0 | T17: =SUM(T4:T15) -> 0 | V17: TOTAL | W17: =SUM(W4:W15) -> 17260 | Y17: =SUM(Y4:Y15) -> 1799.01 | Z17: =SUM(Z4:Z15) -> 0 | AA17: =SUM(AA4:AA15) -> 0
A18: SALDO KM | B18: =SUM(60000-B17) -> 53674 | H18: SALDO KM | I18: =SUM(60000-I17) -> 44244 | O18: SALDO KM | P18: =SUM(60000-P17) -> 43357 | V18: SALDO KM | W18: =SUM(60000-W17) -> 42740
B21: CAR_05 | I21: CAR_06 | P21: CAR_07 | W21: CAR_08
B22: KM RODADO | C22: KM MENSAL | D22: ABASTECIMENTO | E22: LAVA_RAPIDO | F22: BORRACHARIA | I22: KM RODADO | J22: KM MENSAL | K22: ABASTECIMENTO | L22: LAVA_RAPIDO | M22: BORRACHARIA | P22: KM RODADO | Q22: KM MENSAL | R22: ABASTECIMENTO | S22: LAVA_RAPIDO | T22: BORRACHARIA | W22: KM RODADO | X22: KM MENSAL | Y22: ABASTECIMENTO | Z22: LAVA_RAPIDO | AA22: BORRACHARIA
A23: JAN | C23: 0 | D23: 0 | E23: 0 | F23: 0 | H23: JAN | J23: 0 | K23: 0 | L23: 0 | M23: 0 | O23: JAN | Q23: 0 | R23: 0 | S23: 0 | T23: 0 | V23: JAN | X23: 0 | Y23: 0 | Z23: 0 | AA23: 0
A24: FEV | B24: ='Ualace-Desmob2'!H15 -> 1610 | C24: =SUM(5000-B24) -> 3390 | D24: ='Ualace-Desmob2'!U16 -> 907.76 | E24: ='Ualace-Desmob2'!AC16 -> 0 | F24: ='Ualace-Desmob2'!AK16 -> 0 | H24: FEV | I24: ='Claudio-Desmob'!H13 -> 0 | J24: =SUM(5000-I24) -> 5000 | K24: ='Claudio-Desmob'!U14 -> 0 | L24: ='Claudio-Desmob'!AC14 -> 0 | M24: ='Claudio-Desmob'!AK14 -> 0 | O24: FEV | P24: ='Andre Placido'!H11 -> 0 | Q24: =SUM(5000-P24) -> 5000 | R24: ='Andre Placido'!U12 -> 0 | S24: ='Andre Placido'!AC12 -> 0 | T24: ='Andre Placido'!AK12 -> 0 | V24: FEV | W24: =Ednei!H11 -> 0 | X24: =SUM(5000-W24) -> 5000 | Y24: =Ednei!U12 -> 0 | Z24: =Ednei!AE12 -> 0 | AA24: =Ednei!AN12 -> 0
A25: MAR | B25: ='Ualace-Desmob2'!H19 -> 1827 | C25: =SUM(5000-B25) -> 3173 | D25: ='Ualace-Desmob2'!U20 -> 980.03 | E25: ='Ualace-Desmob2'!AC20 -> 180 | F25: ='Ualace-Desmob2'!AK20 -> 0 | H25: MAR | I25: ='Claudio-Desmob'!H17 -> 1341 | J25: =SUM(5000-I25) -> 3659 | K25: ='Claudio-Desmob'!U18 -> 813.24 | L25: ='Claudio-Desmob'!AC18 -> 40 | M25: ='Claudio-Desmob'!AK18 -> 0 | O25: MAR | P25: ='Andre Placido'!H15 -> 0 | Q25: =SUM(5000-P25) -> 5000 | R25: ='Andre Placido'!U16 -> 0 | S25: ='Andre Placido'!AC16 -> 0 | T25: ='Andre Placido'!AK16 -> 0 | V25: MAR | W25: =Ednei!H15 -> 0 | X25: =SUM(5000-W25) -> 5000 | Y25: =Ednei!U16 -> 0 | Z25: =Ednei!AE16 -> 0 | AA25: =Ednei!AN16 -> 0
A26: ABR | B26: ='Ualace-Desmob2'!H23 -> 1101 | C26: =SUM(5000-B26) -> 3899 | D26: ='Ualace-Desmob2'!U24 -> 930.52 | E26: ='Ualace-Desmob2'!AC24 -> 0 | F26: ='Ualace-Desmob2'!AK24 -> 0 | H26: ABR | I26: ='Claudio-Desmob'!H21 -> 2114 | J26: =SUM(5000-I26) -> 2886 | K26: ='Claudio-Desmob'!U22 -> 1278.42 | L26: ='Claudio-Desmob'!AC22 -> 0 | M26: ='Claudio-Desmob'!AK22 -> 0 | O26: ABR | P26: ='Andre Placido'!H19 -> -964 | Q26: =SUM(5000-P26) -> 5964 | R26: ='Andre Placido'!U20 -> 0 | S26: ='Andre Placido'!AC20 -> 0 | T26: ='Andre Placido'!AK20 -> 0 | V26: ABR | W26: =Ednei!H19 -> 938 | X26: =SUM(5000-W26) -> 4062 | Y26: =Ednei!U200 -> 0 | Z26: =Ednei!AE20 -> 0 | AA26: =Ednei!AN200 -> 0
A27: MAI | B27: ='Ualace-Desmob2'!H27 -> 1326 | C27: =SUM(5000-B27) -> 3674 | D27: ='Ualace-Desmob2'!U28 -> 838.34 | E27: ='Ualace-Desmob2'!AC28 -> 0 | F27: ='Ualace-Desmob2'!AK28 -> 0 | H27: MAI | I27: ='Claudio-Desmob'!H25 -> 2068 | J27: =SUM(5000-I27) -> 2932 | K27: ='Claudio-Desmob'!U26 -> 1266.37 | L27: ='Claudio-Desmob'!AC26 -> 0 | M27: ='Claudio-Desmob'!AK26 -> 0 | O27: MAI | P27: ='Andre Placido'!H27 -> 1724 | Q27: =SUM(5000-P27) -> 3276 | R27: ='Andre Placido'!U28 -> 0 | S27: ='Andre Placido'!AC28 -> 0 | T27: ='Andre Placido'!AK28 -> 0 | V27: MAI | W27: =Ednei!H23 -> 2160 | X27: =SUM(5000-W27) -> 2840 | Y27: =Ednei!U24 -> 0 | Z27: =Ednei!AE24 -> 0 | AA27: =Ednei!AN24 -> 0
A28: JUN | B28: ='Ualace-Desmob2'!H31 -> 2563 | C28: =SUM(5000-B28) -> 2437 | D28: ='Ualace-Desmob2'!U32 -> 848.51 | E28: ='Ualace-Desmob2'!AC32 -> 0 | F28: ='Ualace-Desmob2'!AK32 -> 0 | H28: JUN | I28: ='Claudio-Desmob'!H29 -> 1338 | J28: =SUM(5000-I28) -> 3662 | K28: ='Claudio-Desmob'!U30 -> 981.88 | L28: ='Claudio-Desmob'!AC30 -> 0 | M28: ='Claudio-Desmob'!AK30 -> 0 | O28: JUN | P28: ='Andre Placido'!H31 -> 0 | Q28: =SUM(5000-P28) -> 5000 | R28: ='Andre Placido'!U32 -> 0 | S28: ='Andre Placido'!AC32 -> 0 | T28: ='Andre Placido'!AK32 -> 0 | V28: JUN | W28: =Ednei!H27 -> 0 | X28: =SUM(5000-W28) -> 5000 | Y28: =Ednei!U28 -> 0 | Z28: =Ednei!AE28 -> 0 | AA28: =Ednei!AN28 -> 0
A29: JUL | B29: ='Ualace-Desmob2'!H35 -> 1661 | C29: =SUM(5000-B29) -> 3339 | D29: ='Ualace-Desmob2'!U36 -> 1105.78 | E29: ='Ualace-Desmob2'!AC36 -> 0 | F29: ='Ualace-Desmob2'!AK36 -> 0 | H29: JUL | I29: ='Claudio-Desmob'!H33 -> 2288 | J29: =SUM(5000-I29) -> 2712 | K29: ='Claudio-Desmob'!U34 -> 1349.07 | L29: ='Claudio-Desmob'!AC34 -> 0 | M29: ='Claudio-Desmob'!AK34 -> 0 | O29: JUL | P29: ='Andre Placido'!H35 -> 0 | Q29: =SUM(5000-P29) -> 5000 | R29: ='Andre Placido'!U36 -> 0 | S29: ='Andre Placido'!AC36 -> 0 | T29: ='Andre Placido'!AK36 -> 0 | V29: JUL | W29: =Ednei!H31 -> 0 | X29: =SUM(5000-W29) -> 5000 | Y29: =Ednei!U32 -> 0 | Z29: =Ednei!AE32 -> 0 | AA29: =Ednei!AN32 -> 0
A30: AGO | B30: ='Ualace-Desmob2'!H39 -> 1255 | C30: =SUM(5000-B30) -> 3745 | D30: ='Ualace-Desmob2'!U40 -> 864.63 | E30: ='Ualace-Desmob2'!AC40 -> 0 | F30: ='Ualace-Desmob2'!AK40 -> 0 | H30: AGO | I30: ='Claudio-Desmob'!H37 -> 1594 | J30: =SUM(5000-I30) -> 3406 | K30: ='Claudio-Desmob'!U38 -> 862.75 | L30: ='Claudio-Desmob'!AC38 -> 0 | M30: ='Claudio-Desmob'!AK38 -> 0 | O30: AGO | P30: ='Andre Placido'!H39 -> 0 | Q30: =SUM(5000-P30) -> 5000 | R30: ='Andre Placido'!U40 -> 0 | S30: ='Andre Placido'!AC40 -> 0 | T30: ='Andre Placido'!AK40 -> 0 | V30: AGO | W30: =Ednei!H35 -> 0 | X30: =SUM(5000-W30) -> 5000 | Y30: =Ednei!U36 -> 0 | Z30: =Ednei!AE36 -> 0 | AA30: =Ednei!AN36 -> 0
A31: SET | B31: ='Ualace-Desmob2'!H43 -> 2193 | C31: =SUM(5000-B31) -> 2807 | D31: ='Ualace-Desmob2'!U44 -> 1071.8 | E31: ='Ualace-Desmob2'!AC44 -> 0 | F31: ='Ualace-Desmob2'!AK5 -> 0 | H31: SET | I31: ='Claudio-Desmob'!H41 -> 2121 | J31: =SUM(5000-I31) -> 2879 | K31: ='Claudio-Desmob'!U42 -> 924.98 | L31: ='Claudio-Desmob'!AC42 -> 0 | M31: ='Claudio-Desmob'!AK42 -> 0 | O31: SET | P31: ='Andre Placido'!H43 -> 0 | Q31: =SUM(5000-P31) -> 5000 | R31: ='Andre Placido'!U44 -> 0 | S31: ='Andre Placido'!AC44 -> 0 | T31: ='Andre Placido'!AK44 -> 0 | V31: SET | W31: =Ednei!H39 -> 0 | X31: =SUM(5000-W31) -> 5000 | Y31: =Ednei!U40 -> 0 | Z31: =Ednei!AE40 -> 0 | AA31: =Ednei!AN40 -> 0
A32: OUT | B32: ='Ualace-Desmob2'!H47 -> 1991 | C32: =SUM(5000-B32) -> 3009 | D32: ='Ualace-Desmob2'!U48 -> 1444.17 | E32: ='Ualace-Desmob2'!AC48 -> 0 | F32: ='Ualace-Desmob2'!AK48 -> 0 | H32: OUT | I32: ='Claudio-Desmob'!H45 -> 1825 | J32: =SUM(5000-I32) -> 3175 | K32: ='Claudio-Desmob'!U46 -> 0 | L32: ='Claudio-Desmob'!AC46 -> 0 | M32: ='Claudio-Desmob'!AK46 -> 0 | O32: OUT | P32: ='Andre Placido'!H47 -> 0 | Q32: =SUM(5000-P32) -> 5000 | R32: ='Andre Placido'!U48 -> 0 | S32: ='Andre Placido'!AC48 -> 0 | T32: ='Andre Placido'!AK48 -> 0 | V32: OUT | W32: =Ednei!H43 -> 0 | X32: =SUM(5000-W32) -> 5000 | Y32: =Ednei!U44 -> 0 | Z32: =Ednei!AE44 -> 0 | AA32: =Ednei!AN44 -> 0
A33: NOV | B33: ='Ualace-Desmob2'!H51 -> 2050 | C33: =SUM(5000-B33) -> 2950 | D33: ='Ualace-Desmob2'!U52 -> 777.06 | E33: ='Ualace-Desmob2'!AC52 -> 0 | F33: ='Ualace-Desmob2'!AK52 -> 0 | H33: NOV | I33: ='Claudio-Desmob'!H53 -> 2596 | J33: =SUM(5000-I33) -> 2404 | K33: ='Claudio-Desmob'!U54 -> 1292.59 | L33: ='Claudio-Desmob'!AC54 -> 0 | M33: ='Claudio-Desmob'!AK54 -> 0 | O33: NOV | P33: ='Andre Placido'!H51 -> 0 | Q33: =SUM(5000-P33) -> 5000 | R33: ='Andre Placido'!U52 -> 0 | S33: ='Andre Placido'!AC52 -> 0 | T33: ='Andre Placido'!AK52 -> 0 | V33: NOV | W33: =Ednei!H47 -> 0 | X33: =SUM(5000-W33) -> 5000 | Y33: =Ednei!U48 -> 0 | Z33: =Ednei!AE48 -> 0 | AA33: =Ednei!AN48 -> 0
A34: DEZ | B34: ='Ualace-Desmob2'!H55 -> 765 | C34: =SUM(5000-B34) -> 4235 | D34: ='Ualace-Desmob2'!U56 -> 0 | E34: ='Ualace-Desmob2'!AC56 -> 0 | F34: ='Ualace-Desmob2'!AK56 -> 0 | H34: DEZ | I34: ='Claudio-Desmob'!H57 -> 1544 | J34: =SUM(5000-I34) -> 3456 | K34: ='Claudio-Desmob'!U58 -> 780.03 | L34: ='Claudio-Desmob'!AC58 -> 0 | M34: ='Claudio-Desmob'!AK58 -> 0 | O34: DEZ | P34: ='Andre Placido'!H55 -> 0 | Q34: =SUM(5000-P34) -> 5000 | R34: ='Andre Placido'!U56 -> 0 | S34: ='Andre Placido'!AC56 -> 0 | T34: ='Andre Placido'!AK56 -> 0 | V34: DEZ | W34: =Ednei!H51 -> 0 | X34: =SUM(5000-W34) -> 5000 | Y34: =Ednei!U52 -> 0 | Z34: =Ednei!AE52 -> 0 | AA34: =Ednei!AN52 -> 0
A36: TOTAL | B36: =SUM(B23:B34) -> 18342 | D36: =SUM(D23:D34) -> 9768.6 | E36: =SUM(E23:E34) -> 180 | F36: =SUM(F23:F34) -> 0 | H36: TOTAL | I36: =SUM(I23:I34) -> 18829 | K36: =SUM(K23:K34) -> 9549.33 | L36: =SUM(L23:L34) -> 40 | M36: =SUM(M23:M34) -> 0 | O36: TOTAL | P36: =SUM(P23:P34) -> 760 | R36: =SUM(R23:R34) -> 0 | S36: =SUM(S23:S34) -> 0 | T36: =SUM(T23:T34) -> 0 | V36: TOTAL | W36: =SUM(W23:W34) -> 3098 | Y36: =SUM(Y23:Y34) -> 0 | Z36: =SUM(Z23:Z34) -> 0 | AA36: =SUM(AA23:AA34) -> 0
A37: SALDO KM | B37: =SUM(60000-B36) -> 41658 | H37: SALDO KM | I37: =SUM(60000-I36) -> 41171 | O37: SALDO KM | P37: =SUM(60000-P36) -> 59240 | V37: SALDO KM | W37: =SUM(60000-W36) -> 56902
B40: CAR_09 | I40: CAR_10 | P40: CAR_11 | W40: CAR_12
B41: KM | C41: KM MENSAL | D41: ABASTECIMENTO | E41: LAVA_RAPIDO | F41: BORRACHARIA | I41: KM | J41: KM MENSAL | K41: ABASTECIMENTO | L41: LAVA_RAPIDO | M41: BORRACHARIA | P41: KM | Q41: KM MENSAL | R41: ABASTECIMENTO | S41: LAVA_RAPIDO | T41: BORRACHARIA | W41: KM | X41: KM MENSAL | Y41: ABASTECIMENTO | Z41: LAVA_RAPIDO | AA41: BORRACHARIA
A42: JAN | H42: JAN | O42: JAN | V42: JAN
A43: FEV | B43: ='Ualace-Desmob3'!H11 -> 0 | C43: =SUM(5000-B43) -> 5000 | D43: ='Ualace-Desmob3'!U12 -> 0 | E43: ='Ualace-Desmob3'!AE12 -> 0 | F43: ='Ualace-Desmob3'!AN12 -> 0 | H43: FEV | I43: =CAR_10!H11 -> 0 | J43: =SUM(5000-I43) -> 5000 | K43: =CAR_10!U12 -> 0 | L43: =CAR_10!AE12 -> 0 | M43: =CAR_10!AN12 -> 0 | O43: FEV | P43: =CAR_11!H11 -> 0 | Q43: =SUM(5000-P43) -> 5000 | R43: =CAR_11!U12 -> 0 | S43: =CAR_11!AE12 -> 0 | T43: =CAR_11!AN12 -> 0 | V43: FEV | W43: =CAR_12!H11 -> 0 | X43: =SUM(5000-W43) -> 5000 | Y43: =CAR_12!U12 -> 0 | Z43: =CAR_12!AE12 -> 0 | AA43: =CAR_12!AN12 -> 0
A44: MAR | B44: ='Ualace-Desmob3'!H15 -> 0 | C44: =SUM(5000-B44) -> 5000 | D44: ='Ualace-Desmob3'!U16 -> 0 | E44: ='Ualace-Desmob3'!AE16 -> 0 | F44: ='Ualace-Desmob3'!AN16 -> 0 | H44: MAR | I44: =CAR_10!H15 -> 0 | J44: =SUM(5000-I44) -> 5000 | K44: =CAR_10!U16 -> 0 | L44: =CAR_10!AE16 -> 0 | M44: =CAR_10!AN16 -> 0 | O44: MAR | P44: =CAR_11!H15 -> 0 | Q44: =SUM(5000-P44) -> 5000 | R44: =CAR_11!U16 -> 0 | S44: =CAR_11!AE16 -> 0 | T44: =CAR_11!AN16 -> 0 | V44: MAR | W44: =CAR_12!H15 -> 0 | X44: =SUM(5000-W44) -> 5000 | Y44: =CAR_12!U16 -> 0 | Z44: =CAR_12!AE16 -> 0 | AA44: =CAR_12!AN16 -> 0
A45: ABR | B45: ='Ualace-Desmob3'!H19 -> 826 | C45: =SUM(5000-B45) -> 4174 | D45: ='Ualace-Desmob3'!U20 -> 0 | E45: ='Ualace-Desmob3'!AE20 -> 0 | F45: ='Ualace-Desmob3'!AN20 -> 0 | H45: ABR | I45: =CAR_10!H19 -> 0 | J45: =SUM(5000-I45) -> 5000 | K45: =CAR_10!U20 -> 0 | L45: =CAR_10!AE20 -> 0 | M45: =CAR_10!AN20 -> 0 | O45: ABR | P45: =CAR_11!H19 -> 0 | Q45: =SUM(5000-P45) -> 5000 | R45: =CAR_11!U20 -> 0 | S45: =CAR_11!AE20 -> 0 | T45: =CAR_11!AN20 -> 0 | V45: ABR | W45: =CAR_12!H19 -> 0 | X45: =SUM(5000-W45) -> 5000 | Y45: =CAR_12!U20 -> 0 | Z45: =CAR_12!AE20 -> 0 | AA45: =CAR_12!AN20 -> 0
A46: MAI | B46: ='Ualace-Desmob3'!H23 -> 1523 | C46: =SUM(5000-B46) -> 3477 | D46: ='Ualace-Desmob3'!U24 -> 0 | E46: ='Ualace-Desmob3'!AE24 -> 0 | F46: ='Ualace-Desmob3'!AN24 -> 0 | H46: MAI | I46: =CAR_10!H23 -> 0 | J46: =SUM(5000-I46) -> 5000 | K46: =CAR_10!U24 -> 0 | L46: =CAR_10!AE24 -> 0 | M46: =CAR_10!AN24 -> 0 | O46: MAI | P46: =CAR_11!H23 -> 0 | Q46: =SUM(5000-P46) -> 5000 | R46: =CAR_11!U24 -> 0 | S46: =CAR_11!AE24 -> 0 | T46: =CAR_11!AN24 -> 0 | V46: MAI | W46: =CAR_12!H23 -> 0 | X46: =SUM(5000-W46) -> 5000 | Y46: =CAR_12!U24 -> 0 | Z46: =CAR_12!AE24 -> 0 | AA46: =CAR_12!AN24 -> 0
A47: JUN | B47: ='Ualace-Desmob3'!H27 -> 0 | C47: =SUM(5000-B47) -> 5000 | D47: ='Ualace-Desmob3'!U28 -> 0 | E47: ='Ualace-Desmob3'!AE28 -> 0 | F47: ='Ualace-Desmob3'!AN28 -> 0 | H47: JUN | I47: =CAR_10!H27 -> 0 | J47: =SUM(5000-I47) -> 5000 | K47: =CAR_10!U28 -> 0 | L47: =CAR_10!AE28 -> 0 | M47: =CAR_10!AN28 -> 0 | O47: JUN | P47: =CAR_11!H27 -> 0 | Q47: =SUM(5000-P47) -> 5000 | R47: =CAR_11!U28 -> 0 | S47: =CAR_11!AE28 -> 0 | T47: =CAR_11!AN28 -> 0 | V47: JUN | W47: =CAR_12!H27 -> 0 | X47: =SUM(5000-W47) -> 5000 | Y47: =CAR_12!U28 -> 0 | Z47: =CAR_12!AE28 -> 0 | AA47: =CAR_12!AN28 -> 0
...

Sheet Andre Placido
A2: Veiculo | B2: UEK4H95 | D2: Placa: | E2: Polo | H2: km | I2: 3000
A3: Substituição (data) | B3: 46137 | D3: Placa: | E3: TDY8E51 | H3: Modelo | I3: Argo
A4: Contrato de Locação | B4: 2484 | D4: Rastreador | E4: Unidas - 3s | H4: Data mob. | I4: 46132
A7: REGISTRO DE KM | J7: ABASTECIMENTO | W7: LAVA_RAPIDO | AE7: BORRACHARIA
B9: Fevereiro | J9: Fevereiro | W9: Fevereiro | AE9: Fevereiro
A10: KM (Rodados) | B10: 1ª Leitura | C10: 2ª Leitura | D10: 3ª Leitura | E10: 4ª Leitura | F10: 15 dias Rodados | G10: 30 dias Rodados | H10: Total Mensal | J10: DATA | W10: DATA | AE10: DATA
F11: =SUM(C11-B11) -> 0 | G11: =SUM(E11-D11) -> 0 | H11: =SUM(F11:G11) -> 0 | J11: VALOR | W11: VALOR | AE11: VALOR
T12: TOTAL | U12: =SUM(K11:U11) -> 0 | AB12: TOTAL | AC12: =SUM(X11:AC11) -> 0 | AJ12: TOTAL | AK12: =SUM(AF11:AK11) -> 0
B13: Março | J13: Março | W13: =J13 -> Março | AE13: =W13 -> Março
A14: KM (Rodados) | B14: 1ª Leitura | C14: 2ª Leitura | D14: 3ª Leitura | E14: 4ª Leitura | F14: 15 dias Rodados | G14: 30 dias Rodados | H14: Total Mensal | J14: DATA | W14: DATA | AE14: DATA
F15: =SUM(C15-B15) -> 0 | G15: =SUM(E15-D15) -> 0 | H15: =SUM(F15:G15) -> 0 | J15: VALOR | W15: VALOR | AE15: VALOR
T16: TOTAL | U16: =SUM(K15:U15) -> 0 | AB16: TOTAL | AC16: =SUM(X15:AC15) -> 0 | AJ16: TOTAL | AK16: =SUM(AF15:AK15) -> 0
A17: UEK4H95 | B17: Abril | J17: Abril | W17: =J17 -> Abril | AE17: =W17 -> Abril
A18: KM (Rodados) | B18: 1ª Leitura | C18: 2ª Leitura | D18: 3ª Leitura | E18: 4ª Leitura | F18: 15 dias Rodados | G18: 30 dias Rodados | H18: Total Mensal | J18: DATA | W18: DATA | AE18: DATA
D19: 964 | F19: =SUM(C19-B19) -> 0 | G19: =SUM(E19-D19) -> -964 | H19: =SUM(F19:G19) -> -964 | J19: VALOR | W19: VALOR | AE19: VALOR
T20: TOTAL | U20: =SUM(K19:U19) -> 0 | AB20: TOTAL | AC20: =SUM(X19:AC19) -> 0 | AJ20: TOTAL | AK20: =SUM(AF19:AK19) -> 0
A21: TDY8E51 | B21: Abril | J21: Abril | W21: =J21 -> Abril | AE21: =W21 -> Abril
A22: KM (Rodados) | B22: 1ª Leitura | C22: 2ª Leitura | D22: 3ª Leitura | E22: 4ª Leitura | F22: 15 dias Rodados | G22: 30 dias Rodados | H22: Total Mensal | J22: DATA | W22: DATA | AE22: DATA
D23: 32749 | E23: 33100 | F23: =SUM(C23-B23) -> 0 | G23: =SUM(E23-D23) -> 351 | H23: =SUM(F23:G23) -> 351 | J23: VALOR | W23: VALOR | AE23: VALOR
T24: TOTAL | U24: =SUM(K23:U23) -> 0 | AB24: TOTAL | AC24: =SUM(X23:AC23) -> 0 | AJ24: TOTAL | AK24: =SUM(AF23:AK23) -> 0
B25: Maio | J25: Maio | W25: =J25 -> Maio | AE25: =W25 -> Maio
A26: KM (Rodados) | B26: 1ª Leitura | C26: 2ª Leitura | D26: 3ª Leitura | E26: 4ª Leitura | F26: 15 dias Rodados | G26: 30 dias Rodados | H26: Total Mensal | J26: DATA | W26: DATA | AE26: DATA
B27: 33100 | E27: 34824 | F27: =SUM(C27-B27) -> -33100 | G27: =SUM(E27-D27) -> 34824 | H27: =SUM(F27:G27) -> 1724 | J27: VALOR | W27: VALOR | AE27: VALOR
T28: TOTAL | U28: =SUM(K27:U27) -> 0 | AB28: TOTAL | AC28: =SUM(X27:AC27) -> 0 | AJ28: TOTAL | AK28: =SUM(AF27:AK27) -> 0
B29: Junho | J29: Junho | W29: =J29 -> Junho | AE29: =W29 -> Junho
A30: KM (Rodados) | B30: 1ª Leitura | C30: 2ª Leitura | D30: 3ª Leitura | E30: 4ª Leitura | F30: 15 dias Rodados | G30: 30 dias Rodados | H30: Total Mensal | J30: DATA | W30: DATA | AE30: DATA
F31: =SUM(C31-B31) -> 0 | G31: =SUM(E31-D31) -> 0 | H31: =SUM(F31:G31) -> 0 | J31: VALOR | W31: VALOR | AE31: VALOR
T32: TOTAL | U32: =SUM(K31:U31) -> 0 | AB32: TOTAL | AC32: =SUM(X31:AC31) -> 0 | AJ32: TOTAL | AK32: =SUM(AF31:AK31) -> 0
B33: Julho | J33: Julho | W33: =J33 -> Julho | AE33: =W33 -> Julho
A34: KM (Rodados) | B34: 1ª Leitura | C34: 2ª Leitura | D34: 3ª Leitura | E34: 4ª Leitura | F34: 15 dias Rodados | G34: 30 dias Rodados | H34: Total Mensal | J34: DATA | W34: DATA | AE34: DATA
F35: =SUM(C35-B35) -> 0 | G35: =SUM(E35-D35) -> 0 | H35: =SUM(F35:G35) -> 0 | J35: VALOR | W35: VALOR | AE35: VALOR
T36: TOTAL | U36: =SUM(K35:U35) -> 0 | AB36: TOTAL | AC36: =SUM(X35:AC35) -> 0 | AJ36: TOTAL | AK36: =SUM(AF35:AK35) -> 0
B37: Agosto | J37: Agosto | W37: =J37 -> Agosto | AE37: =W37 -> Agosto
A38: KM (Rodados) | B38: 1ª Leitura | C38: 2ª Leitura | D38: 3ª Leitura | E38: 4ª Leitura | F38: 15 dias Rodados | G38: 30 dias Rodados | H38: Total Mensal | J38: DATA | W38: DATA | AE38: DATA
F39: =SUM(C39-B39) -> 0 | G39: =SUM(E39-D39) -> 0 | H39: =SUM(F39:G39) -> 0 | J39: VALOR | W39: VALOR | AE39: VALOR
T40: TOTAL | U40: =SUM(K39:U39) -> 0 | AB40: TOTAL | AC40: =SUM(X39:AC39) -> 0 | AJ40: TOTAL | AK40: =SUM(AF39:AK39) -> 0
B41: Setembro | J41: Setembro | W41: =J41 -> Setembro | AE41: =W41 -> Setembro
A42: KM (Rodados) | B42: 1ª Leitura | C42: 2ª Leitura | D42: 3ª Leitura | E42: 4ª Leitura | F42: 15 dias Rodados | G42: 30 dias Rodados | H42: Total Mensal | J42: DATA | W42: DATA | AE42: DATA
F43: =SUM(C43-B43) -> 0 | G43: =SUM(E43-D43) -> 0 | H43: =SUM(F43:G43) -> 0 | J43: VALOR | W43: VALOR | AE43: VALOR
T44: TOTAL | U44: =SUM(K43:U43) -> 0 | AB44: TOTAL | AC44: =SUM(X43:AC43) -> 0 | AJ44: TOTAL | AK44: =SUM(AF43:AK43) -> 0
...

Sheet Ednei
A2: Veiculo | B2: Onix | D2: Placa: | E2: SYS9D28 | H2: km | I2: 3000
A3: Substituição (data) | D3: Placa: | H3: Modelo
A4: Contrato de Locação | B4: 2484 | D4: Rastreador | E4: Unidas - 3s | H4: Data Desmob | I4: 46132
A7: REGISTRO DE KM | J7: ABASTECIMENTO | Y7: LAVA_RAPIDO | AH7: BORRACHARIA
B9: Fevereiro | J9: Fevereiro | Y9: Fevereiro | AH9: Fevereiro
A10: KM (Rodados) | B10: 1ª Leitura | C10: 2ª Leitura | D10: 3ª Leitura | E10: 4ª Leitura | F10: 15 dias Rodados | G10: 30 dias Rodados | H10: Total Mensal | J10: DATA | Y10: DATA | AH10: DATA
F11: =SUM(C11-B11) -> 0 | G11: =SUM(E11-D11) -> 0 | H11: =SUM(F11:G11) -> 0 | J11: VALOR | Y11: VALOR | AH11: VALOR
T12: TOTAL | U12: =SUM(K11:U11) -> 0 | AD12: TOTAL | AE12: =SUM(Z11:AE11) -> 0 | AM12: TOTAL | AN12: =SUM(AI11:AN11) -> 0
B13: Março | J13: Março | Y13: =J13 -> Março | AH13: =Y13 -> Março
A14: KM (Rodados) | B14: 1ª Leitura | C14: 2ª Leitura | D14: 3ª Leitura | E14: 4ª Leitura | F14: 15 dias Rodados | G14: 30 dias Rodados | H14: Total Mensal | J14: DATA | Y14: DATA | AH14: DATA
F15: =SUM(C15-B15) -> 0 | G15: =SUM(E15-D15) -> 0 | H15: =SUM(F15:G15) -> 0 | J15: VALOR | Y15: VALOR | AH15: VALOR
T16: TOTAL | U16: =SUM(K15:U15) -> 0 | AD16: TOTAL | AE16: =SUM(Z15:AE15) -> 0 | AM16: TOTAL | AN16: =SUM(AI15:AN15) -> 0
B17: Abril | J17: Abril | Y17: =J17 -> Abril | AH17: =Y17 -> Abril
A18: KM (Rodados) | B18: 1ª Leitura | C18: 2ª Leitura | D18: 3ª Leitura | E18: 4ª Leitura | F18: 15 dias Rodados | G18: 30 dias Rodados | H18: Total Mensal | J18: DATA | Y18: DATA | AH18: DATA
D19: 52737 | E19: 53675 | F19: =SUM(C19-B19) -> 0 | G19: =SUM(E19-D19) -> 938 | H19: =SUM(F19:G19) -> 938 | J19: VALOR | Y19: VALOR | AH19: VALOR
T20: TOTAL | U20: =SUM(K19:U19) -> 0 | AD20: TOTAL | AE20: =SUM(Z19:AE19) -> 0 | AM20: TOTAL | AN20: =SUM(AI19:AN19) -> 0
B21: Maio | J21: Maio | Y21: =J21 -> Maio | AH21: =Y21 -> Maio
A22: KM (Rodados) | B22: 1ª Leitura | C22: 2ª Leitura | D22: 3ª Leitura | E22: 4ª Leitura | F22: 15 dias Rodados | G22: 30 dias Rodados | H22: Total Mensal | J22: DATA | Y22: DATA | AH22: DATA
B23: 53675 | E23: 55835 | F23: =SUM(C23-B23) -> -53675 | G23: =SUM(E23-D23) -> 55835 | H23: =SUM(F23:G23) -> 2160 | J23: VALOR | Y23: VALOR | AH23: VALOR
T24: TOTAL | U24: =SUM(K23:U23) -> 0 | AD24: TOTAL | AE24: =SUM(Z23:AE23) -> 0 | AM24: TOTAL | AN24: =SUM(AI23:AN23) -> 0
B25: Junho | J25: Junho | Y25: =J25 -> Junho | AH25: =Y25 -> Junho
A26: KM (Rodados) | B26: 1ª Leitura | C26: 2ª Leitura | D26: 3ª Leitura | E26: 4ª Leitura | F26: 15 dias Rodados | G26: 30 dias Rodados | H26: Total Mensal | J26: DATA | Y26: DATA | AH26: DATA
F27: =SUM(C27-B27) -> 0 | G27: =SUM(E27-D27) -> 0 | H27: =SUM(F27:G27) -> 0 | J27: VALOR | Y27: VALOR | AH27: VALOR
T28: TOTAL | U28: =SUM(K27:U27) -> 0 | AD28: TOTAL | AE28: =SUM(Z27:AE27) -> 0 | AM28: TOTAL | AN28: =SUM(AI27:AN27) -> 0
B29: Julho | J29: Julho | Y29: =J29 -> Julho | AH29: =Y29 -> Julho
A30: KM (Rodados) | B30: 1ª Leitura | C30: 2ª Leitura | D30: 3ª Leitura | E30: 4ª Leitura | F30: 15 dias Rodados | G30: 30 dias Rodados | H30: Total Mensal | J30: DATA | Y30: DATA | AH30: DATA
F31: =SUM(C31-B31) -> 0 | G31: =SUM(E31-D31) -> 0 | H31: =SUM(F31:G31) -> 0 | J31: VALOR | Y31: VALOR | AH31: VALOR
T32: TOTAL | U32: =SUM(K31:U31) -> 0 | AD32: TOTAL | AE32: =SUM(Z31:AE31) -> 0 | AM32: TOTAL | AN32: =SUM(AI31:AN31) -> 0
B33: Agosto | J33: Agosto | Y33: =J33 -> Agosto | AH33: =Y33 -> Agosto
A34: KM (Rodados) | B34: 1ª Leitura | C34: 2ª Leitura | D34: 3ª Leitura | E34: 4ª Leitura | F34: 15 dias Rodados | G34: 30 dias Rodados | H34: Total Mensal | J34: DATA | Y34: DATA | AH34: DATA
F35: =SUM(C35-B35) -> 0 | G35: =SUM(E35-D35) -> 0 | H35: =SUM(F35:G35) -> 0 | J35: VALOR | Y35: VALOR | AH35: VALOR
T36: TOTAL | U36: =SUM(K35:U35) -> 0 | AD36: TOTAL | AE36: =SUM(Z35:AE35) -> 0 | AM36: TOTAL | AN36: =SUM(AI35:AN35) -> 0
B37: Setembro | J37: Setembro | Y37: =J37 -> Setembro | AH37: =Y37 -> Setembro
A38: KM (Rodados) | B38: 1ª Leitura | C38: 2ª Leitura | D38: 3ª Leitura | E38: 4ª Leitura | F38: 15 dias Rodados | G38: 30 dias Rodados | H38: Total Mensal | J38: DATA | Y38: DATA | AH38: DATA
F39: =SUM(C39-B39) -> 0 | G39: =SUM(E39-D39) -> 0 | H39: =SUM(F39:G39) -> 0 | J39: VALOR | Y39: VALOR | AH39: VALOR
T40: TOTAL | U40: =SUM(K39:U39) -> 0 | AD40: TOTAL | AE40: =SUM(Z39:AE39) -> 0 | AM40: TOTAL | AN40: =SUM(AI39:AN39) -> 0
B41: Outubro | J41: Outubro | Y41: =J41 -> Outubro | AH41: =Y41 -> Outubro
A42: KM (Rodados) | B42: 1ª Leitura | C42: 2ª Leitura | D42: 3ª Leitura | E42: 4ª Leitura | F42: 15 dias Rodados | G42: 30 dias Rodados | H42: Total Mensal | J42: DATA | Y42: DATA | AH42: DATA
F43: =SUM(C43-B43) -> 0 | G43: =SUM(E43-D43) -> 0 | H43: =SUM(F43:G43) -> 0 | J43: VALOR | Y43: VALOR | AH43: VALOR
T44: TOTAL | U44: =SUM(K43:U43) -> 0 | AD44: TOTAL | AE44: =SUM(Z43:AE43) -> 0 | AM44: TOTAL | AN44: =SUM(AI43:AN43) -> 0
...

Sheet Claudio-Desmob
A2: Veiculo | B2: Argo | D2: Placa: | E2: TCY1C25 | H2: KM | I2: 3000km
A3: Substituição 1ª | B3: 45955 | D3: Placa: | E3: TCV9F12 | H3: Modelo | I3: Argo
A4: Substituição 2ª | B4: 45962 | D4: Placa: | E4: TES6H46 | H4: Modelo | I4: C3
A5: Substituição 3ª | B5: 46122 | D5: Placa: | E5: SHK5D77 | H5: Modelo | I5: Onix
A6: Contrato de Locação | B6: 2484 | D6: Rastreador | E6: Unidas - 3S | H6: Data mob. | I6: 45728 | J6: Data desmob. | K6: 46179
A9: REGISTRO DE KM | J9: ABASTECIMENTO | W9: LAVA_RAPIDO | AE9: BORRACHARIA
B11: Fevereiro | J11: Fevereiro | W11: Fevereiro | AE11: Fevereiro
A12: KM (Rodados) | B12: 1ª Leitura | C12: 2ª Leitura | D12: 3ª Leitura | E12: 4ª Leitura | F12: 15 dias Rodados | G12: 30 dias Rodados | H12: Total Mensal | J12: DATA | W12: DATA | AE12: DATA
F13: =SUM(C13-B13) -> 0 | G13: =SUM(E13-D13) -> 0 | H13: =SUM(F13:G13) -> 0 | J13: VALOR | W13: VALOR | AE13: VALOR
T14: TOTAL | U14: =SUM(K13:U13) -> 0 | AB14: TOTAL | AC14: =SUM(X13:AC13) -> 0 | AJ14: TOTAL | AK14: =SUM(AF13:AK13) -> 0
A15: Retirado 12/03/2025 | B15: Março | J15: Março | W15: =J15 -> Março | AE15: =W15 -> Março
A16: KM (Rodados) | B16: 1ª Leitura | C16: 2ª Leitura | D16: 3ª Leitura | E16: 4ª Leitura | F16: 15 dias Rodados | G16: 30 dias Rodados | H16: Total Mensal | J16: DATA | K16: 45730 | L16: 45734 | M16: 45741 | N16: 45744 | W16: DATA | X16: 45738 | AE16: DATA
B17: 12832 | C17: 13247 | D17: 13247 | E17: 14173 | F17: =SUM(C17-B17) -> 415 | G17: =SUM(E17-D17) -> 926 | H17: =SUM(F17:G17) -> 1341 | J17: VALOR | K17: 253.28 | L17: 190.8 | M17: 260.11 | N17: 109.05 | W17: VALOR | X17: 40 | AE17: VALOR
T18: TOTAL | U18: =SUM(K17:U17) -> 813.24 | AB18: TOTAL | AC18: =SUM(X17:AC17) -> 40 | AJ18: TOTAL | AK18: =SUM(AF17:AK17) -> 0
B19: Abril | J19: Abril | W19: =J19 -> Abril | AE19: =W19 -> Abril
