Workbook

Sheet Resumo Geral
A1: RESUMO GERAL MENSAL
B5: JAN | C5: FEV | D5: MAR | E5: ABR | F5: MAI | G5: JUN | H5: JUL | I5: AGO | J5: SET | K5: OUT | L5: NOV | M5: DEZ
A6: ABASTECIMENTO | B6: ='Resumo Individual'!D5+'Resumo Individual'!K5+'Resumo Individual'!D24+'Resumo Individual'!K24+'Resumo Individual'!D43+'Resumo Individual'!K43 -> 1045.42 | C6: ='Resumo Individual'!D6+'Resumo Individual'!K6+'Resumo Individual'!D25+'Resumo Individual'!K25+'Resumo Individual'!D44+'Resumo Individual'!K44 -> 1960.31 | D6: ='Resumo Individual'!D7+'Resumo Individual'!K7+'Resumo Individual'!D26+'Resumo Individual'!K26+'Resumo Individual'!D45+'Resumo Individual'!K45 -> 2218.6 | E6: ='Resumo Individual'!D8+'Resumo Individual'!K8+'Resumo Individual'!D27+'Resumo Individual'!K27+'Resumo Individual'!D46+'Resumo Individual'!K46 -> 2484.87 | F6: ='Resumo Individual'!D9+'Resumo Individual'!K9+'Resumo Individual'!D28+'Resumo Individual'!K28+'Resumo Individual'!D47+'Resumo Individual'!K47 -> 2290.46 | G6: ='Resumo Individual'!D10+'Resumo Individual'!K10+'Resumo Individual'!D29+'Resumo Individual'!K29+'Resumo Individual'!D48+'Resumo Individual'!K48 -> 1245.78 | H6: ='Resumo Individual'!D11+'Resumo Individual'!K11+'Resumo Individual'!D30+'Resumo Individual'!K30+'Resumo Individual'!D49+'Resumo Individual'!K49 -> 1416.65 | I6: ='Resumo Individual'!D12+'Resumo Individual'!K12+'Resumo Individual'!D31+'Resumo Individual'!K31+'Resumo Individual'!D50+'Resumo Individual'!K50 -> 4413.72 | J6: ='Resumo Individual'!D13+'Resumo Individual'!K13+'Resumo Individual'!D32+'Resumo Individual'!K32+'Resumo Individual'!D51+'Resumo Individual'!K51 -> 7627.61 | K6: ='Resumo Individual'!D14+'Resumo Individual'!K14+'Resumo Individual'!D33+'Resumo Individual'!K33+'Resumo Individual'!D52+'Resumo Individual'!K52 -> 10693.81 | L6: ='Resumo Individual'!D15+'Resumo Individual'!K15+'Resumo Individual'!D34+'Resumo Individual'!K34+'Resumo Individual'!D53+'Resumo Individual'!K53 -> 5235.49 | M6: ='Resumo Individual'!D16+'Resumo Individual'!K16+'Resumo Individual'!D35+'Resumo Individual'!K35+'Resumo Individual'!D54+'Resumo Individual'!K54 -> 6789
A8: LAVA JATO | B8: ='Resumo Individual'!E5+'Resumo Individual'!L5+'Resumo Individual'!E24+'Resumo Individual'!L24+'Resumo Individual'!E43+'Resumo Individual'!L43 -> 45 | C8: ='Resumo Individual'!E6+'Resumo Individual'!L6+'Resumo Individual'!E25+'Resumo Individual'!L25+'Resumo Individual'!E44+'Resumo Individual'!L44 -> 45 | D8: ='Resumo Individual'!E7+'Resumo Individual'!L7+'Resumo Individual'!E26+'Resumo Individual'!L26+'Resumo Individual'!E45+'Resumo Individual'!L45 -> 45 | E8: ='Resumo Individual'!E8+'Resumo Individual'!L8+'Resumo Individual'!E27+'Resumo Individual'!L27+'Resumo Individual'!E46+'Resumo Individual'!L46 -> 0 | F8: ='Resumo Individual'!E9+'Resumo Individual'!L9+'Resumo Individual'!E28+'Resumo Individual'!L28+'Resumo Individual'!E47+'Resumo Individual'!L47 -> 0 | G8: ='Resumo Individual'!E10+'Resumo Individual'!L10+'Resumo Individual'!E29+'Resumo Individual'!L29+'Resumo Individual'!E48+'Resumo Individual'!L48 -> 0 | H8: ='Resumo Individual'!E11+'Resumo Individual'!L11+'Resumo Individual'!E30+'Resumo Individual'!L30+'Resumo Individual'!E49+'Resumo Individual'!L49 -> 0 | I8: ='Resumo Individual'!E12+'Resumo Individual'!L12+'Resumo Individual'!E31+'Resumo Individual'!L31+'Resumo Individual'!E50+'Resumo Individual'!L50 -> 0 | J8: ='Resumo Individual'!E13+'Resumo Individual'!L13+'Resumo Individual'!E32+'Resumo Individual'!L32+'Resumo Individual'!E51+'Resumo Individual'!L51 -> 0 | K8: ='Resumo Individual'!E14+'Resumo Individual'!L14+'Resumo Individual'!E33+'Resumo Individual'!L33+'Resumo Individual'!E52+'Resumo Individual'!L52 -> 0 | L8: ='Resumo Individual'!E15+'Resumo Individual'!L15+'Resumo Individual'!E34+'Resumo Individual'!L34+'Resumo Individual'!E53+'Resumo Individual'!L53 -> 0 | M8: ='Resumo Individual'!E16+'Resumo Individual'!L16+'Resumo Individual'!E35+'Resumo Individual'!L35+'Resumo Individual'!E54+'Resumo Individual'!L54 -> 90
A10: BORRACHARIA | B10: ='Resumo Individual'!F5+'Resumo Individual'!M5+'Resumo Individual'!F24+'Resumo Individual'!M24+'Resumo Individual'!F43+'Resumo Individual'!M43 -> 0 | C10: ='Resumo Individual'!F6+'Resumo Individual'!M6+'Resumo Individual'!F25+'Resumo Individual'!M25+'Resumo Individual'!F44+'Resumo Individual'!M44 -> 0 | D10: ='Resumo Individual'!F7+'Resumo Individual'!M7+'Resumo Individual'!F26+'Resumo Individual'!M26+'Resumo Individual'!F45+'Resumo Individual'!M45 -> 0 | E10: ='Resumo Individual'!F8+'Resumo Individual'!M8+'Resumo Individual'!F27+'Resumo Individual'!M27+'Resumo Individual'!F46+'Resumo Individual'!M46 -> 0 | F10: ='Resumo Individual'!F9+'Resumo Individual'!M9+'Resumo Individual'!F28+'Resumo Individual'!M28+'Resumo Individual'!F47+'Resumo Individual'!M47 -> 0 | G10: ='Resumo Individual'!F10+'Resumo Individual'!M10+'Resumo Individual'!F29+'Resumo Individual'!M29+'Resumo Individual'!F48+'Resumo Individual'!M48 -> 0 | H10: ='Resumo Individual'!F11+'Resumo Individual'!M11+'Resumo Individual'!F30+'Resumo Individual'!M30+'Resumo Individual'!F49+'Resumo Individual'!M49 -> 0 | I10: ='Resumo Individual'!F12+'Resumo Individual'!M12+'Resumo Individual'!F31+'Resumo Individual'!M31+'Resumo Individual'!F50+'Resumo Individual'!M50 -> 0 | J10: ='Resumo Individual'!F13+'Resumo Individual'!M13+'Resumo Individual'!F32+'Resumo Individual'!M32+'Resumo Individual'!F51+'Resumo Individual'!M51 -> 0 | K10: ='Resumo Individual'!F14+'Resumo Individual'!M14+'Resumo Individual'!F33+'Resumo Individual'!M33+'Resumo Individual'!F52+'Resumo Individual'!M52 -> 0 | L10: ='Resumo Individual'!F15+'Resumo Individual'!M15+'Resumo Individual'!F34+'Resumo Individual'!M34+'Resumo Individual'!F53+'Resumo Individual'!M53 -> 0 | M10: ='Resumo Individual'!F16+'Resumo Individual'!M16+'Resumo Individual'!F35+'Resumo Individual'!M35+'Resumo Individual'!F54+'Resumo Individual'!M54 -> 0
B14: JAN | C14: FEV | D14: MAR | E14: ABR | F14: MAI | G14: JUN | H14: JUL | I14: AGO | J14: SET | K14: OUT | L14: NOV | M14: DEZ
A15: Medição
A17: Contrato de Locação
A19: Lucro Car's | B19: =B15-B17 -> 0 | C19: =C15-C17 -> 0 | D19: =D15-D17 -> 0 | E19: =E15-E17 -> 0 | F19: =F15-F17 -> 0 | G19: =G15-G17 -> 0 | H19: =H15-H17 -> 0 | I19: =I15-I17 -> 0 | ... M19: =M15-M17 -> 0

Sheet Resumo Individual
C1: RESUMO INDIVIDUAL POR VEÍCULO
B3: CAR 01 | I3: CAR 02
B4: KM RODADO | C4: KM MENSAL | D4: ABASTECIMENTO | E4: LAVA JATO | F4: BORRACHARIA | I4: KM RODADO | J4: KM MENSAL | K4: ABASTECIMENTO | L4: LAVA JATO | M4: BORRACHARIA
A5: JAN | B5: ='Jhonny-Devol'!H14 -> 0 | C5: =3000-B5 -> 3000 | D5: ='Jhonny-Devol'!U15 -> 0 | E5: ='Jhonny-Devol'!AD15 -> 0 | F5: ='Jhonny-Devol'!AL15 -> 0 | H5: JAN | I5: ='Roniere-Desmob'!H13 -> 0 | J5: =SUM(3000-I5) -> 3000 | K5: ='Roniere-Desmob'!U14 -> 0 | L5: ='Roniere-Desmob'!AC14 -> 0 | M5: ='Roniere-Desmob'!AK14 -> 0
A6: FEV | B6: ='Jhonny-Devol'!H18 -> 0 | C6: =3000-B6 -> 3000 | D6: ='Jhonny-Devol'!U19 -> 0 | E6: ='Jhonny-Devol'!AD19 -> 0 | F6: ='Jhonny-Devol'!AL19 -> 0 | H6: FEV | I6: ='Roniere-Desmob'!H17 -> 0 | J6: =SUM(3000-I6) -> 3000 | K6: ='Roniere-Desmob'!U18 -> 0 | L6: ='Roniere-Desmob'!AC18 -> 0 | M6: ='Roniere-Desmob'!AK18 -> 0
A7: MAR | B7: ='Jhonny-Devol'!H22 -> 0 | C7: =3000-B7 -> 3000 | D7: ='Jhonny-Devol'!U23 -> 0 | E7: ='Jhonny-Devol'!AD23 -> 0 | F7: ='Jhonny-Devol'!AL23 -> 0 | H7: MAR | I7: ='Roniere-Desmob'!H21 -> 0 | J7: =SUM(3000-I7) -> 3000 | K7: ='Roniere-Desmob'!U22 -> 0 | L7: ='Roniere-Desmob'!AC22 -> 0 | M7: ='Roniere-Desmob'!AK22 -> 0
A8: ABR | B8: ='Jhonny-Devol'!H26 -> 0 | C8: =3000-B8 -> 3000 | D8: ='Jhonny-Devol'!U27 -> 0 | E8: ='Jhonny-Devol'!AD27 -> 0 | F8: ='Jhonny-Devol'!AL27 -> 0 | H8: ABR | I8: ='Roniere-Desmob'!H25 -> 0 | J8: =SUM(3000-I8) -> 3000 | K8: ='Roniere-Desmob'!U26 -> 0 | L8: ='Roniere-Desmob'!AC26 -> 0 | M8: ='Roniere-Desmob'!AK26 -> 0
A9: MAI | B9: ='Jhonny-Devol'!H30 -> 0 | C9: =3000-B9 -> 3000 | D9: ='Jhonny-Devol'!U31 -> 0 | E9: ='Jhonny-Devol'!AD31 -> 0 | F9: ='Jhonny-Devol'!AL31 -> 0 | H9: MAI | I9: ='Roniere-Desmob'!H29 -> 0 | J9: =SUM(3000-I9) -> 3000 | K9: ='Roniere-Desmob'!U30 -> 0 | L9: ='Roniere-Desmob'!AC30 -> 0 | M9: ='Roniere-Desmob'!AK30 -> 0
A10: JUN | B10: ='Jhonny-Devol'!H34 -> 0 | C10: =3000-B10 -> 3000 | D10: ='Jhonny-Devol'!U35 -> 0 | E10: ='Jhonny-Devol'!AD35 -> 0 | F10: ='Jhonny-Devol'!AL35 -> 0 | H10: JUN | I10: ='Roniere-Desmob'!H33 -> 0 | J10: =SUM(3000-I10) -> 3000 | K10: ='Roniere-Desmob'!U34 -> 0 | L10: ='Roniere-Desmob'!AC34 -> 0 | M10: ='Roniere-Desmob'!AK34 -> 0
A11: JUL | B11: ='Jhonny-Devol'!H38 -> 0 | C11: =3000-B11 -> 3000 | D11: ='Jhonny-Devol'!U39 -> 403.52 | E11: ='Jhonny-Devol'!AD39 -> 0 | F11: ='Jhonny-Devol'!AL39 -> 0 | H11: JUL | I11: ='Roniere-Desmob'!H37 -> 0 | J11: =SUM(3000-I11) -> 3000 | K11: ='Roniere-Desmob'!U38 -> 0 | L11: ='Roniere-Desmob'!AC38 -> 0 | M11: ='Roniere-Desmob'!AK38 -> 0
A12: AGO | B12: ='Jhonny-Devol'!H42 -> 2500 | C12: =3000-B12 -> 500 | D12: ='Jhonny-Devol'!U43 -> 1726.47 | E12: ='Jhonny-Devol'!AD43 -> 0 | F12: ='Jhonny-Devol'!AL43 -> 0 | H12: AGO | I12: ='Roniere-Desmob'!H41 -> 1886 | J12: =SUM(3000-I12) -> 1114 | K12: ='Roniere-Desmob'!U42 -> 1448.15 | L12: ='Roniere-Desmob'!AC42 -> 0 | M12: ='Roniere-Desmob'!AK42 -> 0
A13: SET | B13: ='Jhonny-Devol'!H46 -> 3552 | C13: =3000-B13 -> -552 | D13: ='Jhonny-Devol'!U47 -> 1936.96 | E13: ='Jhonny-Devol'!AD47 -> 0 | F13: ='Jhonny-Devol'!AL47 -> 0 | H13: SET | I13: ='Roniere-Desmob'!H45 -> 2490 | J13: =SUM(3000-I13) -> 510 | K13: ='Roniere-Desmob'!U46 -> 1893.63 | L13: ='Roniere-Desmob'!AC46 -> 0 | M13: ='Roniere-Desmob'!AK46 -> 0
A14: OUT | B14: ='Jhonny-Devol'!H50 -> 4707 | C14: =3000-B14 -> -1707 | D14: ='Jhonny-Devol'!U51 -> 2478.9 | E14: ='Jhonny-Devol'!AD51 -> 0 | F14: ='Jhonny-Devol'!AL51 -> 0 | H14: OUT | I14: ='Roniere-Desmob'!H49 -> 46899 | J14: =SUM(3000-I14) -> -43899 | K14: ='Roniere-Desmob'!U50 -> 2339.89 | L14: ='Roniere-Desmob'!AC50 -> 0 | M14: ='Roniere-Desmob'!AK50 -> 0
A15: NOV | B15: ='Jhonny-Devol'!H54 -> 0 | C15: =3000-B15 -> 3000 | D15: ='Jhonny-Devol'!U55 -> 1496.89 | E15: ='Jhonny-Devol'!AD55 -> 0 | F15: ='Jhonny-Devol'!AL55 -> 0 | H15: NOV | I15: ='Roniere-Desmob'!H53 -> 1052 | J15: =SUM(3000-I15) -> 1948 | K15: ='Roniere-Desmob'!U54 -> 765.14 | L15: ='Roniere-Desmob'!AC54 -> 0 | M15: ='Roniere-Desmob'!AK54 -> 0
A16: DEZ | B16: ='Jhonny-Devol'!H58 -> 3743 | C16: =3000-B16 -> -743 | D16: ='Jhonny-Devol'!U59 -> 1451.13 | E16: ='Jhonny-Devol'!AD59 -> 45 | F16: ='Jhonny-Devol'!AL59 -> 0 | H16: DEZ | I16: ='Roniere-Desmob'!H57 -> 1998 | J16: =SUM(3000-I16) -> 1002 | K16: ='Roniere-Desmob'!U58 -> 1431.11 | L16: ='Roniere-Desmob'!AC58 -> 0 | M16: ='Roniere-Desmob'!AK58 -> 0
A18: TOTAL | B18: =SUM(B5:B16) -> 14502 | D18: =SUM(D5:D16) -> 9493.87 | E18: =SUM(E5:E16) -> 45 | F18: =SUM(F5:F16) -> 0 | H18: TOTAL | I18: =SUM(I5:I16) -> 54325 | K18: =SUM(K5:K16) -> 7877.92 | L18: =SUM(L5:L16) -> 0 | M18: =SUM(M5:M16) -> 0
A19: SALDO KM | B19: =SUM(36000-B18) -> 21498 | H19: SALDO KM | I19: =SUM(36000-I18) -> -18325
B22: CAR 03 | I22: CAR 04
B23: KM RODADO | C23: KM MENSAL | D23: ABASTECIMENTO | E23: LAVA JATO | F23: BORRACHARIA | I23: KM RODADO | J23: KM MENSAL | K23: ABASTECIMENTO | L23: LAVA JATO | M23: BORRACHARIA
A24: JAN | B24: ='Rute - Devolvido'!H13 -> 0 | C24: =SUM(5000-B24) -> 5000 | D24: ='Rute - Devolvido'!U14 -> 0 | E24: ='Rute - Devolvido'!AC14 -> 0 | F24: ='Rute - Devolvido'!AK14 -> 0 | H24: JAN | I24: ='Francisco de Morais-Desmob'!H14 -> 0 | J24: =SUM(5000-I24) -> 5000 | K24: ='Francisco de Morais-Desmob'!U15 -> 0 | L24: ='Francisco de Morais-Desmob'!AC15 -> 0 | M24: ='Francisco de Morais-Desmob'!AK15 -> 0
A25: FEV | B25: ='Rute - Devolvido'!H17 -> 0 | C25: =SUM(5000-B25) -> 5000 | D25: ='Rute - Devolvido'!U18 -> 0 | E25: ='Rute - Devolvido'!AC18 -> 0 | F25: ='Rute - Devolvido'!AK18 -> 0 | H25: FEV | I25: ='Francisco de Morais-Desmob'!H18 -> 0 | J25: =SUM(5000-I25) -> 5000 | K25: ='Francisco de Morais-Desmob'!U19 -> 0 | L25: ='Francisco de Morais-Desmob'!AC19 -> 0 | M25: ='Francisco de Morais-Desmob'!AK19 -> 0
A26: MAR | B26: ='Rute - Devolvido'!H21 -> 0 | C26: =SUM(5000-B26) -> 5000 | D26: ='Rute - Devolvido'!U22 -> 0 | E26: ='Rute - Devolvido'!AC22 -> 0 | F26: ='Rute - Devolvido'!AK22 -> 0 | H26: MAR | I26: ='Francisco de Morais-Desmob'!H22 -> 0 | J26: =SUM(5000-I26) -> 5000 | K26: ='Francisco de Morais-Desmob'!U23 -> 0 | L26: ='Francisco de Morais-Desmob'!AC23 -> 0 | M26: ='Francisco de Morais-Desmob'!AK23 -> 0
A27: ABR | B27: ='Rute - Devolvido'!H25 -> 0 | C27: =SUM(5000-B27) -> 5000 | D27: ='Rute - Devolvido'!U26 -> 0 | E27: ='Rute - Devolvido'!AC26 -> 0 | F27: ='Rute - Devolvido'!AK26 -> 0 | H27: ABR | I27: ='Francisco de Morais-Desmob'!H26 -> 0 | J27: =SUM(5000-I27) -> 5000 | K27: ='Francisco de Morais-Desmob'!U27 -> 0 | L27: ='Francisco de Morais-Desmob'!AC27 -> 0 | M27: ='Francisco de Morais-Desmob'!AK27 -> 0
A28: MAI | B28: ='Rute - Devolvido'!H29 -> 0 | C28: =SUM(5000-B28) -> 5000 | D28: ='Rute - Devolvido'!U30 -> 0 | E28: ='Rute - Devolvido'!AC30 -> 0 | F28: ='Rute - Devolvido'!AK30 -> 0 | H28: MAI | I28: ='Francisco de Morais-Desmob'!H30 -> 0 | J28: =SUM(5000-I28) -> 5000 | K28: ='Francisco de Morais-Desmob'!U31 -> 0 | L28: ='Francisco de Morais-Desmob'!AC31 -> 0 | M28: ='Francisco de Morais-Desmob'!AK31 -> 0
A29: JUN | B29: ='Rute - Devolvido'!H33 -> 0 | C29: =SUM(5000-B29) -> 5000 | D29: ='Rute - Devolvido'!U34 -> 0 | E29: ='Rute - Devolvido'!AC34 -> 0 | F29: ='Rute - Devolvido'!AK34 -> 0 | H29: JUN | I29: ='Francisco de Morais-Desmob'!H34 -> 0 | J29: =SUM(5000-I29) -> 5000 | K29: ='Francisco de Morais-Desmob'!U35 -> 0 | L29: ='Francisco de Morais-Desmob'!AC35 -> 0 | M29: ='Francisco de Morais-Desmob'!AK35 -> 0
A30: JUL | B30: ='Rute - Devolvido'!H37 -> 0 | C30: =SUM(5000-B30) -> 5000 | D30: ='Rute - Devolvido'!U38 -> 0 | E30: ='Rute - Devolvido'!AC38 -> 0 | F30: ='Rute - Devolvido'!AK38 -> 0 | H30: JUL | I30: ='Francisco de Morais-Desmob'!H38 -> 0 | J30: =SUM(5000-I30) -> 5000 | K30: ='Francisco de Morais-Desmob'!U39 -> 0 | L30: ='Francisco de Morais-Desmob'!AC39 -> 0 | M30: ='Francisco de Morais-Desmob'!AK39 -> 0
A31: AGO | B31: ='Rute - Devolvido'!H41 -> 1655 | C31: =SUM(5000-B31) -> 3345 | D31: ='Rute - Devolvido'!U42 -> 1239.1 | E31: ='Rute - Devolvido'!AC42 -> 0 | F31: ='Rute - Devolvido'!AK42 -> 0 | H31: AGO | I31: ='Francisco de Morais-Desmob'!H42 -> 0 | J31: =SUM(5000-I31) -> 5000 | K31: ='Francisco de Morais-Desmob'!U43 -> 0 | L31: ='Francisco de Morais-Desmob'!AC43 -> 0 | M31: ='Francisco de Morais-Desmob'!AK43 -> 0
A32: SET | B32: ='Rute - Devolvido'!H45 -> 3635 | C32: =SUM(5000-B32) -> 1365 | D32: ='Rute - Devolvido'!U46 -> 2024.56 | E32: ='Rute - Devolvido'!AC46 -> 0 | F32: ='Rute - Devolvido'!AK46 -> 0 | H32: SET | I32: ='Francisco de Morais-Desmob'!H46 -> 2920 | J32: =SUM(5000-I32) -> 2080 | K32: ='Francisco de Morais-Desmob'!U47 -> 1772.46 | L32: ='Francisco de Morais-Desmob'!AC47 -> 0 | M32: ='Francisco de Morais-Desmob'!AK47 -> 0
A33: OUT | B33: ='Rute - Devolvido'!H49 -> -47094 | C33: =SUM(5000-B33) -> 52094 | D33: ='Rute - Devolvido'!U50 -> 3211.82 | E33: ='Rute - Devolvido'!AC50 -> 0 | F33: ='Rute - Devolvido'!AK50 -> 0 | H33: OUT | I33: ='Francisco de Morais-Desmob'!H50 -> 5903 | J33: =SUM(5000-I33) -> -903 | K33: ='Francisco de Morais-Desmob'!U51 -> 2663.2 | L33: ='Francisco de Morais-Desmob'!AC51 -> 0 | M33: ='Francisco de Morais-Desmob'!AK51 -> 0
A34: NOV | B34: ='Rute - Devolvido'!H53 -> 0 | C34: =SUM(5000-B34) -> 5000 | D34: ='Rute - Devolvido'!U54 -> 1537.92 | E34: ='Rute - Devolvido'!AC54 -> 0 | F34: ='Rute - Devolvido'!AK54 -> 0 | H34: NOV | I34: ='Francisco de Morais-Desmob'!H54 -> 2037 | J34: =SUM(5000-I34) -> 2963 | K34: ='Francisco de Morais-Desmob'!U55 -> 1435.54 | L34: ='Francisco de Morais-Desmob'!AC55 -> 0 | M34: ='Francisco de Morais-Desmob'!AK55 -> 0
A35: DEZ | B35: ='Rute - Devolvido'!H57 -> 2601 | C35: =SUM(5000-B35) -> 2399 | D35: ='Rute - Devolvido'!U58 -> 2161.45 | E35: ='Rute - Devolvido'!AC58 -> 45 | F35: ='Rute - Devolvido'!AK58 -> 0 | H35: DEZ | I35: ='Francisco de Morais-Desmob'!H58 -> 3916 | J35: =SUM(5000-I35) -> 1084 | K35: ='Francisco de Morais-Desmob'!U59 -> 1745.31 | L35: ='Francisco de Morais-Desmob'!AC59 -> 0 | M35: ='Francisco de Morais-Desmob'!AK59 -> 0
A37: TOTAL | B37: =SUM(B24:B35) -> -39203 | D37: =SUM(D24:D35) -> 10174.85 | E37: =SUM(E24:E35) -> 45 | F37: =SUM(F24:F35) -> 0 | H37: TOTAL | I37: =SUM(I24:I35) -> 14776 | K37: =SUM(K24:K35) -> 7616.51 | L37: =SUM(L24:L35) -> 0 | M37: =SUM(M24:M35) -> 0
A38: SALDO KM | B38: =SUM(60000-B37) -> 99203 | H38: SALDO KM | I38: =SUM(60000-I37) -> 45224
B41: CAR 05 | I41: CAR 06
B42: KM RODADO | C42: KM MENSAL | D42: ABASTECIMENTO | E42: LAVA JATO | F42: BORRACHARIA | I42: KM RODADO | J42: KM MENSAL | K42: ABASTECIMENTO | L42: LAVA JATO | M42: BORRACHARIA
A43: JAN | B43: ='Washington-Devolvido'!H14 -> 2055 | C43: =SUM(5000-B43) -> 2945 | D43: ='Washington-Devolvido'!U15 -> 1045.42 | E43: ='Washington-Devolvido'!AC15 -> 45 | F43: ='Washington-Devolvido'!AK15 -> 0 | H43: JAN | I43: ='Francisco de Morais'!H13 -> 0 | J43: =SUM(5000-I43) -> 5000 | K43: ='Francisco de Morais'!U14 -> 0 | L43: ='Francisco de Morais'!AC14 -> 0 | M43: ='Francisco de Morais'!AK14 -> 0
A44: FEV | B44: ='Washington-Devolvido'!H18 -> 4253 | C44: =SUM(5000-B44) -> 747 | D44: ='Washington-Devolvido'!U19 -> 1960.31 | E44: ='Washington-Devolvido'!AC19 -> 45 | F44: ='Washington-Devolvido'!AK19 -> 0 | H44: FEV | I44: ='Francisco de Morais'!H17 -> 0 | J44: =SUM(5000-I44) -> 5000 | K44: ='Francisco de Morais'!U18 -> 0 | L44: ='Francisco de Morais'!AC18 -> 0 | M44: ='Francisco de Morais'!AK18 -> 0
A45: MAR | B45: ='Washington-Devolvido'!H22 -> 4514 | C45: =SUM(5000-B45) -> 486 | D45: ='Washington-Devolvido'!U23 -> 2218.6 | E45: ='Washington-Devolvido'!AC23 -> 45 | F45: ='Washington-Devolvido'!AK23 -> 0 | H45: MAR | I45: ='Francisco de Morais'!H21 -> 1419 | J45: =SUM(5000-I45) -> 3581 | K45: ='Francisco de Morais'!U22 -> 0 | L45: ='Francisco de Morais'!AC22 -> 0 | M45: ='Francisco de Morais'!AK22 -> 0
A46: ABR | B46: ='Washington-Devolvido'!H26 -> 4050 | C46: =SUM(5000-B46) -> 950 | D46: ='Washington-Devolvido'!U27 -> 2484.87 | E46: ='Washington-Devolvido'!AC27 -> 0 | F46: ='Washington-Devolvido'!AK27 -> 0 | H46: ABR | I46: ='Francisco de Morais'!H25 -> 1576 | J46: =SUM(5000-I46) -> 3424 | K46: ='Francisco de Morais'!U26 -> 0 | L46: ='Francisco de Morais'!AC26 -> 0 | M46: ='Francisco de Morais'!AK26 -> 0
A47: MAI | B47: ='Washington-Devolvido'!H30 -> 5120 | C47: =SUM(5000-B47) -> -120 | D47: ='Washington-Devolvido'!U31 -> 2290.46 | E47: ='Washington-Devolvido'!AC31 -> 0 | F47: ='Washington-Devolvido'!AK31 -> 0 | H47: MAI | I47: ='Francisco de Morais'!H29 -> 3793 | J47: =SUM(5000-I47) -> 1207 | K47: ='Francisco de Morais'!U30 -> 0 | L47: ='Francisco de Morais'!AC30 -> 0 | M47: ='Francisco de Morais'!AK30 -> 0
...

Sheet Luis Daladiuer
B1: GESTÃO DE FROTAS
B2: CONTROLE DE QUILOMETRAGEM, ABASTECIMENTOS, LAVAGENS E SERVIÇOS DE BORRACHARIA
A4: Veiculo: | B4: Renegade | D4: Placa: | E4: TXL2A88 | G4: km | H4: 3000
A6: Contrato Locação: | B6: 3837 | D6: Rastreador: | E6: Unidas - 3S | G6: Data mob.: | H6: 46119
A9: REGISTRO DE KM | J9: ABASTECIMENTO | W9: LAVA JATO | AE9: BORRACHARIA
B11: Janeiro | J11: Janeiro | W11: Janeiro | AE11: Janeiro
A12: KM (Rodados) | B12: 1ª Leitura | C12: 2ª Leitura | D12: 3ª Leitura | E12: 4ª Leitura | F12: 15 dias Rodados | G12: 30 dias Rodados | H12: Total Mensal | J12: DATA | W12: DATA | AE12: DATA
F13: =SUM(C13-B13) -> 0 | G13: =SUM(E13-D13) -> 0 | H13: =SUM(F13:G13) -> 0 | J13: VALOR | W13: VALOR | AE13: VALOR
T14: TOTAL | U14: =SUM(K13:U13) -> 0 | AB14: TOTAL | AC14: =SUM(X13:AC13) -> 0 | AJ14: TOTAL | AK14: =SUM(AF13:AK13) -> 0
B15: Fevereiro | J15: Fevereiro | W15: Fevereiro | AE15: Fevereiro
A16: KM (Rodados) | B16: 1ª Leitura | C16: 2ª Leitura | D16: 3ª Leitura | E16: 4ª Leitura | F16: 15 dias Rodados | G16: 30 dias Rodados | H16: Total Mensal | J16: DATA | W16: DATA | AE16: DATA
F17: =SUM(C17-B17) -> 0 | G17: =SUM(E17-D17) -> 0 | H17: =SUM(F17:G17) -> 0 | J17: VALOR | W17: VALOR | AE17: VALOR
T18: TOTAL | U18: =SUM(K17:U17) -> 0 | AB18: TOTAL | AC18: =SUM(X17:AC17) -> 0 | AJ18: TOTAL | AK18: =SUM(AF17:AK17) -> 0
B19: Março | J19: Março | W19: =J19 -> Março | AE19: =W19 -> Março
A20: KM (Rodados) | B20: 1ª Leitura | C20: 2ª Leitura | D20: 3ª Leitura | E20: 4ª Leitura | F20: 15 dias Rodados | G20: 30 dias Rodados | H20: Total Mensal | J20: DATA | W20: DATA | AE20: DATA
F21: =SUM(C21-B21) -> 0 | G21: =SUM(E21-D21) -> 0 | H21: =SUM(F21:G21) -> 0 | J21: VALOR | W21: VALOR | AE21: VALOR
T22: TOTAL | U22: =SUM(K21:U21) -> 0 | AB22: TOTAL | AC22: =SUM(X21:AC21) -> 0 | AJ22: TOTAL | AK22: =SUM(AF21:AK21) -> 0
B23: Abril | J23: Abril | W23: =J23 -> Abril | AE23: =W23 -> Abril
A24: KM (Rodados) | B24: 1ª Leitura | C24: 2ª Leitura | D24: 3ª Leitura | E24: 4ª Leitura | F24: 15 dias Rodados | G24: 30 dias Rodados | H24: Total Mensal | J24: DATA | W24: DATA | AE24: DATA
B25: 15565 | E25: 18218 | F25: =SUM(C25-B25) -> -15565 | G25: =SUM(E25-D25) -> 18218 | H25: =SUM(F25:G25) -> 2653 | J25: VALOR | W25: VALOR | AE25: VALOR
T26: TOTAL | U26: =SUM(K25:U25) -> 0 | AB26: TOTAL | AC26: =SUM(X25:AC25) -> 0 | AJ26: TOTAL | AK26: =SUM(AF25:AK25) -> 0
B27: Maio | J27: Maio | W27: =J27 -> Maio | AE27: =W27 -> Maio
A28: KM (Rodados) | B28: 1ª Leitura | C28: 2ª Leitura | D28: 3ª Leitura | E28: 4ª Leitura | F28: 15 dias Rodados | G28: 30 dias Rodados | H28: Total Mensal | J28: DATA | W28: DATA | AE28: DATA
B29: 18218 | E29: 21063 | F29: =SUM(C29-B29) -> -18218 | G29: =SUM(E29-D29) -> 21063 | H29: =SUM(F29:G29) -> 2845 | J29: VALOR | W29: VALOR | AE29: VALOR
T30: TOTAL | U30: =SUM(K29:U29) -> 0 | AB30: TOTAL | AC30: =SUM(X29:AC29) -> 0 | AJ30: TOTAL | AK30: =SUM(AF29:AK29) -> 0
B31: Junho | J31: Junho | W31: =J31 -> Junho | AE31: =W31 -> Junho
A32: KM (Rodados) | B32: 1ª Leitura | C32: 2ª Leitura | D32: 3ª Leitura | E32: 4ª Leitura | F32: 15 dias Rodados | G32: 30 dias Rodados | H32: Total Mensal | J32: DATA | W32: DATA | AE32: DATA
F33: =SUM(C33-B33) -> 0 | G33: =SUM(E33-D33) -> 0 | H33: =SUM(F33:G33) -> 0 | J33: VALOR | W33: VALOR | AE33: VALOR
T34: TOTAL | U34: =SUM(K33:U33) -> 0 | AB34: TOTAL | AC34: =SUM(X33:AC33) -> 0 | AJ34: TOTAL | AK34: =SUM(AF33:AK33) -> 0
B35: Julho | J35: Julho | W35: =J35 -> Julho | AE35: =W35 -> Julho
A36: KM (Rodados) | B36: 1ª Leitura | C36: 2ª Leitura | D36: 3ª Leitura | E36: 4ª Leitura | F36: 15 dias Rodados | G36: 30 dias Rodados | H36: Total Mensal | J36: DATA | W36: DATA | AE36: DATA
F37: =SUM(C37-B37) -> 0 | G37: =SUM(E37-D37) -> 0 | H37: =SUM(F37:G37) -> 0 | J37: VALOR | W37: VALOR | AE37: VALOR
T38: TOTAL | U38: =SUM(K37:U37) -> 0 | AB38: TOTAL | AC38: =SUM(X37:AC37) -> 0 | AJ38: TOTAL | AK38: =SUM(AF37:AK37) -> 0
B39: Agosto | J39: Agosto | W39: =J39 -> Agosto | AE39: =W39 -> Agosto
A40: KM (Rodados) | B40: 1ª Leitura | C40: 2ª Leitura | D40: 3ª Leitura | E40: 4ª Leitura | F40: 15 dias Rodados | G40: 30 dias Rodados | H40: Total Mensal | J40: DATA | W40: DATA | AE40: DATA
F41: =SUM(C41-B41) -> 0 | G41: =SUM(E41-D41) -> 0 | H41: =SUM(F41:G41) -> 0 | J41: VALOR | W41: VALOR | AE41: VALOR
T42: TOTAL | U42: =SUM(K41:U41) -> 0 | AB42: TOTAL | AC42: =SUM(X41:AC41) -> 0 | AJ42: TOTAL | AK42: =SUM(AF41:AK41) -> 0
B43: Setembro | J43: Setembro | W43: =J43 -> Setembro | AE43: =W43 -> Setembro
A44: KM (Rodados) | B44: 1ª Leitura | C44: 2ª Leitura | D44: 3ª Leitura | E44: 4ª Leitura | F44: 15 dias Rodados | G44: 30 dias Rodados | H44: Total Mensal | J44: DATA | W44: DATA | AE44: DATA
F45: =SUM(C45-B45) -> 0 | G45: =SUM(E45-D45) -> 0 | H45: =SUM(F45:G45) -> 0 | J45: VALOR | W45: VALOR | AE45: VALOR
...

Sheet Ronieri
B1: GESTÃO DE FROTAS
B2: CONTROLE DE QUILOMETRAGEM, ABASTECIMENTOS, LAVAGENS E SERVIÇOS DE BORRACHARIA
A4: Veiculo: | B4: Tera | D4: Placa: | E4: TXE1H23 | G4: km | H4: 3000
A6: Contrato Locação: | B6: 3837 | D6: Rastreador: | E6: Rastreador Unidas | G6: Data mob.: | H6: 46076
A9: REGISTRO DE KM | J9: ABASTECIMENTO | W9: LAVA JATO | AE9: BORRACHARIA
B11: Janeiro | J11: Janeiro | W11: Janeiro | AE11: Janeiro
A12: KM (Rodados) | B12: 1ª Leitura | C12: 2ª Leitura | D12: 3ª Leitura | E12: 4ª Leitura | F12: 15 dias Rodados | G12: 30 dias Rodados | H12: Total Mensal | J12: DATA | W12: DATA | AE12: DATA
F13: =SUM(C13-B13) -> 0 | G13: =SUM(E13-D13) -> 0 | H13: =SUM(F13:G13) -> 0 | J13: VALOR | W13: VALOR | AE13: VALOR
T14: TOTAL | U14: =SUM(K13:U13) -> 0 | AB14: TOTAL | AC14: =SUM(X13:AC13) -> 0 | AJ14: TOTAL | AK14: =SUM(AF13:AK13) -> 0
B15: Fevereiro | J15: Fevereiro | W15: Fevereiro | AE15: Fevereiro
A16: KM (Rodados) | B16: 1ª Leitura | C16: 2ª Leitura | D16: 3ª Leitura | E16: 4ª Leitura | F16: 15 dias Rodados | G16: 30 dias Rodados | H16: Total Mensal | J16: DATA | W16: DATA | AE16: DATA
D17: 13613 | E17: 14629 | F17: =SUM(C17-B17) -> 0 | G17: =SUM(E17-D17) -> 1016 | H17: =SUM(F17:G17) -> 1016 | J17: VALOR | W17: VALOR | AE17: VALOR
T18: TOTAL | U18: =SUM(K17:U17) -> 0 | AB18: TOTAL | AC18: =SUM(X17:AC17) -> 0 | AJ18: TOTAL | AK18: =SUM(AF17:AK17) -> 0
B19: Março | J19: Março | W19: =J19 -> Março | AE19: =W19 -> Março
A20: KM (Rodados) | B20: 1ª Leitura | C20: 2ª Leitura | D20: 3ª Leitura | E20: 4ª Leitura | F20: 15 dias Rodados | G20: 30 dias Rodados | H20: Total Mensal | J20: DATA | W20: DATA | AE20: DATA
B21: 14629 | E21: 17874 | F21: =SUM(C21-B21) -> -14629 | G21: =SUM(E21-D21) -> 17874 | H21: =SUM(F21:G21) -> 3245 | J21: VALOR | W21: VALOR | AE21: VALOR
T22: TOTAL | U22: =SUM(K21:U21) -> 0 | AB22: TOTAL | AC22: =SUM(X21:AC21) -> 0 | AJ22: TOTAL | AK22: =SUM(AF21:AK21) -> 0
B23: Abril | J23: Abril | W23: =J23 -> Abril | AE23: =W23 -> Abril
A24: KM (Rodados) | B24: 1ª Leitura | C24: 2ª Leitura | D24: 3ª Leitura | E24: 4ª Leitura | F24: 15 dias Rodados | G24: 30 dias Rodados | H24: Total Mensal | J24: DATA | W24: DATA | AE24: DATA
B25: 17874 | E25: 20837 | F25: =SUM(C25-B25) -> -17874 | G25: =SUM(E25-D25) -> 20837 | H25: =SUM(F25:G25) -> 2963 | J25: VALOR | W25: VALOR | AE25: VALOR
T26: TOTAL | U26: =SUM(K25:U25) -> 0 | AB26: TOTAL | AC26: =SUM(X25:AC25) -> 0 | AJ26: TOTAL | AK26: =SUM(AF25:AK25) -> 0
B27: Maio | J27: Maio | W27: =J27 -> Maio | AE27: =W27 -> Maio
A28: KM (Rodados) | B28: 1ª Leitura | C28: 2ª Leitura | D28: 3ª Leitura | E28: 4ª Leitura | F28: 15 dias Rodados | G28: 30 dias Rodados | H28: Total Mensal | J28: DATA | W28: DATA | AE28: DATA
B29: 20837 | E29: 23490 | F29: =SUM(C29-B29) -> -20837 | G29: =SUM(E29-D29) -> 23490 | H29: =SUM(F29:G29) -> 2653 | J29: VALOR | W29: VALOR | AE29: VALOR
T30: TOTAL | U30: =SUM(K29:U29) -> 0 | AB30: TOTAL | AC30: =SUM(X29:AC29) -> 0 | AJ30: TOTAL | AK30: =SUM(AF29:AK29) -> 0
B31: Junho | J31: Junho | W31: =J31 -> Junho | AE31: =W31 -> Junho
A32: KM (Rodados) | B32: 1ª Leitura | C32: 2ª Leitura | D32: 3ª Leitura | E32: 4ª Leitura | F32: 15 dias Rodados | G32: 30 dias Rodados | H32: Total Mensal | J32: DATA | W32: DATA | AE32: DATA
F33: =SUM(C33-B33) -> 0 | G33: =SUM(E33-D33) -> 0 | H33: =SUM(F33:G33) -> 0 | J33: VALOR | W33: VALOR | AE33: VALOR
T34: TOTAL | U34: =SUM(K33:U33) -> 0 | AB34: TOTAL | AC34: =SUM(X33:AC33) -> 0 | AJ34: TOTAL | AK34: =SUM(AF33:AK33) -> 0
B35: Julho | J35: Julho | W35: =J35 -> Julho | AE35: =W35 -> Julho
A36: KM (Rodados) | B36: 1ª Leitura | C36: 2ª Leitura | D36: 3ª Leitura | E36: 4ª Leitura | F36: 15 dias Rodados | G36: 30 dias Rodados | H36: Total Mensal | J36: DATA | W36: DATA | AE36: DATA
F37: =SUM(C37-B37) -> 0 | G37: =SUM(E37-D37) -> 0 | H37: =SUM(F37:G37) -> 0 | J37: VALOR | W37: VALOR | AE37: VALOR
T38: TOTAL | U38: =SUM(K37:U37) -> 0 | AB38: TOTAL | AC38: =SUM(X37:AC37) -> 0 | AJ38: TOTAL | AK38: =SUM(AF37:AK37) -> 0
B39: Agosto | J39: Agosto | W39: =J39 -> Agosto | AE39: =W39 -> Agosto
A40: KM (Rodados) | B40: 1ª Leitura | C40: 2ª Leitura | D40: 3ª Leitura | E40: 4ª Leitura | F40: 15 dias Rodados | G40: 30 dias Rodados | H40: Total Mensal | J40: DATA | W40: DATA | AE40: DATA
F41: =SUM(C41-B41) -> 0 | G41: =SUM(E41-D41) -> 0 | H41: =SUM(F41:G41) -> 0 | J41: VALOR | W41: VALOR | AE41: VALOR
T42: TOTAL | U42: =SUM(K41:U41) -> 0 | AB42: TOTAL | AC42: =SUM(X41:AC41) -> 0 | AJ42: TOTAL | AK42: =SUM(AF41:AK41) -> 0
B43: Setembro | J43: Setembro | W43: =J43 -> Setembro | AE43: =W43 -> Setembro
A44: KM (Rodados) | B44: 1ª Leitura | C44: 2ª Leitura | D44: 3ª Leitura | E44: 4ª Leitura | F44: 15 dias Rodados | G44: 30 dias Rodados | H44: Total Mensal | J44: DATA | W44: DATA | AE44: DATA
F45: =SUM(C45-B45) -> 0 | G45: =SUM(E45-D45) -> 0 | H45: =SUM(F45:G45) -> 0 | J45: VALOR | W45: VALOR | AE45: VALOR
...

Sheet Francisco Augusto
B1: GESTÃO DE FROTAS
B2: CONTROLE DE QUILOMETRAGEM, ABASTECIMENTOS, LAVAGENS E SERVIÇOS DE BORRACHARIA
A4: Veiculo: | B4: Creta | D4: Placa: | E4: TXZ1G58 | G4: KM | H4: 3000
A5: Troca de Condutor: | B5: 46039 | D5: Placa: | E5: TXZ1G58 | G5: Condutores: | H5: De Jurandir para Francisco Augusto
A6: Contrato Locação: | B6: 3837 | D6: Rastreador: | E6: 45 | G6: Data mob.: | H6: 46026
A9: REGISTRO DE KM | J9: ABASTECIMENTO | W9: LAVA JATO | AE9: BORRACHARIA
B11: Janeiro | J11: Janeiro | W11: Janeiro | AE11: Janeiro
A12: KM (Rodados) | B12: 1ª Leitura | C12: 2ª Leitura | D12: 3ª Leitura | E12: 4ª Leitura | F12: 15 dias Rodados | G12: 30 dias Rodados | H12: Total Mensal | J12: DATA | W12: DATA | AE12: DATA
B13: 4281 | C13: 6312 | D13: 6312 | E13: 8327 | F13: =SUM(C13-B13) -> 2031 | G13: =SUM(E13-D13) -> 2015 | H13: =SUM(F13:G13) -> 4046 | J13: VALOR | W13: VALOR | AE13: VALOR
T14: TOTAL | U14: =SUM(K13:U13) -> 0 | AB14: TOTAL | AC14: =SUM(X13:AC13) -> 0 | AJ14: TOTAL | AK14: =SUM(AF13:AK13) -> 0
B15: Fevereiro | J15: Fevereiro | W15: Fevereiro | AE15: Fevereiro
A16: KM (Rodados) | B16: 1ª Leitura | C16: 2ª Leitura | D16: 3ª Leitura | E16: 4ª Leitura | F16: 15 dias Rodados | G16: 30 dias Rodados | H16: Total Mensal | J16: DATA | K16: 46056 | L16: 46060 | M16: 46063 | N16: 46065 | O16: 46074 | P16: 46077 | Q16: 46079 | W16: DATA | AE16: DATA
B17: 8327 | E17: 11107 | F17: =SUM(C17-B17) -> -8327 | G17: =SUM(E17-D17) -> 11107 | H17: =SUM(F17:G17) -> 2780 | J17: VALOR | K17: 217.28 | L17: 203.33 | M17: 204.47 | N17: 205.11 | O17: 241.74 | P17: 179.12 | Q17: 199.76 | W17: VALOR | AE17: VALOR
T18: TOTAL | U18: =SUM(K17:U17) -> 1450.81 | AB18: TOTAL | AC18: =SUM(X17:AC17) -> 0 | AJ18: TOTAL | AK18: =SUM(AF17:AK17) -> 0
B19: Março | J19: Março | W19: =J19 -> Março | AE19: =W19 -> Março
A20: KM (Rodados) | B20: 1ª Leitura | C20: 2ª Leitura | D20: 3ª Leitura | E20: 4ª Leitura | F20: 15 dias Rodados | G20: 30 dias Rodados | H20: Total Mensal | J20: DATA | W20: DATA | AE20: DATA
B21: 11107 | E21: 13602 | F21: =SUM(C21-B21) -> -11107 | G21: =SUM(E21-D21) -> 13602 | H21: =SUM(F21:G21) -> 2495 | J21: VALOR | W21: VALOR | AE21: VALOR
T22: TOTAL | U22: =SUM(K21:U21) -> 0 | AB22: TOTAL | AC22: =SUM(X21:AC21) -> 0 | AJ22: TOTAL | AK22: =SUM(AF21:AK21) -> 0
B23: Abril | J23: Abril | W23: =J23 -> Abril | AE23: =W23 -> Abril
A24: KM (Rodados) | B24: 1ª Leitura | C24: 2ª Leitura | D24: 3ª Leitura | E24: 4ª Leitura | F24: 15 dias Rodados | G24: 30 dias Rodados | H24: Total Mensal | J24: DATA | W24: DATA | AE24: DATA
B25: 13602 | E25: 15974 | F25: =SUM(C25-B25) -> -13602 | G25: =SUM(E25-D25) -> 15974 | H25: =SUM(F25:G25) -> 2372 | J25: VALOR | W25: VALOR | AE25: VALOR
T26: TOTAL | U26: =SUM(K25:U25) -> 0 | AB26: TOTAL | AC26: =SUM(X25:AC25) -> 0 | AJ26: TOTAL | AK26: =SUM(AF25:AK25) -> 0
B27: Maio | J27: Maio | W27: =J27 -> Maio | AE27: =W27 -> Maio
A28: KM (Rodados) | B28: 1ª Leitura | C28: 2ª Leitura | D28: 3ª Leitura | E28: 4ª Leitura | F28: 15 dias Rodados | G28: 30 dias Rodados | H28: Total Mensal | J28: DATA | W28: DATA | AE28: DATA
B29: 15974 | E29: 19400 | F29: =SUM(C29-B29) -> -15974 | G29: =SUM(E29-D29) -> 19400 | H29: =SUM(F29:G29) -> 3426 | J29: VALOR | W29: VALOR | AE29: VALOR
T30: TOTAL | U30: =SUM(K29:U29) -> 0 | AB30: TOTAL | AC30: =SUM(X29:AC29) -> 0 | AJ30: TOTAL | AK30: =SUM(AF29:AK29) -> 0
B31: Junho | J31: Junho | W31: =J31 -> Junho | AE31: =W31 -> Junho
A32: KM (Rodados) | B32: 1ª Leitura | C32: 2ª Leitura | D32: 3ª Leitura | E32: 4ª Leitura | F32: 15 dias Rodados | G32: 30 dias Rodados | H32: Total Mensal | J32: DATA | W32: DATA | AE32: DATA
F33: =SUM(C33-B33) -> 0 | G33: =SUM(E33-D33) -> 0 | H33: =SUM(F33:G33) -> 0 | J33: VALOR | W33: VALOR | AE33: VALOR
T34: TOTAL | U34: =SUM(K33:U33) -> 0 | AB34: TOTAL | AC34: =SUM(X33:AC33) -> 0 | AJ34: TOTAL | AK34: =SUM(AF33:AK33) -> 0
B35: Julho | J35: Julho | W35: =J35 -> Julho | AE35: =W35 -> Julho
A36: KM (Rodados) | B36: 1ª Leitura | C36: 2ª Leitura | D36: 3ª Leitura | E36: 4ª Leitura | F36: 15 dias Rodados | G36: 30 dias Rodados | H36: Total Mensal | J36: DATA | W36: DATA | AE36: DATA
F37: =SUM(C37-B37) -> 0 | G37: =SUM(E37-D37) -> 0 | H37: =SUM(F37:G37) -> 0 | J37: VALOR | W37: VALOR | AE37: VALOR
T38: TOTAL | U38: =SUM(K37:U37) -> 0 | AB38: TOTAL | AC38: =SUM(X37:AC37) -> 0 | AJ38: TOTAL | AK38: =SUM(AF37:AK37) -> 0
B39: Agosto | J39: Agosto | W39: =J39 -> Agosto | AE39: =W39 -> Agosto
A40: KM (Rodados) | B40: 1ª Leitura | C40: 2ª Leitura | D40: 3ª Leitura | E40: 4ª Leitura | F40: 15 dias Rodados | G40: 30 dias Rodados | H40: Total Mensal | J40: DATA | W40: DATA | AE40: DATA
F41: =SUM(C41-B41) -> 0 | G41: =SUM(E41-D41) -> 0 | H41: =SUM(F41:G41) -> 0 | J41: VALOR | W41: VALOR | AE41: VALOR
T42: TOTAL | U42: =SUM(K41:U41) -> 0 | AB42: TOTAL | AC42: =SUM(X41:AC41) -> 0 | AJ42: TOTAL | AK42: =SUM(AF41:AK41) -> 0
B43: Setembro | J43: Setembro | W43: =J43 -> Setembro | AE43: =W43 -> Setembro
A44: KM (Rodados) | B44: 1ª Leitura | C44: 2ª Leitura | D44: 3ª Leitura | E44: 4ª Leitura | F44: 15 dias Rodados | G44: 30 dias Rodados | H44: Total Mensal | J44: DATA | W44: DATA | AE44: DATA
...

Sheet Francisco de Morais
B1: GESTÃO DE FROTAS
B2: CONTROLE DE QUILOMETRAGEM, ABASTECIMENTOS, LAVAGENS E SERVIÇOS DE BORRACHARIA
A4: Veiculo: | B4: Creta | D4: Placa: | E4: TXW4I69 | G4: KM | H4: 3000
A6: Contrato Locação: | B6: 3837 | D6: Rastreador: | E6: Unidas | G6: Data mob.: | H6: 46102
A9: REGISTRO DE KM | J9: ABASTECIMENTO | W9: LAVA JATO | AE9: BORRACHARIA
B11: Janeiro | J11: Janeiro | W11: Janeiro | AE11: Janeiro
A12: KM (Rodados) | B12: 1ª Leitura | C12: 2ª Leitura | D12: 3ª Leitura | E12: 4ª Leitura | F12: 15 dias Rodados | G12: 30 dias Rodados | H12: Total Mensal | J12: DATA | W12: DATA | AE12: DATA
F13: =SUM(C13-B13) -> 0 | G13: =SUM(E13-D13) -> 0 | H13: =SUM(F13:G13) -> 0 | J13: VALOR | W13: VALOR | AE13: VALOR
T14: TOTAL | U14: =SUM(K13:U13) -> 0 | AB14: TOTAL | AC14: =SUM(X13:AC13) -> 0 | AJ14: TOTAL | AK14: =SUM(AF13:AK13) -> 0
B15: Fevereiro | J15: Fevereiro | W15: Fevereiro | AE15: Fevereiro
A16: KM (Rodados) | B16: 1ª Leitura | C16: 2ª Leitura | D16: 3ª Leitura | E16: 4ª Leitura | F16: 15 dias Rodados | G16: 30 dias Rodados | H16: Total Mensal | J16: DATA | W16: DATA | AE16: DATA
F17: =SUM(C17-B17) -> 0 | G17: =SUM(E17-D17) -> 0 | H17: =SUM(F17:G17) -> 0 | J17: VALOR | W17: VALOR | AE17: VALOR
T18: TOTAL | U18: =SUM(K17:U17) -> 0 | AB18: TOTAL | AC18: =SUM(X17:AC17) -> 0 | AJ18: TOTAL | AK18: =SUM(AF17:AK17) -> 0
B19: Março | J19: Março | W19: =J19 -> Março | AE19: =W19 -> Março
A20: KM (Rodados) | B20: 1ª Leitura | C20: 2ª Leitura | D20: 3ª Leitura | E20: 4ª Leitura | F20: 15 dias Rodados | G20: 30 dias Rodados | H20: Total Mensal | J20: DATA | W20: DATA | AE20: DATA
D21: 10690 | E21: 12109 | F21: =SUM(C21-B21) -> 0 | G21: =SUM(E21-D21) -> 1419 | H21: =SUM(F21:G21) -> 1419 | J21: VALOR | W21: VALOR | AE21: VALOR
T22: TOTAL | U22: =SUM(K21:U21) -> 0 | AB22: TOTAL | AC22: =SUM(X21:AC21) -> 0 | AJ22: TOTAL | AK22: =SUM(AF21:AK21) -> 0
B23: Abril | J23: Abril | W23: =J23 -> Abril | AE23: =W23 -> Abril
A24: KM (Rodados) | B24: 1ª Leitura | C24: 2ª Leitura | D24: 3ª Leitura | E24: 4ª Leitura | F24: 15 dias Rodados | G24: 30 dias Rodados | H24: Total Mensal | J24: DATA | W24: DATA | AE24: DATA
B25: 12109 | E25: 13685 | F25: =SUM(C25-B25) -> -12109 | G25: =SUM(E25-D25) -> 13685 | H25: =SUM(F25:G25) -> 1576 | J25: VALOR | W25: VALOR | AE25: VALOR
T26: TOTAL | U26: =SUM(K25:U25) -> 0 | AB26: TOTAL | AC26: =SUM(X25:AC25) -> 0 | AJ26: TOTAL | AK26: =SUM(AF25:AK25) -> 0
B27: Maio | J27: Maio | W27: =J27 -> Maio | AE27: =W27 -> Maio
A28: KM (Rodados) | B28: 1ª Leitura | C28: 2ª Leitura | D28: 3ª Leitura | E28: 4ª Leitura | F28: 15 dias Rodados | G28: 30 dias Rodados | H28: Total Mensal | J28: DATA | W28: DATA | AE28: DATA
B29: 13685 | E29: 17478 | F29: =SUM(C29-B29) -> -13685 | G29: =SUM(E29-D29) -> 17478 | H29: =SUM(F29:G29) -> 3793 | J29: VALOR | W29: VALOR | AE29: VALOR
T30: TOTAL | U30: =SUM(K29:U29) -> 0 | AB30: TOTAL | AC30: =SUM(X29:AC29) -> 0 | AJ30: TOTAL | AK30: =SUM(AF29:AK29) -> 0
B31: Junho | J31: Junho | W31: =J31 -> Junho | AE31: =W31 -> Junho
A32: KM (Rodados) | B32: 1ª Leitura | C32: 2ª Leitura | D32: 3ª Leitura | E32: 4ª Leitura | F32: 15 dias Rodados | G32: 30 dias Rodados | H32: Total Mensal | J32: DATA | W32: DATA | AE32: DATA
F33: =SUM(C33-B33) -> 0 | G33: =SUM(E33-D33) -> 0 | H33: =SUM(F33:G33) -> 0 | J33: VALOR | W33: VALOR | AE33: VALOR
T34: TOTAL | U34: =SUM(K33:U33) -> 0 | AB34: TOTAL | AC34: =SUM(X33:AC33) -> 0 | AJ34: TOTAL | AK34: =SUM(AF33:AK33) -> 0
B35: Julho | J35: Julho | W35: =J35 -> Julho | AE35: =W35 -> Julho
A36: KM (Rodados) | B36: 1ª Leitura | C36: 2ª Leitura | D36: 3ª Leitura | E36: 4ª Leitura | F36: 15 dias Rodados | G36: 30 dias Rodados | H36: Total Mensal | J36: DATA | W36: DATA | AE36: DATA
F37: =SUM(C37-B37) -> 0 | G37: =SUM(E37-D37) -> 0 | H37: =SUM(F37:G37) -> 0 | J37: VALOR | W37: VALOR | AE37: VALOR
T38: TOTAL | U38: =SUM(K37:U37) -> 0 | AB38: TOTAL | AC38: =SUM(X37:AC37) -> 0 | AJ38: TOTAL | AK38: =SUM(AF37:AK37) -> 0
B39: Agosto | J39: Agosto | W39: =J39 -> Agosto | AE39: =W39 -> Agosto
A40: KM (Rodados) | B40: 1ª Leitura | C40: 2ª Leitura | D40: 3ª Leitura | E40: 4ª Leitura | F40: 15 dias Rodados | G40: 30 dias Rodados | H40: Total Mensal | J40: DATA | W40: DATA | AE40: DATA
F41: =SUM(C41-B41) -> 0 | G41: =SUM(E41-D41) -> 0 | H41: =SUM(F41:G41) -> 0 | J41: VALOR | W41: VALOR | AE41: VALOR
T42: TOTAL | U42: =SUM(K41:U41) -> 0 | AB42: TOTAL | AC42: =SUM(X41:AC41) -> 0 | AJ42: TOTAL | AK42: =SUM(AF41:AK41) -> 0
B43: Setembro | J43: Setembro | W43: =J43 -> Setembro | AE43: =W43 -> Setembro
A44: KM (Rodados) | B44: 1ª Leitura | C44: 2ª Leitura | D44: 3ª Leitura | E44: 4ª Leitura | F44: 15 dias Rodados | G44: 30 dias Rodados | H44: Total Mensal | J44: DATA | W44: DATA | AE44: DATA
F45: =SUM(C45-B45) -> 0 | G45: =SUM(E45-D45) -> 0 | H45: =SUM(F45:G45) -> 0 | J45: VALOR | W45: VALOR | AE45: VALOR
...

Sheet Ana Caroline
B1: GESTÃO DE FROTAS
B2: CONTROLE DE QUILOMETRAGEM, ABASTECIMENTOS, LAVAGENS E SERVIÇOS DE BORRACHARIA
A4: Veiculo: | B4: T-Cross | D4: Placa: | E4: TJE8B31 | G4: KM | H4: 3000
A6: Contrato Locação: | B6: 3837 | D6: Rastreador: | E6: 45 | G6: Data mob.: | H6: 46027
A9: REGISTRO DE KM | J9: ABASTECIMENTO | W9: LAVA JATO | AE9: BORRACHARIA
B11: Janeiro | J11: Janeiro | W11: Janeiro | AE11: Janeiro
A12: KM (Rodados) | B12: 1ª Leitura | C12: 2ª Leitura | D12: 3ª Leitura | E12: 4ª Leitura | F12: 15 dias Rodados | G12: 30 dias Rodados | H12: Total Mensal | J12: DATA | K12: 46030 | L12: 46035 | M12: 46039 | N12: 46044 | O12: 46046 | P12: 46051 | W12: DATA | AE12: DATA
B13: 38576 | E13: 40970 | F13: =SUM(C13-B13) -> -38576 | G13: =SUM(E13-D13) -> 40970 | H13: =SUM(F13:G13) -> 2394 | J13: VALOR | K13: 201.97 | L13: 269.02 | M13: 176.85 | N13: 239.8 | O13: 156.6 | P13: 191.64 | W13: VALOR | AE13: VALOR
T14: TOTAL | U14: =SUM(K13:U13) -> 1235.88 | AB14: TOTAL | AC14: =SUM(X13:AC13) -> 0 | AJ14: TOTAL | AK14: =SUM(AF13:AK13) -> 0
B15: Fevereiro | J15: Fevereiro | W15: Fevereiro | AE15: Fevereiro
A16: KM (Rodados) | B16: 1ª Leitura | C16: 2ª Leitura | D16: 3ª Leitura | E16: 4ª Leitura | F16: 15 dias Rodados | G16: 30 dias Rodados | H16: Total Mensal | J16: DATA | W16: DATA | AE16: DATA
B17: 40970 | E17: 43418 | F17: =SUM(C17-B17) -> -40970 | G17: =SUM(E17-D17) -> 43418 | H17: =SUM(F17:G17) -> 2448 | J17: VALOR | W17: VALOR | AE17: VALOR
T18: TOTAL | U18: =SUM(K17:U17) -> 0 | AB18: TOTAL | AC18: =SUM(X17:AC17) -> 0 | AJ18: TOTAL | AK18: =SUM(AF17:AK17) -> 0
B19: Março | J19: Março | W19: =J19 -> Março | AE19: =W19 -> Março
A20: KM (Rodados) | B20: 1ª Leitura | C20: 2ª Leitura | D20: 3ª Leitura | E20: 4ª Leitura | F20: 15 dias Rodados | G20: 30 dias Rodados | H20: Total Mensal | J20: DATA | W20: DATA | AE20: DATA
B21: 43418 | E21: 45867 | F21: =SUM(C21-B21) -> -43418 | G21: =SUM(E21-D21) -> 45867 | H21: =SUM(F21:G21) -> 2449 | J21: VALOR | W21: VALOR | AE21: VALOR
T22: TOTAL | U22: =SUM(K21:U21) -> 0 | AB22: TOTAL | AC22: =SUM(X21:AC21) -> 0 | AJ22: TOTAL | AK22: =SUM(AF21:AK21) -> 0
B23: Abril | J23: Abril | W23: =J23 -> Abril | AE23: =W23 -> Abril
A24: KM (Rodados) | B24: 1ª Leitura | C24: 2ª Leitura | D24: 3ª Leitura | E24: 4ª Leitura | F24: 15 dias Rodados | G24: 30 dias Rodados | H24: Total Mensal | J24: DATA | W24: DATA | AE24: DATA
B25: 45867 | E25: 47944 | F25: =SUM(C25-B25) -> -45867 | G25: =SUM(E25-D25) -> 47944 | H25: =SUM(F25:G25) -> 2077 | J25: VALOR | W25: VALOR | AE25: VALOR
T26: TOTAL | U26: =SUM(K25:U25) -> 0 | AB26: TOTAL | AC26: =SUM(X25:AC25) -> 0 | AJ26: TOTAL | AK26: =SUM(AF25:AK25) -> 0
B27: Maio | J27: Maio | W27: =J27 -> Maio | AE27: =W27 -> Maio
A28: KM (Rodados) | B28: 1ª Leitura | C28: 2ª Leitura | D28: 3ª Leitura | E28: 4ª Leitura | F28: 15 dias Rodados | G28: 30 dias Rodados | H28: Total Mensal | J28: DATA | W28: DATA | AE28: DATA
B29: 47944 | E29: 50399 | F29: =SUM(C29-B29) -> -47944 | G29: =SUM(E29-D29) -> 50399 | H29: =SUM(F29:G29) -> 2455 | J29: VALOR | W29: VALOR | AE29: VALOR
T30: TOTAL | U30: =SUM(K29:U29) -> 0 | AB30: TOTAL | AC30: =SUM(X29:AC29) -> 0 | AJ30: TOTAL | AK30: =SUM(AF29:AK29) -> 0
B31: Junho | J31: Junho | W31: =J31 -> Junho | AE31: =W31 -> Junho
A32: KM (Rodados) | B32: 1ª Leitura | C32: 2ª Leitura | D32: 3ª Leitura | E32: 4ª Leitura | F32: 15 dias Rodados | G32: 30 dias Rodados | H32: Total Mensal | J32: DATA | W32: DATA | AE32: DATA
F33: =SUM(C33-B33) -> 0 | G33: =SUM(E33-D33) -> 0 | H33: =SUM(F33:G33) -> 0 | J33: VALOR | W33: VALOR | AE33: VALOR
T34: TOTAL | U34: =SUM(K33:U33) -> 0 | AB34: TOTAL | AC34: =SUM(X33:AC33) -> 0 | AJ34: TOTAL | AK34: =SUM(AF33:AK33) -> 0
B35: Julho | J35: Julho | W35: =J35 -> Julho | AE35: =W35 -> Julho
A36: KM (Rodados) | B36: 1ª Leitura | C36: 2ª Leitura | D36: 3ª Leitura | E36: 4ª Leitura | F36: 15 dias Rodados | G36: 30 dias Rodados | H36: Total Mensal | J36: DATA | W36: DATA | AE36: DATA
F37: =SUM(C37-B37) -> 0 | G37: =SUM(E37-D37) -> 0 | H37: =SUM(F37:G37) -> 0 | J37: VALOR | W37: VALOR | AE37: VALOR
T38: TOTAL | U38: =SUM(K37:U37) -> 0 | AB38: TOTAL | AC38: =SUM(X37:AC37) -> 0 | AJ38: TOTAL | AK38: =SUM(AF37:AK37) -> 0
B39: Agosto | J39: Agosto | W39: =J39 -> Agosto | AE39: =W39 -> Agosto
A40: KM (Rodados) | B40: 1ª Leitura | C40: 2ª Leitura | D40: 3ª Leitura | E40: 4ª Leitura | F40: 15 dias Rodados | G40: 30 dias Rodados | H40: Total Mensal | J40: DATA | W40: DATA | AE40: DATA
F41: =SUM(C41-B41) -> 0 | G41: =SUM(E41-D41) -> 0 | H41: =SUM(F41:G41) -> 0 | J41: VALOR | W41: VALOR | AE41: VALOR
T42: TOTAL | U42: =SUM(K41:U41) -> 0 | AB42: TOTAL | AC42: =SUM(X41:AC41) -> 0 | AJ42: TOTAL | AK42: =SUM(AF41:AK41) -> 0
B43: Setembro | J43: Setembro | W43: =J43 -> Setembro | AE43: =W43 -> Setembro
A44: KM (Rodados) | B44: 1ª Leitura | C44: 2ª Leitura | D44: 3ª Leitura | E44: 4ª Leitura | F44: 15 dias Rodados | G44: 30 dias Rodados | H44: Total Mensal | J44: DATA | W44: DATA | AE44: DATA
F45: =SUM(C45-B45) -> 0 | G45: =SUM(E45-D45) -> 0 | H45: =SUM(F45:G45) -> 0 | J45: VALOR | W45: VALOR | AE45: VALOR
...

Sheet Eric
A2: Veiculo | B2: TCROSS | D2: Placa: | E2: EVW1E22 | H2: KM | I2: 5000
A3: Substituição: | B3: 45989 | D3: Placa: | E3: TXL2A44 | H3: Modelo: | I3: Renegade
A4: Troca de Condutor: | B4: 46009 | D4: Placa: | E4: TXL2A44 | H4: Condutores: | I4: De Jurandir para Eric
A5: Contrato de Locação | B5: 4335.99 | D5: Rastreador | E5: 45 | H5: Data mob. MDC | I5: 45578
H6: Mob. VSE | I6: 45748
A7: Veículo foi Mobilizado para obra 24.019 Ventos de Santa Eugenia em 01/04/2025, antes pertencia a obra 24.019 Morro do Cruzeiro.
A8: REGISTRO DE KM | J8: ABASTECIMENTO | W8: LAVA_RAPIDO | AE8: BORRACHARIA
B10: Fevereiro | J10: Fevereiro | W10: Fevereiro | AE10: Fevereiro
A11: KM (Rodados) | B11: 1ª Leitura | C11: 2ª Leitura | D11: 3ª Leitura | E11: 4ª Leitura | F11: 15 dias Rodados | G11: 30 dias Rodados | H11: Total Mensal | J11: DATA | W11: DATA | AE11: DATA
F12: =SUM(C12-B12) -> 0 | G12: =SUM(E12-D12) -> 0 | H12: =SUM(F12:G12) -> 0 | J12: VALOR | W12: VALOR | AE12: VALOR
T13: TOTAL | U13: =SUM(K12:U12) -> 0 | AB13: TOTAL | AC13: =SUM(X12:AC12) -> 0 | AJ13: TOTAL | AK13: =SUM(AF12:AK12) -> 0
B14: Março | J14: Março | W14: =J14 -> Março | AE14: =W14 -> Março
A15: KM (Rodados) | B15: 1ª Leitura | C15: 2ª Leitura | D15: 3ª Leitura | E15: 4ª Leitura | F15: 15 dias Rodados | G15: 30 dias Rodados | H15: Total Mensal | J15: DATA | W15: DATA | AE15: DATA
F16: =SUM(C16-B16) -> 0 | G16: =SUM(E16-D16) -> 0 | H16: =SUM(F16:G16) -> 0 | J16: VALOR | W16: VALOR | AE16: VALOR
T17: TOTAL | U17: =SUM(K16:U16) -> 0 | AB17: TOTAL | AC17: =SUM(X16:AC16) -> 0 | AJ17: TOTAL | AK17: =SUM(AF16:AK16) -> 0
B18: Abril | J18: Abril | W18: =J18 -> Abril | AE18: =W18 -> Abril
A19: KM (Rodados) | B19: 1ª Leitura | C19: 2ª Leitura | D19: 3ª Leitura | E19: 4ª Leitura | F19: 15 dias Rodados | G19: 30 dias Rodados | H19: Total Mensal | J19: DATA | W19: DATA | AE19: DATA
F20: =SUM(C20-B20) -> 0 | G20: =SUM(E20-D20) -> 0 | H20: =SUM(F20:G20) -> 0 | J20: VALOR | W20: VALOR | AE20: VALOR
T21: TOTAL | U21: =SUM(K20:U20) -> 0 | AB21: TOTAL | AC21: =SUM(X20:AC20) -> 0 | AJ21: TOTAL | AK21: =SUM(AF20:AK20) -> 0
B22: Maio | J22: Maio | W22: =J22 -> Maio | AE22: =W22 -> Maio
A23: KM (Rodados) | B23: 1ª Leitura | C23: 2ª Leitura | D23: 3ª Leitura | E23: 4ª Leitura | F23: 15 dias Rodados | G23: 30 dias Rodados | H23: Total Mensal | J23: DATA | W23: DATA | AE23: DATA
F24: =SUM(C24-B24) -> 0 | G24: =SUM(E24-D24) -> 0 | H24: =SUM(F24:G24) -> 0 | J24: VALOR | W24: VALOR | AE24: VALOR
T25: TOTAL | U25: =SUM(K24:U24) -> 0 | AB25: TOTAL | AC25: =SUM(X24:AC24) -> 0 | AJ25: TOTAL | AK25: =SUM(AF24:AK24) -> 0
B26: Junho | J26: Junho | W26: =J26 -> Junho | AE26: =W26 -> Junho
A27: KM (Rodados) | B27: 1ª Leitura | C27: 2ª Leitura | D27: 3ª Leitura | E27: 4ª Leitura | F27: 15 dias Rodados | G27: 30 dias Rodados | H27: Total Mensal | J27: DATA | W27: DATA | AE27: DATA
F28: =SUM(C28-B28) -> 0 | G28: =SUM(E28-D28) -> 0 | H28: =SUM(F28:G28) -> 0 | J28: VALOR | W28: VALOR | AE28: VALOR
T29: TOTAL | U29: =SUM(K28:U28) -> 0 | AB29: TOTAL | AC29: =SUM(X28:AC28) -> 0 | AJ29: TOTAL | AK29: =SUM(AF28:AK28) -> 0
B30: Julho | J30: Julho | W30: =J30 -> Julho | AE30: =W30 -> Julho
A31: KM (Rodados) | B31: 1ª Leitura | C31: 2ª Leitura | D31: 3ª Leitura | E31: 4ª Leitura | F31: 15 dias Rodados | G31: 30 dias Rodados | H31: Total Mensal | J31: DATA | W31: DATA | AE31: DATA
F32: =SUM(C32-B32) -> 0 | G32: =SUM(E32-D32) -> 0 | H32: =SUM(F32:G32) -> 0 | J32: VALOR | W32: VALOR | AE32: VALOR
T33: TOTAL | U33: =SUM(K32:U32) -> 0 | AB33: TOTAL | AC33: =SUM(X32:AC32) -> 0 | AJ33: TOTAL | AK33: =SUM(AF32:AK32) -> 0
B34: Agosto | J34: Agosto | W34: =J34 -> Agosto | AE34: =W34 -> Agosto
A35: KM (Rodados) | B35: 1ª Leitura | C35: 2ª Leitura | D35: 3ª Leitura | E35: 4ª Leitura | F35: 15 dias Rodados | G35: 30 dias Rodados | H35: Total Mensal | J35: DATA | W35: DATA | AE35: DATA
F36: =SUM(C36-B36) -> 0 | G36: =SUM(E36-D36) -> 0 | H36: =SUM(F36:G36) -> 0 | J36: VALOR | W36: VALOR | AE36: VALOR
T37: TOTAL | U37: =SUM(K36:U36) -> 0 | AB37: TOTAL | AC37: =SUM(X36:AC36) -> 0 | AJ37: TOTAL | AK37: =SUM(AF36:AK36) -> 0
B38: Setembro | J38: Setembro | W38: =J38 -> Setembro | AE38: =W38 -> Setembro
A39: KM (Rodados) | B39: 1ª Leitura | C39: 2ª Leitura | D39: 3ª Leitura | E39: 4ª Leitura | F39: 15 dias Rodados | G39: 30 dias Rodados | H39: Total Mensal | J39: DATA | W39: DATA | AE39: DATA
F40: =SUM(C40-B40) -> 0 | G40: =SUM(E40-D40) -> 0 | H40: =SUM(F40:G40) -> 0 | J40: VALOR | W40: VALOR | AE40: VALOR
T41: TOTAL | U41: =SUM(K40:U40) -> 0 | AB41: TOTAL | AC41: =SUM(X40:AC40) -> 0 | AJ41: TOTAL | AK41: =SUM(AF40:AK40) -> 0
B42: Outubro | J42: Outubro | W42: =J42 -> Outubro | AE42: =W42 -> Outubro
...

Sheet Nilberto-Desmob
B1: GESTÃO DE FROTAS
B2: CONTROLE DE QUILOMETRAGEM, ABASTECIMENTOS, LAVAGENS E SERVIÇOS DE BORRACHARIA
A4: Veiculo: | B4: T-Cross | D4: Placa: | E4: EKB5J96 | G4: Guinchado: | H4: 45876 | I4: KM | J4: 4500
A5: Substituição: | B5: 45877 | D5: Placa: | E5: TKX8G73 | G5: Modelo: | H5: T-Cross
A6: Contrato Locação: | B6: 3792.09 | D6: Rastreador: | E6: 45 | G6: Data mob.: | H6: 45731 | I6: Data Desmob.: | J6: 46142
A8: Troca de condutor EKB5J96 em 29/04/2025 de Rute para Nilberto
A9: REGISTRO DE KM | J9: ABASTECIMENTO | X9: LAVA JATO | AF9: BORRACHARIA
B11: Janeiro | J11: Janeiro | X11: Janeiro | AF11: Janeiro
A12: KM (Rodados) | B12: 1ª Leitura | C12: 2ª Leitura | D12: 3ª Leitura | E12: 4ª Leitura | F12: 15 dias Rodados | G12: 30 dias Rodados | H12: Total Mensal | J12: DATA | X12: DATA | AF12: DATA
F13: =SUM(C13-B13) -> 0 | G13: =SUM(E13-D13) -> 0 | H13: =SUM(F13:G13) -> 0 | J13: VALOR | X13: VALOR | AF13: VALOR
T14: TOTAL | U14: =SUM(K13:U13) -> 0 | AC14: TOTAL | AD14: =SUM(Y13:AD13) -> 0 | AK14: TOTAL | AL14: =SUM(AG13:AL13) -> 0
B15: Fevereiro | J15: Fevereiro | X15: Fevereiro | AF15: Fevereiro
A16: KM (Rodados) | B16: 1ª Leitura | C16: 2ª Leitura | D16: 3ª Leitura | E16: 4ª Leitura | F16: 15 dias Rodados | G16: 30 dias Rodados | H16: Total Mensal | J16: DATA | X16: DATA | AF16: DATA
F17: =SUM(C17-B17) -> 0 | G17: =SUM(E17-D17) -> 0 | H17: =SUM(F17:G17) -> 0 | J17: VALOR | X17: VALOR | AF17: VALOR
T18: TOTAL | U18: =SUM(K17:U17) -> 0 | AC18: TOTAL | AD18: =SUM(Y17:AD17) -> 0 | AK18: TOTAL | AL18: =SUM(AG17:AL17) -> 0
B19: Março | J19: Março | X19: =J19 -> Março | AF19: =X19 -> Março
A20: KM (Rodados) | B20: 1ª Leitura | C20: 2ª Leitura | D20: 3ª Leitura | E20: 4ª Leitura | F20: 15 dias Rodados | G20: 30 dias Rodados | H20: Total Mensal | J20: DATA | K20: 45734 | L20: 45741 | M20: 45743 | N20: 45745 | O20: 45746 | X20: DATA | Y20: 45745 | AF20: DATA
D21: 57002 | E21: 58682 | F21: =SUM(C21-B21) -> 0 | G21: =SUM(E21-D21) -> 1680 | H21: =SUM(F21:G21) -> 1680 | J21: VALOR | K21: 272.99 | L21: 238.45 | M21: 206.82 | N21: 204.93 | O21: 273.43 | X21: VALOR | Y21: 45 | AF21: VALOR | AG21: 140
T22: TOTAL | U22: =SUM(K21:U21) -> 1196.62 | AC22: TOTAL | AD22: =SUM(Y21:AD21) -> 45 | AK22: TOTAL | AL22: =SUM(AG21:AL21) -> 140
B23: Abril | J23: Abril | X23: =J23 -> Abril | AF23: =X23 -> Abril
A24: KM (Rodados) | B24: 1ª Leitura | C24: 2ª Leitura | D24: 3ª Leitura | E24: 4ª Leitura | F24: 15 dias Rodados | G24: 30 dias Rodados | H24: Total Mensal | J24: DATA | K24: 45750 | L24: 45752 | M24: 45776 | X24: DATA | AF24: DATA
B25: 58682 | C25: 60226 | D25: 60226 | E25: 61679 | F25: =SUM(C25-B25) -> 1544 | G25: =SUM(E25-D25) -> 1453 | H25: =SUM(F25:G25) -> 2997 | J25: VALOR | K25: 196 | L25: 190.34 | M25: 224 | X25: VALOR | AF25: VALOR
T26: TOTAL | U26: =SUM(K25:U25) -> 610.34 | AC26: TOTAL | AD26: =SUM(Y25:AD25) -> 0 | AK26: TOTAL | AL26: =SUM(AG25:AL25) -> 0
B27: Maio | J27: Maio | X27: =J27 -> Maio | AF27: =X27 -> Maio
A28: KM (Rodados) | B28: 1ª Leitura | C28: 2ª Leitura | D28: 3ª Leitura | E28: 4ª Leitura | F28: 15 dias Rodados | G28: 30 dias Rodados | H28: Total Mensal | J28: DATA | K28: 45783 | L28: 45787 | M28: 45792 | N28: 45799 | X28: DATA | AF28: DATA
B29: 61679 | C29: 63251 | D29: 63251 | E29: 64533 | F29: =SUM(C29-B29) -> 1572 | G29: =SUM(E29-D29) -> 1282 | H29: =SUM(F29:G29) -> 2854 | J29: VALOR | K29: 218.05 | L29: 113.46 | M29: 240.93 | N29: 228.33 | X29: VALOR | AF29: VALOR
T30: TOTAL | U30: =SUM(K29:U29) -> 800.77 | AC30: TOTAL | AD30: =SUM(Y29:AD29) -> 0 | AK30: TOTAL | AL30: =SUM(AG29:AL29) -> 0
B31: Junho | J31: Junho | X31: =J31 -> Junho | AF31: =X31 -> Junho
A32: KM (Rodados) | B32: 1ª Leitura | C32: 2ª Leitura | D32: 3ª Leitura | E32: 4ª Leitura | F32: 15 dias Rodados | G32: 30 dias Rodados | H32: Total Mensal | J32: DATA | K32: 45811 | L32: 45813 | M32: 45818 | N32: 45820 | O32: 45822 | P32: 45826 | Q32: 45828 | R32: 45834 | X32: DATA | AF32: DATA
B33: 64533 | C33: 66071 | D33: 66071 | E33: 67578 | F33: =SUM(C33-B33) -> 1538 | G33: =SUM(E33-D33) -> 1507 | H33: =SUM(F33:G33) -> 3045 | J33: VALOR | K33: 176.18 | L33: 179.62 | M33: 204.13 | N33: 182.53 | O33: 90.54 | P33: 223.71 | Q33: 235.5 | R33: 175.03 | X33: VALOR | AF33: VALOR
T34: TOTAL | U34: =SUM(K33:U33) -> 1467.24 | AC34: TOTAL | AD34: =SUM(Y33:AD33) -> 0 | AK34: TOTAL | AL34: =SUM(AG33:AL33) -> 0
B35: Julho | J35: Julho | X35: =J35 -> Julho | AF35: =X35 -> Julho
A36: KM (Rodados) | B36: 1ª Leitura | C36: 2ª Leitura | D36: 3ª Leitura | E36: 4ª Leitura | F36: 15 dias Rodados | G36: 30 dias Rodados | H36: Total Mensal | J36: DATA | K36: 45839 | L36: 45841 | M36: 45846 | N36: 45848 | O36: 45850 | P36: 45853 | Q36: 45860 | R36: 45867 | X36: DATA | AF36: DATA
B37: 67578 | C37: 69248 | D37: 69248 | E37: 70366 | F37: =SUM(C37-B37) -> 1670 | G37: =SUM(E37-D37) -> 1118 | H37: =SUM(F37:G37) -> 2788 | J37: VALOR | K37: 273.75 | L37: 123.2 | M37: 240.24 | N37: 144.45 | O37: 123.57 | P37: 287.43 | Q37: 267.28 | R37: 280.22 | X37: VALOR | AF37: VALOR
A38: EKB5J96 Guinchado em 07/08/2025 | T38: TOTAL | U38: =SUM(K37:U37) -> 1740.14 | AC38: TOTAL | AD38: =SUM(Y37:AD37) -> 0 | AK38: TOTAL | AL38: =SUM(AG37:AL37) -> 0
B39: Agosto | J39: Agosto | X39: =J39 -> Agosto | AF39: =X39 -> Agosto
A40: KM (Rodados) | B40: 1ª Leitura | C40: 2ª Leitura | D40: 3ª Leitura | E40: 4ª Leitura | F40: 15 dias Rodados | G40: 30 dias Rodados | H40: Total Mensal | J40: DATA | K40: 45871 | X40: DATA | AF40: DATA
B41: 70366 | C41: 70683 | F41: =SUM(C41-B41) -> 317 | G41: =SUM(E41-D41) -> 0 | H41: =SUM(F41:G41) -> 317 | J41: VALOR | K41: 204.94 | X41: VALOR | AF41: VALOR
T42: TOTAL | U42: =SUM(K41:U41) -> 204.94 | AC42: TOTAL | AD42: =SUM(Y41:AD41) -> 0 | AK42: TOTAL | AL42: =SUM(AG41:AL41) -> 0
B43: Agosto | J43: Agosto | X43: =J43 -> Agosto | AF43: =X43 -> Agosto
...

Sheet Jair-Desmob
B1: GESTÃO DE FROTAS
B2: CONTROLE DE QUILOMETRAGEM, ABASTECIMENTOS, LAVAGENS E SERVIÇOS DE BORRACHARIA
A4: Veiculo: | B4: T-Cross | D4: Placa: | E4: EXU6G81 | G4: KM | H4: 3000
A5: Substituição: | B5: 45898 | D5: Placa: | E5: TEL5D17 | G5: Modelo: | H5: Tracker
A6: Troca de Condutor | B6: 45906 | D6: Placa: | E6: TEL5D17 | G6: Condutores | H6: Herik para Jair
A7: Contrato Locação: | B7: 3837 | D7: Rastreador: | E7: 45 | G7: Data mob.: | H7: 45870 | I7: Data Desmob.: | J7: 46108
A10: REGISTRO DE KM | J10: ABASTECIMENTO | Y10: LAVA JATO | AG10: BORRACHARIA
B12: Janeiro | J12: Janeiro | Y12: Janeiro | AG12: Janeiro
A13: KM (Rodados) | B13: 1ª Leitura | C13: 2ª Leitura | D13: 3ª Leitura | E13: 4ª Leitura | F13: 15 dias Rodados | G13: 30 dias Rodados | H13: Total Mensal | J13: DATA | Y13: DATA | AG13: DATA
F14: =SUM(C14-B14) -> 0 | G14: =SUM(E14-D14) -> 0 | H14: =SUM(F14:G14) -> 0 | J14: VALOR | Y14: VALOR | AG14: VALOR
T15: TOTAL | U15: =SUM(K14:U14) -> 0 | AD15: TOTAL | AE15: =SUM(Z14:AE14) -> 0 | AL15: TOTAL | AM15: =SUM(AH14:AM14) -> 0
B16: Fevereiro | J16: Fevereiro | Y16: Fevereiro | AG16: Fevereiro
A17: KM (Rodados) | B17: 1ª Leitura | C17: 2ª Leitura | D17: 3ª Leitura | E17: 4ª Leitura | F17: 15 dias Rodados | G17: 30 dias Rodados | H17: Total Mensal | J17: DATA | Y17: DATA | AG17: DATA
F18: =SUM(C18-B18) -> 0 | G18: =SUM(E18-D18) -> 0 | H18: =SUM(F18:G18) -> 0 | J18: VALOR | Y18: VALOR | AG18: VALOR
T19: TOTAL | U19: =SUM(K18:U18) -> 0 | AD19: TOTAL | AE19: =SUM(Z18:AE18) -> 0 | AL19: TOTAL | AM19: =SUM(AH18:AM18) -> 0
B20: Março | J20: Março | Y20: =J20 -> Março | AG20: =Y20 -> Março
A21: KM (Rodados) | B21: 1ª Leitura | C21: 2ª Leitura | D21: 3ª Leitura | E21: 4ª Leitura | F21: 15 dias Rodados | G21: 30 dias Rodados | H21: Total Mensal | J21: DATA | Y21: DATA | AG21: DATA
F22: =SUM(C22-B22) -> 0 | G22: =SUM(E22-D22) -> 0 | H22: =SUM(F22:G22) -> 0 | J22: VALOR | Y22: VALOR | AG22: VALOR
T23: TOTAL | U23: =SUM(K22:U22) -> 0 | AD23: TOTAL | AE23: =SUM(Z22:AE22) -> 0 | AL23: TOTAL | AM23: =SUM(AH22:AM22) -> 0
B24: Abril | J24: Abril | Y24: =J24 -> Abril | AG24: =Y24 -> Abril
A25: KM (Rodados) | B25: 1ª Leitura | C25: 2ª Leitura | D25: 3ª Leitura | E25: 4ª Leitura | F25: 15 dias Rodados | G25: 30 dias Rodados | H25: Total Mensal | J25: DATA | Y25: DATA | AG25: DATA
F26: =SUM(C26-B26) -> 0 | G26: =SUM(E26-D26) -> 0 | H26: =SUM(F26:G26) -> 0 | J26: VALOR | Y26: VALOR | AG26: VALOR
T27: TOTAL | U27: =SUM(K26:U26) -> 0 | AD27: TOTAL | AE27: =SUM(Z26:AE26) -> 0 | AL27: TOTAL | AM27: =SUM(AH26:AM26) -> 0
B28: Maio | J28: Maio | Y28: =J28 -> Maio | AG28: =Y28 -> Maio
A29: KM (Rodados) | B29: 1ª Leitura | C29: 2ª Leitura | D29: 3ª Leitura | E29: 4ª Leitura | F29: 15 dias Rodados | G29: 30 dias Rodados | H29: Total Mensal | J29: DATA | Y29: DATA | AG29: DATA
F30: =SUM(C30-B30) -> 0 | G30: =SUM(E30-D30) -> 0 | H30: =SUM(F30:G30) -> 0 | J30: VALOR | Y30: VALOR | AG30: VALOR
T31: TOTAL | U31: =SUM(K30:U30) -> 0 | AD31: TOTAL | AE31: =SUM(Z30:AE30) -> 0 | AL31: TOTAL | AM31: =SUM(AH30:AM30) -> 0
B32: Junho | J32: Junho | Y32: =J32 -> Junho | AG32: =Y32 -> Junho
A33: KM (Rodados) | B33: 1ª Leitura | C33: 2ª Leitura | D33: 3ª Leitura | E33: 4ª Leitura | F33: 15 dias Rodados | G33: 30 dias Rodados | H33: Total Mensal | J33: DATA | Y33: DATA | AG33: DATA
F34: =SUM(C34-B34) -> 0 | G34: =SUM(E34-D34) -> 0 | H34: =SUM(F34:G34) -> 0 | J34: VALOR | Y34: VALOR | AG34: VALOR
T35: TOTAL | U35: =SUM(K34:U34) -> 0 | AD35: TOTAL | AE35: =SUM(Z34:AE34) -> 0 | AL35: TOTAL | AM35: =SUM(AH34:AM34) -> 0
B36: Julho | J36: Julho | Y36: =J36 -> Julho | AG36: =Y36 -> Julho
A37: KM (Rodados) | B37: 1ª Leitura | C37: 2ª Leitura | D37: 3ª Leitura | E37: 4ª Leitura | F37: 15 dias Rodados | G37: 30 dias Rodados | H37: Total Mensal | J37: DATA | Y37: DATA | AG37: DATA
F38: =SUM(C38-B38) -> 0 | G38: =SUM(E38-D38) -> 0 | H38: =SUM(F38:G38) -> 0 | J38: VALOR | Y38: VALOR | AG38: VALOR
T39: TOTAL | U39: =SUM(K38:U38) -> 0 | AD39: TOTAL | AE39: =SUM(Z38:AE38) -> 0 | AL39: TOTAL | AM39: =SUM(AH38:AM38) -> 0
A40: T-Cross EXU6G81 | B40: Agosto | J40: Agosto | Y40: =J40 -> Agosto | AG40: =Y40 -> Agosto
A41: KM (Rodados) | B41: 1ª Leitura | C41: 2ª Leitura | D41: 3ª Leitura | E41: 4ª Leitura | F41: 15 dias Rodados | G41: 30 dias Rodados | H41: Total Mensal | J41: DATA | K41: 45871 | L41: 45874 | M41: 45878 | N41: 45881 | O41: 45885 | P41: 45890 | Q41: 45895 | R41: 45898 | Y41: DATA | Z41: 45897 | AG41: DATA
B42: 38932 | C42: 40454 | D42: 40454 | E42: 41860 | F42: =SUM(C42-B42) -> 1522 | G42: =SUM(E42-D42) -> 1406 | H42: =SUM(F42:G42) -> 2928 | J42: VALOR | K42: 261.8 | L42: 121.04 | M42: 216.26 | N42: 203.73 | O42: 187.14 | P42: 245.62 | Q42: 238.75 | R42: 181.67 | Y42: VALOR | Z42: 170 | AG42: VALOR
T43: TOTAL | U43: =SUM(K42:U42) -> 1656.01 | AD43: TOTAL | AE43: =SUM(Z42:AE42) -> 170 | AL43: TOTAL | AM43: =SUM(AH42:AM42) -> 0
A44: Tracker TEL5D17 | B44: Setembro | J44: Setembro | Y44: =J44 -> Setembro | AG44: =Y44 -> Setembro
...

Sheet Francisco de Morais-Desmob
B1: GESTÃO DE FROTAS
B2: CONTROLE DE QUILOMETRAGEM, ABASTECIMENTOS, LAVAGENS E SERVIÇOS DE BORRACHARIA
A4: Veiculo: | B4: RENEGADE | D4: Placa: | E4: RPL1J22 | G4: KM | H4: 4500
A5: Substituição: | B5: 45675 | D5: Placa: | E5: SWD0G64 | G5: Modelo: | H5: T-Cross
A7: Contrato Locação: | B7: 3792.09 | D7: Rastreador: | E7: 45 | G7: Data mob.: | H7: 45543 | I7: Data Desmob.: | J7: 46102
A9: Mudou de condutor em 01/04/2025, antes era do Acácio após ficou com o Francisco Junior
A10: REGISTRO DE KM | J10: ABASTECIMENTO | W10: LAVA JATO | AE10: BORRACHARIA
B12: Janeiro | J12: Janeiro | W12: Janeiro | AE12: Janeiro
A13: KM (Rodados) | B13: 1ª Leitura | C13: 2ª Leitura | D13: 3ª Leitura | E13: 4ª Leitura | F13: 15 dias Rodados | G13: 30 dias Rodados | H13: Total Mensal | J13: DATA | W13: DATA | AE13: DATA
