Workbook

Sheet RESUMO
A1: 25.001 AUREN CAJUÍNAS
B5: JAN | C5: FEV | D5: MAR | E5: ABR | F5: MAI | G5: JUN | H5: JUL | I5: AGO | J5: SET | K5: OUT | L5: NOV | M5: DEZ
A6: ABASTECIMENTO 2025 | B6: =SUM('Controle Central'!D4+'Controle Central'!K4+'Controle Central'!R4+'Controle Central'!Y4+'Controle Central'!D23+'Controle Central'!K23+'Controle Central'!R23+'Controle Central'!Y23+'Controle Central'!D42+'Controle Central'!K42+'Controle Central'!R42+'Controle Central'!Y42+'Controle Central'!D61+'Controle Central'!K61+'Controle Central'!R61+'Controle Central'!Y61+'Controle Central'!D80+'Controle Central'!K80+'Controle Central'!R80+'Controle Central'!Y80+'Controle Central'!D98+'Controle Central'!K98+'Controle Central'!R98+'Controle Central'!Y98+'Controle Central'!D116+'Controle Central'!K116+'Controle Central'!R116+'Controle Central'!Y116+'Controle Central'!D134+'Controle Central'!K134) -> 0 | C6: =SUM('Controle Central'!D5+'Controle Central'!K5+'Controle Central'!R5+'Controle Central'!Y5+'Controle Central'!D24+'Controle Central'!K24+'Controle Central'!R24+'Controle Central'!Y24+'Controle Central'!D43+'Controle Central'!K43+'Controle Central'!R43+'Controle Central'!Y43+'Controle Central'!D62+'Controle Central'!K62+'Controle Central'!R62+'Controle Central'!Y62+'Controle Central'!D81+'Controle Central'!K81+'Controle Central'!R81+'Controle Central'!D99+'Controle Central'!K99+'Controle Central'!R99+'Controle Central'!Y99+'Controle Central'!D117+'Controle Central'!K117+'Controle Central'!R117+'Controle Central'!Y117+'Controle Central'!D135+'Controle Central'!K135) -> 4306.66 | D6: =SUM('Controle Central'!D6+'Controle Central'!K6+'Controle Central'!R6+'Controle Central'!Y6+'Controle Central'!D25+'Controle Central'!K25+'Controle Central'!R25+'Controle Central'!Y25+'Controle Central'!D44+'Controle Central'!K44+'Controle Central'!R44+'Controle Central'!Y44+'Controle Central'!D63+'Controle Central'!K63+'Controle Central'!R63+'Controle Central'!Y63+'Controle Central'!D82+'Controle Central'!K82+'Controle Central'!R82+'Controle Central'!Y82+'Controle Central'!D100+'Controle Central'!K100+'Controle Central'!R100+'Controle Central'!Y100+'Controle Central'!D118+'Controle Central'!K118+'Controle Central'!R118+'Controle Central'!Y118+'Controle Central'!D136+'Controle Central'!K136) -> 5225.42 | E6: ='Controle Central'!D7+'Controle Central'!K7+'Controle Central'!R7+'Controle Central'!Y7+'Controle Central'!D26+'Controle Central'!K26+'Controle Central'!R26+'Controle Central'!Y26+'Controle Central'!D45+'Controle Central'!K45+'Controle Central'!R45+'Controle Central'!Y45+'Controle Central'!D64+'Controle Central'!K64+'Controle Central'!R64+'Controle Central'!D83+'Controle Central'!K83+'Controle Central'!R83+'Controle Central'!Y83+'Controle Central'!D101+'Controle Central'!K101+'Controle Central'!R101+'Controle Central'!Y101+'Controle Central'!D119+'Controle Central'!K119+'Controle Central'!R119+'Controle Central'!Y119+'Controle Central'!D137+'Controle Central'!K137 -> 5544.38 | F6: =SUM('Controle Central'!D8+'Controle Central'!K8+'Controle Central'!R8+'Controle Central'!Y8+'Controle Central'!D27+'Controle Central'!K27+'Controle Central'!R27+'Controle Central'!Y27+'Controle Central'!D46+'Controle Central'!K46+'Controle Central'!R46+'Controle Central'!Y46+'Controle Central'!D65+'Controle Central'!K65+'Controle Central'!R65+'Controle Central'!Y65+'Controle Central'!D84+'Controle Central'!K84+'Controle Central'!R84+'Controle Central'!Y84+'Controle Central'!D102+'Controle Central'!K102+'Controle Central'!R102+'Controle Central'!Y102+'Controle Central'!D120+'Controle Central'!K120+'Controle Central'!R120+'Controle Central'!Y120+'Controle Central'!D138+'Controle Central'!K138) -> 3696.81 | G6: =SUM('Controle Central'!D9+'Controle Central'!K9+'Controle Central'!R9+'Controle Central'!Y9+'Controle Central'!D28+'Controle Central'!K28+'Controle Central'!R28+'Controle Central'!Y28+'Controle Central'!D47+'Controle Central'!K47+'Controle Central'!R47+'Controle Central'!Y47+'Controle Central'!D66+'Controle Central'!K66+'Controle Central'!R66+'Controle Central'!Y66+'Controle Central'!D85+'Controle Central'!K85+'Controle Central'!R85+'Controle Central'!Y85+'Controle Central'!D103+'Controle Central'!K103+'Controle Central'!R103+'Controle Central'!Y103+'Controle Central'!D121+'Controle Central'!K121+'Controle Central'!R121+'Controle Central'!Y121+'Controle Central'!D139+'Controle Central'!K139) -> 3406.54 | H6: =SUM('Controle Central'!D10+'Controle Central'!K10+'Controle Central'!R10+'Controle Central'!Y10+'Controle Central'!D29+'Controle Central'!K29+'Controle Central'!R29+'Controle Central'!D48+'Controle Central'!K48+'Controle Central'!R48+'Controle Central'!Y48+'Controle Central'!D67+'Controle Central'!K67+'Controle Central'!R67+'Controle Central'!Y67+'Controle Central'!D86+'Controle Central'!K86+'Controle Central'!R86+'Controle Central'!Y86+'Controle Central'!D104+'Controle Central'!K104+'Controle Central'!R104+'Controle Central'!Y104+'Controle Central'!D122+'Controle Central'!K122+'Controle Central'!R122+'Controle Central'!Y122+'Controle Central'!D140+'Controle Central'!K140) -> 7216.04 | I6: =SUM('Controle Central'!D11+'Controle Central'!K11+'Controle Central'!R11+'Controle Central'!Y11+'Controle Central'!D30+'Controle Central'!K30+'Controle Central'!R30+'Controle Central'!Y30+'Controle Central'!D49+'Controle Central'!K49+'Controle Central'!R49+'Controle Central'!Y49+'Controle Central'!D68+'Controle Central'!K68+'Controle Central'!R68+'Controle Central'!Y68+'Controle Central'!D87+'Controle Central'!K87+'Controle Central'!R87+'Controle Central'!Y87+'Controle Central'!D105+'Controle Central'!K105+'Controle Central'!R105+'Controle Central'!Y105+'Controle Central'!D123+'Controle Central'!K123+'Controle Central'!R123+'Controle Central'!Y123+'Controle Central'!D141+'Controle Central'!K141) -> 8960.714 | J6: =SUM('Controle Central'!D12+'Controle Central'!K12+'Controle Central'!R12+'Controle Central'!Y12+'Controle Central'!D31+'Controle Central'!K31+'Controle Central'!R31+'Controle Central'!Y31+'Controle Central'!D50+'Controle Central'!K50+'Controle Central'!R50+'Controle Central'!Y50+'Controle Central'!D69+'Controle Central'!K69+'Controle Central'!R69+'Controle Central'!Y69+'Controle Central'!D88+'Controle Central'!K88+'Controle Central'!R88+'Controle Central'!Y88+'Controle Central'!D106+'Controle Central'!K106+'Controle Central'!R106+'Controle Central'!Y106+'Controle Central'!D124+'Controle Central'!K124+'Controle Central'!R124+'Controle Central'!Y124+'Controle Central'!D142+'Controle Central'!K142) -> 8913.73 | K6: =SUM('Controle Central'!D13+'Controle Central'!K13+'Controle Central'!R13+'Controle Central'!Y13+'Controle Central'!D32+'Controle Central'!K32+'Controle Central'!R32+'Controle Central'!Y32+'Controle Central'!D51+'Controle Central'!K51+'Controle Central'!R51+'Controle Central'!Y51+'Controle Central'!D70+'Controle Central'!K70+'Controle Central'!R70+'Controle Central'!Y70+'Controle Central'!D89+'Controle Central'!K89+'Controle Central'!R89+'Controle Central'!Y89+'Controle Central'!D107+'Controle Central'!K107+'Controle Central'!R107+'Controle Central'!Y107+'Controle Central'!D125+'Controle Central'!K125+'Controle Central'!R125+'Controle Central'!Y125+'Controle Central'!D143+'Controle Central'!K143) -> 10065.3 | L6: =SUM('Controle Central'!D14+'Controle Central'!K14+'Controle Central'!R14+'Controle Central'!Y14+'Controle Central'!D33+'Controle Central'!K33+'Controle Central'!R33+'Controle Central'!Y33+'Controle Central'!D52+'Controle Central'!K52+'Controle Central'!R52+'Controle Central'!Y52+'Controle Central'!D71+'Controle Central'!K71+'Controle Central'!R71+'Controle Central'!Y71+'Controle Central'!D90+'Controle Central'!K90+'Controle Central'!R90+'Controle Central'!Y90+'Controle Central'!D108+'Controle Central'!K108+'Controle Central'!R108+'Controle Central'!Y108+'Controle Central'!D126+'Controle Central'!K126+'Controle Central'!R126+'Controle Central'!Y126+'Controle Central'!D144+'Controle Central'!K144) -> 10218.49 | M6: =SUM('Controle Central'!D15+'Controle Central'!K15+'Controle Central'!R15+'Controle Central'!Y15+'Controle Central'!D34+'Controle Central'!K34+'Controle Central'!R34+'Controle Central'!Y34+'Controle Central'!D53+'Controle Central'!K53+'Controle Central'!R53+'Controle Central'!Y53+'Controle Central'!D72+'Controle Central'!K72+'Controle Central'!R72+'Controle Central'!Y72+'Controle Central'!D91+'Controle Central'!K91+'Controle Central'!R91+'Controle Central'!Y91+'Controle Central'!D109+'Controle Central'!K109+'Controle Central'!R109+'Controle Central'!Y109+'Controle Central'!D127+'Controle Central'!K127+'Controle Central'!R127+'Controle Central'!Y127+'Controle Central'!D145+'Controle Central'!K145) -> 10463.92
A7: ABASTECIMENTO 2026
A10: LAVA_RAPIDO | B10: =SUM('Controle Central'!E4+'Controle Central'!L4+'Controle Central'!S4+'Controle Central'!Z4+'Controle Central'!E23+'Controle Central'!L23+'Controle Central'!S23+'Controle Central'!Z23+'Controle Central'!E42+'Controle Central'!L42+'Controle Central'!S42+'Controle Central'!Z42+'Controle Central'!E61+'Controle Central'!L61+'Controle Central'!S61+'Controle Central'!Z61+'Controle Central'!E80+'Controle Central'!L80+'Controle Central'!S80+'Controle Central'!Z80+'Controle Central'!E98+'Controle Central'!L98+'Controle Central'!S98+'Controle Central'!Z98+'Controle Central'!E116+'Controle Central'!L116+'Controle Central'!S116+'Controle Central'!Z116+'Controle Central'!E134+'Controle Central'!L134) -> 0 | C10: =SUM('Controle Central'!E5,'Controle Central'!L5,'Controle Central'!S5,'Controle Central'!Z5,'Controle Central'!E24,'Controle Central'!L24,'Controle Central'!S24,'Controle Central'!Z24,'Controle Central'!E43,'Controle Central'!L43,'Controle Central'!S43,'Controle Central'!Z43,'Controle Central'!E62,'Controle Central'!L62,'Controle Central'!S62,'Controle Central'!Z62,'Controle Central'!E81,'Controle Central'!L81,'Controle Central'!S81,'Controle Central'!Z81,'Controle Central'!E99,'Controle Central'!L99,'Controle Central'!S99,'Controle Central'!Z99,'Controle Central'!E117,'Controle Central'!L117,'Controle Central'!S117,'Controle Central'!Z117,'Controle Central'!E135,'Controle Central'!L135) -> 0 | D10: =SUM('Controle Central'!E6,'Controle Central'!L6,'Controle Central'!S6,'Controle Central'!Z6,'Controle Central'!E25,'Controle Central'!L25,'Controle Central'!S25,'Controle Central'!Z25,'Controle Central'!E44,'Controle Central'!L44,'Controle Central'!S44,'Controle Central'!Z44,'Controle Central'!E63,'Controle Central'!L63,'Controle Central'!S63,'Controle Central'!Z63,'Controle Central'!E82,'Controle Central'!L82,'Controle Central'!S82,'Controle Central'!Z82,'Controle Central'!E100,'Controle Central'!L100,'Controle Central'!S100,'Controle Central'!Z100,'Controle Central'!E118,'Controle Central'!L118,'Controle Central'!S118,'Controle Central'!Z118,'Controle Central'!E136,'Controle Central'!L136) -> 0 | E10: =SUM('Controle Central'!E7,'Controle Central'!L7,'Controle Central'!S7,'Controle Central'!Z7,'Controle Central'!E26,'Controle Central'!L26,'Controle Central'!S26,'Controle Central'!Z26,'Controle Central'!E45,'Controle Central'!L45,'Controle Central'!S45,'Controle Central'!Z45,'Controle Central'!E64,'Controle Central'!L64,'Controle Central'!S64,'Controle Central'!Z64,'Controle Central'!E83,'Controle Central'!L83,'Controle Central'!S83,'Controle Central'!Z83,'Controle Central'!E101,'Controle Central'!L101,'Controle Central'!S101,'Controle Central'!Z101,'Controle Central'!E119,'Controle Central'!L119,'Controle Central'!S119,'Controle Central'!Z119,'Controle Central'!E137,'Controle Central'!L137) -> 0 | F10: =SUM('Controle Central'!E8,'Controle Central'!L8,'Controle Central'!S8,'Controle Central'!Z8,'Controle Central'!E27,'Controle Central'!L27,'Controle Central'!S27,'Controle Central'!Z27,'Controle Central'!E46,'Controle Central'!L46,'Controle Central'!S46,'Controle Central'!Z46,'Controle Central'!E65,'Controle Central'!L65,'Controle Central'!S65,'Controle Central'!Z65,'Controle Central'!E84,'Controle Central'!L84,'Controle Central'!S84,'Controle Central'!Z84,'Controle Central'!E102,'Controle Central'!L102,'Controle Central'!S102,'Controle Central'!Z102,'Controle Central'!E120,'Controle Central'!L120,'Controle Central'!S120,'Controle Central'!Z120,'Controle Central'!E138,'Controle Central'!L138) -> 0 | G10: =SUM('Controle Central'!E9,'Controle Central'!L9,'Controle Central'!S9,'Controle Central'!Z9,'Controle Central'!E28,'Controle Central'!L28,'Controle Central'!S28,'Controle Central'!Z28,'Controle Central'!E47,'Controle Central'!L47,'Controle Central'!S47,'Controle Central'!Z47,'Controle Central'!E66,'Controle Central'!L66,'Controle Central'!S66,'Controle Central'!Z66,'Controle Central'!E85,'Controle Central'!L85,'Controle Central'!S85,'Controle Central'!Z85,'Controle Central'!E103,'Controle Central'!L103,'Controle Central'!S103,'Controle Central'!Z103,'Controle Central'!E121,'Controle Central'!L121,'Controle Central'!S121,'Controle Central'!Z121,'Controle Central'!E139+'Controle Central'!L139) -> 0 | H10: =SUM('Controle Central'!E10,'Controle Central'!L10,'Controle Central'!S10,'Controle Central'!Z10,'Controle Central'!E29,'Controle Central'!L29,'Controle Central'!S29,'Controle Central'!Z29,'Controle Central'!E48,'Controle Central'!L48,'Controle Central'!S48,'Controle Central'!Z48,'Controle Central'!E67,'Controle Central'!L67,'Controle Central'!S67,'Controle Central'!Z67,'Controle Central'!E86,'Controle Central'!L86,'Controle Central'!S86,'Controle Central'!Z86,'Controle Central'!E104,'Controle Central'!L104,'Controle Central'!S104,'Controle Central'!Z104,'Controle Central'!E122,'Controle Central'!L122,'Controle Central'!S122,'Controle Central'!Z122,'Controle Central'!E140,'Controle Central'!L140) -> 0 | I10: =SUM('Controle Central'!L11,'Controle Central'!S11,'Controle Central'!E11,'Controle Central'!Z11,'Controle Central'!Z30,'Controle Central'!S30,'Controle Central'!L30,'Controle Central'!E30,'Controle Central'!E49,'Controle Central'!L49,'Controle Central'!S49,'Controle Central'!Z49,'Controle Central'!Z68,'Controle Central'!S68,'Controle Central'!L68,'Controle Central'!E68,'Controle Central'!E87,'Controle Central'!L87,'Controle Central'!S87,'Controle Central'!Z87,'Controle Central'!Z105,'Controle Central'!Z123,'Controle Central'!S105,'Controle Central'!S123,'Controle Central'!L123,'Controle Central'!L105,'Controle Central'!E123,'Controle Central'!E105,'Controle Central'!E141,'Controle Central'!L141) -> 40 | J10: =SUM('Controle Central'!E12,'Controle Central'!E31,'Controle Central'!L12,'Controle Central'!L31,'Controle Central'!S12,'Controle Central'!S31,'Controle Central'!Z12,'Controle Central'!Z31,'Controle Central'!Z50,'Controle Central'!Z69,'Controle Central'!S50,'Controle Central'!S69,'Controle Central'!L50,'Controle Central'!L69,'Controle Central'!E50,'Controle Central'!E69,'Controle Central'!E88,'Controle Central'!E106,'Controle Central'!L88,'Controle Central'!L106,'Controle Central'!S88,'Controle Central'!S106,'Controle Central'!Z88,'Controle Central'!Z106,'Controle Central'!Z124,'Controle Central'!S124,'Controle Central'!L124,'Controle Central'!E124,'Controle Central'!E142,'Controle Central'!L142) -> 200 | K10: =SUM('Controle Central'!E13,'Controle Central'!L13,'Controle Central'!E32,'Controle Central'!L32,'Controle Central'!S13,'Controle Central'!S32,'Controle Central'!Z13,'Controle Central'!Z32,'Controle Central'!Z51,'Controle Central'!Z70,'Controle Central'!S51,'Controle Central'!S70,'Controle Central'!L51,'Controle Central'!L70,'Controle Central'!E51,'Controle Central'!E70,'Controle Central'!E89,'Controle Central'!E107,'Controle Central'!L89,'Controle Central'!L107,'Controle Central'!S89,'Controle Central'!S107,'Controle Central'!Z107,'Controle Central'!Z89,'Controle Central'!Z125,'Controle Central'!S125,'Controle Central'!L143,'Controle Central'!L125,'Controle Central'!E125,'Controle Central'!E143) -> 0 | L10: =SUM('Controle Central'!E14,'Controle Central'!E33,'Controle Central'!L14,'Controle Central'!L33,'Controle Central'!S14,'Controle Central'!S33,'Controle Central'!Z14,'Controle Central'!Z33,'Controle Central'!Z52,'Controle Central'!Z71,'Controle Central'!S52,'Controle Central'!S71,'Controle Central'!L52,'Controle Central'!L71,'Controle Central'!E52,'Controle Central'!E71,'Controle Central'!E90,'Controle Central'!E108,'Controle Central'!L90,'Controle Central'!L108,'Controle Central'!S90,'Controle Central'!S108,'Controle Central'!Z90,'Controle Central'!Z108,'Controle Central'!Z126,'Controle Central'!S126,'Controle Central'!L126,'Controle Central'!L144,'Controle Central'!E126,'Controle Central'!E144) -> 0 | M10: =SUM('Controle Central'!E15,'Controle Central'!E34,'Controle Central'!L15,'Controle Central'!L34,'Controle Central'!S15,'Controle Central'!S34,'Controle Central'!Z15,'Controle Central'!Z34,'Controle Central'!Z53,'Controle Central'!Z72,'Controle Central'!S53,'Controle Central'!S72,'Controle Central'!L53,'Controle Central'!L72,'Controle Central'!E53,'Controle Central'!E72,'Controle Central'!E91,'Controle Central'!E109,'Controle Central'!L91,'Controle Central'!L109,'Controle Central'!S91,'Controle Central'!S109,'Controle Central'!Z91,'Controle Central'!Z109,'Controle Central'!Z127,'Controle Central'!S127,'Controle Central'!L127,'Controle Central'!E127,'Controle Central'!E145,'Controle Central'!L145) -> 0
A12: BORRACHARIA | B12: =SUM('Controle Central'!F4,'Controle Central'!M4,'Controle Central'!M23,'Controle Central'!F23,'Controle Central'!T4,'Controle Central'!T23,'Controle Central'!AA4,'Controle Central'!AA23,'Controle Central'!AA61,'Controle Central'!AA42,'Controle Central'!T42,'Controle Central'!M42,'Controle Central'!M61,'Controle Central'!F61,'Controle Central'!F42,'Controle Central'!F98,'Controle Central'!F80,'Controle Central'!M80,'Controle Central'!M98,'Controle Central'!T80,'Controle Central'!T98,'Controle Central'!AA80,'Controle Central'!AA98,'Controle Central'!AA116,'Controle Central'!T116,'Controle Central'!M116,'Controle Central'!F116,'Controle Central'!F134,'Controle Central'!M134) -> 0 | C12: =SUM('Controle Central'!F5,'Controle Central'!F24,'Controle Central'!M5,'Controle Central'!M24,'Controle Central'!T24,'Controle Central'!T5,'Controle Central'!AA5,'Controle Central'!AA24,'Controle Central'!AA43,'Controle Central'!AA62,'Controle Central'!T43,'Controle Central'!T62,'Controle Central'!M43,'Controle Central'!M62,'Controle Central'!F43,'Controle Central'!F62,'Controle Central'!F81,'Controle Central'!F99,'Controle Central'!M99,'Controle Central'!M81,'Controle Central'!T99,'Controle Central'!T81,'Controle Central'!AA81,'Controle Central'!AA99,'Controle Central'!AA117,'Controle Central'!T117,'Controle Central'!M117,'Controle Central'!F117,'Controle Central'!F135,'Controle Central'!M135) -> 0 | D12: =SUM('Controle Central'!F6,'Controle Central'!F25,'Controle Central'!M6,'Controle Central'!M25,'Controle Central'!T6,'Controle Central'!T25,'Controle Central'!AA25,'Controle Central'!AA6,'Controle Central'!AA44,'Controle Central'!AA63,'Controle Central'!T63,'Controle Central'!T44,'Controle Central'!M44,'Controle Central'!M63,'Controle Central'!F63,'Controle Central'!F44,'Controle Central'!F82,'Controle Central'!F100,'Controle Central'!M100,'Controle Central'!M82,'Controle Central'!T82,'Controle Central'!T100,'Controle Central'!AA100,'Controle Central'!AA82,'Controle Central'!AA118,'Controle Central'!T118,'Controle Central'!M118,'Controle Central'!M136,'Controle Central'!F118,'Controle Central'!F136) -> 0 | E12: =SUM('Controle Central'!F7,'Controle Central'!F26,'Controle Central'!M26,'Controle Central'!M7,'Controle Central'!T7,'Controle Central'!T26,'Controle Central'!AA7,'Controle Central'!AA26,'Controle Central'!AA45,'Controle Central'!T45,'Controle Central'!AA64,'Controle Central'!T64,'Controle Central'!M45,'Controle Central'!M64,'Controle Central'!F45,'Controle Central'!F64,'Controle Central'!F83,'Controle Central'!F101,'Controle Central'!M83,'Controle Central'!M101,'Controle Central'!T83,'Controle Central'!T101,'Controle Central'!AA83,'Controle Central'!AA101,'Controle Central'!AA119,'Controle Central'!T119,'Controle Central'!M119,'Controle Central'!M137,'Controle Central'!F137,'Controle Central'!F119) -> 0 | F12: =SUM('Controle Central'!F8,'Controle Central'!F27,'Controle Central'!M8,'Controle Central'!M27,'Controle Central'!T8,'Controle Central'!T27,'Controle Central'!AA27,'Controle Central'!AA8,'Controle Central'!AA46,'Controle Central'!AA65,'Controle Central'!T46,'Controle Central'!T65,'Controle Central'!M65,'Controle Central'!M46,'Controle Central'!F46,'Controle Central'!F65,'Controle Central'!F84,'Controle Central'!F102,'Controle Central'!M84,'Controle Central'!M102,'Controle Central'!T84,'Controle Central'!T102,'Controle Central'!AA84,'Controle Central'!AA102,'Controle Central'!AA120,'Controle Central'!T120,'Controle Central'!M120,'Controle Central'!M138,'Controle Central'!F120,'Controle Central'!F138) -> 40 | G12: =SUM('Controle Central'!F9,'Controle Central'!F28,'Controle Central'!M9,'Controle Central'!M28,'Controle Central'!T9,'Controle Central'!T28,'Controle Central'!AA9,'Controle Central'!AA28,'Controle Central'!AA47,'Controle Central'!AA66,'Controle Central'!T47,'Controle Central'!T66,'Controle Central'!M47,'Controle Central'!M66,'Controle Central'!F47,'Controle Central'!F66,'Controle Central'!F85,'Controle Central'!F103,'Controle Central'!M85,'Controle Central'!M103,'Controle Central'!T85,'Controle Central'!T103,'Controle Central'!AA85,'Controle Central'!AA103,'Controle Central'!AA121,'Controle Central'!T121,'Controle Central'!M121,'Controle Central'!M139,'Controle Central'!F139) -> 0 | H12: =SUM('Controle Central'!F10,'Controle Central'!F29,'Controle Central'!M10,'Controle Central'!M29,'Controle Central'!T10,'Controle Central'!T29,'Controle Central'!AA10,'Controle Central'!AA29,'Controle Central'!AA48,'Controle Central'!T48,'Controle Central'!AA67,'Controle Central'!T67,'Controle Central'!M48,'Controle Central'!M67,'Controle Central'!F48,'Controle Central'!F67,'Controle Central'!F86,'Controle Central'!F104,'Controle Central'!M104,'Controle Central'!M86,'Controle Central'!T86,'Controle Central'!T104,'Controle Central'!AA86,'Controle Central'!AA104,'Controle Central'!AA122,'Controle Central'!T122,'Controle Central'!M122,'Controle Central'!M140,'Controle Central'!F122,'Controle Central'!F140) -> 0 | I12: =SUM('Controle Central'!F11,'Controle Central'!F30,'Controle Central'!M11,'Controle Central'!M30,'Controle Central'!T11,'Controle Central'!T30,'Controle Central'!AA11,'Controle Central'!AA30,'Controle Central'!AA49,'Controle Central'!AA68,'Controle Central'!T49,'Controle Central'!T68,'Controle Central'!M49,'Controle Central'!M68,'Controle Central'!F68,'Controle Central'!F49,'Controle Central'!F87,'Controle Central'!F105,'Controle Central'!M87,'Controle Central'!M105,'Controle Central'!T87,'Controle Central'!T105,'Controle Central'!AA87,'Controle Central'!AA105,'Controle Central'!AA123,'Controle Central'!T123,'Controle Central'!M123,'Controle Central'!M141,'Controle Central'!F123,'Controle Central'!F141) -> 0 | J12: =SUM('Controle Central'!F12,'Controle Central'!F31,'Controle Central'!M12,'Controle Central'!M31,'Controle Central'!T12,'Controle Central'!T31,'Controle Central'!AA12,'Controle Central'!AA31,'Controle Central'!AA50,'Controle Central'!T50,'Controle Central'!T69,'Controle Central'!AA69,'Controle Central'!M50,'Controle Central'!M69,'Controle Central'!F69,'Controle Central'!F50,'Controle Central'!F88,'Controle Central'!F106,'Controle Central'!M88,'Controle Central'!M106,'Controle Central'!T88,'Controle Central'!T106,'Controle Central'!AA88,'Controle Central'!AA106,'Controle Central'!AA124,'Controle Central'!T124,'Controle Central'!M124,'Controle Central'!F124,'Controle Central'!F142,'Controle Central'!M142) -> 0 | K12: =SUM('Controle Central'!F13,'Controle Central'!F32,'Controle Central'!M13,'Controle Central'!M32,'Controle Central'!T13,'Controle Central'!T32,'Controle Central'!AA13,'Controle Central'!AA32,'Controle Central'!AA51,'Controle Central'!T51,'Controle Central'!T70,'Controle Central'!AA70,'Controle Central'!M51,'Controle Central'!M70,'Controle Central'!F70,'Controle Central'!F51,'Controle Central'!F89,'Controle Central'!F107,'Controle Central'!M89,'Controle Central'!M107,'Controle Central'!T89,'Controle Central'!T107,'Controle Central'!AA107,'Controle Central'!AA89,'Controle Central'!AA125,'Controle Central'!T125,'Controle Central'!M125,'Controle Central'!F125,'Controle Central'!F143,'Controle Central'!M143) -> 0 | L12: =SUM('Controle Central'!F14,'Controle Central'!M14,'Controle Central'!F33,'Controle Central'!M33,'Controle Central'!T14,'Controle Central'!T33,'Controle Central'!AA33,'Controle Central'!AA14,'Controle Central'!AA52,'Controle Central'!T52,'Controle Central'!M52,'Controle Central'!M71,'Controle Central'!T71,'Controle Central'!AA71,'Controle Central'!AA90,'Controle Central'!T90,'Controle Central'!M90,'Controle Central'!F90,'Controle Central'!F108,'Controle Central'!F126,'Controle Central'!M108,'Controle Central'!M126,'Controle Central'!T108,'Controle Central'!T126,'Controle Central'!AA108,'Controle Central'!AA126,'Controle Central'!M144,'Controle Central'!F144) -> 0 | M12: =SUM('Controle Central'!F15,'Controle Central'!F34,'Controle Central'!M15,'Controle Central'!M34,'Controle Central'!T15,'Controle Central'!T34,'Controle Central'!AA15,'Controle Central'!AA34,'Controle Central'!AA53,'Controle Central'!T53,'Controle Central'!AA72,'Controle Central'!T72,'Controle Central'!M53,'Controle Central'!F53,'Controle Central'!F72,'Controle Central'!M72,'Controle Central'!F91,'Controle Central'!F109,'Controle Central'!M91,'Controle Central'!M109,'Controle Central'!T91,'Controle Central'!T109,'Controle Central'!AA91,'Controle Central'!AA109,'Controle Central'!AA127,'Controle Central'!T127,'Controle Central'!M127,'Controle Central'!M145,'Controle Central'!F127,'Controle Central'!F145) -> 0
B16: JAN | C16: FEV | D16: MAR | E16: ABR | F16: MAI | G16: JUN | H16: JUL | I16: AGO | J16: SET | K16: OUT | L16: NOV | M16: DEZ
A17: Medição
A19: Contrato de Locação
A21: Lucro Car's | B21: =B17-B19 -> 0 | C21: =C17-C19 -> 0 | D21: =D17-D19 -> 0 | E21: =E17-E19 -> 0 | F21: =F17-F19 -> 0 | G21: =G17-G19 -> 0 | H21: =H17-H19 -> 0 | I21: =I17-I19 -> 0 | ... M21: =M17-M19 -> 0

Sheet Controle Central
B2: ERIKA | I2: JOSEANE | P2: ALIRE | W2: LUCIANE
B3: KM RODADO | C3: KM MENSAL | D3: ABASTECIMENTO | E3: LAVA_RAPIDO | F3: BORRACHARIA | I3: KM RODADO | J3: KM MENSAL | K3: ABASTECIMENTO | L3: LAVA_RAPIDO | M3: BORRACHARIA | P3: KM RODADO | Q3: KM MENSAL | R3: ABASTECIMENTO | S3: LAVA_RAPIDO | T3: BORRACHARIA | W3: KM RODADO | X3: KM MENSAL | Y3: ABASTECIMENTO | Z3: LAVA_RAPIDO | AA3: BORRACHARIA
A4: JAN | C4: 0 | D4: 0 | E4: 0 | F4: 0 | H4: JAN | J4: 0 | K4: 0 | L4: 0 | M4: 0 | O4: JAN | Q4: 0 | R4: 0 | S4: 0 | T4: 0 | V4: JAN | X4: 0 | Y4: 0 | Z4: 0 | AA4: 0
A5: FEV | B5: ='Roberto- Devolv'!H11 -> 0 | C5: =SUM(5000-B5) -> 5000 | D5: ='Roberto- Devolv'!U12 -> 0 | E5: ='Roberto- Devolv'!AC12 -> 0 | F5: ='Roberto- Devolv'!AK12 -> 0 | H5: FEV | I5: ='Chris-Desmob'!H11 -> 323 | J5: =SUM(5000-I5) -> 4677 | K5: ='Chris-Desmob'!U12 -> 0 | L5: ='Chris-Desmob'!AC12 -> 0 | M5: ='Chris-Desmob'!AK12 -> 0 | O5: FEV | P5: ='Alain-Desmob'!H12 -> 326 | Q5: =SUM(5000-P5) -> 4674 | R5: ='Alain-Desmob'!U13 -> 0 | S5: ='Alain-Desmob'!AI13 -> 0 | T5: ='Alain-Desmob'!AR13 -> 0 | V5: FEV | W5: ='Marcilio-Desmob'!H13 -> 0 | X5: =SUM(5000-W5) -> 5000 | Y5: ='Marcilio-Desmob'!U14 -> 0 | Z5: ='Marcilio-Desmob'!AK14 -> 0 | AA5: ='Marcilio-Desmob'!AT14 -> 0
A6: MAR | B6: ='Roberto- Devolv'!H15 -> 1257 | C6: =SUM(5000-B6) -> 3743 | D6: ='Roberto- Devolv'!U16 -> 743.17 | E6: ='Roberto- Devolv'!AC16 -> 0 | F6: ='Roberto- Devolv'!AK16 -> 0 | H6: MAR | I6: ='Chris-Desmob'!H15 -> 1735 | J6: =SUM(5000-I6) -> 3265 | K6: ='Chris-Desmob'!U16 -> 1005.98 | L6: ='Chris-Desmob'!AC16 -> 0 | M6: ='Chris-Desmob'!AK16 -> 0 | O6: MAR | P6: ='Alain-Desmob'!H16 -> 3483 | Q6: =SUM(5000-P6) -> 1517 | R6: ='Alain-Desmob'!U17 -> 1804.05 | S6: ='Alain-Desmob'!AI17 -> 0 | T6: ='Alain-Desmob'!AR17 -> 0 | V6: MAR | W6: ='Marcilio-Desmob'!H17 -> 657 | X6: =SUM(5000-W6) -> 4343 | Y6: ='Marcilio-Desmob'!U18 -> 346 | Z6: ='Marcilio-Desmob'!AK18 -> 0 | AA6: ='Marcilio-Desmob'!AT18 -> 0
A7: ABR | B7: ='Roberto- Devolv'!H19 -> 4081 | C7: =SUM(5000-B7) -> 919 | D7: ='Roberto- Devolv'!U20 -> 2058.4 | E7: ='Roberto- Devolv'!AC20 -> 0 | F7: ='Roberto- Devolv'!AK20 -> 0 | H7: ABR | I7: ='Chris-Desmob'!H19 -> 1881 | J7: =SUM(5000-I7) -> 3119 | K7: ='Chris-Desmob'!U20 -> 953.58 | L7: ='Chris-Desmob'!AC20 -> 0 | M7: ='Chris-Desmob'!AK20 -> 0 | O7: ABR | P7: ='Alain-Desmob'!H20 -> 3268 | Q7: =SUM(5000-P7) -> 1732 | R7: ='Alain-Desmob'!Z21 -> 0 | S7: ='Alain-Desmob'!AI21 -> 0 | T7: ='Alain-Desmob'!AR21 -> 0 | V7: ABR | W7: ='Marcilio-Desmob'!H21 -> 2902 | X7: =SUM(5000-W7) -> 2098 | Y7: ='Marcilio-Desmob'!AB22 -> 0 | Z7: ='Marcilio-Desmob'!AK22 -> 0 | AA7: ='Marcilio-Desmob'!AT22 -> 0
A8: MAI | B8: ='Roberto- Devolv'!H23 -> 3287 | C8: =SUM(5000-B8) -> 1713 | D8: ='Roberto- Devolv'!U24 -> 2289.44 | E8: ='Roberto- Devolv'!AC24 -> 0 | F8: ='Roberto- Devolv'!AK24 -> 40 | H8: MAI | I8: ='Chris-Desmob'!H23 -> 2424 | J8: =SUM(5000-I8) -> 2576 | K8: ='Chris-Desmob'!U24 -> 1407.37 | L8: ='Chris-Desmob'!AC24 -> 0 | M8: ='Chris-Desmob'!AK24 -> 0 | O8: MAI | P8: ='Alain-Desmob'!H24 -> 4177 | Q8: =SUM(5000-P8) -> 823 | R8: ='Alain-Desmob'!Z25 -> 0 | S8: ='Alain-Desmob'!AI25 -> 0 | T8: ='Alain-Desmob'!AR25 -> 0 | V8: MAI | W8: ='Marcilio-Desmob'!H25 -> 3743 | X8: =SUM(5000-W8) -> 1257 | Y8: ='Marcilio-Desmob'!AB26 -> 0 | Z8: ='Marcilio-Desmob'!AK26 -> 0 | AA8: ='Marcilio-Desmob'!AT26 -> 0
A9: JUN | B9: ='Roberto- Devolv'!H27 -> 3480 | C9: =SUM(5000-B9) -> 1520 | D9: ='Roberto- Devolv'!U28 -> 1793.83 | E9: ='Roberto- Devolv'!AC28 -> 0 | F9: ='Roberto- Devolv'!AK28 -> 0 | H9: JUN | I9: ='Chris-Desmob'!H27 -> 2657 | J9: =SUM(5000-I9) -> 2343 | K9: ='Chris-Desmob'!U28 -> 763.62 | L9: ='Chris-Desmob'!AC28 -> 0 | M9: ='Roberto- Devolv'!AK28 -> 0 | O9: JUN | P9: ='Alain-Desmob'!H28 -> 4171 | Q9: =SUM(5000-P9) -> 829 | R9: ='Alain-Desmob'!Z29 -> 0 | S9: ='Alain-Desmob'!AI29 -> 0 | T9: ='Alain-Desmob'!AR29 -> 0 | V9: JUN | W9: ='Marcilio-Desmob'!H29 -> 3153 | X9: =SUM(5000-W9) -> 1847 | Y9: ='Marcilio-Desmob'!AB30 -> 0 | Z9: ='Marcilio-Desmob'!AK30 -> 0 | AA9: ='Marcilio-Desmob'!AT30 -> 0
A10: JUL | B10: ='Roberto- Devolv'!H31 -> 2925 | C10: =SUM(5000-B10) -> 2075 | D10: ='Roberto- Devolv'!U32 -> 1924.17 | E10: ='Roberto- Devolv'!AC32 -> 0 | F10: ='Roberto- Devolv'!AK32 -> 0 | H10: JUL | I10: ='Chris-Desmob'!H31 -> 2884 | J10: =SUM(5000-I10) -> 2116 | K10: ='Chris-Desmob'!U32 -> 1535.47 | L10: ='Chris-Desmob'!AC32 -> 0 | M10: ='Chris-Desmob'!AK32 -> 0 | O10: JUL | P10: ='Alain-Desmob'!H32 -> 3138 | Q10: =SUM(5000-P10) -> 1862 | R10: ='Alain-Desmob'!Z33 -> 0 | S10: ='Alain-Desmob'!AI33 -> 0 | T10: ='Alain-Desmob'!AR33 -> 0 | V10: JUL | W10: ='Marcilio-Desmob'!H33 -> 2966 | X10: =SUM(5000-W10) -> 2034 | Y10: ='Marcilio-Desmob'!AB34 -> 0 | Z10: ='Marcilio-Desmob'!AK34 -> 0 | AA10: ='Marcilio-Desmob'!AT34 -> 0
A11: AGO | B11: ='Roberto- Devolv'!H35 -> 2937 | C11: =SUM(5000-B11) -> 2063 | D11: ='Roberto- Devolv'!U36 -> 2154.074 | E11: ='Roberto- Devolv'!AC36 -> 0 | F11: ='Roberto- Devolv'!AK36 -> 0 | H11: AGO | I11: ='Chris-Desmob'!H35 -> 2292 | J11: =SUM(5000-I11) -> 2708 | K11: ='Chris-Desmob'!U36 -> 1581.46 | L11: ='Chris-Desmob'!AC36 -> 0 | M11: ='Chris-Desmob'!AK36 -> 0 | O11: AGO | P11: ='Alain-Desmob'!H36 -> 3784 | Q11: =SUM(5000-P11) -> 1216 | R11: ='Alain-Desmob'!Z37 -> 0 | S11: ='Alain-Desmob'!AI37 -> 0 | T11: ='Alain-Desmob'!AR37 -> 0 | V11: AGO | W11: ='Marcilio-Desmob'!H37 -> 2566 | X11: =SUM(5000-W11) -> 2434 | Y11: ='Marcilio-Desmob'!AB38 -> 0 | Z11: ='Marcilio-Desmob'!AK38 -> 0 | AA11: ='Marcilio-Desmob'!AT38 -> 0
A12: SET | B12: ='Roberto- Devolv'!H39 -> 2938 | C12: =SUM(5000-B12) -> 2062 | D12: ='Roberto- Devolv'!U40 -> 1606.49 | E12: ='Roberto- Devolv'!AC40 -> 0 | F12: ='Roberto- Devolv'!AK40 -> 0 | H12: SET | I12: ='Chris-Desmob'!H39 -> 2440 | J12: =SUM(5000-I12) -> 2560 | K12: ='Chris-Desmob'!U40 -> 1316.07 | L12: ='Chris-Desmob'!AC40 -> 0 | M12: ='Chris-Desmob'!AK40 -> 0 | O12: SET | P12: ='Alain-Desmob'!H36 -> 3784 | Q12: =SUM(5000-P12) -> 1216 | R12: ='Alain-Desmob'!Z41 -> 0 | S12: ='Alain-Desmob'!AI41 -> 0 | T12: ='Alain-Desmob'!AR41 -> 0 | V12: SET | W12: ='Marcilio-Desmob'!H41 -> 2482 | X12: =SUM(5000-W12) -> 2518 | Y12: ='Marcilio-Desmob'!AB42 -> 0 | Z12: ='Marcilio-Desmob'!AK42 -> 0 | AA12: ='Marcilio-Desmob'!AT42 -> 0
A13: OUT | B13: ='Roberto- Devolv'!H43 -> 2470 | C13: =SUM(5000-B13) -> 2530 | D13: ='Roberto- Devolv'!U44 -> 1308.7 | E13: ='Roberto- Devolv'!AC44 -> 0 | F13: ='Roberto- Devolv'!AK44 -> 0 | H13: OUT | I13: ='Chris-Desmob'!H43 -> 1979 | J13: =SUM(5000-I13) -> 3021 | K13: ='Chris-Desmob'!U44 -> 964.64 | L13: ='Chris-Desmob'!AC44 -> 0 | M13: ='Chris-Desmob'!AK44 -> 0 | O13: OUT | P13: ='Alain-Desmob'!H40 -> 2735 | Q13: =SUM(5000-P13) -> 2265 | R13: ='Alain-Desmob'!Z45 -> 0 | S13: ='Alain-Desmob'!AI45 -> 0 | T13: ='Alain-Desmob'!AR45 -> 0 | V13: OUT | W13: ='Marcilio-Desmob'!H45 -> 2278 | X13: =SUM(5000-W13) -> 2722 | Y13: ='Marcilio-Desmob'!AB46 -> 0 | Z13: ='Marcilio-Desmob'!AK46 -> 0 | AA13: ='Marcilio-Desmob'!AT46 -> 0
A14: NOV | B14: ='Roberto- Devolv'!H47 -> 1403 | C14: =SUM(5000-B14) -> 3597 | D14: ='Roberto- Devolv'!U48 -> 854.63 | E14: ='Roberto- Devolv'!AC48 -> 0 | F14: ='Roberto- Devolv'!AK48 -> 0 | H14: NOV | I14: ='Chris-Desmob'!H47 -> 0 | J14: =SUM(5000-I14) -> 5000 | K14: ='Chris-Desmob'!U48 -> 0 | L14: ='Chris-Desmob'!AC48 -> 0 | M14: ='Chris-Desmob'!AK48 -> 0 | O14: NOV | P14: ='Alain-Desmob'!H44 -> 4344 | Q14: =SUM(5000-P14) -> 656 | R14: ='Alain-Desmob'!Z49 -> 0 | S14: ='Alain-Desmob'!AI49 -> 0 | T14: ='Alain-Desmob'!AR49 -> 0 | V14: NOV | W14: ='Marcilio-Desmob'!H49 -> 1329 | X14: =SUM(5000-W14) -> 3671 | Y14: ='Marcilio-Desmob'!AB50 -> 0 | Z14: ='Marcilio-Desmob'!AK50 -> 0 | AA14: ='Marcilio-Desmob'!AT50 -> 0
A15: DEZ | B15: ='Roberto- Devolv'!H51 -> 0 | C15: =SUM(5000-B15) -> 5000 | D15: ='Roberto- Devolv'!U52 -> 0 | E15: ='Roberto- Devolv'!AC52 -> 0 | F15: ='Roberto- Devolv'!AK52 -> 0 | H15: DEZ | I15: ='Chris-Desmob'!H51 -> 0 | J15: =SUM(5000-I15) -> 5000 | K15: ='Chris-Desmob'!U52 -> 0 | L15: ='Chris-Desmob'!AC48 -> 0 | M15: ='Chris-Desmob'!AK48 -> 0 | O15: DEZ | P15: ='Alain-Desmob'!H48 -> 2478 | Q15: =SUM(5000-P15) -> 2522 | R15: ='Alain-Desmob'!Z53 -> 0 | S15: ='Alain-Desmob'!AI49 -> 0 | T15: ='Alain-Desmob'!AR53 -> 0 | V15: DEZ | W15: ='Marcilio-Desmob'!H53 -> 2541 | X15: =SUM(5000-W15) -> 2459 | Y15: ='Marcilio-Desmob'!AB54 -> 0 | Z15: ='Marcilio-Desmob'!AK54 -> 0 | AA15: ='Marcilio-Desmob'!AT54 -> 0
A17: TOTAL | B17: =SUM(B4:B15) -> 24778 | D17: =SUM(D4:D15) -> 14732.904 | E17: =SUM(E4:E15) -> 0 | F17: =SUM(F4:F15) -> 40 | H17: TOTAL | I17: =SUM(I4:I15) -> 18615 | K17: =SUM(K4:K15) -> 9528.19 | L17: =SUM(L4:L15) -> 0 | M17: =SUM(M4:M15) -> 0 | O17: TOTAL | P17: =SUM(P4:P15) -> 35688 | R17: =SUM(R4:R15) -> 1804.05 | S17: =SUM(S4:S15) -> 0 | T17: =SUM(T4:T15) -> 0 | V17: TOTAL | W17: =SUM(W4:W15) -> 24617 | Y17: =SUM(Y4:Y15) -> 346 | Z17: =SUM(Z4:Z15) -> 0 | AA17: =SUM(AA4:AA15) -> 0
A18: SALDO KM | B18: =SUM(60000-B17) -> 35222 | H18: SALDO KM | I18: =SUM(60000-I17) -> 41385 | O18: SALDO KM | P18: =SUM(60000-P17) -> 24312 | V18: SALDO KM | W18: =SUM(60000-W17) -> 35383
B21: CAR_05 | I21: CAR_06 | P21: CAR_07 | W21: CAR_08
B22: KM RODADO | C22: KM MENSAL | D22: ABASTECIMENTO | E22: LAVA_RAPIDO | F22: BORRACHARIA | I22: KM RODADO | J22: KM MENSAL | K22: ABASTECIMENTO | L22: LAVA_RAPIDO | M22: BORRACHARIA | P22: KM RODADO | Q22: KM MENSAL | R22: ABASTECIMENTO | S22: LAVA_RAPIDO | T22: BORRACHARIA | W22: KM RODADO | X22: KM MENSAL | Y22: ABASTECIMENTO | Z22: LAVA_RAPIDO | AA22: BORRACHARIA
A23: JAN | C23: 0 | D23: 0 | E23: 0 | F23: 0 | H23: JAN | J23: 0 | K23: 0 | L23: 0 | M23: 0 | O23: JAN | Q23: 0 | R23: 0 | S23: 0 | T23: 0 | V23: JAN | X23: 0 | Y23: 0 | Z23: 0 | AA23: 0
A24: FEV | B24: =Yanca!H14 -> 0 | C24: =SUM(5000-B24) -> 5000 | D24: =Yanca!U15 -> 0 | E24: =Yanca!AC15 -> 0 | F24: =Yanca!AK15 -> 0 | H24: FEV | I24: =Elisson!H13 -> 0 | J24: =SUM(5000-I24) -> 5000 | K24: =Elisson!U14 -> 0 | L24: =Elisson!AC14 -> 0 | M24: =Elisson!AK14 -> 0 | O24: FEV | P24: ='Geovani-Desmob'!H11 -> 0 | Q24: =SUM(5000-P24) -> 5000 | R24: ='Geovani-Desmob'!U12 -> 0 | S24: ='Geovani-Desmob'!AC12 -> 0 | T24: ='Geovani-Desmob'!AK12 -> 0 | V24: FEV | W24: ='Eider Breno-Desmob'!H12 -> 0 | X24: =SUM(5000-W24) -> 5000 | Y24: ='Eider Breno-Desmob'!U13 -> 0 | Z24: ='Eider Breno-Desmob'!AE13 -> 0 | AA24: ='Eider Breno-Desmob'!AN13 -> 0
A25: MAR | B25: =Yanca!H18 -> 0 | C25: =SUM(5000-B25) -> 5000 | D25: =Yanca!U19 -> 0 | E25: =Yanca!AC19 -> 0 | F25: =Yanca!AK19 -> 0 | H25: MAR | I25: =Elisson!H17 -> 0 | J25: =SUM(5000-I25) -> 5000 | K25: =Elisson!U18 -> 0 | L25: =Elisson!AC18 -> 0 | M25: =Elisson!AK18 -> 0 | O25: MAR | P25: ='Geovani-Desmob'!H15 -> 0 | Q25: =SUM(5000-P25) -> 5000 | R25: ='Geovani-Desmob'!U16 -> 0 | S25: ='Geovani-Desmob'!AC16 -> 0 | T25: ='Geovani-Desmob'!AK16 -> 0 | V25: MAR | W25: ='Eider Breno-Desmob'!H16 -> 0 | X25: =SUM(5000-W25) -> 5000 | Y25: ='Eider Breno-Desmob'!U17 -> 0 | Z25: ='Eider Breno-Desmob'!AE17 -> 0 | AA25: ='Eider Breno-Desmob'!AN17 -> 0
A26: ABR | B26: =Yanca!H22 -> 0 | C26: =SUM(5000-B26) -> 5000 | D26: =Yanca!U23 -> 0 | E26: =Yanca!AC23 -> 0 | F26: =Yanca!AK23 -> 0 | H26: ABR | I26: =Elisson!H21 -> 0 | J26: =SUM(5000-I26) -> 5000 | K26: =Elisson!U22 -> 0 | L26: =Elisson!AC22 -> 0 | M26: =Elisson!AK22 -> 0 | O26: ABR | P26: ='Geovani-Desmob'!H19 -> 0 | Q26: =SUM(5000-P26) -> 5000 | R26: ='Geovani-Desmob'!U20 -> 0 | S26: ='Geovani-Desmob'!AC20 -> 0 | T26: ='Geovani-Desmob'!AK20 -> 0 | V26: ABR | W26: ='Eider Breno-Desmob'!H20 -> 0 | X26: =SUM(5000-W26) -> 5000 | Y26: ='Eider Breno-Desmob'!U201 -> 0 | Z26: ='Eider Breno-Desmob'!AE21 -> 0 | AA26: ='Eider Breno-Desmob'!AN201 -> 0
A27: MAI | B27: =Yanca!H26 -> 0 | C27: =SUM(5000-B27) -> 5000 | D27: =Yanca!U27 -> 0 | E27: =Yanca!AC27 -> 0 | F27: =Yanca!AK27 -> 0 | H27: MAI | I27: =Elisson!H25 -> 0 | J27: =SUM(5000-I27) -> 5000 | K27: =Elisson!U26 -> 0 | L27: =Elisson!AC26 -> 0 | M27: =Elisson!AK26 -> 0 | O27: MAI | P27: ='Geovani-Desmob'!H23 -> 0 | Q27: =SUM(5000-P27) -> 5000 | R27: ='Geovani-Desmob'!U24 -> 0 | S27: ='Geovani-Desmob'!AC24 -> 0 | T27: ='Geovani-Desmob'!AK24 -> 0 | V27: MAI | W27: ='Eider Breno-Desmob'!H24 -> 0 | X27: =SUM(5000-W27) -> 5000 | Y27: ='Eider Breno-Desmob'!U25 -> 0 | Z27: ='Eider Breno-Desmob'!AE25 -> 0 | AA27: ='Eider Breno-Desmob'!AN25 -> 0
A28: JUN | B28: =Yanca!H30 -> 3261 | C28: =SUM(5000-B28) -> 1739 | D28: =Yanca!U31 -> 849.09 | E28: =Yanca!AC31 -> 0 | F28: =Yanca!AK31 -> 0 | H28: JUN | I28: =Elisson!H29 -> 0 | J28: =SUM(5000-I28) -> 5000 | K28: =Elisson!U30 -> 0 | L28: =Elisson!AC30 -> 0 | M28: =Elisson!AK30 -> 0 | O28: JUN | P28: ='Geovani-Desmob'!H27 -> 0 | Q28: =SUM(5000-P28) -> 5000 | R28: ='Geovani-Desmob'!U28 -> 0 | S28: ='Geovani-Desmob'!AC28 -> 0 | T28: ='Geovani-Desmob'!AK28 -> 0 | V28: JUN | W28: ='Eider Breno-Desmob'!H28 -> 0 | X28: =SUM(5000-W28) -> 5000 | Y28: ='Eider Breno-Desmob'!U29 -> 0 | Z28: ='Eider Breno-Desmob'!AE29 -> 0 | AA28: ='Eider Breno-Desmob'!AN29 -> 0
A29: JUL | B29: =Yanca!H34 -> 2509 | C29: =SUM(5000-B29) -> 2491 | D29: =Yanca!U35 -> 1401.77 | E29: =Yanca!AC35 -> 0 | F29: =Yanca!AK35 -> 0 | H29: JUL | I29: =Elisson!H33 -> 1760 | J29: =SUM(5000-I29) -> 3240 | K29: =Elisson!U34 -> 790.6 | L29: =Elisson!AC34 -> 0 | M29: =Elisson!AK34 -> 0 | O29: JUL | P29: ='Geovani-Desmob'!H31 -> 2511 | Q29: =SUM(5000-P29) -> 2489 | R29: ='Geovani-Desmob'!U32 -> 1564.03 | S29: ='Geovani-Desmob'!AC32 -> 0 | T29: ='Geovani-Desmob'!AK32 -> 0 | V29: JUL | W29: ='Eider Breno-Desmob'!H32 -> 672 | X29: =SUM(5000-W29) -> 4328 | Y29: ='Eider Breno-Desmob'!U33 -> 274.09 | Z29: ='Eider Breno-Desmob'!AE33 -> 0 | AA29: ='Eider Breno-Desmob'!AN33 -> 0
A30: AGO | B30: =Yanca!H38 -> 2496 | C30: =SUM(5000-B30) -> 2504 | D30: =Yanca!U39 -> 1445.53 | E30: =Yanca!AC39 -> 0 | F30: =Yanca!AK39 -> 0 | H30: AGO | I30: =Elisson!H37 -> 2237 | J30: =SUM(5000-I30) -> 2763 | K30: =Elisson!U38 -> 1039.7 | L30: =Elisson!AC38 -> 40 | M30: =Elisson!AK38 -> 0 | O30: AGO | P30: ='Geovani-Desmob'!H35 -> 2513 | Q30: =SUM(5000-P30) -> 2487 | R30: ='Geovani-Desmob'!U36 -> 1286.47 | S30: ='Geovani-Desmob'!AC36 -> 0 | T30: ='Geovani-Desmob'!AK36 -> 0 | V30: AGO | W30: ='Eider Breno-Desmob'!H36 -> 3020 | X30: =SUM(5000-W30) -> 1980 | Y30: ='Eider Breno-Desmob'!U37 -> 1453.48 | Z30: ='Eider Breno-Desmob'!AE37 -> 0 | AA30: ='Eider Breno-Desmob'!AN37 -> 0
A31: SET | B31: =Yanca!H42 -> 2430 | C31: =SUM(5000-B31) -> 2570 | D31: =Yanca!U43 -> 1347.08 | E31: =Yanca!AC43 -> 80 | F31: =Yanca!AK7 -> 0 | H31: SET | I31: =Elisson!H45 -> 3447 | J31: =SUM(5000-I31) -> 1553 | K31: =Elisson!U46 -> 1534.59 | L31: =Elisson!AC46 -> 120 | M31: =Elisson!AK46 -> 0 | O31: SET | P31: ='Geovani-Desmob'!H39 -> 2099 | Q31: =SUM(5000-P31) -> 2901 | R31: ='Geovani-Desmob'!U40 -> 1333.14 | S31: ='Geovani-Desmob'!AC40 -> 0 | T31: ='Geovani-Desmob'!AK40 -> 0 | V31: SET | W31: ='Eider Breno-Desmob'!H40 -> 1844 | X31: =SUM(5000-W31) -> 3156 | Y31: ='Eider Breno-Desmob'!U41 -> 688.1 | Z31: ='Eider Breno-Desmob'!AE41 -> 0 | AA31: ='Eider Breno-Desmob'!AN41 -> 0
A32: OUT | B32: =Yanca!H46 -> 1811 | C32: =SUM(5000-B32) -> 3189 | D32: =Yanca!U47 -> 1126.64 | E32: =Yanca!AC47 -> 0 | F32: =Yanca!AK47 -> 0 | H32: OUT | I32: =Elisson!H49 -> 3116 | J32: =SUM(5000-I32) -> 1884 | K32: =Elisson!U50 -> 1675.32 | L32: =Elisson!AC50 -> 0 | M32: =Elisson!AK50 -> 0 | O32: OUT | P32: ='Geovani-Desmob'!H43 -> 347 | Q32: =SUM(5000-P32) -> 4653 | R32: ='Geovani-Desmob'!U44 -> 159.79 | S32: ='Geovani-Desmob'!AC44 -> 0 | T32: ='Geovani-Desmob'!AK44 -> 0 | V32: OUT | W32: ='Eider Breno-Desmob'!H44 -> 2526 | X32: =SUM(5000-W32) -> 2474 | Y32: ='Eider Breno-Desmob'!U45 -> 1168.78 | Z32: ='Eider Breno-Desmob'!AE45 -> 0 | AA32: ='Eider Breno-Desmob'!AN45 -> 0
A33: NOV | B33: =Yanca!H50 -> 1343 | C33: =SUM(5000-B33) -> 3657 | D33: =Yanca!U51 -> 742.3 | E33: =Yanca!AC51 -> 0 | F33: =Yanca!AK51 -> 0 | H33: NOV | I33: =Elisson!H53 -> 2083 | J33: =SUM(5000-I33) -> 2917 | K33: =Elisson!U54 -> 480.01 | L33: =Elisson!AC54 -> 0 | M33: =Elisson!AK54 -> 0 | O33: NOV | P33: ='Geovani-Desmob'!H47 -> 0 | Q33: =SUM(5000-P33) -> 5000 | R33: ='Geovani-Desmob'!U48 -> 0 | S33: ='Geovani-Desmob'!AC48 -> 0 | T33: ='Geovani-Desmob'!AK48 -> 0 | V33: NOV | W33: ='Eider Breno-Desmob'!H48 -> 2215 | X33: =SUM(5000-W33) -> 2785 | Y33: ='Eider Breno-Desmob'!U49 -> 930.37 | Z33: ='Eider Breno-Desmob'!AE49 -> 0 | AA33: ='Eider Breno-Desmob'!AN49 -> 0
A34: DEZ | B34: =Yanca!H54 -> 1656 | C34: =SUM(5000-B34) -> 3344 | D34: =Yanca!U55 -> 1033.84 | E34: =Yanca!AC55 -> 0 | F34: =Yanca!AK55 -> 0 | H34: DEZ | I34: =Elisson!H57 -> 2820 | J34: =SUM(5000-I34) -> 2180 | K34: =Elisson!U58 -> 1278.86 | L34: =Elisson!AC58 -> 0 | M34: =Elisson!AK58 -> 0 | O34: DEZ | P34: ='Geovani-Desmob'!H51 -> 0 | Q34: =SUM(5000-P34) -> 5000 | R34: ='Geovani-Desmob'!U52 -> 0 | S34: ='Geovani-Desmob'!AC52 -> 0 | T34: ='Geovani-Desmob'!AK52 -> 0 | V34: DEZ | W34: ='Eider Breno-Desmob'!H52 -> 1892 | X34: =SUM(5000-W34) -> 3108 | Y34: ='Eider Breno-Desmob'!U53 -> 473.88 | Z34: ='Eider Breno-Desmob'!AE53 -> 0 | AA34: ='Eider Breno-Desmob'!AN53 -> 0
A36: TOTAL | B36: =SUM(B23:B34) -> 15506 | D36: =SUM(D23:D34) -> 7946.25 | E36: =SUM(E23:E34) -> 80 | F36: =SUM(F23:F34) -> 0 | H36: TOTAL | I36: =SUM(I23:I34) -> 15463 | K36: =SUM(K23:K34) -> 6799.08 | L36: =SUM(L23:L34) -> 160 | M36: =SUM(M23:M34) -> 0 | O36: TOTAL | P36: =SUM(P23:P34) -> 7470 | R36: =SUM(R23:R34) -> 4343.43 | S36: =SUM(S23:S34) -> 0 | T36: =SUM(T23:T34) -> 0 | V36: TOTAL | W36: =SUM(W23:W34) -> 12169 | Y36: =SUM(Y23:Y34) -> 4988.7 | Z36: =SUM(Z23:Z34) -> 0 | AA36: =SUM(AA23:AA34) -> 0
A37: SALDO KM | B37: =SUM(60000-B36) -> 44494 | H37: SALDO KM | I37: =SUM(60000-I36) -> 44537 | O37: SALDO KM | P37: =SUM(60000-P36) -> 52530 | V37: SALDO KM | W37: =SUM(60000-W36) -> 47831
B40: CAR_09 | I40: CAR_10 | P40: CAR_11 | W40: CAR_12
B41: KM | C41: KM MENSAL | D41: ABASTECIMENTO | E41: LAVA_RAPIDO | F41: BORRACHARIA | I41: KM | J41: KM MENSAL | K41: ABASTECIMENTO | L41: LAVA_RAPIDO | M41: BORRACHARIA | P41: KM | Q41: KM MENSAL | R41: ABASTECIMENTO | S41: LAVA_RAPIDO | T41: BORRACHARIA | W41: KM | X41: KM MENSAL | Y41: ABASTECIMENTO | Z41: LAVA_RAPIDO | AA41: BORRACHARIA
A42: JAN | H42: JAN | O42: JAN | V42: JAN
A43: FEV | B43: ='Tiago Gonçalves - Desmob.'!H11 -> 0 | C43: =SUM(5000-B43) -> 5000 | D43: ='Tiago Gonçalves - Desmob.'!U12 -> 0 | E43: ='Tiago Gonçalves - Desmob.'!AE12 -> 0 | F43: ='Tiago Gonçalves - Desmob.'!AN12 -> 0 | H43: FEV | I43: ='Ilo Hilton'!H13 -> 0 | J43: =SUM(5000-I43) -> 5000 | K43: ='Ilo Hilton'!U14 -> 0 | L43: ='Ilo Hilton'!AE14 -> 0 | M43: ='Ilo Hilton'!AN14 -> 0 | O43: FEV | P43: ='Ubiratan-Desmob'!H11 -> 0 | Q43: =SUM(5000-P43) -> 5000 | R43: ='Ubiratan-Desmob'!U12 -> 0 | S43: ='Ubiratan-Desmob'!AE12 -> 0 | T43: ='Ubiratan-Desmob'!AN12 -> 0 | V43: FEV | W43: ='Ilo Hilton-Desmob'!H11 -> 0 | X43: =SUM(5000-W43) -> 5000 | Y43: ='Ilo Hilton-Desmob'!U12 -> 0 | Z43: ='Ilo Hilton-Desmob'!AE12 -> 0 | AA43: ='Ilo Hilton-Desmob'!AN12 -> 0
A44: MAR | B44: ='Tiago Gonçalves - Desmob.'!H15 -> 0 | C44: =SUM(5000-B44) -> 5000 | D44: ='Tiago Gonçalves - Desmob.'!U16 -> 0 | E44: ='Tiago Gonçalves - Desmob.'!AE16 -> 0 | F44: ='Tiago Gonçalves - Desmob.'!AN16 -> 0 | H44: MAR | I44: ='Ilo Hilton'!H17 -> 0 | J44: =SUM(5000-I44) -> 5000 | K44: ='Ilo Hilton'!U18 -> 0 | L44: ='Ilo Hilton'!AE18 -> 0 | M44: ='Ilo Hilton'!AN18 -> 0 | O44: MAR | P44: ='Ubiratan-Desmob'!H15 -> 0 | Q44: =SUM(5000-P44) -> 5000 | R44: ='Ubiratan-Desmob'!U16 -> 0 | S44: ='Ubiratan-Desmob'!AE16 -> 0 | T44: ='Ubiratan-Desmob'!AN16 -> 0 | V44: MAR | W44: ='Ilo Hilton-Desmob'!H15 -> 0 | X44: =SUM(5000-W44) -> 5000 | Y44: ='Ilo Hilton-Desmob'!U16 -> 0 | Z44: ='Ilo Hilton-Desmob'!AE16 -> 0 | AA44: ='Ilo Hilton-Desmob'!AN16 -> 0
A45: ABR | B45: ='Tiago Gonçalves - Desmob.'!H19 -> 0 | C45: =SUM(5000-B45) -> 5000 | D45: ='Tiago Gonçalves - Desmob.'!U20 -> 0 | E45: ='Tiago Gonçalves - Desmob.'!AE20 -> 0 | F45: ='Tiago Gonçalves - Desmob.'!AN20 -> 0 | H45: ABR | I45: ='Ilo Hilton'!H21 -> 0 | J45: =SUM(5000-I45) -> 5000 | K45: ='Ilo Hilton'!U22 -> 0 | L45: ='Ilo Hilton'!AE22 -> 0 | M45: ='Ilo Hilton'!AN22 -> 0 | O45: ABR | P45: ='Ubiratan-Desmob'!H19 -> 0 | Q45: =SUM(5000-P45) -> 5000 | R45: ='Ubiratan-Desmob'!U20 -> 0 | S45: ='Ubiratan-Desmob'!AE20 -> 0 | T45: ='Ubiratan-Desmob'!AN20 -> 0 | V45: ABR | W45: ='Ilo Hilton-Desmob'!H19 -> 0 | X45: =SUM(5000-W45) -> 5000 | Y45: ='Ilo Hilton-Desmob'!U20 -> 0 | Z45: ='Ilo Hilton-Desmob'!AE20 -> 0 | AA45: ='Ilo Hilton-Desmob'!AN20 -> 0
A46: MAI | B46: ='Tiago Gonçalves - Desmob.'!H23 -> 0 | C46: =SUM(5000-B46) -> 5000 | D46: ='Tiago Gonçalves - Desmob.'!U24 -> 0 | E46: ='Tiago Gonçalves - Desmob.'!AE24 -> 0 | F46: ='Tiago Gonçalves - Desmob.'!AN24 -> 0 | H46: MAI | I46: ='Ilo Hilton'!H25 -> 0 | J46: =SUM(5000-I46) -> 5000 | K46: ='Ilo Hilton'!U26 -> 0 | L46: ='Ilo Hilton'!AE26 -> 0 | M46: ='Ilo Hilton'!AN26 -> 0 | O46: MAI | P46: ='Ubiratan-Desmob'!H23 -> 0 | Q46: =SUM(5000-P46) -> 5000 | R46: ='Ubiratan-Desmob'!U24 -> 0 | S46: ='Ubiratan-Desmob'!AE24 -> 0 | T46: ='Ubiratan-Desmob'!AN24 -> 0 | V46: MAI | W46: ='Ilo Hilton-Desmob'!H23 -> 0 | X46: =SUM(5000-W46) -> 5000 | Y46: ='Ilo Hilton-Desmob'!U24 -> 0 | Z46: ='Ilo Hilton-Desmob'!AE24 -> 0 | AA46: ='Ilo Hilton-Desmob'!AN24 -> 0
A47: JUN | B47: ='Tiago Gonçalves - Desmob.'!H27 -> 0 | C47: =SUM(5000-B47) -> 5000 | D47: ='Tiago Gonçalves - Desmob.'!U28 -> 0 | E47: ='Tiago Gonçalves - Desmob.'!AE28 -> 0 | F47: ='Tiago Gonçalves - Desmob.'!AN28 -> 0 | H47: JUN | I47: ='Ilo Hilton'!H29 -> 0 | J47: =SUM(5000-I47) -> 5000 | K47: ='Ilo Hilton'!U30 -> 0 | L47: ='Ilo Hilton'!AE30 -> 0 | M47: ='Ilo Hilton'!AN30 -> 0 | O47: JUN | P47: ='Ubiratan-Desmob'!H27 -> 0 | Q47: =SUM(5000-P47) -> 5000 | R47: ='Ubiratan-Desmob'!U28 -> 0 | S47: ='Ubiratan-Desmob'!AE28 -> 0 | T47: ='Ubiratan-Desmob'!AN28 -> 0 | V47: JUN | W47: ='Ilo Hilton-Desmob'!H27 -> 0 | X47: =SUM(5000-W47) -> 5000 | Y47: ='Ilo Hilton-Desmob'!U28 -> 0 | Z47: ='Ilo Hilton-Desmob'!AE28 -> 0 | AA47: ='Ilo Hilton-Desmob'!AN28 -> 0
...

Sheet Ademir
A2: Veiculo | B2: Toro | D2: Placa: | E2: TEBIJ42 | H2: km | I2: 3000
A3: Substituição (data) | B3: 46123 | D3: Placa: | E3: PVR4B99 | H3: Modelo | I3: S10
A4: Contrato de Locação | B4: 7553 | D4: Rastreador | E4: Unidas - 3s | H4: Data Mob | I4: 46116
A7: REGISTRO DE KM | J7: ABASTECIMENTO | Y7: LAVA_RAPIDO | AH7: BORRACHARIA
B9: Fevereiro | J9: Fevereiro | Y9: Fevereiro | AH9: Fevereiro
A10: KM (Rodados) | B10: 1ª Leitura | C10: 2ª Leitura | D10: 3ª Leitura | E10: 4ª Leitura | F10: 15 dias Rodados | G10: 30 dias Rodados | H10: Total Mensal | J10: DATA | Y10: DATA | AH10: DATA
F11: =SUM(C11-B11) -> 0 | G11: =SUM(E11-D11) -> 0 | H11: =SUM(F11:G11) -> 0 | J11: VALOR | Y11: VALOR | AH11: VALOR
T12: TOTAL | U12: =SUM(K11:U11) -> 0 | AD12: TOTAL | AE12: =SUM(Z11:AE11) -> 0 | AM12: TOTAL | AN12: =SUM(AI11:AN11) -> 0
B13: Março | J13: Março | Y13: =J13 -> Março | AH13: =Y13 -> Março
A14: KM (Rodados) | B14: 1ª Leitura | C14: 2ª Leitura | D14: 3ª Leitura | E14: 4ª Leitura | F14: 15 dias Rodados | G14: 30 dias Rodados | H14: Total Mensal | J14: DATA | Y14: DATA | AH14: DATA
F15: =SUM(C15-B15) -> 0 | G15: =SUM(E15-D15) -> 0 | H15: =SUM(F15:G15) -> 0 | J15: VALOR | Y15: VALOR | AH15: VALOR
T16: TOTAL | U16: =SUM(K15:U15) -> 0 | AD16: TOTAL | AE16: =SUM(Z15:AE15) -> 0 | AM16: TOTAL | AN16: =SUM(AI15:AN15) -> 0
A17: TEBIJ42 | B17: Abril | J17: Abril | Y17: =J17 -> Abril | AH17: =Y17 -> Abril
A18: KM (Rodados) | B18: 1ª Leitura | C18: 2ª Leitura | D18: 3ª Leitura | E18: 4ª Leitura | F18: 15 dias Rodados | G18: 30 dias Rodados | H18: Total Mensal | J18: DATA | K18: 46121 | L18: 46123 | Y18: DATA | AH18: DATA
B19: 32598 | C19: 32944 | F19: =SUM(C19-B19) -> 346 | G19: =SUM(E19-D19) -> 0 | H19: =SUM(F19:G19) -> 346 | J19: VALOR | K19: 342.64 | L19: 61.74 | Y19: VALOR | AH19: VALOR
T20: TOTAL | U20: =SUM(K19:U19) -> 404.38 | AD20: TOTAL | AE20: =SUM(Z19:AE19) -> 0 | AM20: TOTAL | AN20: =SUM(AI19:AN19) -> 0
A21: PVR4B99 | B21: Abril | J21: Abril | Y21: =J21 -> Abril | AH21: =Y21 -> Abril
A22: KM (Rodados) | B22: 1ª Leitura | C22: 2ª Leitura | D22: 3ª Leitura | E22: 4ª Leitura | F22: 15 dias Rodados | G22: 30 dias Rodados | H22: Total Mensal | J22: DATA | Y22: DATA | AH22: DATA
B23: 48016 | E23: 49352 | F23: =SUM(C23-B23) -> -48016 | G23: =SUM(E23-D23) -> 49352 | H23: =SUM(F23:G23) -> 1336 | J23: VALOR | Y23: VALOR | AH23: VALOR
T24: TOTAL | U24: =SUM(K23:U23) -> 0 | AD24: TOTAL | AE24: =SUM(Z23:AE23) -> 0 | AM24: TOTAL | AN24: =SUM(AI23:AN23) -> 0
B25: Maio | J25: Maio | Y25: =J25 -> Maio | AH25: =Y25 -> Maio
A26: KM (Rodados) | B26: 1ª Leitura | C26: 2ª Leitura | D26: 3ª Leitura | E26: 4ª Leitura | F26: 15 dias Rodados | G26: 30 dias Rodados | H26: Total Mensal | J26: DATA | Y26: DATA | AH26: DATA
B27: 49352 | E27: 51672 | F27: =SUM(C27-B27) -> -49352 | G27: =SUM(E27-D27) -> 51672 | H27: =SUM(F27:G27) -> 2320 | J27: VALOR | Y27: VALOR | AH27: VALOR
T28: TOTAL | U28: =SUM(K27:U27) -> 0 | AD28: TOTAL | AE28: =SUM(Z27:AE27) -> 0 | AM28: TOTAL | AN28: =SUM(AI27:AN27) -> 0
B29: Junho | J29: Junho | Y29: =J29 -> Junho | AH29: =Y29 -> Junho
A30: KM (Rodados) | B30: 1ª Leitura | C30: 2ª Leitura | D30: 3ª Leitura | E30: 4ª Leitura | F30: 15 dias Rodados | G30: 30 dias Rodados | H30: Total Mensal | J30: DATA | Y30: DATA | AH30: DATA
F31: =SUM(C31-B31) -> 0 | G31: =SUM(E31-D31) -> 0 | H31: =SUM(F31:G31) -> 0 | J31: VALOR | Y31: VALOR | AH31: VALOR
T32: TOTAL | U32: =SUM(K31:U31) -> 0 | AD32: TOTAL | AE32: =SUM(Z31:AE31) -> 0 | AM32: TOTAL | AN32: =SUM(AI31:AN31) -> 0
B33: Julho | J33: Julho | Y33: =J33 -> Julho | AH33: =Y33 -> Julho
A34: KM (Rodados) | B34: 1ª Leitura | C34: 2ª Leitura | D34: 3ª Leitura | E34: 4ª Leitura | F34: 15 dias Rodados | G34: 30 dias Rodados | H34: Total Mensal | J34: DATA | Y34: DATA | AH34: DATA
F35: =SUM(C35-B35) -> 0 | G35: =SUM(E35-D35) -> 0 | H35: =SUM(F35:G35) -> 0 | J35: VALOR | Y35: VALOR | AH35: VALOR
T36: TOTAL | U36: =SUM(K35:U35) -> 0 | AD36: TOTAL | AE36: =SUM(Z35:AE35) -> 0 | AM36: TOTAL | AN36: =SUM(AI35:AN35) -> 0
B37: Agosto | J37: Agosto | Y37: =J37 -> Agosto | AH37: =Y37 -> Agosto
A38: KM (Rodados) | B38: 1ª Leitura | C38: 2ª Leitura | D38: 3ª Leitura | E38: 4ª Leitura | F38: 15 dias Rodados | G38: 30 dias Rodados | H38: Total Mensal | J38: DATA | Y38: DATA | AH38: DATA
F39: =SUM(C39-B39) -> 0 | G39: =SUM(E39-D39) -> 0 | H39: =SUM(F39:G39) -> 0 | J39: VALOR | Y39: VALOR | AH39: VALOR
T40: TOTAL | U40: =SUM(K39:U39) -> 0 | AD40: TOTAL | AE40: =SUM(Z39:AE39) -> 0 | AM40: TOTAL | AN40: =SUM(AI39:AN39) -> 0
B41: Setembro | J41: Setembro | Y41: =J41 -> Setembro | AH41: =Y41 -> Setembro
A42: KM (Rodados) | B42: 1ª Leitura | C42: 2ª Leitura | D42: 3ª Leitura | E42: 4ª Leitura | F42: 15 dias Rodados | G42: 30 dias Rodados | H42: Total Mensal | J42: DATA | Y42: DATA | AH42: DATA
F43: =SUM(C43-B43) -> 0 | G43: =SUM(E43-D43) -> 0 | H43: =SUM(F43:G43) -> 0 | J43: VALOR | Y43: VALOR | AH43: VALOR
T44: TOTAL | U44: =SUM(K43:U43) -> 0 | AD44: TOTAL | AE44: =SUM(Z43:AE43) -> 0 | AM44: TOTAL | AN44: =SUM(AI43:AN43) -> 0
...

Sheet Chris
A2: Veiculo | B2: Argo | D2: Placa: | E2: TDQ6I22 | H2: KM | I2: 3000
A3: Substituição (data) | D3: Placa: | H3: Modelo
A4: Contrato de Locação | B4: 2484 | D4: Rastreador | E4: 45 | H4: Data Mob. | I4: 45955
A7: REGISTRO DE KM | J7: ABASTECIMENTO | Y7: LAVA_RAPIDO | AH7: BORRACHARIA
B9: Fevereiro | J9: Fevereiro | Y9: Fevereiro | AH9: Fevereiro
A10: KM (Rodados) | B10: 1ª Leitura | C10: 2ª Leitura | D10: 3ª Leitura | E10: 4ª Leitura | F10: 15 dias Rodados | G10: 30 dias Rodados | H10: Total Mensal | J10: DATA | Y10: DATA | AH10: DATA
F11: =SUM(C11-B11) -> 0 | G11: =SUM(E11-D11) -> 0 | H11: =SUM(F11:G11) -> 0 | J11: VALOR | Y11: VALOR | AH11: VALOR
T12: TOTAL | U12: =SUM(K11:U11) -> 0 | AD12: TOTAL | AE12: =SUM(Z11:AE11) -> 0 | AM12: TOTAL | AN12: =SUM(AI11:AN11) -> 0
B13: Março | J13: Março | Y13: =J13 -> Março | AH13: =Y13 -> Março
A14: KM (Rodados) | B14: 1ª Leitura | C14: 2ª Leitura | D14: 3ª Leitura | E14: 4ª Leitura | F14: 15 dias Rodados | G14: 30 dias Rodados | H14: Total Mensal | J14: DATA | Y14: DATA | AH14: DATA
F15: =SUM(C15-B15) -> 0 | G15: =SUM(E15-D15) -> 0 | H15: =SUM(F15:G15) -> 0 | J15: VALOR | Y15: VALOR | AH15: VALOR
T16: TOTAL | U16: =SUM(K15:U15) -> 0 | AD16: TOTAL | AE16: =SUM(Z15:AE15) -> 0 | AM16: TOTAL | AN16: =SUM(AI15:AN15) -> 0
B17: Abril | J17: Abril | Y17: =J17 -> Abril | AH17: =Y17 -> Abril
A18: KM (Rodados) | B18: 1ª Leitura | C18: 2ª Leitura | D18: 3ª Leitura | E18: 4ª Leitura | F18: 15 dias Rodados | G18: 30 dias Rodados | H18: Total Mensal | J18: DATA | Y18: DATA | AH18: DATA
F19: =SUM(C19-B19) -> 0 | G19: =SUM(E19-D19) -> 0 | H19: =SUM(F19:G19) -> 0 | J19: VALOR | Y19: VALOR | AH19: VALOR
T20: TOTAL | U20: =SUM(K19:U19) -> 0 | AD20: TOTAL | AE20: =SUM(Z19:AE19) -> 0 | AM20: TOTAL | AN20: =SUM(AI19:AN19) -> 0
B21: Maio | J21: Maio | Y21: =J21 -> Maio | AH21: =Y21 -> Maio
A22: KM (Rodados) | B22: 1ª Leitura | C22: 2ª Leitura | D22: 3ª Leitura | E22: 4ª Leitura | F22: 15 dias Rodados | G22: 30 dias Rodados | H22: Total Mensal | J22: DATA | Y22: DATA | AH22: DATA
F23: =SUM(C23-B23) -> 0 | G23: =SUM(E23-D23) -> 0 | H23: =SUM(F23:G23) -> 0 | J23: VALOR | Y23: VALOR | AH23: VALOR
T24: TOTAL | U24: =SUM(K23:U23) -> 0 | AD24: TOTAL | AE24: =SUM(Z23:AE23) -> 0 | AM24: TOTAL | AN24: =SUM(AI23:AN23) -> 0
B25: Junho | J25: Junho | Y25: =J25 -> Junho | AH25: =Y25 -> Junho
A26: KM (Rodados) | B26: 1ª Leitura | C26: 2ª Leitura | D26: 3ª Leitura | E26: 4ª Leitura | F26: 15 dias Rodados | G26: 30 dias Rodados | H26: Total Mensal | J26: DATA | Y26: DATA | AH26: DATA
F27: =SUM(C27-B27) -> 0 | G27: =SUM(E27-D27) -> 0 | H27: =SUM(F27:G27) -> 0 | J27: VALOR | Y27: VALOR | AH27: VALOR
T28: TOTAL | U28: =SUM(K27:U27) -> 0 | AD28: TOTAL | AE28: =SUM(Z27:AE27) -> 0 | AM28: TOTAL | AN28: =SUM(AI27:AN27) -> 0
B29: Julho | J29: Julho | Y29: =J29 -> Julho | AH29: =Y29 -> Julho
A30: KM (Rodados) | B30: 1ª Leitura | C30: 2ª Leitura | D30: 3ª Leitura | E30: 4ª Leitura | F30: 15 dias Rodados | G30: 30 dias Rodados | H30: Total Mensal | J30: DATA | Y30: DATA | AH30: DATA
F31: =SUM(C31-B31) -> 0 | G31: =SUM(E31-D31) -> 0 | H31: =SUM(F31:G31) -> 0 | J31: VALOR | Y31: VALOR | AH31: VALOR
T32: TOTAL | U32: =SUM(K31:U31) -> 0 | AD32: TOTAL | AE32: =SUM(Z31:AE31) -> 0 | AM32: TOTAL | AN32: =SUM(AI31:AN31) -> 0
B33: Agosto | J33: Agosto | Y33: =J33 -> Agosto | AH33: =Y33 -> Agosto
A34: KM (Rodados) | B34: 1ª Leitura | C34: 2ª Leitura | D34: 3ª Leitura | E34: 4ª Leitura | F34: 15 dias Rodados | G34: 30 dias Rodados | H34: Total Mensal | J34: DATA | Y34: DATA | AH34: DATA
F35: =SUM(C35-B35) -> 0 | G35: =SUM(E35-D35) -> 0 | H35: =SUM(F35:G35) -> 0 | J35: VALOR | Y35: VALOR | AH35: VALOR
T36: TOTAL | U36: =SUM(K35:U35) -> 0 | AD36: TOTAL | AE36: =SUM(Z35:AE35) -> 0 | AM36: TOTAL | AN36: =SUM(AI35:AN35) -> 0
B37: Setembro | J37: Setembro | Y37: =J37 -> Setembro | AH37: =Y37 -> Setembro
A38: KM (Rodados) | B38: 1ª Leitura | C38: 2ª Leitura | D38: 3ª Leitura | E38: 4ª Leitura | F38: 15 dias Rodados | G38: 30 dias Rodados | H38: Total Mensal | J38: DATA | Y38: DATA | AH38: DATA
F39: =SUM(C39-B39) -> 0 | G39: =SUM(E39-D39) -> 0 | H39: =SUM(F39:G39) -> 0 | J39: VALOR | Y39: VALOR | AH39: VALOR
T40: TOTAL | U40: =SUM(K39:U39) -> 0 | AD40: TOTAL | AE40: =SUM(Z39:AE39) -> 0 | AM40: TOTAL | AN40: =SUM(AI39:AN39) -> 0
B41: Outubro | J41: Outubro | Y41: =J41 -> Outubro | AH41: =Y41 -> Outubro
A42: KM (Rodados) | B42: 1ª Leitura | C42: 2ª Leitura | D42: 3ª Leitura | E42: 4ª Leitura | F42: 15 dias Rodados | G42: 30 dias Rodados | H42: Total Mensal | J42: DATA | K42: 45958 | L42: 45960 | Y42: DATA | AH42: DATA
D43: 18091 | E43: 18799 | F43: =SUM(C43-B43) -> 0 | G43: =SUM(E43-D43) -> 708 | H43: =SUM(F43:G43) -> 708 | J43: VALOR | K43: 201.9 | L43: 175.88 | Y43: VALOR | AH43: VALOR
T44: TOTAL | U44: =SUM(K43:U43) -> 377.78 | AD44: TOTAL | AE44: =SUM(Z43:AE43) -> 0 | AM44: TOTAL | AN44: =SUM(AI43:AN43) -> 0
...

Sheet Eduardo
A2: Veiculo | B2: Polo | D2: Placa: | E2: EWF6F13 | H2: km | I2: 3000
A3: Substituição (data) | D3: Placa: | H3: Modelo
A4: Contrato de Locação | B4: 2484 | D4: Rastreador | E4: Unidas | H4: Data Mob. | I4: 46112
A7: REGISTRO DE KM | J7: ABASTECIMENTO | Y7: LAVA_RAPIDO | AH7: BORRACHARIA
B9: Fevereiro | J9: Fevereiro | Y9: Fevereiro | AH9: Fevereiro
A10: KM (Rodados) | B10: 1ª Leitura | C10: 2ª Leitura | D10: 3ª Leitura | E10: 4ª Leitura | F10: 15 dias Rodados | G10: 30 dias Rodados | H10: Total Mensal | J10: DATA | Y10: DATA | AH10: DATA
F11: =SUM(C11-B11) -> 0 | G11: =SUM(E11-D11) -> 0 | H11: =SUM(F11:G11) -> 0 | J11: VALOR | Y11: VALOR | AH11: VALOR
T12: TOTAL | U12: =SUM(K11:U11) -> 0 | AD12: TOTAL | AE12: =SUM(Z11:AE11) -> 0 | AM12: TOTAL | AN12: =SUM(AI11:AN11) -> 0
B13: Março | J13: Março | Y13: =J13 -> Março | AH13: =Y13 -> Março
A14: KM (Rodados) | B14: 1ª Leitura | C14: 2ª Leitura | D14: 3ª Leitura | E14: 4ª Leitura | F14: 15 dias Rodados | G14: 30 dias Rodados | H14: Total Mensal | J14: DATA | Y14: DATA | AH14: DATA
F15: =SUM(C15-B15) -> 0 | G15: =SUM(E15-D15) -> 0 | H15: =SUM(F15:G15) -> 0 | J15: VALOR | Y15: VALOR | AH15: VALOR
T16: TOTAL | U16: =SUM(K15:U15) -> 0 | AD16: TOTAL | AE16: =SUM(Z15:AE15) -> 0 | AM16: TOTAL | AN16: =SUM(AI15:AN15) -> 0
B17: Março/Abril | J17: Abril | Y17: =J17 -> Abril | AH17: =Y17 -> Abril
A18: KM (Rodados) | B18: 1ª Leitura | C18: 2ª Leitura | D18: 3ª Leitura | E18: 4ª Leitura | F18: 15 dias Rodados | G18: 30 dias Rodados | H18: Total Mensal | J18: DATA | K18: 46114 | Y18: DATA | AH18: DATA
